## Original File URL: https://github.com/arita37/mlmodels_store/blob/master/log_json/log_json.py


### Error 1, [Traceback at line 48](https://github.com/arita37/mlmodels_store/blob/master/log_json/log_json.py#L48)<br />48..Traceback (most recent call last):
<br />  File "/opt/hostedtoolcache/Python/3.6.10/x64/bin/ml_models", line 11, in <module>
<br />    load_entry_point('mlmodels', 'console_scripts', 'ml_models')()
<br />  File "https://github.com/arita37/mlmodels/tree/2675f1e090030e6958e45c46c6313291532e6ed8/mlmodels/models.py", line 530, in main
<br />    fit_cli(arg)
<br />  File "https://github.com/arita37/mlmodels/tree/2675f1e090030e6958e45c46c6313291532e6ed8/mlmodels/models.py", line 414, in fit_cli
<br />    model_uri = model_p['model_uri']
<br />KeyError: 'model_uri'



### Error 2, [Traceback at line 67](https://github.com/arita37/mlmodels_store/blob/master/log_json/log_json.py#L67)<br />67..Traceback (most recent call last):
<br />  File "/opt/hostedtoolcache/Python/3.6.10/x64/bin/ml_models", line 11, in <module>
<br />    load_entry_point('mlmodels', 'console_scripts', 'ml_models')()
<br />  File "https://github.com/arita37/mlmodels/tree/2675f1e090030e6958e45c46c6313291532e6ed8/mlmodels/models.py", line 530, in main
<br />    fit_cli(arg)
<br />  File "https://github.com/arita37/mlmodels/tree/2675f1e090030e6958e45c46c6313291532e6ed8/mlmodels/models.py", line 413, in fit_cli
<br />    model_p, data_p, compute_p, out_p = config_get_pars(config_file, arg.config_mode)
<br />  File "https://github.com/arita37/mlmodels/tree/2675f1e090030e6958e45c46c6313291532e6ed8/mlmodels/models.py", line 299, in config_get_pars
<br />    out_p     = path_norm_dict( js.get("out_pars") )
<br />  File "https://github.com/arita37/mlmodels/tree/2675f1e090030e6958e45c46c6313291532e6ed8/mlmodels/util.py", line 201, in path_norm_dict
<br />    for k,v in ddict.items():
<br />AttributeError: 'NoneType' object has no attribute 'items'



### Error 3, [Traceback at line 95](https://github.com/arita37/mlmodels_store/blob/master/log_json/log_json.py#L95)<br />95..Traceback (most recent call last):
<br />  File "/opt/hostedtoolcache/Python/3.6.10/x64/bin/ml_models", line 11, in <module>
<br />    load_entry_point('mlmodels', 'console_scripts', 'ml_models')()
<br />  File "https://github.com/arita37/mlmodels/tree/2675f1e090030e6958e45c46c6313291532e6ed8/mlmodels/models.py", line 530, in main
<br />    fit_cli(arg)
<br />  File "https://github.com/arita37/mlmodels/tree/2675f1e090030e6958e45c46c6313291532e6ed8/mlmodels/models.py", line 414, in fit_cli
<br />    model_uri = model_p['model_uri']
<br />KeyError: 'model_uri'



### Error 4, [Traceback at line 114](https://github.com/arita37/mlmodels_store/blob/master/log_json/log_json.py#L114)<br />114..Traceback (most recent call last):
<br />  File "/opt/hostedtoolcache/Python/3.6.10/x64/bin/ml_models", line 11, in <module>
<br />    load_entry_point('mlmodels', 'console_scripts', 'ml_models')()
<br />  File "https://github.com/arita37/mlmodels/tree/2675f1e090030e6958e45c46c6313291532e6ed8/mlmodels/models.py", line 530, in main
<br />    fit_cli(arg)
<br />  File "https://github.com/arita37/mlmodels/tree/2675f1e090030e6958e45c46c6313291532e6ed8/mlmodels/models.py", line 413, in fit_cli
<br />    model_p, data_p, compute_p, out_p = config_get_pars(config_file, arg.config_mode)
<br />  File "https://github.com/arita37/mlmodels/tree/2675f1e090030e6958e45c46c6313291532e6ed8/mlmodels/models.py", line 299, in config_get_pars
<br />    out_p     = path_norm_dict( js.get("out_pars") )
<br />  File "https://github.com/arita37/mlmodels/tree/2675f1e090030e6958e45c46c6313291532e6ed8/mlmodels/util.py", line 201, in path_norm_dict
<br />    for k,v in ddict.items():
<br />AttributeError: 'NoneType' object has no attribute 'items'



### Error 5, [Traceback at line 142](https://github.com/arita37/mlmodels_store/blob/master/log_json/log_json.py#L142)<br />142..Traceback (most recent call last):
<br />  File "/opt/hostedtoolcache/Python/3.6.10/x64/bin/ml_models", line 11, in <module>
<br />    load_entry_point('mlmodels', 'console_scripts', 'ml_models')()
<br />  File "https://github.com/arita37/mlmodels/tree/2675f1e090030e6958e45c46c6313291532e6ed8/mlmodels/models.py", line 530, in main
<br />    fit_cli(arg)
<br />  File "https://github.com/arita37/mlmodels/tree/2675f1e090030e6958e45c46c6313291532e6ed8/mlmodels/models.py", line 414, in fit_cli
<br />    model_uri = model_p['model_uri']
<br />KeyError: 'model_uri'



### Error 6, [Traceback at line 166](https://github.com/arita37/mlmodels_store/blob/master/log_json/log_json.py#L166)<br />166..Traceback (most recent call last):
<br />  File "/opt/hostedtoolcache/Python/3.6.10/x64/bin/ml_models", line 11, in <module>
<br />    load_entry_point('mlmodels', 'console_scripts', 'ml_models')()
<br />  File "https://github.com/arita37/mlmodels/tree/2675f1e090030e6958e45c46c6313291532e6ed8/mlmodels/models.py", line 530, in main
<br />    fit_cli(arg)
<br />  File "https://github.com/arita37/mlmodels/tree/2675f1e090030e6958e45c46c6313291532e6ed8/mlmodels/models.py", line 414, in fit_cli
<br />    model_uri = model_p['model_uri']
<br />KeyError: 'model_uri'



### Error 7, [Traceback at line 190](https://github.com/arita37/mlmodels_store/blob/master/log_json/log_json.py#L190)<br />190..Traceback (most recent call last):
<br />  File "/opt/hostedtoolcache/Python/3.6.10/x64/bin/ml_models", line 11, in <module>
<br />    load_entry_point('mlmodels', 'console_scripts', 'ml_models')()
<br />  File "https://github.com/arita37/mlmodels/tree/2675f1e090030e6958e45c46c6313291532e6ed8/mlmodels/models.py", line 530, in main
<br />    fit_cli(arg)
<br />  File "https://github.com/arita37/mlmodels/tree/2675f1e090030e6958e45c46c6313291532e6ed8/mlmodels/models.py", line 414, in fit_cli
<br />    model_uri = model_p['model_uri']
<br />KeyError: 'model_uri'



### Error 8, [Traceback at line 214](https://github.com/arita37/mlmodels_store/blob/master/log_json/log_json.py#L214)<br />214..Traceback (most recent call last):
<br />  File "/opt/hostedtoolcache/Python/3.6.10/x64/bin/ml_models", line 11, in <module>
<br />    load_entry_point('mlmodels', 'console_scripts', 'ml_models')()
<br />  File "https://github.com/arita37/mlmodels/tree/2675f1e090030e6958e45c46c6313291532e6ed8/mlmodels/models.py", line 530, in main
<br />    fit_cli(arg)
<br />  File "https://github.com/arita37/mlmodels/tree/2675f1e090030e6958e45c46c6313291532e6ed8/mlmodels/models.py", line 414, in fit_cli
<br />    model_uri = model_p['model_uri']
<br />KeyError: 'model_uri'



### Error 9, [Traceback at line 233](https://github.com/arita37/mlmodels_store/blob/master/log_json/log_json.py#L233)<br />233..Traceback (most recent call last):
<br />  File "/opt/hostedtoolcache/Python/3.6.10/x64/bin/ml_models", line 11, in <module>
<br />    load_entry_point('mlmodels', 'console_scripts', 'ml_models')()
<br />  File "https://github.com/arita37/mlmodels/tree/2675f1e090030e6958e45c46c6313291532e6ed8/mlmodels/models.py", line 530, in main
<br />    fit_cli(arg)
<br />  File "https://github.com/arita37/mlmodels/tree/2675f1e090030e6958e45c46c6313291532e6ed8/mlmodels/models.py", line 413, in fit_cli
<br />    model_p, data_p, compute_p, out_p = config_get_pars(config_file, arg.config_mode)
<br />  File "https://github.com/arita37/mlmodels/tree/2675f1e090030e6958e45c46c6313291532e6ed8/mlmodels/models.py", line 297, in config_get_pars
<br />    data_p    = path_norm_dict( js.get("data_pars") )
<br />  File "https://github.com/arita37/mlmodels/tree/2675f1e090030e6958e45c46c6313291532e6ed8/mlmodels/util.py", line 201, in path_norm_dict
<br />    for k,v in ddict.items():
<br />AttributeError: 'NoneType' object has no attribute 'items'



### Error 10, [Traceback at line 261](https://github.com/arita37/mlmodels_store/blob/master/log_json/log_json.py#L261)<br />261..Traceback (most recent call last):
<br />  File "/opt/hostedtoolcache/Python/3.6.10/x64/bin/ml_models", line 11, in <module>
<br />    load_entry_point('mlmodels', 'console_scripts', 'ml_models')()
<br />  File "https://github.com/arita37/mlmodels/tree/2675f1e090030e6958e45c46c6313291532e6ed8/mlmodels/models.py", line 530, in main
<br />    fit_cli(arg)
<br />  File "https://github.com/arita37/mlmodels/tree/2675f1e090030e6958e45c46c6313291532e6ed8/mlmodels/models.py", line 415, in fit_cli
<br />    path      = out_p['path']
<br />KeyError: 'path'



### Error 11, [Traceback at line 285](https://github.com/arita37/mlmodels_store/blob/master/log_json/log_json.py#L285)<br />285..Traceback (most recent call last):
<br />  File "/opt/hostedtoolcache/Python/3.6.10/x64/bin/ml_models", line 11, in <module>
<br />    load_entry_point('mlmodels', 'console_scripts', 'ml_models')()
<br />  File "https://github.com/arita37/mlmodels/tree/2675f1e090030e6958e45c46c6313291532e6ed8/mlmodels/models.py", line 530, in main
<br />    fit_cli(arg)
<br />  File "https://github.com/arita37/mlmodels/tree/2675f1e090030e6958e45c46c6313291532e6ed8/mlmodels/models.py", line 414, in fit_cli
<br />    model_uri = model_p['model_uri']
<br />KeyError: 'model_uri'



### Error 12, [Traceback at line 309](https://github.com/arita37/mlmodels_store/blob/master/log_json/log_json.py#L309)<br />309..Traceback (most recent call last):
<br />  File "/opt/hostedtoolcache/Python/3.6.10/x64/bin/ml_models", line 11, in <module>
<br />    load_entry_point('mlmodels', 'console_scripts', 'ml_models')()
<br />  File "https://github.com/arita37/mlmodels/tree/2675f1e090030e6958e45c46c6313291532e6ed8/mlmodels/models.py", line 530, in main
<br />    fit_cli(arg)
<br />  File "https://github.com/arita37/mlmodels/tree/2675f1e090030e6958e45c46c6313291532e6ed8/mlmodels/models.py", line 414, in fit_cli
<br />    model_uri = model_p['model_uri']
<br />KeyError: 'model_uri'



### Error 13, [Traceback at line 333](https://github.com/arita37/mlmodels_store/blob/master/log_json/log_json.py#L333)<br />333..Traceback (most recent call last):
<br />  File "/opt/hostedtoolcache/Python/3.6.10/x64/bin/ml_models", line 11, in <module>
<br />    load_entry_point('mlmodels', 'console_scripts', 'ml_models')()
<br />  File "https://github.com/arita37/mlmodels/tree/2675f1e090030e6958e45c46c6313291532e6ed8/mlmodels/models.py", line 530, in main
<br />    fit_cli(arg)
<br />  File "https://github.com/arita37/mlmodels/tree/2675f1e090030e6958e45c46c6313291532e6ed8/mlmodels/models.py", line 414, in fit_cli
<br />    model_uri = model_p['model_uri']
<br />KeyError: 'model_uri'



### Error 14, [Traceback at line 352](https://github.com/arita37/mlmodels_store/blob/master/log_json/log_json.py#L352)<br />352..Traceback (most recent call last):
<br />  File "/opt/hostedtoolcache/Python/3.6.10/x64/bin/ml_models", line 11, in <module>
<br />    load_entry_point('mlmodels', 'console_scripts', 'ml_models')()
<br />  File "https://github.com/arita37/mlmodels/tree/2675f1e090030e6958e45c46c6313291532e6ed8/mlmodels/models.py", line 530, in main
<br />    fit_cli(arg)
<br />  File "https://github.com/arita37/mlmodels/tree/2675f1e090030e6958e45c46c6313291532e6ed8/mlmodels/models.py", line 413, in fit_cli
<br />    model_p, data_p, compute_p, out_p = config_get_pars(config_file, arg.config_mode)
<br />  File "https://github.com/arita37/mlmodels/tree/2675f1e090030e6958e45c46c6313291532e6ed8/mlmodels/models.py", line 299, in config_get_pars
<br />    out_p     = path_norm_dict( js.get("out_pars") )
<br />  File "https://github.com/arita37/mlmodels/tree/2675f1e090030e6958e45c46c6313291532e6ed8/mlmodels/util.py", line 201, in path_norm_dict
<br />    for k,v in ddict.items():
<br />AttributeError: 'NoneType' object has no attribute 'items'



### Error 15, [Traceback at line 380](https://github.com/arita37/mlmodels_store/blob/master/log_json/log_json.py#L380)<br />380..Traceback (most recent call last):
<br />  File "/opt/hostedtoolcache/Python/3.6.10/x64/bin/ml_models", line 11, in <module>
<br />    load_entry_point('mlmodels', 'console_scripts', 'ml_models')()
<br />  File "https://github.com/arita37/mlmodels/tree/2675f1e090030e6958e45c46c6313291532e6ed8/mlmodels/models.py", line 530, in main
<br />    fit_cli(arg)
<br />  File "https://github.com/arita37/mlmodels/tree/2675f1e090030e6958e45c46c6313291532e6ed8/mlmodels/models.py", line 414, in fit_cli
<br />    model_uri = model_p['model_uri']
<br />KeyError: 'model_uri'



### Error 16, [Traceback at line 399](https://github.com/arita37/mlmodels_store/blob/master/log_json/log_json.py#L399)<br />399..Traceback (most recent call last):
<br />  File "/opt/hostedtoolcache/Python/3.6.10/x64/bin/ml_models", line 11, in <module>
<br />    load_entry_point('mlmodels', 'console_scripts', 'ml_models')()
<br />  File "https://github.com/arita37/mlmodels/tree/2675f1e090030e6958e45c46c6313291532e6ed8/mlmodels/models.py", line 530, in main
<br />    fit_cli(arg)
<br />  File "https://github.com/arita37/mlmodels/tree/2675f1e090030e6958e45c46c6313291532e6ed8/mlmodels/models.py", line 413, in fit_cli
<br />    model_p, data_p, compute_p, out_p = config_get_pars(config_file, arg.config_mode)
<br />  File "https://github.com/arita37/mlmodels/tree/2675f1e090030e6958e45c46c6313291532e6ed8/mlmodels/models.py", line 299, in config_get_pars
<br />    out_p     = path_norm_dict( js.get("out_pars") )
<br />  File "https://github.com/arita37/mlmodels/tree/2675f1e090030e6958e45c46c6313291532e6ed8/mlmodels/util.py", line 201, in path_norm_dict
<br />    for k,v in ddict.items():
<br />AttributeError: 'NoneType' object has no attribute 'items'



### Error 17, [Traceback at line 427](https://github.com/arita37/mlmodels_store/blob/master/log_json/log_json.py#L427)<br />427..Traceback (most recent call last):
<br />  File "/opt/hostedtoolcache/Python/3.6.10/x64/bin/ml_models", line 11, in <module>
<br />    load_entry_point('mlmodels', 'console_scripts', 'ml_models')()
<br />  File "https://github.com/arita37/mlmodels/tree/2675f1e090030e6958e45c46c6313291532e6ed8/mlmodels/models.py", line 530, in main
<br />    fit_cli(arg)
<br />  File "https://github.com/arita37/mlmodels/tree/2675f1e090030e6958e45c46c6313291532e6ed8/mlmodels/models.py", line 415, in fit_cli
<br />    path      = out_p['path']
<br />KeyError: 'path'



### Error 18, [Traceback at line 446](https://github.com/arita37/mlmodels_store/blob/master/log_json/log_json.py#L446)<br />446..Traceback (most recent call last):
<br />  File "/opt/hostedtoolcache/Python/3.6.10/x64/bin/ml_models", line 11, in <module>
<br />    load_entry_point('mlmodels', 'console_scripts', 'ml_models')()
<br />  File "https://github.com/arita37/mlmodels/tree/2675f1e090030e6958e45c46c6313291532e6ed8/mlmodels/models.py", line 530, in main
<br />    fit_cli(arg)
<br />  File "https://github.com/arita37/mlmodels/tree/2675f1e090030e6958e45c46c6313291532e6ed8/mlmodels/models.py", line 415, in fit_cli
<br />    path      = out_p['path']
<br />KeyError: 'path'



### Error 19, [Traceback at line 465](https://github.com/arita37/mlmodels_store/blob/master/log_json/log_json.py#L465)<br />465..Traceback (most recent call last):
<br />  File "/opt/hostedtoolcache/Python/3.6.10/x64/bin/ml_models", line 11, in <module>
<br />    load_entry_point('mlmodels', 'console_scripts', 'ml_models')()
<br />  File "https://github.com/arita37/mlmodels/tree/2675f1e090030e6958e45c46c6313291532e6ed8/mlmodels/models.py", line 530, in main
<br />    fit_cli(arg)
<br />  File "https://github.com/arita37/mlmodels/tree/2675f1e090030e6958e45c46c6313291532e6ed8/mlmodels/models.py", line 415, in fit_cli
<br />    path      = out_p['path']
<br />KeyError: 'path'



### Error 20, [Traceback at line 486](https://github.com/arita37/mlmodels_store/blob/master/log_json/log_json.py#L486)<br />486..Traceback (most recent call last):
<br />  File "https://github.com/arita37/mlmodels/tree/2675f1e090030e6958e45c46c6313291532e6ed8/mlmodels/models.py", line 72, in module_load
<br />    module = import_module(f"mlmodels.{model_name}")
<br />  File "/opt/hostedtoolcache/Python/3.6.10/x64/lib/python3.6/importlib/__init__.py", line 126, in import_module
<br />    return _bootstrap._gcd_import(name[level:], package, level)
<br />  File "<frozen importlib._bootstrap>", line 994, in _gcd_import
<br />  File "<frozen importlib._bootstrap>", line 971, in _find_and_load
<br />  File "<frozen importlib._bootstrap>", line 955, in _find_and_load_unlocked
<br />  File "<frozen importlib._bootstrap>", line 665, in _load_unlocked
<br />  File "<frozen importlib._bootstrap_external>", line 674, in exec_module
<br />  File "<frozen importlib._bootstrap_external>", line 781, in get_code
<br />  File "<frozen importlib._bootstrap_external>", line 741, in source_to_code
<br />  File "<frozen importlib._bootstrap>", line 219, in _call_with_frames_removed
<br />  File "https://github.com/arita37/mlmodels/tree/2675f1e090030e6958e45c46c6313291532e6ed8/mlmodels/model_gluon/gluonts_model.py", line 152
<br />    if d ==  "single_dataframe" :
<br />                                ^
<br />SyntaxError: invalid syntax



### Error 21, [Traceback at line 506](https://github.com/arita37/mlmodels_store/blob/master/log_json/log_json.py#L506)<br />506..Traceback (most recent call last):
<br />  File "https://github.com/arita37/mlmodels/tree/2675f1e090030e6958e45c46c6313291532e6ed8/mlmodels/models.py", line 84, in module_load
<br />    model_name = str(Path(model_uri).parts[-2]) + "." + str(model_name)
<br />IndexError: tuple index out of range



### Error 22, [Traceback at line 513](https://github.com/arita37/mlmodels_store/blob/master/log_json/log_json.py#L513)<br />513..Traceback (most recent call last):
<br />  File "/opt/hostedtoolcache/Python/3.6.10/x64/bin/ml_models", line 11, in <module>
<br />    load_entry_point('mlmodels', 'console_scripts', 'ml_models')()
<br />  File "https://github.com/arita37/mlmodels/tree/2675f1e090030e6958e45c46c6313291532e6ed8/mlmodels/models.py", line 530, in main
<br />    fit_cli(arg)
<br />  File "https://github.com/arita37/mlmodels/tree/2675f1e090030e6958e45c46c6313291532e6ed8/mlmodels/models.py", line 420, in fit_cli
<br />    module = module_load(model_uri)  # '1_lstm.py
<br />  File "https://github.com/arita37/mlmodels/tree/2675f1e090030e6958e45c46c6313291532e6ed8/mlmodels/models.py", line 89, in module_load
<br />    raise NameError(f"Module {model_name} notfound, {e1}, {e2}")
<br />NameError: Module model_gluon notfound, invalid syntax (gluonts_model.py, line 152), tuple index out of range



### Error 23, [Traceback at line 536](https://github.com/arita37/mlmodels_store/blob/master/log_json/log_json.py#L536)<br />536..Traceback (most recent call last):
<br />  File "https://github.com/arita37/mlmodels/tree/2675f1e090030e6958e45c46c6313291532e6ed8/mlmodels/models.py", line 72, in module_load
<br />    module = import_module(f"mlmodels.{model_name}")
<br />  File "/opt/hostedtoolcache/Python/3.6.10/x64/lib/python3.6/importlib/__init__.py", line 126, in import_module
<br />    return _bootstrap._gcd_import(name[level:], package, level)
<br />  File "<frozen importlib._bootstrap>", line 994, in _gcd_import
<br />  File "<frozen importlib._bootstrap>", line 971, in _find_and_load
<br />  File "<frozen importlib._bootstrap>", line 955, in _find_and_load_unlocked
<br />  File "<frozen importlib._bootstrap>", line 665, in _load_unlocked
<br />  File "<frozen importlib._bootstrap_external>", line 674, in exec_module
<br />  File "<frozen importlib._bootstrap_external>", line 781, in get_code
<br />  File "<frozen importlib._bootstrap_external>", line 741, in source_to_code
<br />  File "<frozen importlib._bootstrap>", line 219, in _call_with_frames_removed
<br />  File "https://github.com/arita37/mlmodels/tree/2675f1e090030e6958e45c46c6313291532e6ed8/mlmodels/model_gluon/gluonts_model.py", line 152
<br />    if d ==  "single_dataframe" :
<br />                                ^
<br />SyntaxError: invalid syntax



### Error 24, [Traceback at line 556](https://github.com/arita37/mlmodels_store/blob/master/log_json/log_json.py#L556)<br />556..Traceback (most recent call last):
<br />  File "https://github.com/arita37/mlmodels/tree/2675f1e090030e6958e45c46c6313291532e6ed8/mlmodels/models.py", line 84, in module_load
<br />    model_name = str(Path(model_uri).parts[-2]) + "." + str(model_name)
<br />IndexError: tuple index out of range



### Error 25, [Traceback at line 563](https://github.com/arita37/mlmodels_store/blob/master/log_json/log_json.py#L563)<br />563..Traceback (most recent call last):
<br />  File "/opt/hostedtoolcache/Python/3.6.10/x64/bin/ml_models", line 11, in <module>
<br />    load_entry_point('mlmodels', 'console_scripts', 'ml_models')()
<br />  File "https://github.com/arita37/mlmodels/tree/2675f1e090030e6958e45c46c6313291532e6ed8/mlmodels/models.py", line 530, in main
<br />    fit_cli(arg)
<br />  File "https://github.com/arita37/mlmodels/tree/2675f1e090030e6958e45c46c6313291532e6ed8/mlmodels/models.py", line 420, in fit_cli
<br />    module = module_load(model_uri)  # '1_lstm.py
<br />  File "https://github.com/arita37/mlmodels/tree/2675f1e090030e6958e45c46c6313291532e6ed8/mlmodels/models.py", line 89, in module_load
<br />    raise NameError(f"Module {model_name} notfound, {e1}, {e2}")
<br />NameError: Module model_gluon notfound, invalid syntax (gluonts_model.py, line 152), tuple index out of range



### Error 26, [Traceback at line 586](https://github.com/arita37/mlmodels_store/blob/master/log_json/log_json.py#L586)<br />586..Traceback (most recent call last):
<br />  File "https://github.com/arita37/mlmodels/tree/2675f1e090030e6958e45c46c6313291532e6ed8/mlmodels/models.py", line 72, in module_load
<br />    module = import_module(f"mlmodels.{model_name}")
<br />  File "/opt/hostedtoolcache/Python/3.6.10/x64/lib/python3.6/importlib/__init__.py", line 126, in import_module
<br />    return _bootstrap._gcd_import(name[level:], package, level)
<br />  File "<frozen importlib._bootstrap>", line 994, in _gcd_import
<br />  File "<frozen importlib._bootstrap>", line 971, in _find_and_load
<br />  File "<frozen importlib._bootstrap>", line 955, in _find_and_load_unlocked
<br />  File "<frozen importlib._bootstrap>", line 665, in _load_unlocked
<br />  File "<frozen importlib._bootstrap_external>", line 674, in exec_module
<br />  File "<frozen importlib._bootstrap_external>", line 781, in get_code
<br />  File "<frozen importlib._bootstrap_external>", line 741, in source_to_code
<br />  File "<frozen importlib._bootstrap>", line 219, in _call_with_frames_removed
<br />  File "https://github.com/arita37/mlmodels/tree/2675f1e090030e6958e45c46c6313291532e6ed8/mlmodels/model_gluon/gluonts_model.py", line 152
<br />    if d ==  "single_dataframe" :
<br />                                ^
<br />SyntaxError: invalid syntax



### Error 27, [Traceback at line 606](https://github.com/arita37/mlmodels_store/blob/master/log_json/log_json.py#L606)<br />606..Traceback (most recent call last):
<br />  File "https://github.com/arita37/mlmodels/tree/2675f1e090030e6958e45c46c6313291532e6ed8/mlmodels/models.py", line 84, in module_load
<br />    model_name = str(Path(model_uri).parts[-2]) + "." + str(model_name)
<br />IndexError: tuple index out of range



### Error 28, [Traceback at line 613](https://github.com/arita37/mlmodels_store/blob/master/log_json/log_json.py#L613)<br />613..Traceback (most recent call last):
<br />  File "/opt/hostedtoolcache/Python/3.6.10/x64/bin/ml_models", line 11, in <module>
<br />    load_entry_point('mlmodels', 'console_scripts', 'ml_models')()
<br />  File "https://github.com/arita37/mlmodels/tree/2675f1e090030e6958e45c46c6313291532e6ed8/mlmodels/models.py", line 530, in main
<br />    fit_cli(arg)
<br />  File "https://github.com/arita37/mlmodels/tree/2675f1e090030e6958e45c46c6313291532e6ed8/mlmodels/models.py", line 420, in fit_cli
<br />    module = module_load(model_uri)  # '1_lstm.py
<br />  File "https://github.com/arita37/mlmodels/tree/2675f1e090030e6958e45c46c6313291532e6ed8/mlmodels/models.py", line 89, in module_load
<br />    raise NameError(f"Module {model_name} notfound, {e1}, {e2}")
<br />NameError: Module model_gluon notfound, invalid syntax (gluonts_model.py, line 152), tuple index out of range



### Error 29, [Traceback at line 636](https://github.com/arita37/mlmodels_store/blob/master/log_json/log_json.py#L636)<br />636..Traceback (most recent call last):
<br />  File "https://github.com/arita37/mlmodels/tree/2675f1e090030e6958e45c46c6313291532e6ed8/mlmodels/models.py", line 72, in module_load
<br />    module = import_module(f"mlmodels.{model_name}")
<br />  File "/opt/hostedtoolcache/Python/3.6.10/x64/lib/python3.6/importlib/__init__.py", line 126, in import_module
<br />    return _bootstrap._gcd_import(name[level:], package, level)
<br />  File "<frozen importlib._bootstrap>", line 994, in _gcd_import
<br />  File "<frozen importlib._bootstrap>", line 971, in _find_and_load
<br />  File "<frozen importlib._bootstrap>", line 955, in _find_and_load_unlocked
<br />  File "<frozen importlib._bootstrap>", line 665, in _load_unlocked
<br />  File "<frozen importlib._bootstrap_external>", line 674, in exec_module
<br />  File "<frozen importlib._bootstrap_external>", line 781, in get_code
<br />  File "<frozen importlib._bootstrap_external>", line 741, in source_to_code
<br />  File "<frozen importlib._bootstrap>", line 219, in _call_with_frames_removed
<br />  File "https://github.com/arita37/mlmodels/tree/2675f1e090030e6958e45c46c6313291532e6ed8/mlmodels/model_gluon/gluonts_model.py", line 152
<br />    if d ==  "single_dataframe" :
<br />                                ^
<br />SyntaxError: invalid syntax



### Error 30, [Traceback at line 656](https://github.com/arita37/mlmodels_store/blob/master/log_json/log_json.py#L656)<br />656..Traceback (most recent call last):
<br />  File "https://github.com/arita37/mlmodels/tree/2675f1e090030e6958e45c46c6313291532e6ed8/mlmodels/models.py", line 84, in module_load
<br />    model_name = str(Path(model_uri).parts[-2]) + "." + str(model_name)
<br />IndexError: tuple index out of range



### Error 31, [Traceback at line 663](https://github.com/arita37/mlmodels_store/blob/master/log_json/log_json.py#L663)<br />663..Traceback (most recent call last):
<br />  File "/opt/hostedtoolcache/Python/3.6.10/x64/bin/ml_models", line 11, in <module>
<br />    load_entry_point('mlmodels', 'console_scripts', 'ml_models')()
<br />  File "https://github.com/arita37/mlmodels/tree/2675f1e090030e6958e45c46c6313291532e6ed8/mlmodels/models.py", line 530, in main
<br />    fit_cli(arg)
<br />  File "https://github.com/arita37/mlmodels/tree/2675f1e090030e6958e45c46c6313291532e6ed8/mlmodels/models.py", line 420, in fit_cli
<br />    module = module_load(model_uri)  # '1_lstm.py
<br />  File "https://github.com/arita37/mlmodels/tree/2675f1e090030e6958e45c46c6313291532e6ed8/mlmodels/models.py", line 89, in module_load
<br />    raise NameError(f"Module {model_name} notfound, {e1}, {e2}")
<br />NameError: Module model_gluon notfound, invalid syntax (gluonts_model.py, line 152), tuple index out of range



### Error 32, [Traceback at line 686](https://github.com/arita37/mlmodels_store/blob/master/log_json/log_json.py#L686)<br />686..Traceback (most recent call last):
<br />  File "https://github.com/arita37/mlmodels/tree/2675f1e090030e6958e45c46c6313291532e6ed8/mlmodels/models.py", line 72, in module_load
<br />    module = import_module(f"mlmodels.{model_name}")
<br />  File "/opt/hostedtoolcache/Python/3.6.10/x64/lib/python3.6/importlib/__init__.py", line 126, in import_module
<br />    return _bootstrap._gcd_import(name[level:], package, level)
<br />  File "<frozen importlib._bootstrap>", line 994, in _gcd_import
<br />  File "<frozen importlib._bootstrap>", line 971, in _find_and_load
<br />  File "<frozen importlib._bootstrap>", line 955, in _find_and_load_unlocked
<br />  File "<frozen importlib._bootstrap>", line 665, in _load_unlocked
<br />  File "<frozen importlib._bootstrap_external>", line 674, in exec_module
<br />  File "<frozen importlib._bootstrap_external>", line 781, in get_code
<br />  File "<frozen importlib._bootstrap_external>", line 741, in source_to_code
<br />  File "<frozen importlib._bootstrap>", line 219, in _call_with_frames_removed
<br />  File "https://github.com/arita37/mlmodels/tree/2675f1e090030e6958e45c46c6313291532e6ed8/mlmodels/model_gluon/gluonts_model.py", line 152
<br />    if d ==  "single_dataframe" :
<br />                                ^
<br />SyntaxError: invalid syntax



### Error 33, [Traceback at line 706](https://github.com/arita37/mlmodels_store/blob/master/log_json/log_json.py#L706)<br />706..Traceback (most recent call last):
<br />  File "https://github.com/arita37/mlmodels/tree/2675f1e090030e6958e45c46c6313291532e6ed8/mlmodels/models.py", line 84, in module_load
<br />    model_name = str(Path(model_uri).parts[-2]) + "." + str(model_name)
<br />IndexError: tuple index out of range



### Error 34, [Traceback at line 713](https://github.com/arita37/mlmodels_store/blob/master/log_json/log_json.py#L713)<br />713..Traceback (most recent call last):
<br />  File "/opt/hostedtoolcache/Python/3.6.10/x64/bin/ml_models", line 11, in <module>
<br />    load_entry_point('mlmodels', 'console_scripts', 'ml_models')()
<br />  File "https://github.com/arita37/mlmodels/tree/2675f1e090030e6958e45c46c6313291532e6ed8/mlmodels/models.py", line 530, in main
<br />    fit_cli(arg)
<br />  File "https://github.com/arita37/mlmodels/tree/2675f1e090030e6958e45c46c6313291532e6ed8/mlmodels/models.py", line 420, in fit_cli
<br />    module = module_load(model_uri)  # '1_lstm.py
<br />  File "https://github.com/arita37/mlmodels/tree/2675f1e090030e6958e45c46c6313291532e6ed8/mlmodels/models.py", line 89, in module_load
<br />    raise NameError(f"Module {model_name} notfound, {e1}, {e2}")
<br />NameError: Module model_gluon notfound, invalid syntax (gluonts_model.py, line 152), tuple index out of range



### Error 35, [Traceback at line 736](https://github.com/arita37/mlmodels_store/blob/master/log_json/log_json.py#L736)<br />736..Traceback (most recent call last):
<br />  File "https://github.com/arita37/mlmodels/tree/2675f1e090030e6958e45c46c6313291532e6ed8/mlmodels/models.py", line 72, in module_load
<br />    module = import_module(f"mlmodels.{model_name}")
<br />  File "/opt/hostedtoolcache/Python/3.6.10/x64/lib/python3.6/importlib/__init__.py", line 126, in import_module
<br />    return _bootstrap._gcd_import(name[level:], package, level)
<br />  File "<frozen importlib._bootstrap>", line 994, in _gcd_import
<br />  File "<frozen importlib._bootstrap>", line 971, in _find_and_load
<br />  File "<frozen importlib._bootstrap>", line 955, in _find_and_load_unlocked
<br />  File "<frozen importlib._bootstrap>", line 665, in _load_unlocked
<br />  File "<frozen importlib._bootstrap_external>", line 674, in exec_module
<br />  File "<frozen importlib._bootstrap_external>", line 781, in get_code
<br />  File "<frozen importlib._bootstrap_external>", line 741, in source_to_code
<br />  File "<frozen importlib._bootstrap>", line 219, in _call_with_frames_removed
<br />  File "https://github.com/arita37/mlmodels/tree/2675f1e090030e6958e45c46c6313291532e6ed8/mlmodels/model_gluon/gluonts_model.py", line 152
<br />    if d ==  "single_dataframe" :
<br />                                ^
<br />SyntaxError: invalid syntax



### Error 36, [Traceback at line 756](https://github.com/arita37/mlmodels_store/blob/master/log_json/log_json.py#L756)<br />756..Traceback (most recent call last):
<br />  File "https://github.com/arita37/mlmodels/tree/2675f1e090030e6958e45c46c6313291532e6ed8/mlmodels/models.py", line 84, in module_load
<br />    model_name = str(Path(model_uri).parts[-2]) + "." + str(model_name)
<br />IndexError: tuple index out of range



### Error 37, [Traceback at line 763](https://github.com/arita37/mlmodels_store/blob/master/log_json/log_json.py#L763)<br />763..Traceback (most recent call last):
<br />  File "/opt/hostedtoolcache/Python/3.6.10/x64/bin/ml_models", line 11, in <module>
<br />    load_entry_point('mlmodels', 'console_scripts', 'ml_models')()
<br />  File "https://github.com/arita37/mlmodels/tree/2675f1e090030e6958e45c46c6313291532e6ed8/mlmodels/models.py", line 530, in main
<br />    fit_cli(arg)
<br />  File "https://github.com/arita37/mlmodels/tree/2675f1e090030e6958e45c46c6313291532e6ed8/mlmodels/models.py", line 420, in fit_cli
<br />    module = module_load(model_uri)  # '1_lstm.py
<br />  File "https://github.com/arita37/mlmodels/tree/2675f1e090030e6958e45c46c6313291532e6ed8/mlmodels/models.py", line 89, in module_load
<br />    raise NameError(f"Module {model_name} notfound, {e1}, {e2}")
<br />NameError: Module model_gluon notfound, invalid syntax (gluonts_model.py, line 152), tuple index out of range



### Error 38, [Traceback at line 786](https://github.com/arita37/mlmodels_store/blob/master/log_json/log_json.py#L786)<br />786..Traceback (most recent call last):
<br />  File "https://github.com/arita37/mlmodels/tree/2675f1e090030e6958e45c46c6313291532e6ed8/mlmodels/models.py", line 72, in module_load
<br />    module = import_module(f"mlmodels.{model_name}")
<br />  File "/opt/hostedtoolcache/Python/3.6.10/x64/lib/python3.6/importlib/__init__.py", line 126, in import_module
<br />    return _bootstrap._gcd_import(name[level:], package, level)
<br />  File "<frozen importlib._bootstrap>", line 994, in _gcd_import
<br />  File "<frozen importlib._bootstrap>", line 971, in _find_and_load
<br />  File "<frozen importlib._bootstrap>", line 955, in _find_and_load_unlocked
<br />  File "<frozen importlib._bootstrap>", line 665, in _load_unlocked
<br />  File "<frozen importlib._bootstrap_external>", line 674, in exec_module
<br />  File "<frozen importlib._bootstrap_external>", line 781, in get_code
<br />  File "<frozen importlib._bootstrap_external>", line 741, in source_to_code
<br />  File "<frozen importlib._bootstrap>", line 219, in _call_with_frames_removed
<br />  File "https://github.com/arita37/mlmodels/tree/2675f1e090030e6958e45c46c6313291532e6ed8/mlmodels/model_gluon/gluonts_model.py", line 152
<br />    if d ==  "single_dataframe" :
<br />                                ^
<br />SyntaxError: invalid syntax



### Error 39, [Traceback at line 806](https://github.com/arita37/mlmodels_store/blob/master/log_json/log_json.py#L806)<br />806..Traceback (most recent call last):
<br />  File "https://github.com/arita37/mlmodels/tree/2675f1e090030e6958e45c46c6313291532e6ed8/mlmodels/models.py", line 84, in module_load
<br />    model_name = str(Path(model_uri).parts[-2]) + "." + str(model_name)
<br />IndexError: tuple index out of range



### Error 40, [Traceback at line 813](https://github.com/arita37/mlmodels_store/blob/master/log_json/log_json.py#L813)<br />813..Traceback (most recent call last):
<br />  File "/opt/hostedtoolcache/Python/3.6.10/x64/bin/ml_models", line 11, in <module>
<br />    load_entry_point('mlmodels', 'console_scripts', 'ml_models')()
<br />  File "https://github.com/arita37/mlmodels/tree/2675f1e090030e6958e45c46c6313291532e6ed8/mlmodels/models.py", line 530, in main
<br />    fit_cli(arg)
<br />  File "https://github.com/arita37/mlmodels/tree/2675f1e090030e6958e45c46c6313291532e6ed8/mlmodels/models.py", line 420, in fit_cli
<br />    module = module_load(model_uri)  # '1_lstm.py
<br />  File "https://github.com/arita37/mlmodels/tree/2675f1e090030e6958e45c46c6313291532e6ed8/mlmodels/models.py", line 89, in module_load
<br />    raise NameError(f"Module {model_name} notfound, {e1}, {e2}")
<br />NameError: Module model_gluon notfound, invalid syntax (gluonts_model.py, line 152), tuple index out of range



### Error 41, [Traceback at line 836](https://github.com/arita37/mlmodels_store/blob/master/log_json/log_json.py#L836)<br />836..Traceback (most recent call last):
<br />  File "https://github.com/arita37/mlmodels/tree/2675f1e090030e6958e45c46c6313291532e6ed8/mlmodels/models.py", line 72, in module_load
<br />    module = import_module(f"mlmodels.{model_name}")
<br />  File "/opt/hostedtoolcache/Python/3.6.10/x64/lib/python3.6/importlib/__init__.py", line 126, in import_module
<br />    return _bootstrap._gcd_import(name[level:], package, level)
<br />  File "<frozen importlib._bootstrap>", line 994, in _gcd_import
<br />  File "<frozen importlib._bootstrap>", line 971, in _find_and_load
<br />  File "<frozen importlib._bootstrap>", line 955, in _find_and_load_unlocked
<br />  File "<frozen importlib._bootstrap>", line 665, in _load_unlocked
<br />  File "<frozen importlib._bootstrap_external>", line 674, in exec_module
<br />  File "<frozen importlib._bootstrap_external>", line 781, in get_code
<br />  File "<frozen importlib._bootstrap_external>", line 741, in source_to_code
<br />  File "<frozen importlib._bootstrap>", line 219, in _call_with_frames_removed
<br />  File "https://github.com/arita37/mlmodels/tree/2675f1e090030e6958e45c46c6313291532e6ed8/mlmodels/model_gluon/gluonts_model.py", line 152
<br />    if d ==  "single_dataframe" :
<br />                                ^
<br />SyntaxError: invalid syntax



### Error 42, [Traceback at line 856](https://github.com/arita37/mlmodels_store/blob/master/log_json/log_json.py#L856)<br />856..Traceback (most recent call last):
<br />  File "https://github.com/arita37/mlmodels/tree/2675f1e090030e6958e45c46c6313291532e6ed8/mlmodels/models.py", line 84, in module_load
<br />    model_name = str(Path(model_uri).parts[-2]) + "." + str(model_name)
<br />IndexError: tuple index out of range



### Error 43, [Traceback at line 863](https://github.com/arita37/mlmodels_store/blob/master/log_json/log_json.py#L863)<br />863..Traceback (most recent call last):
<br />  File "/opt/hostedtoolcache/Python/3.6.10/x64/bin/ml_models", line 11, in <module>
<br />    load_entry_point('mlmodels', 'console_scripts', 'ml_models')()
<br />  File "https://github.com/arita37/mlmodels/tree/2675f1e090030e6958e45c46c6313291532e6ed8/mlmodels/models.py", line 530, in main
<br />    fit_cli(arg)
<br />  File "https://github.com/arita37/mlmodels/tree/2675f1e090030e6958e45c46c6313291532e6ed8/mlmodels/models.py", line 420, in fit_cli
<br />    module = module_load(model_uri)  # '1_lstm.py
<br />  File "https://github.com/arita37/mlmodels/tree/2675f1e090030e6958e45c46c6313291532e6ed8/mlmodels/models.py", line 89, in module_load
<br />    raise NameError(f"Module {model_name} notfound, {e1}, {e2}")
<br />NameError: Module model_gluon notfound, invalid syntax (gluonts_model.py, line 152), tuple index out of range



### Error 44, [Traceback at line 891](https://github.com/arita37/mlmodels_store/blob/master/log_json/log_json.py#L891)<br />891..Traceback (most recent call last):
<br />  File "https://github.com/arita37/mlmodels/tree/2675f1e090030e6958e45c46c6313291532e6ed8/mlmodels/models.py", line 72, in module_load
<br />    module = import_module(f"mlmodels.{model_name}")
<br />  File "/opt/hostedtoolcache/Python/3.6.10/x64/lib/python3.6/importlib/__init__.py", line 126, in import_module
<br />    return _bootstrap._gcd_import(name[level:], package, level)
<br />  File "<frozen importlib._bootstrap>", line 994, in _gcd_import
<br />  File "<frozen importlib._bootstrap>", line 971, in _find_and_load
<br />  File "<frozen importlib._bootstrap>", line 955, in _find_and_load_unlocked
<br />  File "<frozen importlib._bootstrap>", line 665, in _load_unlocked
<br />  File "<frozen importlib._bootstrap_external>", line 674, in exec_module
<br />  File "<frozen importlib._bootstrap_external>", line 781, in get_code
<br />  File "<frozen importlib._bootstrap_external>", line 741, in source_to_code
<br />  File "<frozen importlib._bootstrap>", line 219, in _call_with_frames_removed
<br />  File "https://github.com/arita37/mlmodels/tree/2675f1e090030e6958e45c46c6313291532e6ed8/mlmodels/model_gluon/gluonts_model.py", line 152
<br />    if d ==  "single_dataframe" :
<br />                                ^
<br />SyntaxError: invalid syntax



### Error 45, [Traceback at line 911](https://github.com/arita37/mlmodels_store/blob/master/log_json/log_json.py#L911)<br />911..Traceback (most recent call last):
<br />  File "https://github.com/arita37/mlmodels/tree/2675f1e090030e6958e45c46c6313291532e6ed8/mlmodels/models.py", line 84, in module_load
<br />    model_name = str(Path(model_uri).parts[-2]) + "." + str(model_name)
<br />IndexError: tuple index out of range



### Error 46, [Traceback at line 918](https://github.com/arita37/mlmodels_store/blob/master/log_json/log_json.py#L918)<br />918..Traceback (most recent call last):
<br />  File "/opt/hostedtoolcache/Python/3.6.10/x64/bin/ml_models", line 11, in <module>
<br />    load_entry_point('mlmodels', 'console_scripts', 'ml_models')()
<br />  File "https://github.com/arita37/mlmodels/tree/2675f1e090030e6958e45c46c6313291532e6ed8/mlmodels/models.py", line 530, in main
<br />    fit_cli(arg)
<br />  File "https://github.com/arita37/mlmodels/tree/2675f1e090030e6958e45c46c6313291532e6ed8/mlmodels/models.py", line 420, in fit_cli
<br />    module = module_load(model_uri)  # '1_lstm.py
<br />  File "https://github.com/arita37/mlmodels/tree/2675f1e090030e6958e45c46c6313291532e6ed8/mlmodels/models.py", line 89, in module_load
<br />    raise NameError(f"Module {model_name} notfound, {e1}, {e2}")
<br />NameError: Module model_gluon notfound, invalid syntax (gluonts_model.py, line 152), tuple index out of range



### Error 47, [Traceback at line 941](https://github.com/arita37/mlmodels_store/blob/master/log_json/log_json.py#L941)<br />941..Traceback (most recent call last):
<br />  File "https://github.com/arita37/mlmodels/tree/2675f1e090030e6958e45c46c6313291532e6ed8/mlmodels/models.py", line 72, in module_load
<br />    module = import_module(f"mlmodels.{model_name}")
<br />  File "/opt/hostedtoolcache/Python/3.6.10/x64/lib/python3.6/importlib/__init__.py", line 126, in import_module
<br />    return _bootstrap._gcd_import(name[level:], package, level)
<br />  File "<frozen importlib._bootstrap>", line 994, in _gcd_import
<br />  File "<frozen importlib._bootstrap>", line 971, in _find_and_load
<br />  File "<frozen importlib._bootstrap>", line 955, in _find_and_load_unlocked
<br />  File "<frozen importlib._bootstrap>", line 665, in _load_unlocked
<br />  File "<frozen importlib._bootstrap_external>", line 674, in exec_module
<br />  File "<frozen importlib._bootstrap_external>", line 781, in get_code
<br />  File "<frozen importlib._bootstrap_external>", line 741, in source_to_code
<br />  File "<frozen importlib._bootstrap>", line 219, in _call_with_frames_removed
<br />  File "https://github.com/arita37/mlmodels/tree/2675f1e090030e6958e45c46c6313291532e6ed8/mlmodels/model_gluon/gluonts_model.py", line 152
<br />    if d ==  "single_dataframe" :
<br />                                ^
<br />SyntaxError: invalid syntax



### Error 48, [Traceback at line 961](https://github.com/arita37/mlmodels_store/blob/master/log_json/log_json.py#L961)<br />961..Traceback (most recent call last):
<br />  File "https://github.com/arita37/mlmodels/tree/2675f1e090030e6958e45c46c6313291532e6ed8/mlmodels/models.py", line 84, in module_load
<br />    model_name = str(Path(model_uri).parts[-2]) + "." + str(model_name)
<br />IndexError: tuple index out of range



### Error 49, [Traceback at line 968](https://github.com/arita37/mlmodels_store/blob/master/log_json/log_json.py#L968)<br />968..Traceback (most recent call last):
<br />  File "/opt/hostedtoolcache/Python/3.6.10/x64/bin/ml_models", line 11, in <module>
<br />    load_entry_point('mlmodels', 'console_scripts', 'ml_models')()
<br />  File "https://github.com/arita37/mlmodels/tree/2675f1e090030e6958e45c46c6313291532e6ed8/mlmodels/models.py", line 530, in main
<br />    fit_cli(arg)
<br />  File "https://github.com/arita37/mlmodels/tree/2675f1e090030e6958e45c46c6313291532e6ed8/mlmodels/models.py", line 420, in fit_cli
<br />    module = module_load(model_uri)  # '1_lstm.py
<br />  File "https://github.com/arita37/mlmodels/tree/2675f1e090030e6958e45c46c6313291532e6ed8/mlmodels/models.py", line 89, in module_load
<br />    raise NameError(f"Module {model_name} notfound, {e1}, {e2}")
<br />NameError: Module model_gluon notfound, invalid syntax (gluonts_model.py, line 152), tuple index out of range



### Error 50, [Traceback at line 991](https://github.com/arita37/mlmodels_store/blob/master/log_json/log_json.py#L991)<br />991..Traceback (most recent call last):
<br />  File "https://github.com/arita37/mlmodels/tree/2675f1e090030e6958e45c46c6313291532e6ed8/mlmodels/models.py", line 72, in module_load
<br />    module = import_module(f"mlmodels.{model_name}")
<br />  File "/opt/hostedtoolcache/Python/3.6.10/x64/lib/python3.6/importlib/__init__.py", line 126, in import_module
<br />    return _bootstrap._gcd_import(name[level:], package, level)
<br />  File "<frozen importlib._bootstrap>", line 994, in _gcd_import
<br />  File "<frozen importlib._bootstrap>", line 971, in _find_and_load
<br />  File "<frozen importlib._bootstrap>", line 955, in _find_and_load_unlocked
<br />  File "<frozen importlib._bootstrap>", line 665, in _load_unlocked
<br />  File "<frozen importlib._bootstrap_external>", line 674, in exec_module
<br />  File "<frozen importlib._bootstrap_external>", line 781, in get_code
<br />  File "<frozen importlib._bootstrap_external>", line 741, in source_to_code
<br />  File "<frozen importlib._bootstrap>", line 219, in _call_with_frames_removed
<br />  File "https://github.com/arita37/mlmodels/tree/2675f1e090030e6958e45c46c6313291532e6ed8/mlmodels/model_gluon/gluonts_model.py", line 152
<br />    if d ==  "single_dataframe" :
<br />                                ^
<br />SyntaxError: invalid syntax



### Error 51, [Traceback at line 1011](https://github.com/arita37/mlmodels_store/blob/master/log_json/log_json.py#L1011)<br />1011..Traceback (most recent call last):
<br />  File "https://github.com/arita37/mlmodels/tree/2675f1e090030e6958e45c46c6313291532e6ed8/mlmodels/models.py", line 84, in module_load
<br />    model_name = str(Path(model_uri).parts[-2]) + "." + str(model_name)
<br />IndexError: tuple index out of range



### Error 52, [Traceback at line 1018](https://github.com/arita37/mlmodels_store/blob/master/log_json/log_json.py#L1018)<br />1018..Traceback (most recent call last):
<br />  File "/opt/hostedtoolcache/Python/3.6.10/x64/bin/ml_models", line 11, in <module>
<br />    load_entry_point('mlmodels', 'console_scripts', 'ml_models')()
<br />  File "https://github.com/arita37/mlmodels/tree/2675f1e090030e6958e45c46c6313291532e6ed8/mlmodels/models.py", line 530, in main
<br />    fit_cli(arg)
<br />  File "https://github.com/arita37/mlmodels/tree/2675f1e090030e6958e45c46c6313291532e6ed8/mlmodels/models.py", line 420, in fit_cli
<br />    module = module_load(model_uri)  # '1_lstm.py
<br />  File "https://github.com/arita37/mlmodels/tree/2675f1e090030e6958e45c46c6313291532e6ed8/mlmodels/models.py", line 89, in module_load
<br />    raise NameError(f"Module {model_name} notfound, {e1}, {e2}")
<br />NameError: Module model_gluon notfound, invalid syntax (gluonts_model.py, line 152), tuple index out of range



### Error 53, [Traceback at line 1041](https://github.com/arita37/mlmodels_store/blob/master/log_json/log_json.py#L1041)<br />1041..Traceback (most recent call last):
<br />  File "https://github.com/arita37/mlmodels/tree/2675f1e090030e6958e45c46c6313291532e6ed8/mlmodels/models.py", line 72, in module_load
<br />    module = import_module(f"mlmodels.{model_name}")
<br />  File "/opt/hostedtoolcache/Python/3.6.10/x64/lib/python3.6/importlib/__init__.py", line 126, in import_module
<br />    return _bootstrap._gcd_import(name[level:], package, level)
<br />  File "<frozen importlib._bootstrap>", line 994, in _gcd_import
<br />  File "<frozen importlib._bootstrap>", line 971, in _find_and_load
<br />  File "<frozen importlib._bootstrap>", line 955, in _find_and_load_unlocked
<br />  File "<frozen importlib._bootstrap>", line 665, in _load_unlocked
<br />  File "<frozen importlib._bootstrap_external>", line 674, in exec_module
<br />  File "<frozen importlib._bootstrap_external>", line 781, in get_code
<br />  File "<frozen importlib._bootstrap_external>", line 741, in source_to_code
<br />  File "<frozen importlib._bootstrap>", line 219, in _call_with_frames_removed
<br />  File "https://github.com/arita37/mlmodels/tree/2675f1e090030e6958e45c46c6313291532e6ed8/mlmodels/model_gluon/gluonts_model.py", line 152
<br />    if d ==  "single_dataframe" :
<br />                                ^
<br />SyntaxError: invalid syntax



### Error 54, [Traceback at line 1061](https://github.com/arita37/mlmodels_store/blob/master/log_json/log_json.py#L1061)<br />1061..Traceback (most recent call last):
<br />  File "https://github.com/arita37/mlmodels/tree/2675f1e090030e6958e45c46c6313291532e6ed8/mlmodels/models.py", line 84, in module_load
<br />    model_name = str(Path(model_uri).parts[-2]) + "." + str(model_name)
<br />IndexError: tuple index out of range



### Error 55, [Traceback at line 1068](https://github.com/arita37/mlmodels_store/blob/master/log_json/log_json.py#L1068)<br />1068..Traceback (most recent call last):
<br />  File "/opt/hostedtoolcache/Python/3.6.10/x64/bin/ml_models", line 11, in <module>
<br />    load_entry_point('mlmodels', 'console_scripts', 'ml_models')()
<br />  File "https://github.com/arita37/mlmodels/tree/2675f1e090030e6958e45c46c6313291532e6ed8/mlmodels/models.py", line 530, in main
<br />    fit_cli(arg)
<br />  File "https://github.com/arita37/mlmodels/tree/2675f1e090030e6958e45c46c6313291532e6ed8/mlmodels/models.py", line 420, in fit_cli
<br />    module = module_load(model_uri)  # '1_lstm.py
<br />  File "https://github.com/arita37/mlmodels/tree/2675f1e090030e6958e45c46c6313291532e6ed8/mlmodels/models.py", line 89, in module_load
<br />    raise NameError(f"Module {model_name} notfound, {e1}, {e2}")
<br />NameError: Module model_gluon notfound, invalid syntax (gluonts_model.py, line 152), tuple index out of range



### Error 56, [Traceback at line 1091](https://github.com/arita37/mlmodels_store/blob/master/log_json/log_json.py#L1091)<br />1091..Traceback (most recent call last):
<br />  File "https://github.com/arita37/mlmodels/tree/2675f1e090030e6958e45c46c6313291532e6ed8/mlmodels/models.py", line 72, in module_load
<br />    module = import_module(f"mlmodels.{model_name}")
<br />  File "/opt/hostedtoolcache/Python/3.6.10/x64/lib/python3.6/importlib/__init__.py", line 126, in import_module
<br />    return _bootstrap._gcd_import(name[level:], package, level)
<br />  File "<frozen importlib._bootstrap>", line 994, in _gcd_import
<br />  File "<frozen importlib._bootstrap>", line 971, in _find_and_load
<br />  File "<frozen importlib._bootstrap>", line 955, in _find_and_load_unlocked
<br />  File "<frozen importlib._bootstrap>", line 665, in _load_unlocked
<br />  File "<frozen importlib._bootstrap_external>", line 674, in exec_module
<br />  File "<frozen importlib._bootstrap_external>", line 781, in get_code
<br />  File "<frozen importlib._bootstrap_external>", line 741, in source_to_code
<br />  File "<frozen importlib._bootstrap>", line 219, in _call_with_frames_removed
<br />  File "https://github.com/arita37/mlmodels/tree/2675f1e090030e6958e45c46c6313291532e6ed8/mlmodels/model_gluon/gluonts_model.py", line 152
<br />    if d ==  "single_dataframe" :
<br />                                ^
<br />SyntaxError: invalid syntax



### Error 57, [Traceback at line 1111](https://github.com/arita37/mlmodels_store/blob/master/log_json/log_json.py#L1111)<br />1111..Traceback (most recent call last):
<br />  File "https://github.com/arita37/mlmodels/tree/2675f1e090030e6958e45c46c6313291532e6ed8/mlmodels/models.py", line 84, in module_load
<br />    model_name = str(Path(model_uri).parts[-2]) + "." + str(model_name)
<br />IndexError: tuple index out of range



### Error 58, [Traceback at line 1118](https://github.com/arita37/mlmodels_store/blob/master/log_json/log_json.py#L1118)<br />1118..Traceback (most recent call last):
<br />  File "/opt/hostedtoolcache/Python/3.6.10/x64/bin/ml_models", line 11, in <module>
<br />    load_entry_point('mlmodels', 'console_scripts', 'ml_models')()
<br />  File "https://github.com/arita37/mlmodels/tree/2675f1e090030e6958e45c46c6313291532e6ed8/mlmodels/models.py", line 530, in main
<br />    fit_cli(arg)
<br />  File "https://github.com/arita37/mlmodels/tree/2675f1e090030e6958e45c46c6313291532e6ed8/mlmodels/models.py", line 420, in fit_cli
<br />    module = module_load(model_uri)  # '1_lstm.py
<br />  File "https://github.com/arita37/mlmodels/tree/2675f1e090030e6958e45c46c6313291532e6ed8/mlmodels/models.py", line 89, in module_load
<br />    raise NameError(f"Module {model_name} notfound, {e1}, {e2}")
<br />NameError: Module model_gluon notfound, invalid syntax (gluonts_model.py, line 152), tuple index out of range



### Error 59, [Traceback at line 1141](https://github.com/arita37/mlmodels_store/blob/master/log_json/log_json.py#L1141)<br />1141..Traceback (most recent call last):
<br />  File "https://github.com/arita37/mlmodels/tree/2675f1e090030e6958e45c46c6313291532e6ed8/mlmodels/models.py", line 72, in module_load
<br />    module = import_module(f"mlmodels.{model_name}")
<br />  File "/opt/hostedtoolcache/Python/3.6.10/x64/lib/python3.6/importlib/__init__.py", line 126, in import_module
<br />    return _bootstrap._gcd_import(name[level:], package, level)
<br />  File "<frozen importlib._bootstrap>", line 994, in _gcd_import
<br />  File "<frozen importlib._bootstrap>", line 971, in _find_and_load
<br />  File "<frozen importlib._bootstrap>", line 955, in _find_and_load_unlocked
<br />  File "<frozen importlib._bootstrap>", line 665, in _load_unlocked
<br />  File "<frozen importlib._bootstrap_external>", line 674, in exec_module
<br />  File "<frozen importlib._bootstrap_external>", line 781, in get_code
<br />  File "<frozen importlib._bootstrap_external>", line 741, in source_to_code
<br />  File "<frozen importlib._bootstrap>", line 219, in _call_with_frames_removed
<br />  File "https://github.com/arita37/mlmodels/tree/2675f1e090030e6958e45c46c6313291532e6ed8/mlmodels/model_gluon/gluonts_model.py", line 152
<br />    if d ==  "single_dataframe" :
<br />                                ^
<br />SyntaxError: invalid syntax



### Error 60, [Traceback at line 1161](https://github.com/arita37/mlmodels_store/blob/master/log_json/log_json.py#L1161)<br />1161..Traceback (most recent call last):
<br />  File "https://github.com/arita37/mlmodels/tree/2675f1e090030e6958e45c46c6313291532e6ed8/mlmodels/models.py", line 84, in module_load
<br />    model_name = str(Path(model_uri).parts[-2]) + "." + str(model_name)
<br />IndexError: tuple index out of range



### Error 61, [Traceback at line 1168](https://github.com/arita37/mlmodels_store/blob/master/log_json/log_json.py#L1168)<br />1168..Traceback (most recent call last):
<br />  File "/opt/hostedtoolcache/Python/3.6.10/x64/bin/ml_models", line 11, in <module>
<br />    load_entry_point('mlmodels', 'console_scripts', 'ml_models')()
<br />  File "https://github.com/arita37/mlmodels/tree/2675f1e090030e6958e45c46c6313291532e6ed8/mlmodels/models.py", line 530, in main
<br />    fit_cli(arg)
<br />  File "https://github.com/arita37/mlmodels/tree/2675f1e090030e6958e45c46c6313291532e6ed8/mlmodels/models.py", line 420, in fit_cli
<br />    module = module_load(model_uri)  # '1_lstm.py
<br />  File "https://github.com/arita37/mlmodels/tree/2675f1e090030e6958e45c46c6313291532e6ed8/mlmodels/models.py", line 89, in module_load
<br />    raise NameError(f"Module {model_name} notfound, {e1}, {e2}")
<br />NameError: Module model_gluon notfound, invalid syntax (gluonts_model.py, line 152), tuple index out of range



### Error 62, [Traceback at line 1191](https://github.com/arita37/mlmodels_store/blob/master/log_json/log_json.py#L1191)<br />1191..Traceback (most recent call last):
<br />  File "https://github.com/arita37/mlmodels/tree/2675f1e090030e6958e45c46c6313291532e6ed8/mlmodels/models.py", line 72, in module_load
<br />    module = import_module(f"mlmodels.{model_name}")
<br />  File "/opt/hostedtoolcache/Python/3.6.10/x64/lib/python3.6/importlib/__init__.py", line 126, in import_module
<br />    return _bootstrap._gcd_import(name[level:], package, level)
<br />  File "<frozen importlib._bootstrap>", line 994, in _gcd_import
<br />  File "<frozen importlib._bootstrap>", line 971, in _find_and_load
<br />  File "<frozen importlib._bootstrap>", line 955, in _find_and_load_unlocked
<br />  File "<frozen importlib._bootstrap>", line 665, in _load_unlocked
<br />  File "<frozen importlib._bootstrap_external>", line 674, in exec_module
<br />  File "<frozen importlib._bootstrap_external>", line 781, in get_code
<br />  File "<frozen importlib._bootstrap_external>", line 741, in source_to_code
<br />  File "<frozen importlib._bootstrap>", line 219, in _call_with_frames_removed
<br />  File "https://github.com/arita37/mlmodels/tree/2675f1e090030e6958e45c46c6313291532e6ed8/mlmodels/model_gluon/gluonts_model.py", line 152
<br />    if d ==  "single_dataframe" :
<br />                                ^
<br />SyntaxError: invalid syntax



### Error 63, [Traceback at line 1211](https://github.com/arita37/mlmodels_store/blob/master/log_json/log_json.py#L1211)<br />1211..Traceback (most recent call last):
<br />  File "https://github.com/arita37/mlmodels/tree/2675f1e090030e6958e45c46c6313291532e6ed8/mlmodels/models.py", line 84, in module_load
<br />    model_name = str(Path(model_uri).parts[-2]) + "." + str(model_name)
<br />IndexError: tuple index out of range



### Error 64, [Traceback at line 1218](https://github.com/arita37/mlmodels_store/blob/master/log_json/log_json.py#L1218)<br />1218..Traceback (most recent call last):
<br />  File "/opt/hostedtoolcache/Python/3.6.10/x64/bin/ml_models", line 11, in <module>
<br />    load_entry_point('mlmodels', 'console_scripts', 'ml_models')()
<br />  File "https://github.com/arita37/mlmodels/tree/2675f1e090030e6958e45c46c6313291532e6ed8/mlmodels/models.py", line 530, in main
<br />    fit_cli(arg)
<br />  File "https://github.com/arita37/mlmodels/tree/2675f1e090030e6958e45c46c6313291532e6ed8/mlmodels/models.py", line 420, in fit_cli
<br />    module = module_load(model_uri)  # '1_lstm.py
<br />  File "https://github.com/arita37/mlmodels/tree/2675f1e090030e6958e45c46c6313291532e6ed8/mlmodels/models.py", line 89, in module_load
<br />    raise NameError(f"Module {model_name} notfound, {e1}, {e2}")
<br />NameError: Module model_gluon notfound, invalid syntax (gluonts_model.py, line 152), tuple index out of range



### Error 65, [Traceback at line 1241](https://github.com/arita37/mlmodels_store/blob/master/log_json/log_json.py#L1241)<br />1241..Traceback (most recent call last):
<br />  File "https://github.com/arita37/mlmodels/tree/2675f1e090030e6958e45c46c6313291532e6ed8/mlmodels/models.py", line 72, in module_load
<br />    module = import_module(f"mlmodels.{model_name}")
<br />  File "/opt/hostedtoolcache/Python/3.6.10/x64/lib/python3.6/importlib/__init__.py", line 126, in import_module
<br />    return _bootstrap._gcd_import(name[level:], package, level)
<br />  File "<frozen importlib._bootstrap>", line 994, in _gcd_import
<br />  File "<frozen importlib._bootstrap>", line 971, in _find_and_load
<br />  File "<frozen importlib._bootstrap>", line 955, in _find_and_load_unlocked
<br />  File "<frozen importlib._bootstrap>", line 665, in _load_unlocked
<br />  File "<frozen importlib._bootstrap_external>", line 674, in exec_module
<br />  File "<frozen importlib._bootstrap_external>", line 781, in get_code
<br />  File "<frozen importlib._bootstrap_external>", line 741, in source_to_code
<br />  File "<frozen importlib._bootstrap>", line 219, in _call_with_frames_removed
<br />  File "https://github.com/arita37/mlmodels/tree/2675f1e090030e6958e45c46c6313291532e6ed8/mlmodels/model_gluon/gluonts_model.py", line 152
<br />    if d ==  "single_dataframe" :
<br />                                ^
<br />SyntaxError: invalid syntax



### Error 66, [Traceback at line 1261](https://github.com/arita37/mlmodels_store/blob/master/log_json/log_json.py#L1261)<br />1261..Traceback (most recent call last):
<br />  File "https://github.com/arita37/mlmodels/tree/2675f1e090030e6958e45c46c6313291532e6ed8/mlmodels/models.py", line 84, in module_load
<br />    model_name = str(Path(model_uri).parts[-2]) + "." + str(model_name)
<br />IndexError: tuple index out of range



### Error 67, [Traceback at line 1268](https://github.com/arita37/mlmodels_store/blob/master/log_json/log_json.py#L1268)<br />1268..Traceback (most recent call last):
<br />  File "/opt/hostedtoolcache/Python/3.6.10/x64/bin/ml_models", line 11, in <module>
<br />    load_entry_point('mlmodels', 'console_scripts', 'ml_models')()
<br />  File "https://github.com/arita37/mlmodels/tree/2675f1e090030e6958e45c46c6313291532e6ed8/mlmodels/models.py", line 530, in main
<br />    fit_cli(arg)
<br />  File "https://github.com/arita37/mlmodels/tree/2675f1e090030e6958e45c46c6313291532e6ed8/mlmodels/models.py", line 420, in fit_cli
<br />    module = module_load(model_uri)  # '1_lstm.py
<br />  File "https://github.com/arita37/mlmodels/tree/2675f1e090030e6958e45c46c6313291532e6ed8/mlmodels/models.py", line 89, in module_load
<br />    raise NameError(f"Module {model_name} notfound, {e1}, {e2}")
<br />NameError: Module model_gluon notfound, invalid syntax (gluonts_model.py, line 152), tuple index out of range



### Error 68, [Traceback at line 1294](https://github.com/arita37/mlmodels_store/blob/master/log_json/log_json.py#L1294)<br />1294..Traceback (most recent call last):
<br />  File "/opt/hostedtoolcache/Python/3.6.10/x64/bin/ml_models", line 11, in <module>
<br />    load_entry_point('mlmodels', 'console_scripts', 'ml_models')()
<br />  File "https://github.com/arita37/mlmodels/tree/2675f1e090030e6958e45c46c6313291532e6ed8/mlmodels/models.py", line 530, in main
<br />    fit_cli(arg)
<br />  File "https://github.com/arita37/mlmodels/tree/2675f1e090030e6958e45c46c6313291532e6ed8/mlmodels/models.py", line 415, in fit_cli
<br />    path      = out_p['path']
<br />KeyError: 'path'



### Error 69, [Traceback at line 1318](https://github.com/arita37/mlmodels_store/blob/master/log_json/log_json.py#L1318)<br />1318..Traceback (most recent call last):
<br />  File "/opt/hostedtoolcache/Python/3.6.10/x64/bin/ml_models", line 11, in <module>
<br />    load_entry_point('mlmodels', 'console_scripts', 'ml_models')()
<br />  File "https://github.com/arita37/mlmodels/tree/2675f1e090030e6958e45c46c6313291532e6ed8/mlmodels/models.py", line 530, in main
<br />    fit_cli(arg)
<br />  File "https://github.com/arita37/mlmodels/tree/2675f1e090030e6958e45c46c6313291532e6ed8/mlmodels/models.py", line 415, in fit_cli
<br />    path      = out_p['path']
<br />KeyError: 'path'



### Error 70, [Traceback at line 1342](https://github.com/arita37/mlmodels_store/blob/master/log_json/log_json.py#L1342)<br />1342..Traceback (most recent call last):
<br />  File "/opt/hostedtoolcache/Python/3.6.10/x64/bin/ml_models", line 11, in <module>
<br />    load_entry_point('mlmodels', 'console_scripts', 'ml_models')()
<br />  File "https://github.com/arita37/mlmodels/tree/2675f1e090030e6958e45c46c6313291532e6ed8/mlmodels/models.py", line 530, in main
<br />    fit_cli(arg)
<br />  File "https://github.com/arita37/mlmodels/tree/2675f1e090030e6958e45c46c6313291532e6ed8/mlmodels/models.py", line 415, in fit_cli
<br />    path      = out_p['path']
<br />KeyError: 'path'



### Error 71, [Traceback at line 1361](https://github.com/arita37/mlmodels_store/blob/master/log_json/log_json.py#L1361)<br />1361..Traceback (most recent call last):
<br />  File "/opt/hostedtoolcache/Python/3.6.10/x64/bin/ml_models", line 11, in <module>
<br />    load_entry_point('mlmodels', 'console_scripts', 'ml_models')()
<br />  File "https://github.com/arita37/mlmodels/tree/2675f1e090030e6958e45c46c6313291532e6ed8/mlmodels/models.py", line 530, in main
<br />    fit_cli(arg)
<br />  File "https://github.com/arita37/mlmodels/tree/2675f1e090030e6958e45c46c6313291532e6ed8/mlmodels/models.py", line 413, in fit_cli
<br />    model_p, data_p, compute_p, out_p = config_get_pars(config_file, arg.config_mode)
<br />  File "https://github.com/arita37/mlmodels/tree/2675f1e090030e6958e45c46c6313291532e6ed8/mlmodels/models.py", line 297, in config_get_pars
<br />    data_p    = path_norm_dict( js.get("data_pars") )
<br />  File "https://github.com/arita37/mlmodels/tree/2675f1e090030e6958e45c46c6313291532e6ed8/mlmodels/util.py", line 201, in path_norm_dict
<br />    for k,v in ddict.items():
<br />AttributeError: 'NoneType' object has no attribute 'items'



### Error 72, [Traceback at line 1389](https://github.com/arita37/mlmodels_store/blob/master/log_json/log_json.py#L1389)<br />1389..Traceback (most recent call last):
<br />  File "/opt/hostedtoolcache/Python/3.6.10/x64/bin/ml_models", line 11, in <module>
<br />    load_entry_point('mlmodels', 'console_scripts', 'ml_models')()
<br />  File "https://github.com/arita37/mlmodels/tree/2675f1e090030e6958e45c46c6313291532e6ed8/mlmodels/models.py", line 530, in main
<br />    fit_cli(arg)
<br />  File "https://github.com/arita37/mlmodels/tree/2675f1e090030e6958e45c46c6313291532e6ed8/mlmodels/models.py", line 414, in fit_cli
<br />    model_uri = model_p['model_uri']
<br />KeyError: 'model_uri'



### Error 73, [Traceback at line 1418](https://github.com/arita37/mlmodels_store/blob/master/log_json/log_json.py#L1418)<br />1418..Traceback (most recent call last):
<br />  File "/opt/hostedtoolcache/Python/3.6.10/x64/bin/ml_models", line 11, in <module>
<br />    load_entry_point('mlmodels', 'console_scripts', 'ml_models')()
<br />  File "https://github.com/arita37/mlmodels/tree/2675f1e090030e6958e45c46c6313291532e6ed8/mlmodels/models.py", line 530, in main
<br />    fit_cli(arg)
<br />  File "https://github.com/arita37/mlmodels/tree/2675f1e090030e6958e45c46c6313291532e6ed8/mlmodels/models.py", line 424, in fit_cli
<br />    model, sess = fit(module, model, data_pars=data_p, compute_pars=compute_p, out_pars=out_p)
<br />  File "https://github.com/arita37/mlmodels/tree/2675f1e090030e6958e45c46c6313291532e6ed8/mlmodels/models.py", line 125, in fit
<br />    return module.fit(model, data_pars=data_pars, compute_pars=compute_pars, out_pars=out_pars, **kwarg)
<br />  File "https://github.com/arita37/mlmodels/tree/2675f1e090030e6958e45c46c6313291532e6ed8/mlmodels/model_tch/torchhub.py", line 222, in fit
<br />    train_iter, valid_iter = get_dataset(data_pars)
<br />  File "https://github.com/arita37/mlmodels/tree/2675f1e090030e6958e45c46c6313291532e6ed8/mlmodels/model_tch/torchhub.py", line 190, in get_dataset
<br />    loader = DataLoader(data_pars)
<br />  File "https://github.com/arita37/mlmodels/tree/2675f1e090030e6958e45c46c6313291532e6ed8/mlmodels/dataloader.py", line 209, in __init__
<br />    self.data_info                = data_pars['data_info']
<br />KeyError: 'data_info'



### Error 74, [Traceback at line 1445](https://github.com/arita37/mlmodels_store/blob/master/log_json/log_json.py#L1445)<br />1445..Traceback (most recent call last):
<br />  File "/opt/hostedtoolcache/Python/3.6.10/x64/bin/ml_models", line 11, in <module>
<br />    load_entry_point('mlmodels', 'console_scripts', 'ml_models')()
<br />  File "https://github.com/arita37/mlmodels/tree/2675f1e090030e6958e45c46c6313291532e6ed8/mlmodels/models.py", line 530, in main
<br />    fit_cli(arg)
<br />  File "https://github.com/arita37/mlmodels/tree/2675f1e090030e6958e45c46c6313291532e6ed8/mlmodels/models.py", line 413, in fit_cli
<br />    model_p, data_p, compute_p, out_p = config_get_pars(config_file, arg.config_mode)
<br />  File "https://github.com/arita37/mlmodels/tree/2675f1e090030e6958e45c46c6313291532e6ed8/mlmodels/models.py", line 299, in config_get_pars
<br />    out_p     = path_norm_dict( js.get("out_pars") )
<br />  File "https://github.com/arita37/mlmodels/tree/2675f1e090030e6958e45c46c6313291532e6ed8/mlmodels/util.py", line 201, in path_norm_dict
<br />    for k,v in ddict.items():
<br />AttributeError: 'NoneType' object has no attribute 'items'



### Error 75, [Traceback at line 1478](https://github.com/arita37/mlmodels_store/blob/master/log_json/log_json.py#L1478)<br />1478..Traceback (most recent call last):
<br />  File "/opt/hostedtoolcache/Python/3.6.10/x64/bin/ml_models", line 11, in <module>
<br />    load_entry_point('mlmodels', 'console_scripts', 'ml_models')()
<br />  File "https://github.com/arita37/mlmodels/tree/2675f1e090030e6958e45c46c6313291532e6ed8/mlmodels/models.py", line 530, in main
<br />    fit_cli(arg)
<br />  File "https://github.com/arita37/mlmodels/tree/2675f1e090030e6958e45c46c6313291532e6ed8/mlmodels/models.py", line 424, in fit_cli
<br />    model, sess = fit(module, model, data_pars=data_p, compute_pars=compute_p, out_pars=out_p)
<br />  File "https://github.com/arita37/mlmodels/tree/2675f1e090030e6958e45c46c6313291532e6ed8/mlmodels/models.py", line 125, in fit
<br />    return module.fit(model, data_pars=data_pars, compute_pars=compute_pars, out_pars=out_pars, **kwarg)
<br />  File "https://github.com/arita37/mlmodels/tree/2675f1e090030e6958e45c46c6313291532e6ed8/mlmodels/model_tch/torchhub.py", line 222, in fit
<br />    train_iter, valid_iter = get_dataset(data_pars)
<br />  File "https://github.com/arita37/mlmodels/tree/2675f1e090030e6958e45c46c6313291532e6ed8/mlmodels/model_tch/torchhub.py", line 190, in get_dataset
<br />    loader = DataLoader(data_pars)
<br />  File "https://github.com/arita37/mlmodels/tree/2675f1e090030e6958e45c46c6313291532e6ed8/mlmodels/dataloader.py", line 209, in __init__
<br />    self.data_info                = data_pars['data_info']
<br />KeyError: 'data_info'



### Error 76, [Traceback at line 1505](https://github.com/arita37/mlmodels_store/blob/master/log_json/log_json.py#L1505)<br />1505..Traceback (most recent call last):
<br />  File "/opt/hostedtoolcache/Python/3.6.10/x64/bin/ml_models", line 11, in <module>
<br />    load_entry_point('mlmodels', 'console_scripts', 'ml_models')()
<br />  File "https://github.com/arita37/mlmodels/tree/2675f1e090030e6958e45c46c6313291532e6ed8/mlmodels/models.py", line 530, in main
<br />    fit_cli(arg)
<br />  File "https://github.com/arita37/mlmodels/tree/2675f1e090030e6958e45c46c6313291532e6ed8/mlmodels/models.py", line 413, in fit_cli
<br />    model_p, data_p, compute_p, out_p = config_get_pars(config_file, arg.config_mode)
<br />  File "https://github.com/arita37/mlmodels/tree/2675f1e090030e6958e45c46c6313291532e6ed8/mlmodels/models.py", line 299, in config_get_pars
<br />    out_p     = path_norm_dict( js.get("out_pars") )
<br />  File "https://github.com/arita37/mlmodels/tree/2675f1e090030e6958e45c46c6313291532e6ed8/mlmodels/util.py", line 201, in path_norm_dict
<br />    for k,v in ddict.items():
<br />AttributeError: 'NoneType' object has no attribute 'items'



### Error 77, [Traceback at line 1538](https://github.com/arita37/mlmodels_store/blob/master/log_json/log_json.py#L1538)<br />1538..Traceback (most recent call last):
<br />  File "/opt/hostedtoolcache/Python/3.6.10/x64/bin/ml_models", line 11, in <module>
<br />    load_entry_point('mlmodels', 'console_scripts', 'ml_models')()
<br />  File "https://github.com/arita37/mlmodels/tree/2675f1e090030e6958e45c46c6313291532e6ed8/mlmodels/models.py", line 530, in main
<br />    fit_cli(arg)
<br />  File "https://github.com/arita37/mlmodels/tree/2675f1e090030e6958e45c46c6313291532e6ed8/mlmodels/models.py", line 424, in fit_cli
<br />    model, sess = fit(module, model, data_pars=data_p, compute_pars=compute_p, out_pars=out_p)
<br />  File "https://github.com/arita37/mlmodels/tree/2675f1e090030e6958e45c46c6313291532e6ed8/mlmodels/models.py", line 125, in fit
<br />    return module.fit(model, data_pars=data_pars, compute_pars=compute_pars, out_pars=out_pars, **kwarg)
<br />  File "https://github.com/arita37/mlmodels/tree/2675f1e090030e6958e45c46c6313291532e6ed8/mlmodels/model_tch/torchhub.py", line 222, in fit
<br />    train_iter, valid_iter = get_dataset(data_pars)
<br />  File "https://github.com/arita37/mlmodels/tree/2675f1e090030e6958e45c46c6313291532e6ed8/mlmodels/model_tch/torchhub.py", line 190, in get_dataset
<br />    loader = DataLoader(data_pars)
<br />  File "https://github.com/arita37/mlmodels/tree/2675f1e090030e6958e45c46c6313291532e6ed8/mlmodels/dataloader.py", line 209, in __init__
<br />    self.data_info                = data_pars['data_info']
<br />KeyError: 'data_info'



### Error 78, [Traceback at line 1565](https://github.com/arita37/mlmodels_store/blob/master/log_json/log_json.py#L1565)<br />1565..Traceback (most recent call last):
<br />  File "/opt/hostedtoolcache/Python/3.6.10/x64/bin/ml_models", line 11, in <module>
<br />    load_entry_point('mlmodels', 'console_scripts', 'ml_models')()
<br />  File "https://github.com/arita37/mlmodels/tree/2675f1e090030e6958e45c46c6313291532e6ed8/mlmodels/models.py", line 530, in main
<br />    fit_cli(arg)
<br />  File "https://github.com/arita37/mlmodels/tree/2675f1e090030e6958e45c46c6313291532e6ed8/mlmodels/models.py", line 413, in fit_cli
<br />    model_p, data_p, compute_p, out_p = config_get_pars(config_file, arg.config_mode)
<br />  File "https://github.com/arita37/mlmodels/tree/2675f1e090030e6958e45c46c6313291532e6ed8/mlmodels/models.py", line 299, in config_get_pars
<br />    out_p     = path_norm_dict( js.get("out_pars") )
<br />  File "https://github.com/arita37/mlmodels/tree/2675f1e090030e6958e45c46c6313291532e6ed8/mlmodels/util.py", line 201, in path_norm_dict
<br />    for k,v in ddict.items():
<br />AttributeError: 'NoneType' object has no attribute 'items'



### Error 79, [Traceback at line 1598](https://github.com/arita37/mlmodels_store/blob/master/log_json/log_json.py#L1598)<br />1598..Traceback (most recent call last):
<br />  File "/opt/hostedtoolcache/Python/3.6.10/x64/bin/ml_models", line 11, in <module>
<br />    load_entry_point('mlmodels', 'console_scripts', 'ml_models')()
<br />  File "https://github.com/arita37/mlmodels/tree/2675f1e090030e6958e45c46c6313291532e6ed8/mlmodels/models.py", line 530, in main
<br />    fit_cli(arg)
<br />  File "https://github.com/arita37/mlmodels/tree/2675f1e090030e6958e45c46c6313291532e6ed8/mlmodels/models.py", line 424, in fit_cli
<br />    model, sess = fit(module, model, data_pars=data_p, compute_pars=compute_p, out_pars=out_p)
<br />  File "https://github.com/arita37/mlmodels/tree/2675f1e090030e6958e45c46c6313291532e6ed8/mlmodels/models.py", line 125, in fit
<br />    return module.fit(model, data_pars=data_pars, compute_pars=compute_pars, out_pars=out_pars, **kwarg)
<br />  File "https://github.com/arita37/mlmodels/tree/2675f1e090030e6958e45c46c6313291532e6ed8/mlmodels/model_tch/torchhub.py", line 222, in fit
<br />    train_iter, valid_iter = get_dataset(data_pars)
<br />  File "https://github.com/arita37/mlmodels/tree/2675f1e090030e6958e45c46c6313291532e6ed8/mlmodels/model_tch/torchhub.py", line 190, in get_dataset
<br />    loader = DataLoader(data_pars)
<br />  File "https://github.com/arita37/mlmodels/tree/2675f1e090030e6958e45c46c6313291532e6ed8/mlmodels/dataloader.py", line 209, in __init__
<br />    self.data_info                = data_pars['data_info']
<br />KeyError: 'data_info'



### Error 80, [Traceback at line 1625](https://github.com/arita37/mlmodels_store/blob/master/log_json/log_json.py#L1625)<br />1625..Traceback (most recent call last):
<br />  File "/opt/hostedtoolcache/Python/3.6.10/x64/bin/ml_models", line 11, in <module>
<br />    load_entry_point('mlmodels', 'console_scripts', 'ml_models')()
<br />  File "https://github.com/arita37/mlmodels/tree/2675f1e090030e6958e45c46c6313291532e6ed8/mlmodels/models.py", line 530, in main
<br />    fit_cli(arg)
<br />  File "https://github.com/arita37/mlmodels/tree/2675f1e090030e6958e45c46c6313291532e6ed8/mlmodels/models.py", line 413, in fit_cli
<br />    model_p, data_p, compute_p, out_p = config_get_pars(config_file, arg.config_mode)
<br />  File "https://github.com/arita37/mlmodels/tree/2675f1e090030e6958e45c46c6313291532e6ed8/mlmodels/models.py", line 299, in config_get_pars
<br />    out_p     = path_norm_dict( js.get("out_pars") )
<br />  File "https://github.com/arita37/mlmodels/tree/2675f1e090030e6958e45c46c6313291532e6ed8/mlmodels/util.py", line 201, in path_norm_dict
<br />    for k,v in ddict.items():
<br />AttributeError: 'NoneType' object has no attribute 'items'



### Error 81, [Traceback at line 1658](https://github.com/arita37/mlmodels_store/blob/master/log_json/log_json.py#L1658)<br />1658..Traceback (most recent call last):
<br />  File "/opt/hostedtoolcache/Python/3.6.10/x64/bin/ml_models", line 11, in <module>
<br />    load_entry_point('mlmodels', 'console_scripts', 'ml_models')()
<br />  File "https://github.com/arita37/mlmodels/tree/2675f1e090030e6958e45c46c6313291532e6ed8/mlmodels/models.py", line 530, in main
<br />    fit_cli(arg)
<br />  File "https://github.com/arita37/mlmodels/tree/2675f1e090030e6958e45c46c6313291532e6ed8/mlmodels/models.py", line 424, in fit_cli
<br />    model, sess = fit(module, model, data_pars=data_p, compute_pars=compute_p, out_pars=out_p)
<br />  File "https://github.com/arita37/mlmodels/tree/2675f1e090030e6958e45c46c6313291532e6ed8/mlmodels/models.py", line 125, in fit
<br />    return module.fit(model, data_pars=data_pars, compute_pars=compute_pars, out_pars=out_pars, **kwarg)
<br />  File "https://github.com/arita37/mlmodels/tree/2675f1e090030e6958e45c46c6313291532e6ed8/mlmodels/model_tch/torchhub.py", line 222, in fit
<br />    train_iter, valid_iter = get_dataset(data_pars)
<br />  File "https://github.com/arita37/mlmodels/tree/2675f1e090030e6958e45c46c6313291532e6ed8/mlmodels/model_tch/torchhub.py", line 190, in get_dataset
<br />    loader = DataLoader(data_pars)
<br />  File "https://github.com/arita37/mlmodels/tree/2675f1e090030e6958e45c46c6313291532e6ed8/mlmodels/dataloader.py", line 209, in __init__
<br />    self.data_info                = data_pars['data_info']
<br />KeyError: 'data_info'



### Error 82, [Traceback at line 1685](https://github.com/arita37/mlmodels_store/blob/master/log_json/log_json.py#L1685)<br />1685..Traceback (most recent call last):
<br />  File "/opt/hostedtoolcache/Python/3.6.10/x64/bin/ml_models", line 11, in <module>
<br />    load_entry_point('mlmodels', 'console_scripts', 'ml_models')()
<br />  File "https://github.com/arita37/mlmodels/tree/2675f1e090030e6958e45c46c6313291532e6ed8/mlmodels/models.py", line 530, in main
<br />    fit_cli(arg)
<br />  File "https://github.com/arita37/mlmodels/tree/2675f1e090030e6958e45c46c6313291532e6ed8/mlmodels/models.py", line 413, in fit_cli
<br />    model_p, data_p, compute_p, out_p = config_get_pars(config_file, arg.config_mode)
<br />  File "https://github.com/arita37/mlmodels/tree/2675f1e090030e6958e45c46c6313291532e6ed8/mlmodels/models.py", line 299, in config_get_pars
<br />    out_p     = path_norm_dict( js.get("out_pars") )
<br />  File "https://github.com/arita37/mlmodels/tree/2675f1e090030e6958e45c46c6313291532e6ed8/mlmodels/util.py", line 201, in path_norm_dict
<br />    for k,v in ddict.items():
<br />AttributeError: 'NoneType' object has no attribute 'items'



### Error 83, [Traceback at line 1718](https://github.com/arita37/mlmodels_store/blob/master/log_json/log_json.py#L1718)<br />1718..Traceback (most recent call last):
<br />  File "/opt/hostedtoolcache/Python/3.6.10/x64/bin/ml_models", line 11, in <module>
<br />    load_entry_point('mlmodels', 'console_scripts', 'ml_models')()
<br />  File "https://github.com/arita37/mlmodels/tree/2675f1e090030e6958e45c46c6313291532e6ed8/mlmodels/models.py", line 530, in main
<br />    fit_cli(arg)
<br />  File "https://github.com/arita37/mlmodels/tree/2675f1e090030e6958e45c46c6313291532e6ed8/mlmodels/models.py", line 424, in fit_cli
<br />    model, sess = fit(module, model, data_pars=data_p, compute_pars=compute_p, out_pars=out_p)
<br />  File "https://github.com/arita37/mlmodels/tree/2675f1e090030e6958e45c46c6313291532e6ed8/mlmodels/models.py", line 125, in fit
<br />    return module.fit(model, data_pars=data_pars, compute_pars=compute_pars, out_pars=out_pars, **kwarg)
<br />  File "https://github.com/arita37/mlmodels/tree/2675f1e090030e6958e45c46c6313291532e6ed8/mlmodels/model_tch/torchhub.py", line 222, in fit
<br />    train_iter, valid_iter = get_dataset(data_pars)
<br />  File "https://github.com/arita37/mlmodels/tree/2675f1e090030e6958e45c46c6313291532e6ed8/mlmodels/model_tch/torchhub.py", line 190, in get_dataset
<br />    loader = DataLoader(data_pars)
<br />  File "https://github.com/arita37/mlmodels/tree/2675f1e090030e6958e45c46c6313291532e6ed8/mlmodels/dataloader.py", line 209, in __init__
<br />    self.data_info                = data_pars['data_info']
<br />KeyError: 'data_info'



### Error 84, [Traceback at line 1745](https://github.com/arita37/mlmodels_store/blob/master/log_json/log_json.py#L1745)<br />1745..Traceback (most recent call last):
<br />  File "/opt/hostedtoolcache/Python/3.6.10/x64/bin/ml_models", line 11, in <module>
<br />    load_entry_point('mlmodels', 'console_scripts', 'ml_models')()
<br />  File "https://github.com/arita37/mlmodels/tree/2675f1e090030e6958e45c46c6313291532e6ed8/mlmodels/models.py", line 530, in main
<br />    fit_cli(arg)
<br />  File "https://github.com/arita37/mlmodels/tree/2675f1e090030e6958e45c46c6313291532e6ed8/mlmodels/models.py", line 413, in fit_cli
<br />    model_p, data_p, compute_p, out_p = config_get_pars(config_file, arg.config_mode)
<br />  File "https://github.com/arita37/mlmodels/tree/2675f1e090030e6958e45c46c6313291532e6ed8/mlmodels/models.py", line 299, in config_get_pars
<br />    out_p     = path_norm_dict( js.get("out_pars") )
<br />  File "https://github.com/arita37/mlmodels/tree/2675f1e090030e6958e45c46c6313291532e6ed8/mlmodels/util.py", line 201, in path_norm_dict
<br />    for k,v in ddict.items():
<br />AttributeError: 'NoneType' object has no attribute 'items'



### Error 85, [Traceback at line 1778](https://github.com/arita37/mlmodels_store/blob/master/log_json/log_json.py#L1778)<br />1778..Traceback (most recent call last):
<br />  File "/opt/hostedtoolcache/Python/3.6.10/x64/bin/ml_models", line 11, in <module>
<br />    load_entry_point('mlmodels', 'console_scripts', 'ml_models')()
<br />  File "https://github.com/arita37/mlmodels/tree/2675f1e090030e6958e45c46c6313291532e6ed8/mlmodels/models.py", line 530, in main
<br />    fit_cli(arg)
<br />  File "https://github.com/arita37/mlmodels/tree/2675f1e090030e6958e45c46c6313291532e6ed8/mlmodels/models.py", line 424, in fit_cli
<br />    model, sess = fit(module, model, data_pars=data_p, compute_pars=compute_p, out_pars=out_p)
<br />  File "https://github.com/arita37/mlmodels/tree/2675f1e090030e6958e45c46c6313291532e6ed8/mlmodels/models.py", line 125, in fit
<br />    return module.fit(model, data_pars=data_pars, compute_pars=compute_pars, out_pars=out_pars, **kwarg)
<br />  File "https://github.com/arita37/mlmodels/tree/2675f1e090030e6958e45c46c6313291532e6ed8/mlmodels/model_tch/torchhub.py", line 222, in fit
<br />    train_iter, valid_iter = get_dataset(data_pars)
<br />  File "https://github.com/arita37/mlmodels/tree/2675f1e090030e6958e45c46c6313291532e6ed8/mlmodels/model_tch/torchhub.py", line 190, in get_dataset
<br />    loader = DataLoader(data_pars)
<br />  File "https://github.com/arita37/mlmodels/tree/2675f1e090030e6958e45c46c6313291532e6ed8/mlmodels/dataloader.py", line 209, in __init__
<br />    self.data_info                = data_pars['data_info']
<br />KeyError: 'data_info'



### Error 86, [Traceback at line 1805](https://github.com/arita37/mlmodels_store/blob/master/log_json/log_json.py#L1805)<br />1805..Traceback (most recent call last):
<br />  File "/opt/hostedtoolcache/Python/3.6.10/x64/bin/ml_models", line 11, in <module>
<br />    load_entry_point('mlmodels', 'console_scripts', 'ml_models')()
<br />  File "https://github.com/arita37/mlmodels/tree/2675f1e090030e6958e45c46c6313291532e6ed8/mlmodels/models.py", line 530, in main
<br />    fit_cli(arg)
<br />  File "https://github.com/arita37/mlmodels/tree/2675f1e090030e6958e45c46c6313291532e6ed8/mlmodels/models.py", line 413, in fit_cli
<br />    model_p, data_p, compute_p, out_p = config_get_pars(config_file, arg.config_mode)
<br />  File "https://github.com/arita37/mlmodels/tree/2675f1e090030e6958e45c46c6313291532e6ed8/mlmodels/models.py", line 299, in config_get_pars
<br />    out_p     = path_norm_dict( js.get("out_pars") )
<br />  File "https://github.com/arita37/mlmodels/tree/2675f1e090030e6958e45c46c6313291532e6ed8/mlmodels/util.py", line 201, in path_norm_dict
<br />    for k,v in ddict.items():
<br />AttributeError: 'NoneType' object has no attribute 'items'



### Error 87, [Traceback at line 1838](https://github.com/arita37/mlmodels_store/blob/master/log_json/log_json.py#L1838)<br />1838..Traceback (most recent call last):
<br />  File "/opt/hostedtoolcache/Python/3.6.10/x64/bin/ml_models", line 11, in <module>
<br />    load_entry_point('mlmodels', 'console_scripts', 'ml_models')()
<br />  File "https://github.com/arita37/mlmodels/tree/2675f1e090030e6958e45c46c6313291532e6ed8/mlmodels/models.py", line 530, in main
<br />    fit_cli(arg)
<br />  File "https://github.com/arita37/mlmodels/tree/2675f1e090030e6958e45c46c6313291532e6ed8/mlmodels/models.py", line 424, in fit_cli
<br />    model, sess = fit(module, model, data_pars=data_p, compute_pars=compute_p, out_pars=out_p)
<br />  File "https://github.com/arita37/mlmodels/tree/2675f1e090030e6958e45c46c6313291532e6ed8/mlmodels/models.py", line 125, in fit
<br />    return module.fit(model, data_pars=data_pars, compute_pars=compute_pars, out_pars=out_pars, **kwarg)
<br />  File "https://github.com/arita37/mlmodels/tree/2675f1e090030e6958e45c46c6313291532e6ed8/mlmodels/model_tch/torchhub.py", line 222, in fit
<br />    train_iter, valid_iter = get_dataset(data_pars)
<br />  File "https://github.com/arita37/mlmodels/tree/2675f1e090030e6958e45c46c6313291532e6ed8/mlmodels/model_tch/torchhub.py", line 190, in get_dataset
<br />    loader = DataLoader(data_pars)
<br />  File "https://github.com/arita37/mlmodels/tree/2675f1e090030e6958e45c46c6313291532e6ed8/mlmodels/dataloader.py", line 209, in __init__
<br />    self.data_info                = data_pars['data_info']
<br />KeyError: 'data_info'



### Error 88, [Traceback at line 1865](https://github.com/arita37/mlmodels_store/blob/master/log_json/log_json.py#L1865)<br />1865..Traceback (most recent call last):
<br />  File "/opt/hostedtoolcache/Python/3.6.10/x64/bin/ml_models", line 11, in <module>
<br />    load_entry_point('mlmodels', 'console_scripts', 'ml_models')()
<br />  File "https://github.com/arita37/mlmodels/tree/2675f1e090030e6958e45c46c6313291532e6ed8/mlmodels/models.py", line 530, in main
<br />    fit_cli(arg)
<br />  File "https://github.com/arita37/mlmodels/tree/2675f1e090030e6958e45c46c6313291532e6ed8/mlmodels/models.py", line 413, in fit_cli
<br />    model_p, data_p, compute_p, out_p = config_get_pars(config_file, arg.config_mode)
<br />  File "https://github.com/arita37/mlmodels/tree/2675f1e090030e6958e45c46c6313291532e6ed8/mlmodels/models.py", line 299, in config_get_pars
<br />    out_p     = path_norm_dict( js.get("out_pars") )
<br />  File "https://github.com/arita37/mlmodels/tree/2675f1e090030e6958e45c46c6313291532e6ed8/mlmodels/util.py", line 201, in path_norm_dict
<br />    for k,v in ddict.items():
<br />AttributeError: 'NoneType' object has no attribute 'items'



### Error 89, [Traceback at line 1898](https://github.com/arita37/mlmodels_store/blob/master/log_json/log_json.py#L1898)<br />1898..Traceback (most recent call last):
<br />  File "/opt/hostedtoolcache/Python/3.6.10/x64/bin/ml_models", line 11, in <module>
<br />    load_entry_point('mlmodels', 'console_scripts', 'ml_models')()
<br />  File "https://github.com/arita37/mlmodels/tree/2675f1e090030e6958e45c46c6313291532e6ed8/mlmodels/models.py", line 530, in main
<br />    fit_cli(arg)
<br />  File "https://github.com/arita37/mlmodels/tree/2675f1e090030e6958e45c46c6313291532e6ed8/mlmodels/models.py", line 424, in fit_cli
<br />    model, sess = fit(module, model, data_pars=data_p, compute_pars=compute_p, out_pars=out_p)
<br />  File "https://github.com/arita37/mlmodels/tree/2675f1e090030e6958e45c46c6313291532e6ed8/mlmodels/models.py", line 125, in fit
<br />    return module.fit(model, data_pars=data_pars, compute_pars=compute_pars, out_pars=out_pars, **kwarg)
<br />  File "https://github.com/arita37/mlmodels/tree/2675f1e090030e6958e45c46c6313291532e6ed8/mlmodels/model_tch/torchhub.py", line 222, in fit
<br />    train_iter, valid_iter = get_dataset(data_pars)
<br />  File "https://github.com/arita37/mlmodels/tree/2675f1e090030e6958e45c46c6313291532e6ed8/mlmodels/model_tch/torchhub.py", line 190, in get_dataset
<br />    loader = DataLoader(data_pars)
<br />  File "https://github.com/arita37/mlmodels/tree/2675f1e090030e6958e45c46c6313291532e6ed8/mlmodels/dataloader.py", line 209, in __init__
<br />    self.data_info                = data_pars['data_info']
<br />KeyError: 'data_info'



### Error 90, [Traceback at line 1925](https://github.com/arita37/mlmodels_store/blob/master/log_json/log_json.py#L1925)<br />1925..Traceback (most recent call last):
<br />  File "/opt/hostedtoolcache/Python/3.6.10/x64/bin/ml_models", line 11, in <module>
<br />    load_entry_point('mlmodels', 'console_scripts', 'ml_models')()
<br />  File "https://github.com/arita37/mlmodels/tree/2675f1e090030e6958e45c46c6313291532e6ed8/mlmodels/models.py", line 530, in main
<br />    fit_cli(arg)
<br />  File "https://github.com/arita37/mlmodels/tree/2675f1e090030e6958e45c46c6313291532e6ed8/mlmodels/models.py", line 413, in fit_cli
<br />    model_p, data_p, compute_p, out_p = config_get_pars(config_file, arg.config_mode)
<br />  File "https://github.com/arita37/mlmodels/tree/2675f1e090030e6958e45c46c6313291532e6ed8/mlmodels/models.py", line 299, in config_get_pars
<br />    out_p     = path_norm_dict( js.get("out_pars") )
<br />  File "https://github.com/arita37/mlmodels/tree/2675f1e090030e6958e45c46c6313291532e6ed8/mlmodels/util.py", line 201, in path_norm_dict
<br />    for k,v in ddict.items():
<br />AttributeError: 'NoneType' object has no attribute 'items'



### Error 91, [Traceback at line 1958](https://github.com/arita37/mlmodels_store/blob/master/log_json/log_json.py#L1958)<br />1958..Traceback (most recent call last):
<br />  File "/opt/hostedtoolcache/Python/3.6.10/x64/bin/ml_models", line 11, in <module>
<br />    load_entry_point('mlmodels', 'console_scripts', 'ml_models')()
<br />  File "https://github.com/arita37/mlmodels/tree/2675f1e090030e6958e45c46c6313291532e6ed8/mlmodels/models.py", line 530, in main
<br />    fit_cli(arg)
<br />  File "https://github.com/arita37/mlmodels/tree/2675f1e090030e6958e45c46c6313291532e6ed8/mlmodels/models.py", line 424, in fit_cli
<br />    model, sess = fit(module, model, data_pars=data_p, compute_pars=compute_p, out_pars=out_p)
<br />  File "https://github.com/arita37/mlmodels/tree/2675f1e090030e6958e45c46c6313291532e6ed8/mlmodels/models.py", line 125, in fit
<br />    return module.fit(model, data_pars=data_pars, compute_pars=compute_pars, out_pars=out_pars, **kwarg)
<br />  File "https://github.com/arita37/mlmodels/tree/2675f1e090030e6958e45c46c6313291532e6ed8/mlmodels/model_tch/torchhub.py", line 222, in fit
<br />    train_iter, valid_iter = get_dataset(data_pars)
<br />  File "https://github.com/arita37/mlmodels/tree/2675f1e090030e6958e45c46c6313291532e6ed8/mlmodels/model_tch/torchhub.py", line 190, in get_dataset
<br />    loader = DataLoader(data_pars)
<br />  File "https://github.com/arita37/mlmodels/tree/2675f1e090030e6958e45c46c6313291532e6ed8/mlmodels/dataloader.py", line 209, in __init__
<br />    self.data_info                = data_pars['data_info']
<br />KeyError: 'data_info'



### Error 92, [Traceback at line 1985](https://github.com/arita37/mlmodels_store/blob/master/log_json/log_json.py#L1985)<br />1985..Traceback (most recent call last):
<br />  File "/opt/hostedtoolcache/Python/3.6.10/x64/bin/ml_models", line 11, in <module>
<br />    load_entry_point('mlmodels', 'console_scripts', 'ml_models')()
<br />  File "https://github.com/arita37/mlmodels/tree/2675f1e090030e6958e45c46c6313291532e6ed8/mlmodels/models.py", line 530, in main
<br />    fit_cli(arg)
<br />  File "https://github.com/arita37/mlmodels/tree/2675f1e090030e6958e45c46c6313291532e6ed8/mlmodels/models.py", line 413, in fit_cli
<br />    model_p, data_p, compute_p, out_p = config_get_pars(config_file, arg.config_mode)
<br />  File "https://github.com/arita37/mlmodels/tree/2675f1e090030e6958e45c46c6313291532e6ed8/mlmodels/models.py", line 299, in config_get_pars
<br />    out_p     = path_norm_dict( js.get("out_pars") )
<br />  File "https://github.com/arita37/mlmodels/tree/2675f1e090030e6958e45c46c6313291532e6ed8/mlmodels/util.py", line 201, in path_norm_dict
<br />    for k,v in ddict.items():
<br />AttributeError: 'NoneType' object has no attribute 'items'



### Error 93, [Traceback at line 2018](https://github.com/arita37/mlmodels_store/blob/master/log_json/log_json.py#L2018)<br />2018..Traceback (most recent call last):
<br />  File "/opt/hostedtoolcache/Python/3.6.10/x64/bin/ml_models", line 11, in <module>
<br />    load_entry_point('mlmodels', 'console_scripts', 'ml_models')()
<br />  File "https://github.com/arita37/mlmodels/tree/2675f1e090030e6958e45c46c6313291532e6ed8/mlmodels/models.py", line 530, in main
<br />    fit_cli(arg)
<br />  File "https://github.com/arita37/mlmodels/tree/2675f1e090030e6958e45c46c6313291532e6ed8/mlmodels/models.py", line 424, in fit_cli
<br />    model, sess = fit(module, model, data_pars=data_p, compute_pars=compute_p, out_pars=out_p)
<br />  File "https://github.com/arita37/mlmodels/tree/2675f1e090030e6958e45c46c6313291532e6ed8/mlmodels/models.py", line 125, in fit
<br />    return module.fit(model, data_pars=data_pars, compute_pars=compute_pars, out_pars=out_pars, **kwarg)
<br />  File "https://github.com/arita37/mlmodels/tree/2675f1e090030e6958e45c46c6313291532e6ed8/mlmodels/model_tch/torchhub.py", line 222, in fit
<br />    train_iter, valid_iter = get_dataset(data_pars)
<br />  File "https://github.com/arita37/mlmodels/tree/2675f1e090030e6958e45c46c6313291532e6ed8/mlmodels/model_tch/torchhub.py", line 190, in get_dataset
<br />    loader = DataLoader(data_pars)
<br />  File "https://github.com/arita37/mlmodels/tree/2675f1e090030e6958e45c46c6313291532e6ed8/mlmodels/dataloader.py", line 209, in __init__
<br />    self.data_info                = data_pars['data_info']
<br />KeyError: 'data_info'



### Error 94, [Traceback at line 2045](https://github.com/arita37/mlmodels_store/blob/master/log_json/log_json.py#L2045)<br />2045..Traceback (most recent call last):
<br />  File "/opt/hostedtoolcache/Python/3.6.10/x64/bin/ml_models", line 11, in <module>
<br />    load_entry_point('mlmodels', 'console_scripts', 'ml_models')()
<br />  File "https://github.com/arita37/mlmodels/tree/2675f1e090030e6958e45c46c6313291532e6ed8/mlmodels/models.py", line 530, in main
<br />    fit_cli(arg)
<br />  File "https://github.com/arita37/mlmodels/tree/2675f1e090030e6958e45c46c6313291532e6ed8/mlmodels/models.py", line 413, in fit_cli
<br />    model_p, data_p, compute_p, out_p = config_get_pars(config_file, arg.config_mode)
<br />  File "https://github.com/arita37/mlmodels/tree/2675f1e090030e6958e45c46c6313291532e6ed8/mlmodels/models.py", line 299, in config_get_pars
<br />    out_p     = path_norm_dict( js.get("out_pars") )
<br />  File "https://github.com/arita37/mlmodels/tree/2675f1e090030e6958e45c46c6313291532e6ed8/mlmodels/util.py", line 201, in path_norm_dict
<br />    for k,v in ddict.items():
<br />AttributeError: 'NoneType' object has no attribute 'items'



### Error 95, [Traceback at line 2078](https://github.com/arita37/mlmodels_store/blob/master/log_json/log_json.py#L2078)<br />2078..Traceback (most recent call last):
<br />  File "/opt/hostedtoolcache/Python/3.6.10/x64/bin/ml_models", line 11, in <module>
<br />    load_entry_point('mlmodels', 'console_scripts', 'ml_models')()
<br />  File "https://github.com/arita37/mlmodels/tree/2675f1e090030e6958e45c46c6313291532e6ed8/mlmodels/models.py", line 530, in main
<br />    fit_cli(arg)
<br />  File "https://github.com/arita37/mlmodels/tree/2675f1e090030e6958e45c46c6313291532e6ed8/mlmodels/models.py", line 424, in fit_cli
<br />    model, sess = fit(module, model, data_pars=data_p, compute_pars=compute_p, out_pars=out_p)
<br />  File "https://github.com/arita37/mlmodels/tree/2675f1e090030e6958e45c46c6313291532e6ed8/mlmodels/models.py", line 125, in fit
<br />    return module.fit(model, data_pars=data_pars, compute_pars=compute_pars, out_pars=out_pars, **kwarg)
<br />  File "https://github.com/arita37/mlmodels/tree/2675f1e090030e6958e45c46c6313291532e6ed8/mlmodels/model_tch/torchhub.py", line 222, in fit
<br />    train_iter, valid_iter = get_dataset(data_pars)
<br />  File "https://github.com/arita37/mlmodels/tree/2675f1e090030e6958e45c46c6313291532e6ed8/mlmodels/model_tch/torchhub.py", line 190, in get_dataset
<br />    loader = DataLoader(data_pars)
<br />  File "https://github.com/arita37/mlmodels/tree/2675f1e090030e6958e45c46c6313291532e6ed8/mlmodels/dataloader.py", line 209, in __init__
<br />    self.data_info                = data_pars['data_info']
<br />KeyError: 'data_info'



### Error 96, [Traceback at line 2105](https://github.com/arita37/mlmodels_store/blob/master/log_json/log_json.py#L2105)<br />2105..Traceback (most recent call last):
<br />  File "/opt/hostedtoolcache/Python/3.6.10/x64/bin/ml_models", line 11, in <module>
<br />    load_entry_point('mlmodels', 'console_scripts', 'ml_models')()
<br />  File "https://github.com/arita37/mlmodels/tree/2675f1e090030e6958e45c46c6313291532e6ed8/mlmodels/models.py", line 530, in main
<br />    fit_cli(arg)
<br />  File "https://github.com/arita37/mlmodels/tree/2675f1e090030e6958e45c46c6313291532e6ed8/mlmodels/models.py", line 413, in fit_cli
<br />    model_p, data_p, compute_p, out_p = config_get_pars(config_file, arg.config_mode)
<br />  File "https://github.com/arita37/mlmodels/tree/2675f1e090030e6958e45c46c6313291532e6ed8/mlmodels/models.py", line 299, in config_get_pars
<br />    out_p     = path_norm_dict( js.get("out_pars") )
<br />  File "https://github.com/arita37/mlmodels/tree/2675f1e090030e6958e45c46c6313291532e6ed8/mlmodels/util.py", line 201, in path_norm_dict
<br />    for k,v in ddict.items():
<br />AttributeError: 'NoneType' object has no attribute 'items'



### Error 97, [Traceback at line 2138](https://github.com/arita37/mlmodels_store/blob/master/log_json/log_json.py#L2138)<br />2138..Traceback (most recent call last):
<br />  File "/opt/hostedtoolcache/Python/3.6.10/x64/bin/ml_models", line 11, in <module>
<br />    load_entry_point('mlmodels', 'console_scripts', 'ml_models')()
<br />  File "https://github.com/arita37/mlmodels/tree/2675f1e090030e6958e45c46c6313291532e6ed8/mlmodels/models.py", line 530, in main
<br />    fit_cli(arg)
<br />  File "https://github.com/arita37/mlmodels/tree/2675f1e090030e6958e45c46c6313291532e6ed8/mlmodels/models.py", line 424, in fit_cli
<br />    model, sess = fit(module, model, data_pars=data_p, compute_pars=compute_p, out_pars=out_p)
<br />  File "https://github.com/arita37/mlmodels/tree/2675f1e090030e6958e45c46c6313291532e6ed8/mlmodels/models.py", line 125, in fit
<br />    return module.fit(model, data_pars=data_pars, compute_pars=compute_pars, out_pars=out_pars, **kwarg)
<br />  File "https://github.com/arita37/mlmodels/tree/2675f1e090030e6958e45c46c6313291532e6ed8/mlmodels/model_tch/torchhub.py", line 222, in fit
<br />    train_iter, valid_iter = get_dataset(data_pars)
<br />  File "https://github.com/arita37/mlmodels/tree/2675f1e090030e6958e45c46c6313291532e6ed8/mlmodels/model_tch/torchhub.py", line 190, in get_dataset
<br />    loader = DataLoader(data_pars)
<br />  File "https://github.com/arita37/mlmodels/tree/2675f1e090030e6958e45c46c6313291532e6ed8/mlmodels/dataloader.py", line 209, in __init__
<br />    self.data_info                = data_pars['data_info']
<br />KeyError: 'data_info'



### Error 98, [Traceback at line 2165](https://github.com/arita37/mlmodels_store/blob/master/log_json/log_json.py#L2165)<br />2165..Traceback (most recent call last):
<br />  File "/opt/hostedtoolcache/Python/3.6.10/x64/bin/ml_models", line 11, in <module>
<br />    load_entry_point('mlmodels', 'console_scripts', 'ml_models')()
<br />  File "https://github.com/arita37/mlmodels/tree/2675f1e090030e6958e45c46c6313291532e6ed8/mlmodels/models.py", line 530, in main
<br />    fit_cli(arg)
<br />  File "https://github.com/arita37/mlmodels/tree/2675f1e090030e6958e45c46c6313291532e6ed8/mlmodels/models.py", line 413, in fit_cli
<br />    model_p, data_p, compute_p, out_p = config_get_pars(config_file, arg.config_mode)
<br />  File "https://github.com/arita37/mlmodels/tree/2675f1e090030e6958e45c46c6313291532e6ed8/mlmodels/models.py", line 299, in config_get_pars
<br />    out_p     = path_norm_dict( js.get("out_pars") )
<br />  File "https://github.com/arita37/mlmodels/tree/2675f1e090030e6958e45c46c6313291532e6ed8/mlmodels/util.py", line 201, in path_norm_dict
<br />    for k,v in ddict.items():
<br />AttributeError: 'NoneType' object has no attribute 'items'



### Error 99, [Traceback at line 2198](https://github.com/arita37/mlmodels_store/blob/master/log_json/log_json.py#L2198)<br />2198..Traceback (most recent call last):
<br />  File "/opt/hostedtoolcache/Python/3.6.10/x64/bin/ml_models", line 11, in <module>
<br />    load_entry_point('mlmodels', 'console_scripts', 'ml_models')()
<br />  File "https://github.com/arita37/mlmodels/tree/2675f1e090030e6958e45c46c6313291532e6ed8/mlmodels/models.py", line 530, in main
<br />    fit_cli(arg)
<br />  File "https://github.com/arita37/mlmodels/tree/2675f1e090030e6958e45c46c6313291532e6ed8/mlmodels/models.py", line 424, in fit_cli
<br />    model, sess = fit(module, model, data_pars=data_p, compute_pars=compute_p, out_pars=out_p)
<br />  File "https://github.com/arita37/mlmodels/tree/2675f1e090030e6958e45c46c6313291532e6ed8/mlmodels/models.py", line 125, in fit
<br />    return module.fit(model, data_pars=data_pars, compute_pars=compute_pars, out_pars=out_pars, **kwarg)
<br />  File "https://github.com/arita37/mlmodels/tree/2675f1e090030e6958e45c46c6313291532e6ed8/mlmodels/model_tch/torchhub.py", line 222, in fit
<br />    train_iter, valid_iter = get_dataset(data_pars)
<br />  File "https://github.com/arita37/mlmodels/tree/2675f1e090030e6958e45c46c6313291532e6ed8/mlmodels/model_tch/torchhub.py", line 190, in get_dataset
<br />    loader = DataLoader(data_pars)
<br />  File "https://github.com/arita37/mlmodels/tree/2675f1e090030e6958e45c46c6313291532e6ed8/mlmodels/dataloader.py", line 209, in __init__
<br />    self.data_info                = data_pars['data_info']
<br />KeyError: 'data_info'



### Error 100, [Traceback at line 2225](https://github.com/arita37/mlmodels_store/blob/master/log_json/log_json.py#L2225)<br />2225..Traceback (most recent call last):
<br />  File "/opt/hostedtoolcache/Python/3.6.10/x64/bin/ml_models", line 11, in <module>
<br />    load_entry_point('mlmodels', 'console_scripts', 'ml_models')()
<br />  File "https://github.com/arita37/mlmodels/tree/2675f1e090030e6958e45c46c6313291532e6ed8/mlmodels/models.py", line 530, in main
<br />    fit_cli(arg)
<br />  File "https://github.com/arita37/mlmodels/tree/2675f1e090030e6958e45c46c6313291532e6ed8/mlmodels/models.py", line 413, in fit_cli
<br />    model_p, data_p, compute_p, out_p = config_get_pars(config_file, arg.config_mode)
<br />  File "https://github.com/arita37/mlmodels/tree/2675f1e090030e6958e45c46c6313291532e6ed8/mlmodels/models.py", line 299, in config_get_pars
<br />    out_p     = path_norm_dict( js.get("out_pars") )
<br />  File "https://github.com/arita37/mlmodels/tree/2675f1e090030e6958e45c46c6313291532e6ed8/mlmodels/util.py", line 201, in path_norm_dict
<br />    for k,v in ddict.items():
<br />AttributeError: 'NoneType' object has no attribute 'items'



### Error 101, [Traceback at line 2258](https://github.com/arita37/mlmodels_store/blob/master/log_json/log_json.py#L2258)<br />2258..Traceback (most recent call last):
<br />  File "/opt/hostedtoolcache/Python/3.6.10/x64/bin/ml_models", line 11, in <module>
<br />    load_entry_point('mlmodels', 'console_scripts', 'ml_models')()
<br />  File "https://github.com/arita37/mlmodels/tree/2675f1e090030e6958e45c46c6313291532e6ed8/mlmodels/models.py", line 530, in main
<br />    fit_cli(arg)
<br />  File "https://github.com/arita37/mlmodels/tree/2675f1e090030e6958e45c46c6313291532e6ed8/mlmodels/models.py", line 424, in fit_cli
<br />    model, sess = fit(module, model, data_pars=data_p, compute_pars=compute_p, out_pars=out_p)
<br />  File "https://github.com/arita37/mlmodels/tree/2675f1e090030e6958e45c46c6313291532e6ed8/mlmodels/models.py", line 125, in fit
<br />    return module.fit(model, data_pars=data_pars, compute_pars=compute_pars, out_pars=out_pars, **kwarg)
<br />  File "https://github.com/arita37/mlmodels/tree/2675f1e090030e6958e45c46c6313291532e6ed8/mlmodels/model_tch/torchhub.py", line 222, in fit
<br />    train_iter, valid_iter = get_dataset(data_pars)
<br />  File "https://github.com/arita37/mlmodels/tree/2675f1e090030e6958e45c46c6313291532e6ed8/mlmodels/model_tch/torchhub.py", line 190, in get_dataset
<br />    loader = DataLoader(data_pars)
<br />  File "https://github.com/arita37/mlmodels/tree/2675f1e090030e6958e45c46c6313291532e6ed8/mlmodels/dataloader.py", line 209, in __init__
<br />    self.data_info                = data_pars['data_info']
<br />KeyError: 'data_info'



### Error 102, [Traceback at line 2285](https://github.com/arita37/mlmodels_store/blob/master/log_json/log_json.py#L2285)<br />2285..Traceback (most recent call last):
<br />  File "/opt/hostedtoolcache/Python/3.6.10/x64/bin/ml_models", line 11, in <module>
<br />    load_entry_point('mlmodels', 'console_scripts', 'ml_models')()
<br />  File "https://github.com/arita37/mlmodels/tree/2675f1e090030e6958e45c46c6313291532e6ed8/mlmodels/models.py", line 530, in main
<br />    fit_cli(arg)
<br />  File "https://github.com/arita37/mlmodels/tree/2675f1e090030e6958e45c46c6313291532e6ed8/mlmodels/models.py", line 413, in fit_cli
<br />    model_p, data_p, compute_p, out_p = config_get_pars(config_file, arg.config_mode)
<br />  File "https://github.com/arita37/mlmodels/tree/2675f1e090030e6958e45c46c6313291532e6ed8/mlmodels/models.py", line 299, in config_get_pars
<br />    out_p     = path_norm_dict( js.get("out_pars") )
<br />  File "https://github.com/arita37/mlmodels/tree/2675f1e090030e6958e45c46c6313291532e6ed8/mlmodels/util.py", line 201, in path_norm_dict
<br />    for k,v in ddict.items():
<br />AttributeError: 'NoneType' object has no attribute 'items'



### Error 103, [Traceback at line 2318](https://github.com/arita37/mlmodels_store/blob/master/log_json/log_json.py#L2318)<br />2318..Traceback (most recent call last):
<br />  File "/opt/hostedtoolcache/Python/3.6.10/x64/bin/ml_models", line 11, in <module>
<br />    load_entry_point('mlmodels', 'console_scripts', 'ml_models')()
<br />  File "https://github.com/arita37/mlmodels/tree/2675f1e090030e6958e45c46c6313291532e6ed8/mlmodels/models.py", line 530, in main
<br />    fit_cli(arg)
<br />  File "https://github.com/arita37/mlmodels/tree/2675f1e090030e6958e45c46c6313291532e6ed8/mlmodels/models.py", line 424, in fit_cli
<br />    model, sess = fit(module, model, data_pars=data_p, compute_pars=compute_p, out_pars=out_p)
<br />  File "https://github.com/arita37/mlmodels/tree/2675f1e090030e6958e45c46c6313291532e6ed8/mlmodels/models.py", line 125, in fit
<br />    return module.fit(model, data_pars=data_pars, compute_pars=compute_pars, out_pars=out_pars, **kwarg)
<br />  File "https://github.com/arita37/mlmodels/tree/2675f1e090030e6958e45c46c6313291532e6ed8/mlmodels/model_tch/torchhub.py", line 222, in fit
<br />    train_iter, valid_iter = get_dataset(data_pars)
<br />  File "https://github.com/arita37/mlmodels/tree/2675f1e090030e6958e45c46c6313291532e6ed8/mlmodels/model_tch/torchhub.py", line 190, in get_dataset
<br />    loader = DataLoader(data_pars)
<br />  File "https://github.com/arita37/mlmodels/tree/2675f1e090030e6958e45c46c6313291532e6ed8/mlmodels/dataloader.py", line 209, in __init__
<br />    self.data_info                = data_pars['data_info']
<br />KeyError: 'data_info'



### Error 104, [Traceback at line 2345](https://github.com/arita37/mlmodels_store/blob/master/log_json/log_json.py#L2345)<br />2345..Traceback (most recent call last):
<br />  File "/opt/hostedtoolcache/Python/3.6.10/x64/bin/ml_models", line 11, in <module>
<br />    load_entry_point('mlmodels', 'console_scripts', 'ml_models')()
<br />  File "https://github.com/arita37/mlmodels/tree/2675f1e090030e6958e45c46c6313291532e6ed8/mlmodels/models.py", line 530, in main
<br />    fit_cli(arg)
<br />  File "https://github.com/arita37/mlmodels/tree/2675f1e090030e6958e45c46c6313291532e6ed8/mlmodels/models.py", line 413, in fit_cli
<br />    model_p, data_p, compute_p, out_p = config_get_pars(config_file, arg.config_mode)
<br />  File "https://github.com/arita37/mlmodels/tree/2675f1e090030e6958e45c46c6313291532e6ed8/mlmodels/models.py", line 299, in config_get_pars
<br />    out_p     = path_norm_dict( js.get("out_pars") )
<br />  File "https://github.com/arita37/mlmodels/tree/2675f1e090030e6958e45c46c6313291532e6ed8/mlmodels/util.py", line 201, in path_norm_dict
<br />    for k,v in ddict.items():
<br />AttributeError: 'NoneType' object has no attribute 'items'



### Error 105, [Traceback at line 2378](https://github.com/arita37/mlmodels_store/blob/master/log_json/log_json.py#L2378)<br />2378..Traceback (most recent call last):
<br />  File "/opt/hostedtoolcache/Python/3.6.10/x64/bin/ml_models", line 11, in <module>
<br />    load_entry_point('mlmodels', 'console_scripts', 'ml_models')()
<br />  File "https://github.com/arita37/mlmodels/tree/2675f1e090030e6958e45c46c6313291532e6ed8/mlmodels/models.py", line 530, in main
<br />    fit_cli(arg)
<br />  File "https://github.com/arita37/mlmodels/tree/2675f1e090030e6958e45c46c6313291532e6ed8/mlmodels/models.py", line 424, in fit_cli
<br />    model, sess = fit(module, model, data_pars=data_p, compute_pars=compute_p, out_pars=out_p)
<br />  File "https://github.com/arita37/mlmodels/tree/2675f1e090030e6958e45c46c6313291532e6ed8/mlmodels/models.py", line 125, in fit
<br />    return module.fit(model, data_pars=data_pars, compute_pars=compute_pars, out_pars=out_pars, **kwarg)
<br />  File "https://github.com/arita37/mlmodels/tree/2675f1e090030e6958e45c46c6313291532e6ed8/mlmodels/model_tch/torchhub.py", line 222, in fit
<br />    train_iter, valid_iter = get_dataset(data_pars)
<br />  File "https://github.com/arita37/mlmodels/tree/2675f1e090030e6958e45c46c6313291532e6ed8/mlmodels/model_tch/torchhub.py", line 190, in get_dataset
<br />    loader = DataLoader(data_pars)
<br />  File "https://github.com/arita37/mlmodels/tree/2675f1e090030e6958e45c46c6313291532e6ed8/mlmodels/dataloader.py", line 209, in __init__
<br />    self.data_info                = data_pars['data_info']
<br />KeyError: 'data_info'



### Error 106, [Traceback at line 2405](https://github.com/arita37/mlmodels_store/blob/master/log_json/log_json.py#L2405)<br />2405..Traceback (most recent call last):
<br />  File "/opt/hostedtoolcache/Python/3.6.10/x64/bin/ml_models", line 11, in <module>
<br />    load_entry_point('mlmodels', 'console_scripts', 'ml_models')()
<br />  File "https://github.com/arita37/mlmodels/tree/2675f1e090030e6958e45c46c6313291532e6ed8/mlmodels/models.py", line 530, in main
<br />    fit_cli(arg)
<br />  File "https://github.com/arita37/mlmodels/tree/2675f1e090030e6958e45c46c6313291532e6ed8/mlmodels/models.py", line 413, in fit_cli
<br />    model_p, data_p, compute_p, out_p = config_get_pars(config_file, arg.config_mode)
<br />  File "https://github.com/arita37/mlmodels/tree/2675f1e090030e6958e45c46c6313291532e6ed8/mlmodels/models.py", line 299, in config_get_pars
<br />    out_p     = path_norm_dict( js.get("out_pars") )
<br />  File "https://github.com/arita37/mlmodels/tree/2675f1e090030e6958e45c46c6313291532e6ed8/mlmodels/util.py", line 201, in path_norm_dict
<br />    for k,v in ddict.items():
<br />AttributeError: 'NoneType' object has no attribute 'items'



### Error 107, [Traceback at line 2438](https://github.com/arita37/mlmodels_store/blob/master/log_json/log_json.py#L2438)<br />2438..Traceback (most recent call last):
<br />  File "/opt/hostedtoolcache/Python/3.6.10/x64/bin/ml_models", line 11, in <module>
<br />    load_entry_point('mlmodels', 'console_scripts', 'ml_models')()
<br />  File "https://github.com/arita37/mlmodels/tree/2675f1e090030e6958e45c46c6313291532e6ed8/mlmodels/models.py", line 530, in main
<br />    fit_cli(arg)
<br />  File "https://github.com/arita37/mlmodels/tree/2675f1e090030e6958e45c46c6313291532e6ed8/mlmodels/models.py", line 424, in fit_cli
<br />    model, sess = fit(module, model, data_pars=data_p, compute_pars=compute_p, out_pars=out_p)
<br />  File "https://github.com/arita37/mlmodels/tree/2675f1e090030e6958e45c46c6313291532e6ed8/mlmodels/models.py", line 125, in fit
<br />    return module.fit(model, data_pars=data_pars, compute_pars=compute_pars, out_pars=out_pars, **kwarg)
<br />  File "https://github.com/arita37/mlmodels/tree/2675f1e090030e6958e45c46c6313291532e6ed8/mlmodels/model_tch/torchhub.py", line 222, in fit
<br />    train_iter, valid_iter = get_dataset(data_pars)
<br />  File "https://github.com/arita37/mlmodels/tree/2675f1e090030e6958e45c46c6313291532e6ed8/mlmodels/model_tch/torchhub.py", line 190, in get_dataset
<br />    loader = DataLoader(data_pars)
<br />  File "https://github.com/arita37/mlmodels/tree/2675f1e090030e6958e45c46c6313291532e6ed8/mlmodels/dataloader.py", line 209, in __init__
<br />    self.data_info                = data_pars['data_info']
<br />KeyError: 'data_info'



### Error 108, [Traceback at line 2465](https://github.com/arita37/mlmodels_store/blob/master/log_json/log_json.py#L2465)<br />2465..Traceback (most recent call last):
<br />  File "/opt/hostedtoolcache/Python/3.6.10/x64/bin/ml_models", line 11, in <module>
<br />    load_entry_point('mlmodels', 'console_scripts', 'ml_models')()
<br />  File "https://github.com/arita37/mlmodels/tree/2675f1e090030e6958e45c46c6313291532e6ed8/mlmodels/models.py", line 530, in main
<br />    fit_cli(arg)
<br />  File "https://github.com/arita37/mlmodels/tree/2675f1e090030e6958e45c46c6313291532e6ed8/mlmodels/models.py", line 413, in fit_cli
<br />    model_p, data_p, compute_p, out_p = config_get_pars(config_file, arg.config_mode)
<br />  File "https://github.com/arita37/mlmodels/tree/2675f1e090030e6958e45c46c6313291532e6ed8/mlmodels/models.py", line 299, in config_get_pars
<br />    out_p     = path_norm_dict( js.get("out_pars") )
<br />  File "https://github.com/arita37/mlmodels/tree/2675f1e090030e6958e45c46c6313291532e6ed8/mlmodels/util.py", line 201, in path_norm_dict
<br />    for k,v in ddict.items():
<br />AttributeError: 'NoneType' object has no attribute 'items'



### Error 109, [Traceback at line 2498](https://github.com/arita37/mlmodels_store/blob/master/log_json/log_json.py#L2498)<br />2498..Traceback (most recent call last):
<br />  File "/opt/hostedtoolcache/Python/3.6.10/x64/bin/ml_models", line 11, in <module>
<br />    load_entry_point('mlmodels', 'console_scripts', 'ml_models')()
<br />  File "https://github.com/arita37/mlmodels/tree/2675f1e090030e6958e45c46c6313291532e6ed8/mlmodels/models.py", line 530, in main
<br />    fit_cli(arg)
<br />  File "https://github.com/arita37/mlmodels/tree/2675f1e090030e6958e45c46c6313291532e6ed8/mlmodels/models.py", line 424, in fit_cli
<br />    model, sess = fit(module, model, data_pars=data_p, compute_pars=compute_p, out_pars=out_p)
<br />  File "https://github.com/arita37/mlmodels/tree/2675f1e090030e6958e45c46c6313291532e6ed8/mlmodels/models.py", line 125, in fit
<br />    return module.fit(model, data_pars=data_pars, compute_pars=compute_pars, out_pars=out_pars, **kwarg)
<br />  File "https://github.com/arita37/mlmodels/tree/2675f1e090030e6958e45c46c6313291532e6ed8/mlmodels/model_tch/torchhub.py", line 222, in fit
<br />    train_iter, valid_iter = get_dataset(data_pars)
<br />  File "https://github.com/arita37/mlmodels/tree/2675f1e090030e6958e45c46c6313291532e6ed8/mlmodels/model_tch/torchhub.py", line 190, in get_dataset
<br />    loader = DataLoader(data_pars)
<br />  File "https://github.com/arita37/mlmodels/tree/2675f1e090030e6958e45c46c6313291532e6ed8/mlmodels/dataloader.py", line 209, in __init__
<br />    self.data_info                = data_pars['data_info']
<br />KeyError: 'data_info'



### Error 110, [Traceback at line 2525](https://github.com/arita37/mlmodels_store/blob/master/log_json/log_json.py#L2525)<br />2525..Traceback (most recent call last):
<br />  File "/opt/hostedtoolcache/Python/3.6.10/x64/bin/ml_models", line 11, in <module>
<br />    load_entry_point('mlmodels', 'console_scripts', 'ml_models')()
<br />  File "https://github.com/arita37/mlmodels/tree/2675f1e090030e6958e45c46c6313291532e6ed8/mlmodels/models.py", line 530, in main
<br />    fit_cli(arg)
<br />  File "https://github.com/arita37/mlmodels/tree/2675f1e090030e6958e45c46c6313291532e6ed8/mlmodels/models.py", line 413, in fit_cli
<br />    model_p, data_p, compute_p, out_p = config_get_pars(config_file, arg.config_mode)
<br />  File "https://github.com/arita37/mlmodels/tree/2675f1e090030e6958e45c46c6313291532e6ed8/mlmodels/models.py", line 299, in config_get_pars
<br />    out_p     = path_norm_dict( js.get("out_pars") )
<br />  File "https://github.com/arita37/mlmodels/tree/2675f1e090030e6958e45c46c6313291532e6ed8/mlmodels/util.py", line 201, in path_norm_dict
<br />    for k,v in ddict.items():
<br />AttributeError: 'NoneType' object has no attribute 'items'



### Error 111, [Traceback at line 2558](https://github.com/arita37/mlmodels_store/blob/master/log_json/log_json.py#L2558)<br />2558..Traceback (most recent call last):
<br />  File "/opt/hostedtoolcache/Python/3.6.10/x64/bin/ml_models", line 11, in <module>
<br />    load_entry_point('mlmodels', 'console_scripts', 'ml_models')()
<br />  File "https://github.com/arita37/mlmodels/tree/2675f1e090030e6958e45c46c6313291532e6ed8/mlmodels/models.py", line 530, in main
<br />    fit_cli(arg)
<br />  File "https://github.com/arita37/mlmodels/tree/2675f1e090030e6958e45c46c6313291532e6ed8/mlmodels/models.py", line 424, in fit_cli
<br />    model, sess = fit(module, model, data_pars=data_p, compute_pars=compute_p, out_pars=out_p)
<br />  File "https://github.com/arita37/mlmodels/tree/2675f1e090030e6958e45c46c6313291532e6ed8/mlmodels/models.py", line 125, in fit
<br />    return module.fit(model, data_pars=data_pars, compute_pars=compute_pars, out_pars=out_pars, **kwarg)
<br />  File "https://github.com/arita37/mlmodels/tree/2675f1e090030e6958e45c46c6313291532e6ed8/mlmodels/model_tch/torchhub.py", line 222, in fit
<br />    train_iter, valid_iter = get_dataset(data_pars)
<br />  File "https://github.com/arita37/mlmodels/tree/2675f1e090030e6958e45c46c6313291532e6ed8/mlmodels/model_tch/torchhub.py", line 190, in get_dataset
<br />    loader = DataLoader(data_pars)
<br />  File "https://github.com/arita37/mlmodels/tree/2675f1e090030e6958e45c46c6313291532e6ed8/mlmodels/dataloader.py", line 209, in __init__
<br />    self.data_info                = data_pars['data_info']
<br />KeyError: 'data_info'



### Error 112, [Traceback at line 2585](https://github.com/arita37/mlmodels_store/blob/master/log_json/log_json.py#L2585)<br />2585..Traceback (most recent call last):
<br />  File "/opt/hostedtoolcache/Python/3.6.10/x64/bin/ml_models", line 11, in <module>
<br />    load_entry_point('mlmodels', 'console_scripts', 'ml_models')()
<br />  File "https://github.com/arita37/mlmodels/tree/2675f1e090030e6958e45c46c6313291532e6ed8/mlmodels/models.py", line 530, in main
<br />    fit_cli(arg)
<br />  File "https://github.com/arita37/mlmodels/tree/2675f1e090030e6958e45c46c6313291532e6ed8/mlmodels/models.py", line 413, in fit_cli
<br />    model_p, data_p, compute_p, out_p = config_get_pars(config_file, arg.config_mode)
<br />  File "https://github.com/arita37/mlmodels/tree/2675f1e090030e6958e45c46c6313291532e6ed8/mlmodels/models.py", line 299, in config_get_pars
<br />    out_p     = path_norm_dict( js.get("out_pars") )
<br />  File "https://github.com/arita37/mlmodels/tree/2675f1e090030e6958e45c46c6313291532e6ed8/mlmodels/util.py", line 201, in path_norm_dict
<br />    for k,v in ddict.items():
<br />AttributeError: 'NoneType' object has no attribute 'items'



### Error 113, [Traceback at line 2618](https://github.com/arita37/mlmodels_store/blob/master/log_json/log_json.py#L2618)<br />2618..Traceback (most recent call last):
<br />  File "/opt/hostedtoolcache/Python/3.6.10/x64/bin/ml_models", line 11, in <module>
<br />    load_entry_point('mlmodels', 'console_scripts', 'ml_models')()
<br />  File "https://github.com/arita37/mlmodels/tree/2675f1e090030e6958e45c46c6313291532e6ed8/mlmodels/models.py", line 530, in main
<br />    fit_cli(arg)
<br />  File "https://github.com/arita37/mlmodels/tree/2675f1e090030e6958e45c46c6313291532e6ed8/mlmodels/models.py", line 424, in fit_cli
<br />    model, sess = fit(module, model, data_pars=data_p, compute_pars=compute_p, out_pars=out_p)
<br />  File "https://github.com/arita37/mlmodels/tree/2675f1e090030e6958e45c46c6313291532e6ed8/mlmodels/models.py", line 125, in fit
<br />    return module.fit(model, data_pars=data_pars, compute_pars=compute_pars, out_pars=out_pars, **kwarg)
<br />  File "https://github.com/arita37/mlmodels/tree/2675f1e090030e6958e45c46c6313291532e6ed8/mlmodels/model_tch/torchhub.py", line 222, in fit
<br />    train_iter, valid_iter = get_dataset(data_pars)
<br />  File "https://github.com/arita37/mlmodels/tree/2675f1e090030e6958e45c46c6313291532e6ed8/mlmodels/model_tch/torchhub.py", line 190, in get_dataset
<br />    loader = DataLoader(data_pars)
<br />  File "https://github.com/arita37/mlmodels/tree/2675f1e090030e6958e45c46c6313291532e6ed8/mlmodels/dataloader.py", line 209, in __init__
<br />    self.data_info                = data_pars['data_info']
<br />KeyError: 'data_info'



### Error 114, [Traceback at line 2645](https://github.com/arita37/mlmodels_store/blob/master/log_json/log_json.py#L2645)<br />2645..Traceback (most recent call last):
<br />  File "/opt/hostedtoolcache/Python/3.6.10/x64/bin/ml_models", line 11, in <module>
<br />    load_entry_point('mlmodels', 'console_scripts', 'ml_models')()
<br />  File "https://github.com/arita37/mlmodels/tree/2675f1e090030e6958e45c46c6313291532e6ed8/mlmodels/models.py", line 530, in main
<br />    fit_cli(arg)
<br />  File "https://github.com/arita37/mlmodels/tree/2675f1e090030e6958e45c46c6313291532e6ed8/mlmodels/models.py", line 413, in fit_cli
<br />    model_p, data_p, compute_p, out_p = config_get_pars(config_file, arg.config_mode)
<br />  File "https://github.com/arita37/mlmodels/tree/2675f1e090030e6958e45c46c6313291532e6ed8/mlmodels/models.py", line 299, in config_get_pars
<br />    out_p     = path_norm_dict( js.get("out_pars") )
<br />  File "https://github.com/arita37/mlmodels/tree/2675f1e090030e6958e45c46c6313291532e6ed8/mlmodels/util.py", line 201, in path_norm_dict
<br />    for k,v in ddict.items():
<br />AttributeError: 'NoneType' object has no attribute 'items'



### Error 115, [Traceback at line 2678](https://github.com/arita37/mlmodels_store/blob/master/log_json/log_json.py#L2678)<br />2678..Traceback (most recent call last):
<br />  File "/opt/hostedtoolcache/Python/3.6.10/x64/bin/ml_models", line 11, in <module>
<br />    load_entry_point('mlmodels', 'console_scripts', 'ml_models')()
<br />  File "https://github.com/arita37/mlmodels/tree/2675f1e090030e6958e45c46c6313291532e6ed8/mlmodels/models.py", line 530, in main
<br />    fit_cli(arg)
<br />  File "https://github.com/arita37/mlmodels/tree/2675f1e090030e6958e45c46c6313291532e6ed8/mlmodels/models.py", line 424, in fit_cli
<br />    model, sess = fit(module, model, data_pars=data_p, compute_pars=compute_p, out_pars=out_p)
<br />  File "https://github.com/arita37/mlmodels/tree/2675f1e090030e6958e45c46c6313291532e6ed8/mlmodels/models.py", line 125, in fit
<br />    return module.fit(model, data_pars=data_pars, compute_pars=compute_pars, out_pars=out_pars, **kwarg)
<br />  File "https://github.com/arita37/mlmodels/tree/2675f1e090030e6958e45c46c6313291532e6ed8/mlmodels/model_tch/torchhub.py", line 222, in fit
<br />    train_iter, valid_iter = get_dataset(data_pars)
<br />  File "https://github.com/arita37/mlmodels/tree/2675f1e090030e6958e45c46c6313291532e6ed8/mlmodels/model_tch/torchhub.py", line 190, in get_dataset
<br />    loader = DataLoader(data_pars)
<br />  File "https://github.com/arita37/mlmodels/tree/2675f1e090030e6958e45c46c6313291532e6ed8/mlmodels/dataloader.py", line 209, in __init__
<br />    self.data_info                = data_pars['data_info']
<br />KeyError: 'data_info'



### Error 116, [Traceback at line 2705](https://github.com/arita37/mlmodels_store/blob/master/log_json/log_json.py#L2705)<br />2705..Traceback (most recent call last):
<br />  File "/opt/hostedtoolcache/Python/3.6.10/x64/bin/ml_models", line 11, in <module>
<br />    load_entry_point('mlmodels', 'console_scripts', 'ml_models')()
<br />  File "https://github.com/arita37/mlmodels/tree/2675f1e090030e6958e45c46c6313291532e6ed8/mlmodels/models.py", line 530, in main
<br />    fit_cli(arg)
<br />  File "https://github.com/arita37/mlmodels/tree/2675f1e090030e6958e45c46c6313291532e6ed8/mlmodels/models.py", line 413, in fit_cli
<br />    model_p, data_p, compute_p, out_p = config_get_pars(config_file, arg.config_mode)
<br />  File "https://github.com/arita37/mlmodels/tree/2675f1e090030e6958e45c46c6313291532e6ed8/mlmodels/models.py", line 299, in config_get_pars
<br />    out_p     = path_norm_dict( js.get("out_pars") )
<br />  File "https://github.com/arita37/mlmodels/tree/2675f1e090030e6958e45c46c6313291532e6ed8/mlmodels/util.py", line 201, in path_norm_dict
<br />    for k,v in ddict.items():
<br />AttributeError: 'NoneType' object has no attribute 'items'



### Error 117, [Traceback at line 2738](https://github.com/arita37/mlmodels_store/blob/master/log_json/log_json.py#L2738)<br />2738..Traceback (most recent call last):
<br />  File "/opt/hostedtoolcache/Python/3.6.10/x64/bin/ml_models", line 11, in <module>
<br />    load_entry_point('mlmodels', 'console_scripts', 'ml_models')()
<br />  File "https://github.com/arita37/mlmodels/tree/2675f1e090030e6958e45c46c6313291532e6ed8/mlmodels/models.py", line 530, in main
<br />    fit_cli(arg)
<br />  File "https://github.com/arita37/mlmodels/tree/2675f1e090030e6958e45c46c6313291532e6ed8/mlmodels/models.py", line 424, in fit_cli
<br />    model, sess = fit(module, model, data_pars=data_p, compute_pars=compute_p, out_pars=out_p)
<br />  File "https://github.com/arita37/mlmodels/tree/2675f1e090030e6958e45c46c6313291532e6ed8/mlmodels/models.py", line 125, in fit
<br />    return module.fit(model, data_pars=data_pars, compute_pars=compute_pars, out_pars=out_pars, **kwarg)
<br />  File "https://github.com/arita37/mlmodels/tree/2675f1e090030e6958e45c46c6313291532e6ed8/mlmodels/model_tch/torchhub.py", line 222, in fit
<br />    train_iter, valid_iter = get_dataset(data_pars)
<br />  File "https://github.com/arita37/mlmodels/tree/2675f1e090030e6958e45c46c6313291532e6ed8/mlmodels/model_tch/torchhub.py", line 190, in get_dataset
<br />    loader = DataLoader(data_pars)
<br />  File "https://github.com/arita37/mlmodels/tree/2675f1e090030e6958e45c46c6313291532e6ed8/mlmodels/dataloader.py", line 209, in __init__
<br />    self.data_info                = data_pars['data_info']
<br />KeyError: 'data_info'



### Error 118, [Traceback at line 2765](https://github.com/arita37/mlmodels_store/blob/master/log_json/log_json.py#L2765)<br />2765..Traceback (most recent call last):
<br />  File "/opt/hostedtoolcache/Python/3.6.10/x64/bin/ml_models", line 11, in <module>
<br />    load_entry_point('mlmodels', 'console_scripts', 'ml_models')()
<br />  File "https://github.com/arita37/mlmodels/tree/2675f1e090030e6958e45c46c6313291532e6ed8/mlmodels/models.py", line 530, in main
<br />    fit_cli(arg)
<br />  File "https://github.com/arita37/mlmodels/tree/2675f1e090030e6958e45c46c6313291532e6ed8/mlmodels/models.py", line 413, in fit_cli
<br />    model_p, data_p, compute_p, out_p = config_get_pars(config_file, arg.config_mode)
<br />  File "https://github.com/arita37/mlmodels/tree/2675f1e090030e6958e45c46c6313291532e6ed8/mlmodels/models.py", line 299, in config_get_pars
<br />    out_p     = path_norm_dict( js.get("out_pars") )
<br />  File "https://github.com/arita37/mlmodels/tree/2675f1e090030e6958e45c46c6313291532e6ed8/mlmodels/util.py", line 201, in path_norm_dict
<br />    for k,v in ddict.items():
<br />AttributeError: 'NoneType' object has no attribute 'items'



### Error 119, [Traceback at line 2798](https://github.com/arita37/mlmodels_store/blob/master/log_json/log_json.py#L2798)<br />2798..Traceback (most recent call last):
<br />  File "/opt/hostedtoolcache/Python/3.6.10/x64/bin/ml_models", line 11, in <module>
<br />    load_entry_point('mlmodels', 'console_scripts', 'ml_models')()
<br />  File "https://github.com/arita37/mlmodels/tree/2675f1e090030e6958e45c46c6313291532e6ed8/mlmodels/models.py", line 530, in main
<br />    fit_cli(arg)
<br />  File "https://github.com/arita37/mlmodels/tree/2675f1e090030e6958e45c46c6313291532e6ed8/mlmodels/models.py", line 424, in fit_cli
<br />    model, sess = fit(module, model, data_pars=data_p, compute_pars=compute_p, out_pars=out_p)
<br />  File "https://github.com/arita37/mlmodels/tree/2675f1e090030e6958e45c46c6313291532e6ed8/mlmodels/models.py", line 125, in fit
<br />    return module.fit(model, data_pars=data_pars, compute_pars=compute_pars, out_pars=out_pars, **kwarg)
<br />  File "https://github.com/arita37/mlmodels/tree/2675f1e090030e6958e45c46c6313291532e6ed8/mlmodels/model_tch/torchhub.py", line 222, in fit
<br />    train_iter, valid_iter = get_dataset(data_pars)
<br />  File "https://github.com/arita37/mlmodels/tree/2675f1e090030e6958e45c46c6313291532e6ed8/mlmodels/model_tch/torchhub.py", line 190, in get_dataset
<br />    loader = DataLoader(data_pars)
<br />  File "https://github.com/arita37/mlmodels/tree/2675f1e090030e6958e45c46c6313291532e6ed8/mlmodels/dataloader.py", line 209, in __init__
<br />    self.data_info                = data_pars['data_info']
<br />KeyError: 'data_info'



### Error 120, [Traceback at line 2825](https://github.com/arita37/mlmodels_store/blob/master/log_json/log_json.py#L2825)<br />2825..Traceback (most recent call last):
<br />  File "/opt/hostedtoolcache/Python/3.6.10/x64/bin/ml_models", line 11, in <module>
<br />    load_entry_point('mlmodels', 'console_scripts', 'ml_models')()
<br />  File "https://github.com/arita37/mlmodels/tree/2675f1e090030e6958e45c46c6313291532e6ed8/mlmodels/models.py", line 530, in main
<br />    fit_cli(arg)
<br />  File "https://github.com/arita37/mlmodels/tree/2675f1e090030e6958e45c46c6313291532e6ed8/mlmodels/models.py", line 413, in fit_cli
<br />    model_p, data_p, compute_p, out_p = config_get_pars(config_file, arg.config_mode)
<br />  File "https://github.com/arita37/mlmodels/tree/2675f1e090030e6958e45c46c6313291532e6ed8/mlmodels/models.py", line 299, in config_get_pars
<br />    out_p     = path_norm_dict( js.get("out_pars") )
<br />  File "https://github.com/arita37/mlmodels/tree/2675f1e090030e6958e45c46c6313291532e6ed8/mlmodels/util.py", line 201, in path_norm_dict
<br />    for k,v in ddict.items():
<br />AttributeError: 'NoneType' object has no attribute 'items'



### Error 121, [Traceback at line 2858](https://github.com/arita37/mlmodels_store/blob/master/log_json/log_json.py#L2858)<br />2858..Traceback (most recent call last):
<br />  File "/opt/hostedtoolcache/Python/3.6.10/x64/bin/ml_models", line 11, in <module>
<br />    load_entry_point('mlmodels', 'console_scripts', 'ml_models')()
<br />  File "https://github.com/arita37/mlmodels/tree/2675f1e090030e6958e45c46c6313291532e6ed8/mlmodels/models.py", line 530, in main
<br />    fit_cli(arg)
<br />  File "https://github.com/arita37/mlmodels/tree/2675f1e090030e6958e45c46c6313291532e6ed8/mlmodels/models.py", line 424, in fit_cli
<br />    model, sess = fit(module, model, data_pars=data_p, compute_pars=compute_p, out_pars=out_p)
<br />  File "https://github.com/arita37/mlmodels/tree/2675f1e090030e6958e45c46c6313291532e6ed8/mlmodels/models.py", line 125, in fit
<br />    return module.fit(model, data_pars=data_pars, compute_pars=compute_pars, out_pars=out_pars, **kwarg)
<br />  File "https://github.com/arita37/mlmodels/tree/2675f1e090030e6958e45c46c6313291532e6ed8/mlmodels/model_tch/torchhub.py", line 222, in fit
<br />    train_iter, valid_iter = get_dataset(data_pars)
<br />  File "https://github.com/arita37/mlmodels/tree/2675f1e090030e6958e45c46c6313291532e6ed8/mlmodels/model_tch/torchhub.py", line 190, in get_dataset
<br />    loader = DataLoader(data_pars)
<br />  File "https://github.com/arita37/mlmodels/tree/2675f1e090030e6958e45c46c6313291532e6ed8/mlmodels/dataloader.py", line 209, in __init__
<br />    self.data_info                = data_pars['data_info']
<br />KeyError: 'data_info'



### Error 122, [Traceback at line 2885](https://github.com/arita37/mlmodels_store/blob/master/log_json/log_json.py#L2885)<br />2885..Traceback (most recent call last):
<br />  File "/opt/hostedtoolcache/Python/3.6.10/x64/bin/ml_models", line 11, in <module>
<br />    load_entry_point('mlmodels', 'console_scripts', 'ml_models')()
<br />  File "https://github.com/arita37/mlmodels/tree/2675f1e090030e6958e45c46c6313291532e6ed8/mlmodels/models.py", line 530, in main
<br />    fit_cli(arg)
<br />  File "https://github.com/arita37/mlmodels/tree/2675f1e090030e6958e45c46c6313291532e6ed8/mlmodels/models.py", line 413, in fit_cli
<br />    model_p, data_p, compute_p, out_p = config_get_pars(config_file, arg.config_mode)
<br />  File "https://github.com/arita37/mlmodels/tree/2675f1e090030e6958e45c46c6313291532e6ed8/mlmodels/models.py", line 299, in config_get_pars
<br />    out_p     = path_norm_dict( js.get("out_pars") )
<br />  File "https://github.com/arita37/mlmodels/tree/2675f1e090030e6958e45c46c6313291532e6ed8/mlmodels/util.py", line 201, in path_norm_dict
<br />    for k,v in ddict.items():
<br />AttributeError: 'NoneType' object has no attribute 'items'



### Error 123, [Traceback at line 2918](https://github.com/arita37/mlmodels_store/blob/master/log_json/log_json.py#L2918)<br />2918..Traceback (most recent call last):
<br />  File "/opt/hostedtoolcache/Python/3.6.10/x64/bin/ml_models", line 11, in <module>
<br />    load_entry_point('mlmodels', 'console_scripts', 'ml_models')()
<br />  File "https://github.com/arita37/mlmodels/tree/2675f1e090030e6958e45c46c6313291532e6ed8/mlmodels/models.py", line 530, in main
<br />    fit_cli(arg)
<br />  File "https://github.com/arita37/mlmodels/tree/2675f1e090030e6958e45c46c6313291532e6ed8/mlmodels/models.py", line 424, in fit_cli
<br />    model, sess = fit(module, model, data_pars=data_p, compute_pars=compute_p, out_pars=out_p)
<br />  File "https://github.com/arita37/mlmodels/tree/2675f1e090030e6958e45c46c6313291532e6ed8/mlmodels/models.py", line 125, in fit
<br />    return module.fit(model, data_pars=data_pars, compute_pars=compute_pars, out_pars=out_pars, **kwarg)
<br />  File "https://github.com/arita37/mlmodels/tree/2675f1e090030e6958e45c46c6313291532e6ed8/mlmodels/model_tch/torchhub.py", line 222, in fit
<br />    train_iter, valid_iter = get_dataset(data_pars)
<br />  File "https://github.com/arita37/mlmodels/tree/2675f1e090030e6958e45c46c6313291532e6ed8/mlmodels/model_tch/torchhub.py", line 190, in get_dataset
<br />    loader = DataLoader(data_pars)
<br />  File "https://github.com/arita37/mlmodels/tree/2675f1e090030e6958e45c46c6313291532e6ed8/mlmodels/dataloader.py", line 209, in __init__
<br />    self.data_info                = data_pars['data_info']
<br />KeyError: 'data_info'



### Error 124, [Traceback at line 2945](https://github.com/arita37/mlmodels_store/blob/master/log_json/log_json.py#L2945)<br />2945..Traceback (most recent call last):
<br />  File "/opt/hostedtoolcache/Python/3.6.10/x64/bin/ml_models", line 11, in <module>
<br />    load_entry_point('mlmodels', 'console_scripts', 'ml_models')()
<br />  File "https://github.com/arita37/mlmodels/tree/2675f1e090030e6958e45c46c6313291532e6ed8/mlmodels/models.py", line 530, in main
<br />    fit_cli(arg)
<br />  File "https://github.com/arita37/mlmodels/tree/2675f1e090030e6958e45c46c6313291532e6ed8/mlmodels/models.py", line 413, in fit_cli
<br />    model_p, data_p, compute_p, out_p = config_get_pars(config_file, arg.config_mode)
<br />  File "https://github.com/arita37/mlmodels/tree/2675f1e090030e6958e45c46c6313291532e6ed8/mlmodels/models.py", line 299, in config_get_pars
<br />    out_p     = path_norm_dict( js.get("out_pars") )
<br />  File "https://github.com/arita37/mlmodels/tree/2675f1e090030e6958e45c46c6313291532e6ed8/mlmodels/util.py", line 201, in path_norm_dict
<br />    for k,v in ddict.items():
<br />AttributeError: 'NoneType' object has no attribute 'items'



### Error 125, [Traceback at line 2978](https://github.com/arita37/mlmodels_store/blob/master/log_json/log_json.py#L2978)<br />2978..Traceback (most recent call last):
<br />  File "/opt/hostedtoolcache/Python/3.6.10/x64/bin/ml_models", line 11, in <module>
<br />    load_entry_point('mlmodels', 'console_scripts', 'ml_models')()
<br />  File "https://github.com/arita37/mlmodels/tree/2675f1e090030e6958e45c46c6313291532e6ed8/mlmodels/models.py", line 530, in main
<br />    fit_cli(arg)
<br />  File "https://github.com/arita37/mlmodels/tree/2675f1e090030e6958e45c46c6313291532e6ed8/mlmodels/models.py", line 424, in fit_cli
<br />    model, sess = fit(module, model, data_pars=data_p, compute_pars=compute_p, out_pars=out_p)
<br />  File "https://github.com/arita37/mlmodels/tree/2675f1e090030e6958e45c46c6313291532e6ed8/mlmodels/models.py", line 125, in fit
<br />    return module.fit(model, data_pars=data_pars, compute_pars=compute_pars, out_pars=out_pars, **kwarg)
<br />  File "https://github.com/arita37/mlmodels/tree/2675f1e090030e6958e45c46c6313291532e6ed8/mlmodels/model_tch/textcnn.py", line 361, in fit
<br />    train_iter, valid_iter, vocab = get_dataset(data_pars, out_pars)
<br />  File "https://github.com/arita37/mlmodels/tree/2675f1e090030e6958e45c46c6313291532e6ed8/mlmodels/model_tch/textcnn.py", line 414, in get_dataset
<br />    dataset        = data_pars['data_info'].get('dataset', None)
<br />KeyError: 'data_info'



### Error 126, [Traceback at line 3003](https://github.com/arita37/mlmodels_store/blob/master/log_json/log_json.py#L3003)<br />3003..Traceback (most recent call last):
<br />  File "/opt/hostedtoolcache/Python/3.6.10/x64/bin/ml_models", line 11, in <module>
<br />    load_entry_point('mlmodels', 'console_scripts', 'ml_models')()
<br />  File "https://github.com/arita37/mlmodels/tree/2675f1e090030e6958e45c46c6313291532e6ed8/mlmodels/models.py", line 530, in main
<br />    fit_cli(arg)
<br />  File "https://github.com/arita37/mlmodels/tree/2675f1e090030e6958e45c46c6313291532e6ed8/mlmodels/models.py", line 413, in fit_cli
<br />    model_p, data_p, compute_p, out_p = config_get_pars(config_file, arg.config_mode)
<br />  File "https://github.com/arita37/mlmodels/tree/2675f1e090030e6958e45c46c6313291532e6ed8/mlmodels/models.py", line 297, in config_get_pars
<br />    data_p    = path_norm_dict( js.get("data_pars") )
<br />  File "https://github.com/arita37/mlmodels/tree/2675f1e090030e6958e45c46c6313291532e6ed8/mlmodels/util.py", line 201, in path_norm_dict
<br />    for k,v in ddict.items():
<br />AttributeError: 'NoneType' object has no attribute 'items'



### Error 127, [Traceback at line 3034](https://github.com/arita37/mlmodels_store/blob/master/log_json/log_json.py#L3034)<br />3034..Traceback (most recent call last):
<br />  File "/opt/hostedtoolcache/Python/3.6.10/x64/bin/ml_models", line 11, in <module>
<br />    load_entry_point('mlmodels', 'console_scripts', 'ml_models')()
<br />  File "https://github.com/arita37/mlmodels/tree/2675f1e090030e6958e45c46c6313291532e6ed8/mlmodels/models.py", line 530, in main
<br />    fit_cli(arg)
<br />  File "https://github.com/arita37/mlmodels/tree/2675f1e090030e6958e45c46c6313291532e6ed8/mlmodels/models.py", line 421, in fit_cli
<br />    model = model_create(module, model_p, data_p, compute_p)  # Exact map JSON and paramters
<br />  File "https://github.com/arita37/mlmodels/tree/2675f1e090030e6958e45c46c6313291532e6ed8/mlmodels/models.py", line 113, in model_create
<br />    model = module.Model(model_pars=model_pars, data_pars=data_pars, compute_pars=compute_pars, **kwarg)
<br />  File "https://github.com/arita37/mlmodels/tree/2675f1e090030e6958e45c46c6313291532e6ed8/mlmodels/model_keras/namentity_crm_bilstm.py", line 66, in __init__
<br />    data_set, internal_states = get_dataset(data_pars)
<br />  File "https://github.com/arita37/mlmodels/tree/2675f1e090030e6958e45c46c6313291532e6ed8/mlmodels/model_keras/namentity_crm_bilstm.py", line 182, in get_dataset
<br />    loader = DataLoader(data_pars)
<br />  File "https://github.com/arita37/mlmodels/tree/2675f1e090030e6958e45c46c6313291532e6ed8/mlmodels/dataloader.py", line 209, in __init__
<br />    self.data_info                = data_pars['data_info']
<br />KeyError: 'data_info'



### Error 128, [Traceback at line 3061](https://github.com/arita37/mlmodels_store/blob/master/log_json/log_json.py#L3061)<br />3061..Traceback (most recent call last):
<br />  File "/opt/hostedtoolcache/Python/3.6.10/x64/bin/ml_models", line 11, in <module>
<br />    load_entry_point('mlmodels', 'console_scripts', 'ml_models')()
<br />  File "https://github.com/arita37/mlmodels/tree/2675f1e090030e6958e45c46c6313291532e6ed8/mlmodels/models.py", line 530, in main
<br />    fit_cli(arg)
<br />  File "https://github.com/arita37/mlmodels/tree/2675f1e090030e6958e45c46c6313291532e6ed8/mlmodels/models.py", line 413, in fit_cli
<br />    model_p, data_p, compute_p, out_p = config_get_pars(config_file, arg.config_mode)
<br />  File "https://github.com/arita37/mlmodels/tree/2675f1e090030e6958e45c46c6313291532e6ed8/mlmodels/models.py", line 299, in config_get_pars
<br />    out_p     = path_norm_dict( js.get("out_pars") )
<br />  File "https://github.com/arita37/mlmodels/tree/2675f1e090030e6958e45c46c6313291532e6ed8/mlmodels/util.py", line 201, in path_norm_dict
<br />    for k,v in ddict.items():
<br />AttributeError: 'NoneType' object has no attribute 'items'



### Error 129, [Traceback at line 3089](https://github.com/arita37/mlmodels_store/blob/master/log_json/log_json.py#L3089)<br />3089..Traceback (most recent call last):
<br />  File "/opt/hostedtoolcache/Python/3.6.10/x64/bin/ml_models", line 11, in <module>
<br />    load_entry_point('mlmodels', 'console_scripts', 'ml_models')()
<br />  File "https://github.com/arita37/mlmodels/tree/2675f1e090030e6958e45c46c6313291532e6ed8/mlmodels/models.py", line 530, in main
<br />    fit_cli(arg)
<br />  File "https://github.com/arita37/mlmodels/tree/2675f1e090030e6958e45c46c6313291532e6ed8/mlmodels/models.py", line 415, in fit_cli
<br />    path      = out_p['path']
<br />KeyError: 'path'



### Error 130, [Traceback at line 3108](https://github.com/arita37/mlmodels_store/blob/master/log_json/log_json.py#L3108)<br />3108..Traceback (most recent call last):
<br />  File "/opt/hostedtoolcache/Python/3.6.10/x64/bin/ml_models", line 11, in <module>
<br />    load_entry_point('mlmodels', 'console_scripts', 'ml_models')()
<br />  File "https://github.com/arita37/mlmodels/tree/2675f1e090030e6958e45c46c6313291532e6ed8/mlmodels/models.py", line 530, in main
<br />    fit_cli(arg)
<br />  File "https://github.com/arita37/mlmodels/tree/2675f1e090030e6958e45c46c6313291532e6ed8/mlmodels/models.py", line 413, in fit_cli
<br />    model_p, data_p, compute_p, out_p = config_get_pars(config_file, arg.config_mode)
<br />  File "https://github.com/arita37/mlmodels/tree/2675f1e090030e6958e45c46c6313291532e6ed8/mlmodels/models.py", line 299, in config_get_pars
<br />    out_p     = path_norm_dict( js.get("out_pars") )
<br />  File "https://github.com/arita37/mlmodels/tree/2675f1e090030e6958e45c46c6313291532e6ed8/mlmodels/util.py", line 201, in path_norm_dict
<br />    for k,v in ddict.items():
<br />AttributeError: 'NoneType' object has no attribute 'items'



### Error 131, [Traceback at line 3138](https://github.com/arita37/mlmodels_store/blob/master/log_json/log_json.py#L3138)<br />3138..Traceback (most recent call last):
<br />  File "https://github.com/arita37/mlmodels/tree/2675f1e090030e6958e45c46c6313291532e6ed8/mlmodels/models.py", line 72, in module_load
<br />    module = import_module(f"mlmodels.{model_name}")
<br />  File "/opt/hostedtoolcache/Python/3.6.10/x64/lib/python3.6/importlib/__init__.py", line 126, in import_module
<br />    return _bootstrap._gcd_import(name[level:], package, level)
<br />  File "<frozen importlib._bootstrap>", line 994, in _gcd_import
<br />  File "<frozen importlib._bootstrap>", line 971, in _find_and_load
<br />  File "<frozen importlib._bootstrap>", line 953, in _find_and_load_unlocked
<br />ModuleNotFoundError: No module named 'mlmodels.model_keras.Autokeras'



### Error 132, [Traceback at line 3150](https://github.com/arita37/mlmodels_store/blob/master/log_json/log_json.py#L3150)<br />3150..Traceback (most recent call last):
<br />  File "https://github.com/arita37/mlmodels/tree/2675f1e090030e6958e45c46c6313291532e6ed8/mlmodels/models.py", line 84, in module_load
<br />    model_name = str(Path(model_uri).parts[-2]) + "." + str(model_name)
<br />IndexError: tuple index out of range



### Error 133, [Traceback at line 3157](https://github.com/arita37/mlmodels_store/blob/master/log_json/log_json.py#L3157)<br />3157..Traceback (most recent call last):
<br />  File "/opt/hostedtoolcache/Python/3.6.10/x64/bin/ml_models", line 11, in <module>
<br />    load_entry_point('mlmodels', 'console_scripts', 'ml_models')()
<br />  File "https://github.com/arita37/mlmodels/tree/2675f1e090030e6958e45c46c6313291532e6ed8/mlmodels/models.py", line 530, in main
<br />    fit_cli(arg)
<br />  File "https://github.com/arita37/mlmodels/tree/2675f1e090030e6958e45c46c6313291532e6ed8/mlmodels/models.py", line 420, in fit_cli
<br />    module = module_load(model_uri)  # '1_lstm.py
<br />  File "https://github.com/arita37/mlmodels/tree/2675f1e090030e6958e45c46c6313291532e6ed8/mlmodels/models.py", line 89, in module_load
<br />    raise NameError(f"Module {model_name} notfound, {e1}, {e2}")
<br />NameError: Module model_keras.Autokeras notfound, No module named 'mlmodels.model_keras.Autokeras', tuple index out of range



### Error 134, [Traceback at line 3178](https://github.com/arita37/mlmodels_store/blob/master/log_json/log_json.py#L3178)<br />3178..Traceback (most recent call last):
<br />  File "/opt/hostedtoolcache/Python/3.6.10/x64/bin/ml_models", line 11, in <module>
<br />    load_entry_point('mlmodels', 'console_scripts', 'ml_models')()
<br />  File "https://github.com/arita37/mlmodels/tree/2675f1e090030e6958e45c46c6313291532e6ed8/mlmodels/models.py", line 530, in main
<br />    fit_cli(arg)
<br />  File "https://github.com/arita37/mlmodels/tree/2675f1e090030e6958e45c46c6313291532e6ed8/mlmodels/models.py", line 413, in fit_cli
<br />    model_p, data_p, compute_p, out_p = config_get_pars(config_file, arg.config_mode)
<br />  File "https://github.com/arita37/mlmodels/tree/2675f1e090030e6958e45c46c6313291532e6ed8/mlmodels/models.py", line 299, in config_get_pars
<br />    out_p     = path_norm_dict( js.get("out_pars") )
<br />  File "https://github.com/arita37/mlmodels/tree/2675f1e090030e6958e45c46c6313291532e6ed8/mlmodels/util.py", line 201, in path_norm_dict
<br />    for k,v in ddict.items():
<br />AttributeError: 'NoneType' object has no attribute 'items'



### Error 135, [Traceback at line 3208](https://github.com/arita37/mlmodels_store/blob/master/log_json/log_json.py#L3208)<br />3208..Traceback (most recent call last):
<br />  File "https://github.com/arita37/mlmodels/tree/2675f1e090030e6958e45c46c6313291532e6ed8/mlmodels/models.py", line 72, in module_load
<br />    module = import_module(f"mlmodels.{model_name}")
<br />  File "/opt/hostedtoolcache/Python/3.6.10/x64/lib/python3.6/importlib/__init__.py", line 126, in import_module
<br />    return _bootstrap._gcd_import(name[level:], package, level)
<br />  File "<frozen importlib._bootstrap>", line 994, in _gcd_import
<br />  File "<frozen importlib._bootstrap>", line 971, in _find_and_load
<br />  File "<frozen importlib._bootstrap>", line 953, in _find_and_load_unlocked
<br />ModuleNotFoundError: No module named 'mlmodels.model_keras.textvae'



### Error 136, [Traceback at line 3220](https://github.com/arita37/mlmodels_store/blob/master/log_json/log_json.py#L3220)<br />3220..Traceback (most recent call last):
<br />  File "https://github.com/arita37/mlmodels/tree/2675f1e090030e6958e45c46c6313291532e6ed8/mlmodels/models.py", line 84, in module_load
<br />    model_name = str(Path(model_uri).parts[-2]) + "." + str(model_name)
<br />IndexError: tuple index out of range



### Error 137, [Traceback at line 3227](https://github.com/arita37/mlmodels_store/blob/master/log_json/log_json.py#L3227)<br />3227..Traceback (most recent call last):
<br />  File "/opt/hostedtoolcache/Python/3.6.10/x64/bin/ml_models", line 11, in <module>
<br />    load_entry_point('mlmodels', 'console_scripts', 'ml_models')()
<br />  File "https://github.com/arita37/mlmodels/tree/2675f1e090030e6958e45c46c6313291532e6ed8/mlmodels/models.py", line 530, in main
<br />    fit_cli(arg)
<br />  File "https://github.com/arita37/mlmodels/tree/2675f1e090030e6958e45c46c6313291532e6ed8/mlmodels/models.py", line 420, in fit_cli
<br />    module = module_load(model_uri)  # '1_lstm.py
<br />  File "https://github.com/arita37/mlmodels/tree/2675f1e090030e6958e45c46c6313291532e6ed8/mlmodels/models.py", line 89, in module_load
<br />    raise NameError(f"Module {model_name} notfound, {e1}, {e2}")
<br />NameError: Module model_keras.textvae notfound, No module named 'mlmodels.model_keras.textvae', tuple index out of range



### Error 138, [Traceback at line 3248](https://github.com/arita37/mlmodels_store/blob/master/log_json/log_json.py#L3248)<br />3248..Traceback (most recent call last):
<br />  File "/opt/hostedtoolcache/Python/3.6.10/x64/bin/ml_models", line 11, in <module>
<br />    load_entry_point('mlmodels', 'console_scripts', 'ml_models')()
<br />  File "https://github.com/arita37/mlmodels/tree/2675f1e090030e6958e45c46c6313291532e6ed8/mlmodels/models.py", line 530, in main
<br />    fit_cli(arg)
<br />  File "https://github.com/arita37/mlmodels/tree/2675f1e090030e6958e45c46c6313291532e6ed8/mlmodels/models.py", line 413, in fit_cli
<br />    model_p, data_p, compute_p, out_p = config_get_pars(config_file, arg.config_mode)
<br />  File "https://github.com/arita37/mlmodels/tree/2675f1e090030e6958e45c46c6313291532e6ed8/mlmodels/models.py", line 299, in config_get_pars
<br />    out_p     = path_norm_dict( js.get("out_pars") )
<br />  File "https://github.com/arita37/mlmodels/tree/2675f1e090030e6958e45c46c6313291532e6ed8/mlmodels/util.py", line 201, in path_norm_dict
<br />    for k,v in ddict.items():
<br />AttributeError: 'NoneType' object has no attribute 'items'



### Error 139, [Traceback at line 3315](https://github.com/arita37/mlmodels_store/blob/master/log_json/log_json.py#L3315)<br />3315..Traceback (most recent call last):
<br />  File "/opt/hostedtoolcache/Python/3.6.10/x64/bin/ml_models", line 11, in <module>
<br />    load_entry_point('mlmodels', 'console_scripts', 'ml_models')()
<br />  File "https://github.com/arita37/mlmodels/tree/2675f1e090030e6958e45c46c6313291532e6ed8/mlmodels/models.py", line 530, in main
<br />    fit_cli(arg)
<br />  File "https://github.com/arita37/mlmodels/tree/2675f1e090030e6958e45c46c6313291532e6ed8/mlmodels/models.py", line 424, in fit_cli
<br />    model, sess = fit(module, model, data_pars=data_p, compute_pars=compute_p, out_pars=out_p)
<br />  File "https://github.com/arita37/mlmodels/tree/2675f1e090030e6958e45c46c6313291532e6ed8/mlmodels/models.py", line 125, in fit
<br />    return module.fit(model, data_pars=data_pars, compute_pars=compute_pars, out_pars=out_pars, **kwarg)
<br />  File "https://github.com/arita37/mlmodels/tree/2675f1e090030e6958e45c46c6313291532e6ed8/mlmodels/model_keras/textcnn.py", line 69, in fit
<br />    Xtrain, Xtest, ytrain, ytest = get_dataset(data_pars)
<br />  File "https://github.com/arita37/mlmodels/tree/2675f1e090030e6958e45c46c6313291532e6ed8/mlmodels/model_keras/textcnn.py", line 143, in get_dataset
<br />    maxlen       = data_pars['data_info']['maxlen']
<br />KeyError: 'data_info'



### Error 140, [Traceback at line 3340](https://github.com/arita37/mlmodels_store/blob/master/log_json/log_json.py#L3340)<br />3340..Traceback (most recent call last):
<br />  File "/opt/hostedtoolcache/Python/3.6.10/x64/bin/ml_models", line 11, in <module>
<br />    load_entry_point('mlmodels', 'console_scripts', 'ml_models')()
<br />  File "https://github.com/arita37/mlmodels/tree/2675f1e090030e6958e45c46c6313291532e6ed8/mlmodels/models.py", line 530, in main
<br />    fit_cli(arg)
<br />  File "https://github.com/arita37/mlmodels/tree/2675f1e090030e6958e45c46c6313291532e6ed8/mlmodels/models.py", line 413, in fit_cli
<br />    model_p, data_p, compute_p, out_p = config_get_pars(config_file, arg.config_mode)
<br />  File "https://github.com/arita37/mlmodels/tree/2675f1e090030e6958e45c46c6313291532e6ed8/mlmodels/models.py", line 299, in config_get_pars
<br />    out_p     = path_norm_dict( js.get("out_pars") )
<br />  File "https://github.com/arita37/mlmodels/tree/2675f1e090030e6958e45c46c6313291532e6ed8/mlmodels/util.py", line 201, in path_norm_dict
<br />    for k,v in ddict.items():
<br />AttributeError: 'NoneType' object has no attribute 'items'
