## Original File URL: https://github.com/arita37/mlmodels_store/blob/master/log_jupyter/log_jupyter.py


### Error 1, [Traceback at line 80](https://github.com/arita37/mlmodels_store/blob/master/log_jupyter/log_jupyter.py#L80)<br />80..Traceback (most recent call last):
<br />  File "https://github.com/arita37/mlmodels/tree/6ca6da91408244e26c157e9e6467cc18ede43e71/mlmodels/example//keras-textcnn.py", line 37, in <module>
<br />    _, _   =  module.fit(model, data_pars=data_pars, compute_pars=compute_pars, out_pars=out_pars)          # fit the model
<br />  File "https://github.com/arita37/mlmodels/tree/6ca6da91408244e26c157e9e6467cc18ede43e71/mlmodels/model_keras/textcnn.py", line 69, in fit
<br />    Xtrain, Xtest, ytrain, ytest = get_dataset(data_pars)
<br />  File "https://github.com/arita37/mlmodels/tree/6ca6da91408244e26c157e9e6467cc18ede43e71/mlmodels/model_keras/textcnn.py", line 143, in get_dataset
<br />    maxlen       = data_pars['data_info']['maxlen']
<br />KeyError: 'data_info'



### Error 2, [Traceback at line 98](https://github.com/arita37/mlmodels_store/blob/master/log_jupyter/log_jupyter.py#L98)<br />98..Traceback (most recent call last):
<br />  File "https://github.com/arita37/mlmodels/tree/6ca6da91408244e26c157e9e6467cc18ede43e71/mlmodels/models.py", line 72, in module_load
<br />    module = import_module(f"mlmodels.{model_name}")
<br />  File "/opt/hostedtoolcache/Python/3.6.11/x64/lib/python3.6/importlib/__init__.py", line 126, in import_module
<br />    return _bootstrap._gcd_import(name[level:], package, level)
<br />  File "<frozen importlib._bootstrap>", line 994, in _gcd_import
<br />  File "<frozen importlib._bootstrap>", line 971, in _find_and_load
<br />  File "<frozen importlib._bootstrap>", line 953, in _find_and_load_unlocked
<br />ModuleNotFoundError: No module named 'mlmodels.model_sklearn.sklearn'



### Error 3, [Traceback at line 110](https://github.com/arita37/mlmodels_store/blob/master/log_jupyter/log_jupyter.py#L110)<br />110..Traceback (most recent call last):
<br />  File "https://github.com/arita37/mlmodels/tree/6ca6da91408244e26c157e9e6467cc18ede43e71/mlmodels/models.py", line 84, in module_load
<br />    model_name = str(Path(model_uri).parts[-2]) + "." + str(model_name)
<br />IndexError: tuple index out of range



### Error 4, [Traceback at line 117](https://github.com/arita37/mlmodels_store/blob/master/log_jupyter/log_jupyter.py#L117)<br />117..Traceback (most recent call last):
<br />  File "https://github.com/arita37/mlmodels/tree/6ca6da91408244e26c157e9e6467cc18ede43e71/mlmodels/example//sklearn_titanic_svm.py", line 20, in <module>
<br />    module        =  module_load( model_uri= model_uri )                           # Load file definition
<br />  File "https://github.com/arita37/mlmodels/tree/6ca6da91408244e26c157e9e6467cc18ede43e71/mlmodels/models.py", line 89, in module_load
<br />    raise NameError(f"Module {model_name} notfound, {e1}, {e2}")
<br />NameError: Module model_sklearn.sklearn notfound, No module named 'mlmodels.model_sklearn.sklearn', tuple index out of range



### Error 5, [Traceback at line 135](https://github.com/arita37/mlmodels_store/blob/master/log_jupyter/log_jupyter.py#L135)<br />135..Traceback (most recent call last):
<br />  File "https://github.com/arita37/mlmodels/tree/6ca6da91408244e26c157e9e6467cc18ede43e71/mlmodels/example//gluon_automl_titanic.py", line 27, in <module>
<br />    data_path= '../mlmodels/dataset/json/gluon_automl.json'
<br />  File "https://github.com/arita37/mlmodels/tree/6ca6da91408244e26c157e9e6467cc18ede43e71/mlmodels/model_gluon/gluon_automl.py", line 82, in get_params
<br />    with open(data_path, encoding='utf-8') as config_f:
<br />FileNotFoundError: [Errno 2] No such file or directory: '../mlmodels/dataset/json/gluon_automl.json'



### Error 6, [Traceback at line 152](https://github.com/arita37/mlmodels_store/blob/master/log_jupyter/log_jupyter.py#L152)<br />152..Traceback (most recent call last):
<br />  File "https://github.com/arita37/mlmodels/tree/6ca6da91408244e26c157e9e6467cc18ede43e71/mlmodels/example//sklearn_titanic_randomForest_example2.py", line 22, in <module>
<br />    pars = json.load(open( data_path , mode='r'))
<br />FileNotFoundError: [Errno 2] No such file or directory: '../mlmodels/dataset/json/hyper_titanic_randomForest.json'



### Error 7, [Traceback at line 167](https://github.com/arita37/mlmodels_store/blob/master/log_jupyter/log_jupyter.py#L167)<br />167..Traceback (most recent call last):
<br />  File "https://github.com/arita37/mlmodels/tree/6ca6da91408244e26c157e9e6467cc18ede43e71/mlmodels/example//lightgbm_home_retail.py", line 21, in <module>
<br />    pars = json.load(open( data_path , mode='r'))
<br />FileNotFoundError: [Errno 2] No such file or directory: 'hyper_lightgbm_home_retail.json'



### Error 8, [Traceback at line 229](https://github.com/arita37/mlmodels_store/blob/master/log_jupyter/log_jupyter.py#L229)<br />229..Traceback (most recent call last):
<br />  File "/opt/hostedtoolcache/Python/3.6.11/x64/lib/python3.6/site-packages/autogluon/utils/tabular/ml/trainer/abstract_trainer.py", line 360, in train_single_full
<br />    Y_train=y_train, Y_test=y_test, scheduler_options=(self.scheduler_func, self.scheduler_options), verbosity=self.verbosity)
<br />  File "/opt/hostedtoolcache/Python/3.6.11/x64/lib/python3.6/site-packages/autogluon/utils/tabular/ml/models/lgb/lgb_model.py", line 283, in hyperparameter_tune
<br />    directory=directory, lgb_model=self, **params_copy)
<br />  File "/opt/hostedtoolcache/Python/3.6.11/x64/lib/python3.6/site-packages/autogluon/core/decorator.py", line 69, in register_args
<br />    self.update(**kwvars)
<br />  File "/opt/hostedtoolcache/Python/3.6.11/x64/lib/python3.6/site-packages/autogluon/core/decorator.py", line 79, in update
<br />    hp = v.get_hp(name=k)
<br />  File "/opt/hostedtoolcache/Python/3.6.11/x64/lib/python3.6/site-packages/autogluon/core/space.py", line 451, in get_hp
<br />    default_value=self._default)
<br />  File "ConfigSpace/hyperparameters.pyx", line 773, in ConfigSpace.hyperparameters.UniformIntegerHyperparameter.__init__
<br />  File "ConfigSpace/hyperparameters.pyx", line 843, in ConfigSpace.hyperparameters.UniformIntegerHyperparameter.check_default
<br />ValueError: Illegal default value 36



### Error 9, [Traceback at line 426](https://github.com/arita37/mlmodels_store/blob/master/log_jupyter/log_jupyter.py#L426)<br />426..Traceback (most recent call last):
<br />  File "/opt/hostedtoolcache/Python/3.6.11/x64/lib/python3.6/site-packages/distributed/comm/inproc.py", line 288, in connect
<br />    raise IOError("no endpoint for inproc address %r" % (address,))
<br />OSError: no endpoint for inproc address '10.1.0.4/3671/1'



### Error 10, [Traceback at line 464](https://github.com/arita37/mlmodels_store/blob/master/log_jupyter/log_jupyter.py#L464)<br />464..Traceback (most recent call last):
<br />  File "https://github.com/arita37/mlmodels/tree/6ca6da91408244e26c157e9e6467cc18ede43e71/mlmodels/models.py", line 72, in module_load
<br />    module = import_module(f"mlmodels.{model_name}")
<br />  File "/opt/hostedtoolcache/Python/3.6.11/x64/lib/python3.6/importlib/__init__.py", line 126, in import_module
<br />    return _bootstrap._gcd_import(name[level:], package, level)
<br />  File "<frozen importlib._bootstrap>", line 994, in _gcd_import
<br />  File "<frozen importlib._bootstrap>", line 971, in _find_and_load
<br />  File "<frozen importlib._bootstrap>", line 955, in _find_and_load_unlocked
<br />  File "<frozen importlib._bootstrap>", line 665, in _load_unlocked
<br />  File "<frozen importlib._bootstrap_external>", line 674, in exec_module
<br />  File "<frozen importlib._bootstrap_external>", line 781, in get_code
<br />  File "<frozen importlib._bootstrap_external>", line 741, in source_to_code
<br />  File "<frozen importlib._bootstrap>", line 219, in _call_with_frames_removed
<br />  File "https://github.com/arita37/mlmodels/tree/6ca6da91408244e26c157e9e6467cc18ede43e71/mlmodels/model_sklearn/model_lightgbm.py", line 316
<br />    else:
<br />       ^
<br />SyntaxError: invalid syntax



### Error 11, [Traceback at line 484](https://github.com/arita37/mlmodels_store/blob/master/log_jupyter/log_jupyter.py#L484)<br />484..Traceback (most recent call last):
<br />  File "https://github.com/arita37/mlmodels/tree/6ca6da91408244e26c157e9e6467cc18ede43e71/mlmodels/models.py", line 84, in module_load
<br />    model_name = str(Path(model_uri).parts[-2]) + "." + str(model_name)
<br />IndexError: tuple index out of range



### Error 12, [Traceback at line 491](https://github.com/arita37/mlmodels_store/blob/master/log_jupyter/log_jupyter.py#L491)<br />491..Traceback (most recent call last):
<br />  File "https://github.com/arita37/mlmodels/tree/6ca6da91408244e26c157e9e6467cc18ede43e71/mlmodels/example//lightgbm.py", line 23, in <module>
<br />    module        =  module_load( model_uri= model_uri)
<br />  File "https://github.com/arita37/mlmodels/tree/6ca6da91408244e26c157e9e6467cc18ede43e71/mlmodels/models.py", line 89, in module_load
<br />    raise NameError(f"Module {model_name} notfound, {e1}, {e2}")
<br />NameError: Module model_sklearn.model_lightgbm notfound, invalid syntax (model_lightgbm.py, line 316), tuple index out of range



### Error 13, [Traceback at line 519](https://github.com/arita37/mlmodels_store/blob/master/log_jupyter/log_jupyter.py#L519)<br />519..Traceback (most recent call last):
<br />  File "https://github.com/arita37/mlmodels/tree/6ca6da91408244e26c157e9e6467cc18ede43e71/mlmodels/models.py", line 72, in module_load
<br />    module = import_module(f"mlmodels.{model_name}")
<br />  File "/opt/hostedtoolcache/Python/3.6.11/x64/lib/python3.6/importlib/__init__.py", line 126, in import_module
<br />    return _bootstrap._gcd_import(name[level:], package, level)
<br />  File "<frozen importlib._bootstrap>", line 994, in _gcd_import
<br />  File "<frozen importlib._bootstrap>", line 971, in _find_and_load
<br />  File "<frozen importlib._bootstrap>", line 953, in _find_and_load_unlocked
<br />ModuleNotFoundError: No module named 'mlmodels.model_sklearn.sklearn'



### Error 14, [Traceback at line 531](https://github.com/arita37/mlmodels_store/blob/master/log_jupyter/log_jupyter.py#L531)<br />531..Traceback (most recent call last):
<br />  File "https://github.com/arita37/mlmodels/tree/6ca6da91408244e26c157e9e6467cc18ede43e71/mlmodels/models.py", line 84, in module_load
<br />    model_name = str(Path(model_uri).parts[-2]) + "." + str(model_name)
<br />IndexError: tuple index out of range



### Error 15, [Traceback at line 538](https://github.com/arita37/mlmodels_store/blob/master/log_jupyter/log_jupyter.py#L538)<br />538..Traceback (most recent call last):
<br />  File "https://github.com/arita37/mlmodels/tree/6ca6da91408244e26c157e9e6467cc18ede43e71/mlmodels/example//sklearn_titanic_randomForest.py", line 21, in <module>
<br />    module        =  module_load( model_uri= model_uri )                           # Load file definition
<br />  File "https://github.com/arita37/mlmodels/tree/6ca6da91408244e26c157e9e6467cc18ede43e71/mlmodels/models.py", line 89, in module_load
<br />    raise NameError(f"Module {model_name} notfound, {e1}, {e2}")
<br />NameError: Module model_sklearn.sklearn notfound, No module named 'mlmodels.model_sklearn.sklearn', tuple index out of range



### Error 16, [Traceback at line 555](https://github.com/arita37/mlmodels_store/blob/master/log_jupyter/log_jupyter.py#L555)<br />555..Traceback (most recent call last):
<br />  File "https://github.com/arita37/mlmodels/tree/6ca6da91408244e26c157e9e6467cc18ede43e71/mlmodels/example//lightgbm_titanic.py", line 21, in <module>
<br />    pars = json.load(open( data_path , mode='r'))
<br />FileNotFoundError: [Errno 2] No such file or directory: 'hyper_lightgbm_titanic.json'



### Error 17, [Traceback at line 569](https://github.com/arita37/mlmodels_store/blob/master/log_jupyter/log_jupyter.py#L569)<br />569..Traceback (most recent call last):
<br />  File "https://github.com/arita37/mlmodels/tree/6ca6da91408244e26c157e9e6467cc18ede43e71/mlmodels/example//lightgbm_glass.py", line 16, in <module>
<br />    print( os.getcwd())
<br />NameError: name 'os' is not defined



### Error 18, [Traceback at line 635](https://github.com/arita37/mlmodels_store/blob/master/log_jupyter/log_jupyter.py#L635)<br />635..Traceback (most recent call last):
<br />  File "https://github.com/arita37/mlmodels/tree/6ca6da91408244e26c157e9e6467cc18ede43e71/mlmodels/example//keras_charcnn_reuters.py", line 28, in <module>
<br />    pars = json.load(open( config_path , mode='r'))[config_mode]
<br />FileNotFoundError: [Errno 2] No such file or directory: 'reuters_charcnn.json'
<br />SyntaxError: invalid syntax



### Error 19, [Traceback at line 675](https://github.com/arita37/mlmodels_store/blob/master/log_jupyter/log_jupyter.py#L675)<br />675..Traceback (most recent call last):
<br />  File "https://github.com/arita37/mlmodels/tree/6ca6da91408244e26c157e9e6467cc18ede43e71/mlmodels/models.py", line 72, in module_load
<br />    module = import_module(f"mlmodels.{model_name}")
<br />  File "/opt/hostedtoolcache/Python/3.6.11/x64/lib/python3.6/importlib/__init__.py", line 126, in import_module
<br />    return _bootstrap._gcd_import(name[level:], package, level)
<br />  File "<frozen importlib._bootstrap>", line 994, in _gcd_import
<br />  File "<frozen importlib._bootstrap>", line 971, in _find_and_load
<br />  File "<frozen importlib._bootstrap>", line 953, in _find_and_load_unlocked
<br />ModuleNotFoundError: No module named 'mlmodels.model_sklearn.sklearn'



### Error 20, [Traceback at line 687](https://github.com/arita37/mlmodels_store/blob/master/log_jupyter/log_jupyter.py#L687)<br />687..Traceback (most recent call last):
<br />  File "https://github.com/arita37/mlmodels/tree/6ca6da91408244e26c157e9e6467cc18ede43e71/mlmodels/models.py", line 84, in module_load
<br />    model_name = str(Path(model_uri).parts[-2]) + "." + str(model_name)
<br />IndexError: tuple index out of range



### Error 21, [Traceback at line 694](https://github.com/arita37/mlmodels_store/blob/master/log_jupyter/log_jupyter.py#L694)<br />694..Traceback (most recent call last):
<br />  File "https://github.com/arita37/mlmodels/tree/6ca6da91408244e26c157e9e6467cc18ede43e71/mlmodels/example//sklearn.py", line 34, in <module>
<br />    module        =  module_load( model_uri= model_uri )                           # Load file definition
<br />  File "https://github.com/arita37/mlmodels/tree/6ca6da91408244e26c157e9e6467cc18ede43e71/mlmodels/models.py", line 89, in module_load
<br />    raise NameError(f"Module {model_name} notfound, {e1}, {e2}")
<br />NameError: Module model_sklearn.sklearn notfound, No module named 'mlmodels.model_sklearn.sklearn', tuple index out of range



### Error 22, [Traceback at line 710](https://github.com/arita37/mlmodels_store/blob/master/log_jupyter/log_jupyter.py#L710)<br />710..Traceback (most recent call last):
<br />  File "https://github.com/arita37/mlmodels/tree/6ca6da91408244e26c157e9e6467cc18ede43e71/mlmodels/example//tensorflow__lstm_json.py", line 13, in <module>
<br />    print( os.getcwd())
<br />NameError: name 'os' is not defined



### Error 23, [Traceback at line 722](https://github.com/arita37/mlmodels_store/blob/master/log_jupyter/log_jupyter.py#L722)<br />722..Traceback (most recent call last):
<br />  File "https://github.com/arita37/mlmodels/tree/6ca6da91408244e26c157e9e6467cc18ede43e71/mlmodels/models.py", line 72, in module_load
<br />    module = import_module(f"mlmodels.{model_name}")
<br />  File "/opt/hostedtoolcache/Python/3.6.11/x64/lib/python3.6/importlib/__init__.py", line 126, in import_module
<br />    return _bootstrap._gcd_import(name[level:], package, level)
<br />  File "<frozen importlib._bootstrap>", line 994, in _gcd_import
<br />  File "<frozen importlib._bootstrap>", line 971, in _find_and_load
<br />  File "<frozen importlib._bootstrap>", line 953, in _find_and_load_unlocked
<br />ModuleNotFoundError: No module named 'mlmodels.model_sklearn.sklearn'



### Error 24, [Traceback at line 734](https://github.com/arita37/mlmodels_store/blob/master/log_jupyter/log_jupyter.py#L734)<br />734..Traceback (most recent call last):
<br />  File "https://github.com/arita37/mlmodels/tree/6ca6da91408244e26c157e9e6467cc18ede43e71/mlmodels/models.py", line 84, in module_load
<br />    model_name = str(Path(model_uri).parts[-2]) + "." + str(model_name)
<br />IndexError: tuple index out of range



### Error 25, [Traceback at line 741](https://github.com/arita37/mlmodels_store/blob/master/log_jupyter/log_jupyter.py#L741)<br />741..Traceback (most recent call last):
<br />  File "https://github.com/arita37/mlmodels/tree/6ca6da91408244e26c157e9e6467cc18ede43e71/mlmodels/example//benchmark_timeseries_m5.py", line 27, in <module>
<br />    import mxnet as mx
<br />  File "/opt/hostedtoolcache/Python/3.6.11/x64/lib/python3.6/site-packages/mxnet/__init__.py", line 31, in <module>
<br />    from . import contrib
<br />  File "/opt/hostedtoolcache/Python/3.6.11/x64/lib/python3.6/site-packages/mxnet/contrib/__init__.py", line 31, in <module>
<br />    from . import onnx
<br />  File "/opt/hostedtoolcache/Python/3.6.11/x64/lib/python3.6/site-packages/mxnet/contrib/onnx/__init__.py", line 19, in <module>
<br />    from .onnx2mx.import_model import import_model, get_model_metadata
<br />  File "/opt/hostedtoolcache/Python/3.6.11/x64/lib/python3.6/site-packages/mxnet/contrib/onnx/onnx2mx/__init__.py", line 20, in <module>
<br />    from . import import_model
<br />  File "/opt/hostedtoolcache/Python/3.6.11/x64/lib/python3.6/site-packages/mxnet/contrib/onnx/onnx2mx/import_model.py", line 22, in <module>
<br />    from .import_onnx import GraphProto
<br />  File "/opt/hostedtoolcache/Python/3.6.11/x64/lib/python3.6/site-packages/mxnet/contrib/onnx/onnx2mx/import_onnx.py", line 26, in <module>
<br />    from ._import_helper import _convert_map as convert_map
<br />  File "/opt/hostedtoolcache/Python/3.6.11/x64/lib/python3.6/site-packages/mxnet/contrib/onnx/onnx2mx/_import_helper.py", line 21, in <module>
<br />    from ._op_translations import identity, random_uniform, random_normal, sample_multinomial
<br />  File "/opt/hostedtoolcache/Python/3.6.11/x64/lib/python3.6/site-packages/mxnet/contrib/onnx/onnx2mx/_op_translations.py", line 22, in <module>
<br />    from . import _translation_utils as translation_utils
<br />  File "/opt/hostedtoolcache/Python/3.6.11/x64/lib/python3.6/site-packages/mxnet/contrib/onnx/onnx2mx/_translation_utils.py", line 23, in <module>
<br />    from .... import  module
<br />  File "/opt/hostedtoolcache/Python/3.6.11/x64/lib/python3.6/site-packages/mxnet/module/__init__.py", line 22, in <module>
<br />    from .base_module import BaseModule
<br />  File "/opt/hostedtoolcache/Python/3.6.11/x64/lib/python3.6/site-packages/mxnet/module/base_module.py", line 31, in <module>
<br />    from ..model import BatchEndParam
<br />  File "/opt/hostedtoolcache/Python/3.6.11/x64/lib/python3.6/site-packages/mxnet/model.py", line 46, in <module>
<br />    from sklearn.base import BaseEstimator
<br />  File "https://github.com/arita37/mlmodels/tree/6ca6da91408244e26c157e9e6467cc18ede43e71/mlmodels/example/sklearn.py", line 34, in <module>
<br />    module        =  module_load( model_uri= model_uri )                           # Load file definition
<br />  File "https://github.com/arita37/mlmodels/tree/6ca6da91408244e26c157e9e6467cc18ede43e71/mlmodels/models.py", line 89, in module_load
<br />    raise NameError(f"Module {model_name} notfound, {e1}, {e2}")
<br />NameError: Module model_sklearn.sklearn notfound, No module named 'mlmodels.model_sklearn.sklearn', tuple index out of range



### Error 26, [Traceback at line 781](https://github.com/arita37/mlmodels_store/blob/master/log_jupyter/log_jupyter.py#L781)<br />781..Traceback (most recent call last):
<br />  File "https://github.com/arita37/mlmodels/tree/6ca6da91408244e26c157e9e6467cc18ede43e71/mlmodels/models.py", line 72, in module_load
<br />    module = import_module(f"mlmodels.{model_name}")
<br />  File "/opt/hostedtoolcache/Python/3.6.11/x64/lib/python3.6/importlib/__init__.py", line 126, in import_module
<br />    return _bootstrap._gcd_import(name[level:], package, level)
<br />  File "<frozen importlib._bootstrap>", line 994, in _gcd_import
<br />  File "<frozen importlib._bootstrap>", line 971, in _find_and_load
<br />  File "<frozen importlib._bootstrap>", line 953, in _find_and_load_unlocked
<br />ModuleNotFoundError: No module named 'mlmodels.model_sklearn.sklearn'



### Error 27, [Traceback at line 793](https://github.com/arita37/mlmodels_store/blob/master/log_jupyter/log_jupyter.py#L793)<br />793..Traceback (most recent call last):
<br />  File "https://github.com/arita37/mlmodels/tree/6ca6da91408244e26c157e9e6467cc18ede43e71/mlmodels/models.py", line 84, in module_load
<br />    model_name = str(Path(model_uri).parts[-2]) + "." + str(model_name)
<br />IndexError: tuple index out of range



### Error 28, [Traceback at line 800](https://github.com/arita37/mlmodels_store/blob/master/log_jupyter/log_jupyter.py#L800)<br />800..Traceback (most recent call last):
<br />  File "https://github.com/arita37/mlmodels/tree/6ca6da91408244e26c157e9e6467cc18ede43e71/mlmodels/example/benchmark_timeseries_m5.py", line 27, in <module>
<br />    import mxnet as mx
<br />  File "/opt/hostedtoolcache/Python/3.6.11/x64/lib/python3.6/site-packages/mxnet/__init__.py", line 31, in <module>
<br />    from . import contrib
<br />  File "/opt/hostedtoolcache/Python/3.6.11/x64/lib/python3.6/site-packages/mxnet/contrib/__init__.py", line 31, in <module>
<br />    from . import onnx
<br />  File "/opt/hostedtoolcache/Python/3.6.11/x64/lib/python3.6/site-packages/mxnet/contrib/onnx/__init__.py", line 19, in <module>
<br />    from .onnx2mx.import_model import import_model, get_model_metadata
<br />  File "/opt/hostedtoolcache/Python/3.6.11/x64/lib/python3.6/site-packages/mxnet/contrib/onnx/onnx2mx/__init__.py", line 20, in <module>
<br />    from . import import_model
<br />  File "/opt/hostedtoolcache/Python/3.6.11/x64/lib/python3.6/site-packages/mxnet/contrib/onnx/onnx2mx/import_model.py", line 22, in <module>
<br />    from .import_onnx import GraphProto
<br />  File "/opt/hostedtoolcache/Python/3.6.11/x64/lib/python3.6/site-packages/mxnet/contrib/onnx/onnx2mx/import_onnx.py", line 26, in <module>
<br />    from ._import_helper import _convert_map as convert_map
<br />  File "/opt/hostedtoolcache/Python/3.6.11/x64/lib/python3.6/site-packages/mxnet/contrib/onnx/onnx2mx/_import_helper.py", line 21, in <module>
<br />    from ._op_translations import identity, random_uniform, random_normal, sample_multinomial
<br />  File "/opt/hostedtoolcache/Python/3.6.11/x64/lib/python3.6/site-packages/mxnet/contrib/onnx/onnx2mx/_op_translations.py", line 22, in <module>
<br />    from . import _translation_utils as translation_utils
<br />  File "/opt/hostedtoolcache/Python/3.6.11/x64/lib/python3.6/site-packages/mxnet/contrib/onnx/onnx2mx/_translation_utils.py", line 23, in <module>
<br />    from .... import  module
<br />  File "/opt/hostedtoolcache/Python/3.6.11/x64/lib/python3.6/site-packages/mxnet/module/__init__.py", line 22, in <module>
<br />    from .base_module import BaseModule
<br />  File "/opt/hostedtoolcache/Python/3.6.11/x64/lib/python3.6/site-packages/mxnet/module/base_module.py", line 31, in <module>
<br />    from ..model import BatchEndParam
<br />  File "/opt/hostedtoolcache/Python/3.6.11/x64/lib/python3.6/site-packages/mxnet/model.py", line 46, in <module>
<br />    from sklearn.base import BaseEstimator
<br />  File "https://github.com/arita37/mlmodels/tree/6ca6da91408244e26c157e9e6467cc18ede43e71/mlmodels/example/sklearn.py", line 34, in <module>
<br />    module        =  module_load( model_uri= model_uri )                           # Load file definition
<br />  File "https://github.com/arita37/mlmodels/tree/6ca6da91408244e26c157e9e6467cc18ede43e71/mlmodels/models.py", line 89, in module_load
<br />    raise NameError(f"Module {model_name} notfound, {e1}, {e2}")
<br />NameError: Module model_sklearn.sklearn notfound, No module named 'mlmodels.model_sklearn.sklearn', tuple index out of range



### Error 29, [Traceback at line 850](https://github.com/arita37/mlmodels_store/blob/master/log_jupyter/log_jupyter.py#L850)<br />850..Traceback (most recent call last):
<br />  File "https://github.com/arita37/mlmodels/tree/6ca6da91408244e26c157e9e6467cc18ede43e71/mlmodels/example//arun_model.py", line 27, in <module>
<br />    pars = json.load(open(config_path , mode='r'))[config_mode]
<br />FileNotFoundError: [Errno 2] No such file or directory: 'https://github.com/arita37/mlmodels/tree/6ca6da91408244e26c157e9e6467cc18ede43e71/mlmodels/model_keras/ardmn.json'



### Error 30, [Traceback at line 862](https://github.com/arita37/mlmodels_store/blob/master/log_jupyter/log_jupyter.py#L862)<br />862..Traceback (most recent call last):
<br />  File "https://github.com/arita37/mlmodels/tree/6ca6da91408244e26c157e9e6467cc18ede43e71/mlmodels/example//arun_hyper.py", line 2, in <module>
<br />    from jsoncomment import JsonComment ; json = JsonComment(), copy
<br />NameError: name 'copy' is not defined



### Error 31, [Traceback at line 874](https://github.com/arita37/mlmodels_store/blob/master/log_jupyter/log_jupyter.py#L874)<br />874..Traceback (most recent call last):
<br />  File "https://github.com/arita37/mlmodels/tree/6ca6da91408244e26c157e9e6467cc18ede43e71/mlmodels/example//lightgbm_glass.py", line 16, in <module>
<br />    print( os.getcwd())
<br />NameError: name 'os' is not defined
<br />SyntaxError: invalid syntax
