## Original File URL: https://github.com/arita37/mlmodels_store/blob/master/log_json/log_json.py


### Error 1, [Traceback at line 83](https://github.com/arita37/mlmodels_store/blob/master/log_json/log_json.py#L83)<br />83..Traceback (most recent call last):
<br />  File "/opt/hostedtoolcache/Python/3.6.10/x64/bin/ml_models", line 11, in <module>
<br />    load_entry_point('mlmodels', 'console_scripts', 'ml_models')()
<br />  File "https://github.com/arita37/mlmodels/tree/a463a24ea257f46bfcbd4006f805952aace8f2b1/mlmodels/models.py", line 530, in main
<br />    fit_cli(arg)
<br />  File "https://github.com/arita37/mlmodels/tree/a463a24ea257f46bfcbd4006f805952aace8f2b1/mlmodels/models.py", line 424, in fit_cli
<br />    model, sess = fit(module, model, data_pars=data_p, compute_pars=compute_p, out_pars=out_p)
<br />TypeError: 'Model' object is not iterable



### Error 2, [Traceback at line 137](https://github.com/arita37/mlmodels_store/blob/master/log_json/log_json.py#L137)<br />137..Traceback (most recent call last):
<br />  File "/opt/hostedtoolcache/Python/3.6.10/x64/bin/ml_models", line 11, in <module>
<br />    load_entry_point('mlmodels', 'console_scripts', 'ml_models')()
<br />  File "https://github.com/arita37/mlmodels/tree/a463a24ea257f46bfcbd4006f805952aace8f2b1/mlmodels/models.py", line 530, in main
<br />    fit_cli(arg)
<br />  File "https://github.com/arita37/mlmodels/tree/a463a24ea257f46bfcbd4006f805952aace8f2b1/mlmodels/models.py", line 424, in fit_cli
<br />    model, sess = fit(module, model, data_pars=data_p, compute_pars=compute_p, out_pars=out_p)
<br />TypeError: 'Model' object is not iterable



### Error 3, [Traceback at line 196](https://github.com/arita37/mlmodels_store/blob/master/log_json/log_json.py#L196)<br />196..Traceback (most recent call last):
<br />  File "/opt/hostedtoolcache/Python/3.6.10/x64/bin/ml_models", line 11, in <module>
<br />    load_entry_point('mlmodels', 'console_scripts', 'ml_models')()
<br />  File "https://github.com/arita37/mlmodels/tree/a463a24ea257f46bfcbd4006f805952aace8f2b1/mlmodels/models.py", line 530, in main
<br />    fit_cli(arg)
<br />  File "https://github.com/arita37/mlmodels/tree/a463a24ea257f46bfcbd4006f805952aace8f2b1/mlmodels/models.py", line 424, in fit_cli
<br />    model, sess = fit(module, model, data_pars=data_p, compute_pars=compute_p, out_pars=out_p)
<br />TypeError: 'Model' object is not iterable



### Error 4, [Traceback at line 250](https://github.com/arita37/mlmodels_store/blob/master/log_json/log_json.py#L250)<br />250..Traceback (most recent call last):
<br />  File "/opt/hostedtoolcache/Python/3.6.10/x64/bin/ml_models", line 11, in <module>
<br />    load_entry_point('mlmodels', 'console_scripts', 'ml_models')()
<br />  File "https://github.com/arita37/mlmodels/tree/a463a24ea257f46bfcbd4006f805952aace8f2b1/mlmodels/models.py", line 530, in main
<br />    fit_cli(arg)
<br />  File "https://github.com/arita37/mlmodels/tree/a463a24ea257f46bfcbd4006f805952aace8f2b1/mlmodels/models.py", line 424, in fit_cli
<br />    model, sess = fit(module, model, data_pars=data_p, compute_pars=compute_p, out_pars=out_p)
<br />TypeError: 'Model' object is not iterable



### Error 5, [Traceback at line 314](https://github.com/arita37/mlmodels_store/blob/master/log_json/log_json.py#L314)<br />314..Traceback (most recent call last):
<br />  File "/opt/hostedtoolcache/Python/3.6.10/x64/bin/ml_models", line 11, in <module>
<br />    load_entry_point('mlmodels', 'console_scripts', 'ml_models')()
<br />  File "https://github.com/arita37/mlmodels/tree/a463a24ea257f46bfcbd4006f805952aace8f2b1/mlmodels/models.py", line 530, in main
<br />    fit_cli(arg)
<br />  File "https://github.com/arita37/mlmodels/tree/a463a24ea257f46bfcbd4006f805952aace8f2b1/mlmodels/models.py", line 424, in fit_cli
<br />    model, sess = fit(module, model, data_pars=data_p, compute_pars=compute_p, out_pars=out_p)
<br />TypeError: 'Model' object is not iterable



### Error 6, [Traceback at line 368](https://github.com/arita37/mlmodels_store/blob/master/log_json/log_json.py#L368)<br />368..Traceback (most recent call last):
<br />  File "/opt/hostedtoolcache/Python/3.6.10/x64/bin/ml_models", line 11, in <module>
<br />    load_entry_point('mlmodels', 'console_scripts', 'ml_models')()
<br />  File "https://github.com/arita37/mlmodels/tree/a463a24ea257f46bfcbd4006f805952aace8f2b1/mlmodels/models.py", line 530, in main
<br />    fit_cli(arg)
<br />  File "https://github.com/arita37/mlmodels/tree/a463a24ea257f46bfcbd4006f805952aace8f2b1/mlmodels/models.py", line 424, in fit_cli
<br />    model, sess = fit(module, model, data_pars=data_p, compute_pars=compute_p, out_pars=out_p)
<br />TypeError: 'Model' object is not iterable



### Error 7, [Traceback at line 421](https://github.com/arita37/mlmodels_store/blob/master/log_json/log_json.py#L421)<br />421..Traceback (most recent call last):
<br />  File "/opt/hostedtoolcache/Python/3.6.10/x64/bin/ml_models", line 11, in <module>
<br />    load_entry_point('mlmodels', 'console_scripts', 'ml_models')()
<br />  File "https://github.com/arita37/mlmodels/tree/a463a24ea257f46bfcbd4006f805952aace8f2b1/mlmodels/models.py", line 530, in main
<br />    fit_cli(arg)
<br />  File "https://github.com/arita37/mlmodels/tree/a463a24ea257f46bfcbd4006f805952aace8f2b1/mlmodels/models.py", line 424, in fit_cli
<br />    model, sess = fit(module, model, data_pars=data_p, compute_pars=compute_p, out_pars=out_p)
<br />TypeError: 'Model' object is not iterable



### Error 8, [Traceback at line 457](https://github.com/arita37/mlmodels_store/blob/master/log_json/log_json.py#L457)<br />457..Traceback (most recent call last):
<br />  File "/opt/hostedtoolcache/Python/3.6.10/x64/bin/ml_models", line 11, in <module>
<br />    load_entry_point('mlmodels', 'console_scripts', 'ml_models')()
<br />  File "https://github.com/arita37/mlmodels/tree/a463a24ea257f46bfcbd4006f805952aace8f2b1/mlmodels/models.py", line 530, in main
<br />    fit_cli(arg)
<br />  File "https://github.com/arita37/mlmodels/tree/a463a24ea257f46bfcbd4006f805952aace8f2b1/mlmodels/models.py", line 421, in fit_cli
<br />    model = model_create(module, model_p, data_p, compute_p)  # Exact map JSON and paramters
<br />  File "https://github.com/arita37/mlmodels/tree/a463a24ea257f46bfcbd4006f805952aace8f2b1/mlmodels/models.py", line 113, in model_create
<br />    model = module.Model(model_pars=model_pars, data_pars=data_pars, compute_pars=compute_pars, **kwarg)
<br />  File "https://github.com/arita37/mlmodels/tree/a463a24ea257f46bfcbd4006f805952aace8f2b1/mlmodels/model_gluon/gluonts_model.py", line 81, in __init__
<br />    mpars['encoder'] = MLPEncoder()   #bug in seq2seq
<br />  File "/opt/hostedtoolcache/Python/3.6.10/x64/lib/python3.6/site-packages/gluonts/core/component.py", line 424, in init_wrapper
<br />    model = PydanticModel(**{**nmargs, **kwargs})
<br />  File "pydantic/main.py", line 283, in pydantic.main.BaseModel.__init__
<br />pydantic.error_wrappers.ValidationError: 1 validation error for MLPEncoderModel
<br />layer_sizes
<br />  field required (type=value_error.missing)
<br />
<br />  
<br />
<br />
<br /> ************ JSON File https://github.com/arita37/mlmodels/tree/a463a24ea257f46bfcbd4006f805952aace8f2b1/mlmodels/dataset/json/benchmark_timeseries/test02/model_list.json 
<br />
<br />
<br />
<br />
<br />
<br /> ************************************************************************************************************************
<br />
<br />  ml_models --do fit --config_file https://github.com/arita37/mlmodels/tree/a463a24ea257f46bfcbd4006f805952aace8f2b1/mlmodels/dataset/json/benchmark_timeseries/test02/model_list.json  --config_mode fb_prophet  
<br />fit
<br />
<br />  ##### Load JSON https://github.com/arita37/mlmodels/tree/a463a24ea257f46bfcbd4006f805952aace8f2b1/mlmodels/dataset/json/benchmark_timeseries/test02/model_list.json 



### Error 9, [Traceback at line 490](https://github.com/arita37/mlmodels_store/blob/master/log_json/log_json.py#L490)<br />490..Traceback (most recent call last):
<br />  File "/opt/hostedtoolcache/Python/3.6.10/x64/bin/ml_models", line 11, in <module>
<br />    load_entry_point('mlmodels', 'console_scripts', 'ml_models')()
<br />  File "https://github.com/arita37/mlmodels/tree/a463a24ea257f46bfcbd4006f805952aace8f2b1/mlmodels/models.py", line 530, in main
<br />    fit_cli(arg)
<br />  File "https://github.com/arita37/mlmodels/tree/a463a24ea257f46bfcbd4006f805952aace8f2b1/mlmodels/models.py", line 415, in fit_cli
<br />    path      = out_p['path']
<br />KeyError: 'path'



### Error 10, [Traceback at line 509](https://github.com/arita37/mlmodels_store/blob/master/log_json/log_json.py#L509)<br />509..Traceback (most recent call last):
<br />  File "/opt/hostedtoolcache/Python/3.6.10/x64/bin/ml_models", line 11, in <module>
<br />    load_entry_point('mlmodels', 'console_scripts', 'ml_models')()
<br />  File "https://github.com/arita37/mlmodels/tree/a463a24ea257f46bfcbd4006f805952aace8f2b1/mlmodels/models.py", line 530, in main
<br />    fit_cli(arg)
<br />  File "https://github.com/arita37/mlmodels/tree/a463a24ea257f46bfcbd4006f805952aace8f2b1/mlmodels/models.py", line 415, in fit_cli
<br />    path      = out_p['path']
<br />KeyError: 'path'



### Error 11, [Traceback at line 528](https://github.com/arita37/mlmodels_store/blob/master/log_json/log_json.py#L528)<br />528..Traceback (most recent call last):
<br />  File "/opt/hostedtoolcache/Python/3.6.10/x64/bin/ml_models", line 11, in <module>
<br />    load_entry_point('mlmodels', 'console_scripts', 'ml_models')()
<br />  File "https://github.com/arita37/mlmodels/tree/a463a24ea257f46bfcbd4006f805952aace8f2b1/mlmodels/models.py", line 530, in main
<br />    fit_cli(arg)
<br />  File "https://github.com/arita37/mlmodels/tree/a463a24ea257f46bfcbd4006f805952aace8f2b1/mlmodels/models.py", line 415, in fit_cli
<br />    path      = out_p['path']
<br />KeyError: 'path'



### Error 12, [Traceback at line 582](https://github.com/arita37/mlmodels_store/blob/master/log_json/log_json.py#L582)<br />582..Traceback (most recent call last):
<br />  File "/opt/hostedtoolcache/Python/3.6.10/x64/bin/ml_models", line 11, in <module>
<br />    load_entry_point('mlmodels', 'console_scripts', 'ml_models')()
<br />  File "https://github.com/arita37/mlmodels/tree/a463a24ea257f46bfcbd4006f805952aace8f2b1/mlmodels/models.py", line 530, in main
<br />    fit_cli(arg)
<br />  File "https://github.com/arita37/mlmodels/tree/a463a24ea257f46bfcbd4006f805952aace8f2b1/mlmodels/models.py", line 424, in fit_cli
<br />    model, sess = fit(module, model, data_pars=data_p, compute_pars=compute_p, out_pars=out_p)
<br />TypeError: 'Model' object is not iterable



### Error 13, [Traceback at line 636](https://github.com/arita37/mlmodels_store/blob/master/log_json/log_json.py#L636)<br />636..Traceback (most recent call last):
<br />  File "/opt/hostedtoolcache/Python/3.6.10/x64/bin/ml_models", line 11, in <module>
<br />    load_entry_point('mlmodels', 'console_scripts', 'ml_models')()
<br />  File "https://github.com/arita37/mlmodels/tree/a463a24ea257f46bfcbd4006f805952aace8f2b1/mlmodels/models.py", line 530, in main
<br />    fit_cli(arg)
<br />  File "https://github.com/arita37/mlmodels/tree/a463a24ea257f46bfcbd4006f805952aace8f2b1/mlmodels/models.py", line 424, in fit_cli
<br />    model, sess = fit(module, model, data_pars=data_p, compute_pars=compute_p, out_pars=out_p)
<br />TypeError: 'Model' object is not iterable



### Error 14, [Traceback at line 695](https://github.com/arita37/mlmodels_store/blob/master/log_json/log_json.py#L695)<br />695..Traceback (most recent call last):
<br />  File "/opt/hostedtoolcache/Python/3.6.10/x64/bin/ml_models", line 11, in <module>
<br />    load_entry_point('mlmodels', 'console_scripts', 'ml_models')()
<br />  File "https://github.com/arita37/mlmodels/tree/a463a24ea257f46bfcbd4006f805952aace8f2b1/mlmodels/models.py", line 530, in main
<br />    fit_cli(arg)
<br />  File "https://github.com/arita37/mlmodels/tree/a463a24ea257f46bfcbd4006f805952aace8f2b1/mlmodels/models.py", line 424, in fit_cli
<br />    model, sess = fit(module, model, data_pars=data_p, compute_pars=compute_p, out_pars=out_p)
<br />TypeError: 'Model' object is not iterable



### Error 15, [Traceback at line 749](https://github.com/arita37/mlmodels_store/blob/master/log_json/log_json.py#L749)<br />749..Traceback (most recent call last):
<br />  File "/opt/hostedtoolcache/Python/3.6.10/x64/bin/ml_models", line 11, in <module>
<br />    load_entry_point('mlmodels', 'console_scripts', 'ml_models')()
<br />  File "https://github.com/arita37/mlmodels/tree/a463a24ea257f46bfcbd4006f805952aace8f2b1/mlmodels/models.py", line 530, in main
<br />    fit_cli(arg)
<br />  File "https://github.com/arita37/mlmodels/tree/a463a24ea257f46bfcbd4006f805952aace8f2b1/mlmodels/models.py", line 424, in fit_cli
<br />    model, sess = fit(module, model, data_pars=data_p, compute_pars=compute_p, out_pars=out_p)
<br />TypeError: 'Model' object is not iterable



### Error 16, [Traceback at line 813](https://github.com/arita37/mlmodels_store/blob/master/log_json/log_json.py#L813)<br />813..Traceback (most recent call last):
<br />  File "/opt/hostedtoolcache/Python/3.6.10/x64/bin/ml_models", line 11, in <module>
<br />    load_entry_point('mlmodels', 'console_scripts', 'ml_models')()
<br />  File "https://github.com/arita37/mlmodels/tree/a463a24ea257f46bfcbd4006f805952aace8f2b1/mlmodels/models.py", line 530, in main
<br />    fit_cli(arg)
<br />  File "https://github.com/arita37/mlmodels/tree/a463a24ea257f46bfcbd4006f805952aace8f2b1/mlmodels/models.py", line 424, in fit_cli
<br />    model, sess = fit(module, model, data_pars=data_p, compute_pars=compute_p, out_pars=out_p)
<br />TypeError: 'Model' object is not iterable



### Error 17, [Traceback at line 867](https://github.com/arita37/mlmodels_store/blob/master/log_json/log_json.py#L867)<br />867..Traceback (most recent call last):
<br />  File "/opt/hostedtoolcache/Python/3.6.10/x64/bin/ml_models", line 11, in <module>
<br />    load_entry_point('mlmodels', 'console_scripts', 'ml_models')()
<br />  File "https://github.com/arita37/mlmodels/tree/a463a24ea257f46bfcbd4006f805952aace8f2b1/mlmodels/models.py", line 530, in main
<br />    fit_cli(arg)
<br />  File "https://github.com/arita37/mlmodels/tree/a463a24ea257f46bfcbd4006f805952aace8f2b1/mlmodels/models.py", line 424, in fit_cli
<br />    model, sess = fit(module, model, data_pars=data_p, compute_pars=compute_p, out_pars=out_p)
<br />TypeError: 'Model' object is not iterable



### Error 18, [Traceback at line 920](https://github.com/arita37/mlmodels_store/blob/master/log_json/log_json.py#L920)<br />920..Traceback (most recent call last):
<br />  File "/opt/hostedtoolcache/Python/3.6.10/x64/bin/ml_models", line 11, in <module>
<br />    load_entry_point('mlmodels', 'console_scripts', 'ml_models')()
<br />  File "https://github.com/arita37/mlmodels/tree/a463a24ea257f46bfcbd4006f805952aace8f2b1/mlmodels/models.py", line 530, in main
<br />    fit_cli(arg)
<br />  File "https://github.com/arita37/mlmodels/tree/a463a24ea257f46bfcbd4006f805952aace8f2b1/mlmodels/models.py", line 424, in fit_cli
<br />    model, sess = fit(module, model, data_pars=data_p, compute_pars=compute_p, out_pars=out_p)
<br />TypeError: 'Model' object is not iterable



### Error 19, [Traceback at line 956](https://github.com/arita37/mlmodels_store/blob/master/log_json/log_json.py#L956)<br />956..Traceback (most recent call last):
<br />  File "/opt/hostedtoolcache/Python/3.6.10/x64/bin/ml_models", line 11, in <module>
<br />    load_entry_point('mlmodels', 'console_scripts', 'ml_models')()
<br />  File "https://github.com/arita37/mlmodels/tree/a463a24ea257f46bfcbd4006f805952aace8f2b1/mlmodels/models.py", line 530, in main
<br />    fit_cli(arg)
<br />  File "https://github.com/arita37/mlmodels/tree/a463a24ea257f46bfcbd4006f805952aace8f2b1/mlmodels/models.py", line 421, in fit_cli
<br />    model = model_create(module, model_p, data_p, compute_p)  # Exact map JSON and paramters
<br />  File "https://github.com/arita37/mlmodels/tree/a463a24ea257f46bfcbd4006f805952aace8f2b1/mlmodels/models.py", line 113, in model_create
<br />    model = module.Model(model_pars=model_pars, data_pars=data_pars, compute_pars=compute_pars, **kwarg)
<br />  File "https://github.com/arita37/mlmodels/tree/a463a24ea257f46bfcbd4006f805952aace8f2b1/mlmodels/model_gluon/gluonts_model.py", line 81, in __init__
<br />    mpars['encoder'] = MLPEncoder()   #bug in seq2seq
<br />  File "/opt/hostedtoolcache/Python/3.6.10/x64/lib/python3.6/site-packages/gluonts/core/component.py", line 424, in init_wrapper
<br />    model = PydanticModel(**{**nmargs, **kwargs})
<br />  File "pydantic/main.py", line 283, in pydantic.main.BaseModel.__init__
<br />pydantic.error_wrappers.ValidationError: 1 validation error for MLPEncoderModel
<br />layer_sizes
<br />  field required (type=value_error.missing)
<br />
<br />  
<br />
<br />
<br /> ************ JSON File https://github.com/arita37/mlmodels/tree/a463a24ea257f46bfcbd4006f805952aace8f2b1/mlmodels/dataset/json/benchmark_timeseries/test01/fbprophet.json 
<br />
<br />
<br />
<br />
<br />
<br /> ************************************************************************************************************************
<br />
<br />  ml_models --do fit --config_file https://github.com/arita37/mlmodels/tree/a463a24ea257f46bfcbd4006f805952aace8f2b1/mlmodels/dataset/json/benchmark_timeseries/test01/fbprophet.json  --config_mode test  
<br />fit
<br />
<br />  ##### Load JSON https://github.com/arita37/mlmodels/tree/a463a24ea257f46bfcbd4006f805952aace8f2b1/mlmodels/dataset/json/benchmark_timeseries/test01/fbprophet.json 



### Error 20, [Traceback at line 989](https://github.com/arita37/mlmodels_store/blob/master/log_json/log_json.py#L989)<br />989..Traceback (most recent call last):
<br />  File "/opt/hostedtoolcache/Python/3.6.10/x64/bin/ml_models", line 11, in <module>
<br />    load_entry_point('mlmodels', 'console_scripts', 'ml_models')()
<br />  File "https://github.com/arita37/mlmodels/tree/a463a24ea257f46bfcbd4006f805952aace8f2b1/mlmodels/models.py", line 530, in main
<br />    fit_cli(arg)
<br />  File "https://github.com/arita37/mlmodels/tree/a463a24ea257f46bfcbd4006f805952aace8f2b1/mlmodels/models.py", line 415, in fit_cli
<br />    path      = out_p['path']
<br />KeyError: 'path'



### Error 21, [Traceback at line 1013](https://github.com/arita37/mlmodels_store/blob/master/log_json/log_json.py#L1013)<br />1013..Traceback (most recent call last):
<br />  File "/opt/hostedtoolcache/Python/3.6.10/x64/bin/ml_models", line 11, in <module>
<br />    load_entry_point('mlmodels', 'console_scripts', 'ml_models')()
<br />  File "https://github.com/arita37/mlmodels/tree/a463a24ea257f46bfcbd4006f805952aace8f2b1/mlmodels/models.py", line 530, in main
<br />    fit_cli(arg)
<br />  File "https://github.com/arita37/mlmodels/tree/a463a24ea257f46bfcbd4006f805952aace8f2b1/mlmodels/models.py", line 414, in fit_cli
<br />    model_uri = model_p['model_uri']
<br />KeyError: 'model_uri'



### Error 22, [Traceback at line 1037](https://github.com/arita37/mlmodels_store/blob/master/log_json/log_json.py#L1037)<br />1037..Traceback (most recent call last):
<br />  File "/opt/hostedtoolcache/Python/3.6.10/x64/bin/ml_models", line 11, in <module>
<br />    load_entry_point('mlmodels', 'console_scripts', 'ml_models')()
<br />  File "https://github.com/arita37/mlmodels/tree/a463a24ea257f46bfcbd4006f805952aace8f2b1/mlmodels/models.py", line 530, in main
<br />    fit_cli(arg)
<br />  File "https://github.com/arita37/mlmodels/tree/a463a24ea257f46bfcbd4006f805952aace8f2b1/mlmodels/models.py", line 415, in fit_cli
<br />    path      = out_p['path']
<br />KeyError: 'path'



### Error 23, [Traceback at line 1061](https://github.com/arita37/mlmodels_store/blob/master/log_json/log_json.py#L1061)<br />1061..Traceback (most recent call last):
<br />  File "/opt/hostedtoolcache/Python/3.6.10/x64/bin/ml_models", line 11, in <module>
<br />    load_entry_point('mlmodels', 'console_scripts', 'ml_models')()
<br />  File "https://github.com/arita37/mlmodels/tree/a463a24ea257f46bfcbd4006f805952aace8f2b1/mlmodels/models.py", line 530, in main
<br />    fit_cli(arg)
<br />  File "https://github.com/arita37/mlmodels/tree/a463a24ea257f46bfcbd4006f805952aace8f2b1/mlmodels/models.py", line 415, in fit_cli
<br />    path      = out_p['path']
<br />KeyError: 'path'



### Error 24, [Traceback at line 1080](https://github.com/arita37/mlmodels_store/blob/master/log_json/log_json.py#L1080)<br />1080..Traceback (most recent call last):
<br />  File "/opt/hostedtoolcache/Python/3.6.10/x64/bin/ml_models", line 11, in <module>
<br />    load_entry_point('mlmodels', 'console_scripts', 'ml_models')()
<br />  File "https://github.com/arita37/mlmodels/tree/a463a24ea257f46bfcbd4006f805952aace8f2b1/mlmodels/models.py", line 530, in main
<br />    fit_cli(arg)
<br />  File "https://github.com/arita37/mlmodels/tree/a463a24ea257f46bfcbd4006f805952aace8f2b1/mlmodels/models.py", line 413, in fit_cli
<br />    model_p, data_p, compute_p, out_p = config_get_pars(config_file, arg.config_mode)
<br />  File "https://github.com/arita37/mlmodels/tree/a463a24ea257f46bfcbd4006f805952aace8f2b1/mlmodels/models.py", line 297, in config_get_pars
<br />    data_p    = path_norm_dict( js.get("data_pars") )
<br />  File "https://github.com/arita37/mlmodels/tree/a463a24ea257f46bfcbd4006f805952aace8f2b1/mlmodels/util.py", line 201, in path_norm_dict
<br />    for k,v in ddict.items():
<br />AttributeError: 'NoneType' object has no attribute 'items'



### Error 25, [Traceback at line 1108](https://github.com/arita37/mlmodels_store/blob/master/log_json/log_json.py#L1108)<br />1108..Traceback (most recent call last):
<br />  File "/opt/hostedtoolcache/Python/3.6.10/x64/bin/ml_models", line 11, in <module>
<br />    load_entry_point('mlmodels', 'console_scripts', 'ml_models')()
<br />  File "https://github.com/arita37/mlmodels/tree/a463a24ea257f46bfcbd4006f805952aace8f2b1/mlmodels/models.py", line 530, in main
<br />    fit_cli(arg)
<br />  File "https://github.com/arita37/mlmodels/tree/a463a24ea257f46bfcbd4006f805952aace8f2b1/mlmodels/models.py", line 414, in fit_cli
<br />    model_uri = model_p['model_uri']
<br />KeyError: 'model_uri'



### Error 26, [Traceback at line 1127](https://github.com/arita37/mlmodels_store/blob/master/log_json/log_json.py#L1127)<br />1127..Traceback (most recent call last):
<br />  File "/opt/hostedtoolcache/Python/3.6.10/x64/bin/ml_models", line 11, in <module>
<br />    load_entry_point('mlmodels', 'console_scripts', 'ml_models')()
<br />  File "https://github.com/arita37/mlmodels/tree/a463a24ea257f46bfcbd4006f805952aace8f2b1/mlmodels/models.py", line 530, in main
<br />    fit_cli(arg)
<br />  File "https://github.com/arita37/mlmodels/tree/a463a24ea257f46bfcbd4006f805952aace8f2b1/mlmodels/models.py", line 413, in fit_cli
<br />    model_p, data_p, compute_p, out_p = config_get_pars(config_file, arg.config_mode)
<br />  File "https://github.com/arita37/mlmodels/tree/a463a24ea257f46bfcbd4006f805952aace8f2b1/mlmodels/models.py", line 297, in config_get_pars
<br />    data_p    = path_norm_dict( js.get("data_pars") )
<br />  File "https://github.com/arita37/mlmodels/tree/a463a24ea257f46bfcbd4006f805952aace8f2b1/mlmodels/util.py", line 201, in path_norm_dict
<br />    for k,v in ddict.items():
<br />AttributeError: 'NoneType' object has no attribute 'items'



### Error 27, [Traceback at line 1155](https://github.com/arita37/mlmodels_store/blob/master/log_json/log_json.py#L1155)<br />1155..Traceback (most recent call last):
<br />  File "/opt/hostedtoolcache/Python/3.6.10/x64/bin/ml_models", line 11, in <module>
<br />    load_entry_point('mlmodels', 'console_scripts', 'ml_models')()
<br />  File "https://github.com/arita37/mlmodels/tree/a463a24ea257f46bfcbd4006f805952aace8f2b1/mlmodels/models.py", line 530, in main
<br />    fit_cli(arg)
<br />  File "https://github.com/arita37/mlmodels/tree/a463a24ea257f46bfcbd4006f805952aace8f2b1/mlmodels/models.py", line 414, in fit_cli
<br />    model_uri = model_p['model_uri']
<br />KeyError: 'model_uri'



### Error 28, [Traceback at line 1179](https://github.com/arita37/mlmodels_store/blob/master/log_json/log_json.py#L1179)<br />1179..Traceback (most recent call last):
<br />  File "/opt/hostedtoolcache/Python/3.6.10/x64/bin/ml_models", line 11, in <module>
<br />    load_entry_point('mlmodels', 'console_scripts', 'ml_models')()
<br />  File "https://github.com/arita37/mlmodels/tree/a463a24ea257f46bfcbd4006f805952aace8f2b1/mlmodels/models.py", line 530, in main
<br />    fit_cli(arg)
<br />  File "https://github.com/arita37/mlmodels/tree/a463a24ea257f46bfcbd4006f805952aace8f2b1/mlmodels/models.py", line 414, in fit_cli
<br />    model_uri = model_p['model_uri']
<br />KeyError: 'model_uri'



### Error 29, [Traceback at line 1203](https://github.com/arita37/mlmodels_store/blob/master/log_json/log_json.py#L1203)<br />1203..Traceback (most recent call last):
<br />  File "/opt/hostedtoolcache/Python/3.6.10/x64/bin/ml_models", line 11, in <module>
<br />    load_entry_point('mlmodels', 'console_scripts', 'ml_models')()
<br />  File "https://github.com/arita37/mlmodels/tree/a463a24ea257f46bfcbd4006f805952aace8f2b1/mlmodels/models.py", line 530, in main
<br />    fit_cli(arg)
<br />  File "https://github.com/arita37/mlmodels/tree/a463a24ea257f46bfcbd4006f805952aace8f2b1/mlmodels/models.py", line 414, in fit_cli
<br />    model_uri = model_p['model_uri']
<br />KeyError: 'model_uri'



### Error 30, [Traceback at line 1222](https://github.com/arita37/mlmodels_store/blob/master/log_json/log_json.py#L1222)<br />1222..Traceback (most recent call last):
<br />  File "/opt/hostedtoolcache/Python/3.6.10/x64/bin/ml_models", line 11, in <module>
<br />    load_entry_point('mlmodels', 'console_scripts', 'ml_models')()
<br />  File "https://github.com/arita37/mlmodels/tree/a463a24ea257f46bfcbd4006f805952aace8f2b1/mlmodels/models.py", line 530, in main
<br />    fit_cli(arg)
<br />  File "https://github.com/arita37/mlmodels/tree/a463a24ea257f46bfcbd4006f805952aace8f2b1/mlmodels/models.py", line 413, in fit_cli
<br />    model_p, data_p, compute_p, out_p = config_get_pars(config_file, arg.config_mode)
<br />  File "https://github.com/arita37/mlmodels/tree/a463a24ea257f46bfcbd4006f805952aace8f2b1/mlmodels/models.py", line 299, in config_get_pars
<br />    out_p     = path_norm_dict( js.get("out_pars") )
<br />  File "https://github.com/arita37/mlmodels/tree/a463a24ea257f46bfcbd4006f805952aace8f2b1/mlmodels/util.py", line 201, in path_norm_dict
<br />    for k,v in ddict.items():
<br />AttributeError: 'NoneType' object has no attribute 'items'



### Error 31, [Traceback at line 1250](https://github.com/arita37/mlmodels_store/blob/master/log_json/log_json.py#L1250)<br />1250..Traceback (most recent call last):
<br />  File "/opt/hostedtoolcache/Python/3.6.10/x64/bin/ml_models", line 11, in <module>
<br />    load_entry_point('mlmodels', 'console_scripts', 'ml_models')()
<br />  File "https://github.com/arita37/mlmodels/tree/a463a24ea257f46bfcbd4006f805952aace8f2b1/mlmodels/models.py", line 530, in main
<br />    fit_cli(arg)
<br />  File "https://github.com/arita37/mlmodels/tree/a463a24ea257f46bfcbd4006f805952aace8f2b1/mlmodels/models.py", line 415, in fit_cli
<br />    path      = out_p['path']
<br />KeyError: 'path'



### Error 32, [Traceback at line 1274](https://github.com/arita37/mlmodels_store/blob/master/log_json/log_json.py#L1274)<br />1274..Traceback (most recent call last):
<br />  File "/opt/hostedtoolcache/Python/3.6.10/x64/bin/ml_models", line 11, in <module>
<br />    load_entry_point('mlmodels', 'console_scripts', 'ml_models')()
<br />  File "https://github.com/arita37/mlmodels/tree/a463a24ea257f46bfcbd4006f805952aace8f2b1/mlmodels/models.py", line 530, in main
<br />    fit_cli(arg)
<br />  File "https://github.com/arita37/mlmodels/tree/a463a24ea257f46bfcbd4006f805952aace8f2b1/mlmodels/models.py", line 414, in fit_cli
<br />    model_uri = model_p['model_uri']
<br />KeyError: 'model_uri'



### Error 33, [Traceback at line 1298](https://github.com/arita37/mlmodels_store/blob/master/log_json/log_json.py#L1298)<br />1298..Traceback (most recent call last):
<br />  File "/opt/hostedtoolcache/Python/3.6.10/x64/bin/ml_models", line 11, in <module>
<br />    load_entry_point('mlmodels', 'console_scripts', 'ml_models')()
<br />  File "https://github.com/arita37/mlmodels/tree/a463a24ea257f46bfcbd4006f805952aace8f2b1/mlmodels/models.py", line 530, in main
<br />    fit_cli(arg)
<br />  File "https://github.com/arita37/mlmodels/tree/a463a24ea257f46bfcbd4006f805952aace8f2b1/mlmodels/models.py", line 414, in fit_cli
<br />    model_uri = model_p['model_uri']
<br />KeyError: 'model_uri'



### Error 34, [Traceback at line 1317](https://github.com/arita37/mlmodels_store/blob/master/log_json/log_json.py#L1317)<br />1317..Traceback (most recent call last):
<br />  File "/opt/hostedtoolcache/Python/3.6.10/x64/bin/ml_models", line 11, in <module>
<br />    load_entry_point('mlmodels', 'console_scripts', 'ml_models')()
<br />  File "https://github.com/arita37/mlmodels/tree/a463a24ea257f46bfcbd4006f805952aace8f2b1/mlmodels/models.py", line 530, in main
<br />    fit_cli(arg)
<br />  File "https://github.com/arita37/mlmodels/tree/a463a24ea257f46bfcbd4006f805952aace8f2b1/mlmodels/models.py", line 413, in fit_cli
<br />    model_p, data_p, compute_p, out_p = config_get_pars(config_file, arg.config_mode)
<br />  File "https://github.com/arita37/mlmodels/tree/a463a24ea257f46bfcbd4006f805952aace8f2b1/mlmodels/models.py", line 299, in config_get_pars
<br />    out_p     = path_norm_dict( js.get("out_pars") )
<br />  File "https://github.com/arita37/mlmodels/tree/a463a24ea257f46bfcbd4006f805952aace8f2b1/mlmodels/util.py", line 201, in path_norm_dict
<br />    for k,v in ddict.items():
<br />AttributeError: 'NoneType' object has no attribute 'items'



### Error 35, [Traceback at line 1345](https://github.com/arita37/mlmodels_store/blob/master/log_json/log_json.py#L1345)<br />1345..Traceback (most recent call last):
<br />  File "/opt/hostedtoolcache/Python/3.6.10/x64/bin/ml_models", line 11, in <module>
<br />    load_entry_point('mlmodels', 'console_scripts', 'ml_models')()
<br />  File "https://github.com/arita37/mlmodels/tree/a463a24ea257f46bfcbd4006f805952aace8f2b1/mlmodels/models.py", line 530, in main
<br />    fit_cli(arg)
<br />  File "https://github.com/arita37/mlmodels/tree/a463a24ea257f46bfcbd4006f805952aace8f2b1/mlmodels/models.py", line 414, in fit_cli
<br />    model_uri = model_p['model_uri']
<br />KeyError: 'model_uri'



### Error 36, [Traceback at line 1364](https://github.com/arita37/mlmodels_store/blob/master/log_json/log_json.py#L1364)<br />1364..Traceback (most recent call last):
<br />  File "/opt/hostedtoolcache/Python/3.6.10/x64/bin/ml_models", line 11, in <module>
<br />    load_entry_point('mlmodels', 'console_scripts', 'ml_models')()
<br />  File "https://github.com/arita37/mlmodels/tree/a463a24ea257f46bfcbd4006f805952aace8f2b1/mlmodels/models.py", line 530, in main
<br />    fit_cli(arg)
<br />  File "https://github.com/arita37/mlmodels/tree/a463a24ea257f46bfcbd4006f805952aace8f2b1/mlmodels/models.py", line 413, in fit_cli
<br />    model_p, data_p, compute_p, out_p = config_get_pars(config_file, arg.config_mode)
<br />  File "https://github.com/arita37/mlmodels/tree/a463a24ea257f46bfcbd4006f805952aace8f2b1/mlmodels/models.py", line 299, in config_get_pars
<br />    out_p     = path_norm_dict( js.get("out_pars") )
<br />  File "https://github.com/arita37/mlmodels/tree/a463a24ea257f46bfcbd4006f805952aace8f2b1/mlmodels/util.py", line 201, in path_norm_dict
<br />    for k,v in ddict.items():
<br />AttributeError: 'NoneType' object has no attribute 'items'



### Error 37, [Traceback at line 1392](https://github.com/arita37/mlmodels_store/blob/master/log_json/log_json.py#L1392)<br />1392..Traceback (most recent call last):
<br />  File "/opt/hostedtoolcache/Python/3.6.10/x64/bin/ml_models", line 11, in <module>
<br />    load_entry_point('mlmodels', 'console_scripts', 'ml_models')()
<br />  File "https://github.com/arita37/mlmodels/tree/a463a24ea257f46bfcbd4006f805952aace8f2b1/mlmodels/models.py", line 530, in main
<br />    fit_cli(arg)
<br />  File "https://github.com/arita37/mlmodels/tree/a463a24ea257f46bfcbd4006f805952aace8f2b1/mlmodels/models.py", line 414, in fit_cli
<br />    model_uri = model_p['model_uri']
<br />KeyError: 'model_uri'



### Error 38, [Traceback at line 1411](https://github.com/arita37/mlmodels_store/blob/master/log_json/log_json.py#L1411)<br />1411..Traceback (most recent call last):
<br />  File "/opt/hostedtoolcache/Python/3.6.10/x64/bin/ml_models", line 11, in <module>
<br />    load_entry_point('mlmodels', 'console_scripts', 'ml_models')()
<br />  File "https://github.com/arita37/mlmodels/tree/a463a24ea257f46bfcbd4006f805952aace8f2b1/mlmodels/models.py", line 530, in main
<br />    fit_cli(arg)
<br />  File "https://github.com/arita37/mlmodels/tree/a463a24ea257f46bfcbd4006f805952aace8f2b1/mlmodels/models.py", line 413, in fit_cli
<br />    model_p, data_p, compute_p, out_p = config_get_pars(config_file, arg.config_mode)
<br />  File "https://github.com/arita37/mlmodels/tree/a463a24ea257f46bfcbd4006f805952aace8f2b1/mlmodels/models.py", line 299, in config_get_pars
<br />    out_p     = path_norm_dict( js.get("out_pars") )
<br />  File "https://github.com/arita37/mlmodels/tree/a463a24ea257f46bfcbd4006f805952aace8f2b1/mlmodels/util.py", line 201, in path_norm_dict
<br />    for k,v in ddict.items():
<br />AttributeError: 'NoneType' object has no attribute 'items'



### Error 39, [Traceback at line 1439](https://github.com/arita37/mlmodels_store/blob/master/log_json/log_json.py#L1439)<br />1439..Traceback (most recent call last):
<br />  File "/opt/hostedtoolcache/Python/3.6.10/x64/bin/ml_models", line 11, in <module>
<br />    load_entry_point('mlmodels', 'console_scripts', 'ml_models')()
<br />  File "https://github.com/arita37/mlmodels/tree/a463a24ea257f46bfcbd4006f805952aace8f2b1/mlmodels/models.py", line 530, in main
<br />    fit_cli(arg)
<br />  File "https://github.com/arita37/mlmodels/tree/a463a24ea257f46bfcbd4006f805952aace8f2b1/mlmodels/models.py", line 414, in fit_cli
<br />    model_uri = model_p['model_uri']
<br />KeyError: 'model_uri'



### Error 40, [Traceback at line 1463](https://github.com/arita37/mlmodels_store/blob/master/log_json/log_json.py#L1463)<br />1463..Traceback (most recent call last):
<br />  File "/opt/hostedtoolcache/Python/3.6.10/x64/bin/ml_models", line 11, in <module>
<br />    load_entry_point('mlmodels', 'console_scripts', 'ml_models')()
<br />  File "https://github.com/arita37/mlmodels/tree/a463a24ea257f46bfcbd4006f805952aace8f2b1/mlmodels/models.py", line 530, in main
<br />    fit_cli(arg)
<br />  File "https://github.com/arita37/mlmodels/tree/a463a24ea257f46bfcbd4006f805952aace8f2b1/mlmodels/models.py", line 414, in fit_cli
<br />    model_uri = model_p['model_uri']
<br />KeyError: 'model_uri'



### Error 41, [Traceback at line 1492](https://github.com/arita37/mlmodels_store/blob/master/log_json/log_json.py#L1492)<br />1492..Traceback (most recent call last):
<br />  File "/opt/hostedtoolcache/Python/3.6.10/x64/bin/ml_models", line 11, in <module>
<br />    load_entry_point('mlmodels', 'console_scripts', 'ml_models')()
<br />  File "https://github.com/arita37/mlmodels/tree/a463a24ea257f46bfcbd4006f805952aace8f2b1/mlmodels/models.py", line 530, in main
<br />    fit_cli(arg)
<br />  File "https://github.com/arita37/mlmodels/tree/a463a24ea257f46bfcbd4006f805952aace8f2b1/mlmodels/models.py", line 424, in fit_cli
<br />    model, sess = fit(module, model, data_pars=data_p, compute_pars=compute_p, out_pars=out_p)
<br />  File "https://github.com/arita37/mlmodels/tree/a463a24ea257f46bfcbd4006f805952aace8f2b1/mlmodels/models.py", line 125, in fit
<br />    return module.fit(model, data_pars=data_pars, compute_pars=compute_pars, out_pars=out_pars, **kwarg)
<br />  File "https://github.com/arita37/mlmodels/tree/a463a24ea257f46bfcbd4006f805952aace8f2b1/mlmodels/model_tch/torchhub.py", line 222, in fit
<br />    train_iter, valid_iter = get_dataset(data_pars)
<br />  File "https://github.com/arita37/mlmodels/tree/a463a24ea257f46bfcbd4006f805952aace8f2b1/mlmodels/model_tch/torchhub.py", line 190, in get_dataset
<br />    loader = DataLoader(data_pars)
<br />  File "https://github.com/arita37/mlmodels/tree/a463a24ea257f46bfcbd4006f805952aace8f2b1/mlmodels/dataloader.py", line 236, in __init__
<br />    self.data_info                = data_pars['data_info']
<br />KeyError: 'data_info'



### Error 42, [Traceback at line 1519](https://github.com/arita37/mlmodels_store/blob/master/log_json/log_json.py#L1519)<br />1519..Traceback (most recent call last):
<br />  File "/opt/hostedtoolcache/Python/3.6.10/x64/bin/ml_models", line 11, in <module>
<br />    load_entry_point('mlmodels', 'console_scripts', 'ml_models')()
<br />  File "https://github.com/arita37/mlmodels/tree/a463a24ea257f46bfcbd4006f805952aace8f2b1/mlmodels/models.py", line 530, in main
<br />    fit_cli(arg)
<br />  File "https://github.com/arita37/mlmodels/tree/a463a24ea257f46bfcbd4006f805952aace8f2b1/mlmodels/models.py", line 413, in fit_cli
<br />    model_p, data_p, compute_p, out_p = config_get_pars(config_file, arg.config_mode)
<br />  File "https://github.com/arita37/mlmodels/tree/a463a24ea257f46bfcbd4006f805952aace8f2b1/mlmodels/models.py", line 299, in config_get_pars
<br />    out_p     = path_norm_dict( js.get("out_pars") )
<br />  File "https://github.com/arita37/mlmodels/tree/a463a24ea257f46bfcbd4006f805952aace8f2b1/mlmodels/util.py", line 201, in path_norm_dict
<br />    for k,v in ddict.items():
<br />AttributeError: 'NoneType' object has no attribute 'items'



### Error 43, [Traceback at line 1552](https://github.com/arita37/mlmodels_store/blob/master/log_json/log_json.py#L1552)<br />1552..Traceback (most recent call last):
<br />  File "/opt/hostedtoolcache/Python/3.6.10/x64/bin/ml_models", line 11, in <module>
<br />    load_entry_point('mlmodels', 'console_scripts', 'ml_models')()
<br />  File "https://github.com/arita37/mlmodels/tree/a463a24ea257f46bfcbd4006f805952aace8f2b1/mlmodels/models.py", line 530, in main
<br />    fit_cli(arg)
<br />  File "https://github.com/arita37/mlmodels/tree/a463a24ea257f46bfcbd4006f805952aace8f2b1/mlmodels/models.py", line 424, in fit_cli
<br />    model, sess = fit(module, model, data_pars=data_p, compute_pars=compute_p, out_pars=out_p)
<br />  File "https://github.com/arita37/mlmodels/tree/a463a24ea257f46bfcbd4006f805952aace8f2b1/mlmodels/models.py", line 125, in fit
<br />    return module.fit(model, data_pars=data_pars, compute_pars=compute_pars, out_pars=out_pars, **kwarg)
<br />  File "https://github.com/arita37/mlmodels/tree/a463a24ea257f46bfcbd4006f805952aace8f2b1/mlmodels/model_tch/torchhub.py", line 222, in fit
<br />    train_iter, valid_iter = get_dataset(data_pars)
<br />  File "https://github.com/arita37/mlmodels/tree/a463a24ea257f46bfcbd4006f805952aace8f2b1/mlmodels/model_tch/torchhub.py", line 190, in get_dataset
<br />    loader = DataLoader(data_pars)
<br />  File "https://github.com/arita37/mlmodels/tree/a463a24ea257f46bfcbd4006f805952aace8f2b1/mlmodels/dataloader.py", line 236, in __init__
<br />    self.data_info                = data_pars['data_info']
<br />KeyError: 'data_info'



### Error 44, [Traceback at line 1579](https://github.com/arita37/mlmodels_store/blob/master/log_json/log_json.py#L1579)<br />1579..Traceback (most recent call last):
<br />  File "/opt/hostedtoolcache/Python/3.6.10/x64/bin/ml_models", line 11, in <module>
<br />    load_entry_point('mlmodels', 'console_scripts', 'ml_models')()
<br />  File "https://github.com/arita37/mlmodels/tree/a463a24ea257f46bfcbd4006f805952aace8f2b1/mlmodels/models.py", line 530, in main
<br />    fit_cli(arg)
<br />  File "https://github.com/arita37/mlmodels/tree/a463a24ea257f46bfcbd4006f805952aace8f2b1/mlmodels/models.py", line 413, in fit_cli
<br />    model_p, data_p, compute_p, out_p = config_get_pars(config_file, arg.config_mode)
<br />  File "https://github.com/arita37/mlmodels/tree/a463a24ea257f46bfcbd4006f805952aace8f2b1/mlmodels/models.py", line 299, in config_get_pars
<br />    out_p     = path_norm_dict( js.get("out_pars") )
<br />  File "https://github.com/arita37/mlmodels/tree/a463a24ea257f46bfcbd4006f805952aace8f2b1/mlmodels/util.py", line 201, in path_norm_dict
<br />    for k,v in ddict.items():
<br />AttributeError: 'NoneType' object has no attribute 'items'



### Error 45, [Traceback at line 1612](https://github.com/arita37/mlmodels_store/blob/master/log_json/log_json.py#L1612)<br />1612..Traceback (most recent call last):
<br />  File "/opt/hostedtoolcache/Python/3.6.10/x64/bin/ml_models", line 11, in <module>
<br />    load_entry_point('mlmodels', 'console_scripts', 'ml_models')()
<br />  File "https://github.com/arita37/mlmodels/tree/a463a24ea257f46bfcbd4006f805952aace8f2b1/mlmodels/models.py", line 530, in main
<br />    fit_cli(arg)
<br />  File "https://github.com/arita37/mlmodels/tree/a463a24ea257f46bfcbd4006f805952aace8f2b1/mlmodels/models.py", line 424, in fit_cli
<br />    model, sess = fit(module, model, data_pars=data_p, compute_pars=compute_p, out_pars=out_p)
<br />  File "https://github.com/arita37/mlmodels/tree/a463a24ea257f46bfcbd4006f805952aace8f2b1/mlmodels/models.py", line 125, in fit
<br />    return module.fit(model, data_pars=data_pars, compute_pars=compute_pars, out_pars=out_pars, **kwarg)
<br />  File "https://github.com/arita37/mlmodels/tree/a463a24ea257f46bfcbd4006f805952aace8f2b1/mlmodels/model_tch/torchhub.py", line 222, in fit
<br />    train_iter, valid_iter = get_dataset(data_pars)
<br />  File "https://github.com/arita37/mlmodels/tree/a463a24ea257f46bfcbd4006f805952aace8f2b1/mlmodels/model_tch/torchhub.py", line 190, in get_dataset
<br />    loader = DataLoader(data_pars)
<br />  File "https://github.com/arita37/mlmodels/tree/a463a24ea257f46bfcbd4006f805952aace8f2b1/mlmodels/dataloader.py", line 236, in __init__
<br />    self.data_info                = data_pars['data_info']
<br />KeyError: 'data_info'



### Error 46, [Traceback at line 1639](https://github.com/arita37/mlmodels_store/blob/master/log_json/log_json.py#L1639)<br />1639..Traceback (most recent call last):
<br />  File "/opt/hostedtoolcache/Python/3.6.10/x64/bin/ml_models", line 11, in <module>
<br />    load_entry_point('mlmodels', 'console_scripts', 'ml_models')()
<br />  File "https://github.com/arita37/mlmodels/tree/a463a24ea257f46bfcbd4006f805952aace8f2b1/mlmodels/models.py", line 530, in main
<br />    fit_cli(arg)
<br />  File "https://github.com/arita37/mlmodels/tree/a463a24ea257f46bfcbd4006f805952aace8f2b1/mlmodels/models.py", line 413, in fit_cli
<br />    model_p, data_p, compute_p, out_p = config_get_pars(config_file, arg.config_mode)
<br />  File "https://github.com/arita37/mlmodels/tree/a463a24ea257f46bfcbd4006f805952aace8f2b1/mlmodels/models.py", line 299, in config_get_pars
<br />    out_p     = path_norm_dict( js.get("out_pars") )
<br />  File "https://github.com/arita37/mlmodels/tree/a463a24ea257f46bfcbd4006f805952aace8f2b1/mlmodels/util.py", line 201, in path_norm_dict
<br />    for k,v in ddict.items():
<br />AttributeError: 'NoneType' object has no attribute 'items'



### Error 47, [Traceback at line 1672](https://github.com/arita37/mlmodels_store/blob/master/log_json/log_json.py#L1672)<br />1672..Traceback (most recent call last):
<br />  File "/opt/hostedtoolcache/Python/3.6.10/x64/bin/ml_models", line 11, in <module>
<br />    load_entry_point('mlmodels', 'console_scripts', 'ml_models')()
<br />  File "https://github.com/arita37/mlmodels/tree/a463a24ea257f46bfcbd4006f805952aace8f2b1/mlmodels/models.py", line 530, in main
<br />    fit_cli(arg)
<br />  File "https://github.com/arita37/mlmodels/tree/a463a24ea257f46bfcbd4006f805952aace8f2b1/mlmodels/models.py", line 424, in fit_cli
<br />    model, sess = fit(module, model, data_pars=data_p, compute_pars=compute_p, out_pars=out_p)
<br />  File "https://github.com/arita37/mlmodels/tree/a463a24ea257f46bfcbd4006f805952aace8f2b1/mlmodels/models.py", line 125, in fit
<br />    return module.fit(model, data_pars=data_pars, compute_pars=compute_pars, out_pars=out_pars, **kwarg)
<br />  File "https://github.com/arita37/mlmodels/tree/a463a24ea257f46bfcbd4006f805952aace8f2b1/mlmodels/model_tch/torchhub.py", line 222, in fit
<br />    train_iter, valid_iter = get_dataset(data_pars)
<br />  File "https://github.com/arita37/mlmodels/tree/a463a24ea257f46bfcbd4006f805952aace8f2b1/mlmodels/model_tch/torchhub.py", line 190, in get_dataset
<br />    loader = DataLoader(data_pars)
<br />  File "https://github.com/arita37/mlmodels/tree/a463a24ea257f46bfcbd4006f805952aace8f2b1/mlmodels/dataloader.py", line 236, in __init__
<br />    self.data_info                = data_pars['data_info']
<br />KeyError: 'data_info'



### Error 48, [Traceback at line 1699](https://github.com/arita37/mlmodels_store/blob/master/log_json/log_json.py#L1699)<br />1699..Traceback (most recent call last):
<br />  File "/opt/hostedtoolcache/Python/3.6.10/x64/bin/ml_models", line 11, in <module>
<br />    load_entry_point('mlmodels', 'console_scripts', 'ml_models')()
<br />  File "https://github.com/arita37/mlmodels/tree/a463a24ea257f46bfcbd4006f805952aace8f2b1/mlmodels/models.py", line 530, in main
<br />    fit_cli(arg)
<br />  File "https://github.com/arita37/mlmodels/tree/a463a24ea257f46bfcbd4006f805952aace8f2b1/mlmodels/models.py", line 413, in fit_cli
<br />    model_p, data_p, compute_p, out_p = config_get_pars(config_file, arg.config_mode)
<br />  File "https://github.com/arita37/mlmodels/tree/a463a24ea257f46bfcbd4006f805952aace8f2b1/mlmodels/models.py", line 299, in config_get_pars
<br />    out_p     = path_norm_dict( js.get("out_pars") )
<br />  File "https://github.com/arita37/mlmodels/tree/a463a24ea257f46bfcbd4006f805952aace8f2b1/mlmodels/util.py", line 201, in path_norm_dict
<br />    for k,v in ddict.items():
<br />AttributeError: 'NoneType' object has no attribute 'items'



### Error 49, [Traceback at line 1732](https://github.com/arita37/mlmodels_store/blob/master/log_json/log_json.py#L1732)<br />1732..Traceback (most recent call last):
<br />  File "/opt/hostedtoolcache/Python/3.6.10/x64/bin/ml_models", line 11, in <module>
<br />    load_entry_point('mlmodels', 'console_scripts', 'ml_models')()
<br />  File "https://github.com/arita37/mlmodels/tree/a463a24ea257f46bfcbd4006f805952aace8f2b1/mlmodels/models.py", line 530, in main
<br />    fit_cli(arg)
<br />  File "https://github.com/arita37/mlmodels/tree/a463a24ea257f46bfcbd4006f805952aace8f2b1/mlmodels/models.py", line 424, in fit_cli
<br />    model, sess = fit(module, model, data_pars=data_p, compute_pars=compute_p, out_pars=out_p)
<br />  File "https://github.com/arita37/mlmodels/tree/a463a24ea257f46bfcbd4006f805952aace8f2b1/mlmodels/models.py", line 125, in fit
<br />    return module.fit(model, data_pars=data_pars, compute_pars=compute_pars, out_pars=out_pars, **kwarg)
<br />  File "https://github.com/arita37/mlmodels/tree/a463a24ea257f46bfcbd4006f805952aace8f2b1/mlmodels/model_tch/torchhub.py", line 222, in fit
<br />    train_iter, valid_iter = get_dataset(data_pars)
<br />  File "https://github.com/arita37/mlmodels/tree/a463a24ea257f46bfcbd4006f805952aace8f2b1/mlmodels/model_tch/torchhub.py", line 190, in get_dataset
<br />    loader = DataLoader(data_pars)
<br />  File "https://github.com/arita37/mlmodels/tree/a463a24ea257f46bfcbd4006f805952aace8f2b1/mlmodels/dataloader.py", line 236, in __init__
<br />    self.data_info                = data_pars['data_info']
<br />KeyError: 'data_info'



### Error 50, [Traceback at line 1759](https://github.com/arita37/mlmodels_store/blob/master/log_json/log_json.py#L1759)<br />1759..Traceback (most recent call last):
<br />  File "/opt/hostedtoolcache/Python/3.6.10/x64/bin/ml_models", line 11, in <module>
<br />    load_entry_point('mlmodels', 'console_scripts', 'ml_models')()
<br />  File "https://github.com/arita37/mlmodels/tree/a463a24ea257f46bfcbd4006f805952aace8f2b1/mlmodels/models.py", line 530, in main
<br />    fit_cli(arg)
<br />  File "https://github.com/arita37/mlmodels/tree/a463a24ea257f46bfcbd4006f805952aace8f2b1/mlmodels/models.py", line 413, in fit_cli
<br />    model_p, data_p, compute_p, out_p = config_get_pars(config_file, arg.config_mode)
<br />  File "https://github.com/arita37/mlmodels/tree/a463a24ea257f46bfcbd4006f805952aace8f2b1/mlmodels/models.py", line 299, in config_get_pars
<br />    out_p     = path_norm_dict( js.get("out_pars") )
<br />  File "https://github.com/arita37/mlmodels/tree/a463a24ea257f46bfcbd4006f805952aace8f2b1/mlmodels/util.py", line 201, in path_norm_dict
<br />    for k,v in ddict.items():
<br />AttributeError: 'NoneType' object has no attribute 'items'



### Error 51, [Traceback at line 1792](https://github.com/arita37/mlmodels_store/blob/master/log_json/log_json.py#L1792)<br />1792..Traceback (most recent call last):
<br />  File "/opt/hostedtoolcache/Python/3.6.10/x64/bin/ml_models", line 11, in <module>
<br />    load_entry_point('mlmodels', 'console_scripts', 'ml_models')()
<br />  File "https://github.com/arita37/mlmodels/tree/a463a24ea257f46bfcbd4006f805952aace8f2b1/mlmodels/models.py", line 530, in main
<br />    fit_cli(arg)
<br />  File "https://github.com/arita37/mlmodels/tree/a463a24ea257f46bfcbd4006f805952aace8f2b1/mlmodels/models.py", line 424, in fit_cli
<br />    model, sess = fit(module, model, data_pars=data_p, compute_pars=compute_p, out_pars=out_p)
<br />  File "https://github.com/arita37/mlmodels/tree/a463a24ea257f46bfcbd4006f805952aace8f2b1/mlmodels/models.py", line 125, in fit
<br />    return module.fit(model, data_pars=data_pars, compute_pars=compute_pars, out_pars=out_pars, **kwarg)
<br />  File "https://github.com/arita37/mlmodels/tree/a463a24ea257f46bfcbd4006f805952aace8f2b1/mlmodels/model_tch/torchhub.py", line 222, in fit
<br />    train_iter, valid_iter = get_dataset(data_pars)
<br />  File "https://github.com/arita37/mlmodels/tree/a463a24ea257f46bfcbd4006f805952aace8f2b1/mlmodels/model_tch/torchhub.py", line 190, in get_dataset
<br />    loader = DataLoader(data_pars)
<br />  File "https://github.com/arita37/mlmodels/tree/a463a24ea257f46bfcbd4006f805952aace8f2b1/mlmodels/dataloader.py", line 236, in __init__
<br />    self.data_info                = data_pars['data_info']
<br />KeyError: 'data_info'



### Error 52, [Traceback at line 1819](https://github.com/arita37/mlmodels_store/blob/master/log_json/log_json.py#L1819)<br />1819..Traceback (most recent call last):
<br />  File "/opt/hostedtoolcache/Python/3.6.10/x64/bin/ml_models", line 11, in <module>
<br />    load_entry_point('mlmodels', 'console_scripts', 'ml_models')()
<br />  File "https://github.com/arita37/mlmodels/tree/a463a24ea257f46bfcbd4006f805952aace8f2b1/mlmodels/models.py", line 530, in main
<br />    fit_cli(arg)
<br />  File "https://github.com/arita37/mlmodels/tree/a463a24ea257f46bfcbd4006f805952aace8f2b1/mlmodels/models.py", line 413, in fit_cli
<br />    model_p, data_p, compute_p, out_p = config_get_pars(config_file, arg.config_mode)
<br />  File "https://github.com/arita37/mlmodels/tree/a463a24ea257f46bfcbd4006f805952aace8f2b1/mlmodels/models.py", line 299, in config_get_pars
<br />    out_p     = path_norm_dict( js.get("out_pars") )
<br />  File "https://github.com/arita37/mlmodels/tree/a463a24ea257f46bfcbd4006f805952aace8f2b1/mlmodels/util.py", line 201, in path_norm_dict
<br />    for k,v in ddict.items():
<br />AttributeError: 'NoneType' object has no attribute 'items'



### Error 53, [Traceback at line 1852](https://github.com/arita37/mlmodels_store/blob/master/log_json/log_json.py#L1852)<br />1852..Traceback (most recent call last):
<br />  File "/opt/hostedtoolcache/Python/3.6.10/x64/bin/ml_models", line 11, in <module>
<br />    load_entry_point('mlmodels', 'console_scripts', 'ml_models')()
<br />  File "https://github.com/arita37/mlmodels/tree/a463a24ea257f46bfcbd4006f805952aace8f2b1/mlmodels/models.py", line 530, in main
<br />    fit_cli(arg)
<br />  File "https://github.com/arita37/mlmodels/tree/a463a24ea257f46bfcbd4006f805952aace8f2b1/mlmodels/models.py", line 424, in fit_cli
<br />    model, sess = fit(module, model, data_pars=data_p, compute_pars=compute_p, out_pars=out_p)
<br />  File "https://github.com/arita37/mlmodels/tree/a463a24ea257f46bfcbd4006f805952aace8f2b1/mlmodels/models.py", line 125, in fit
<br />    return module.fit(model, data_pars=data_pars, compute_pars=compute_pars, out_pars=out_pars, **kwarg)
<br />  File "https://github.com/arita37/mlmodels/tree/a463a24ea257f46bfcbd4006f805952aace8f2b1/mlmodels/model_tch/torchhub.py", line 222, in fit
<br />    train_iter, valid_iter = get_dataset(data_pars)
<br />  File "https://github.com/arita37/mlmodels/tree/a463a24ea257f46bfcbd4006f805952aace8f2b1/mlmodels/model_tch/torchhub.py", line 190, in get_dataset
<br />    loader = DataLoader(data_pars)
<br />  File "https://github.com/arita37/mlmodels/tree/a463a24ea257f46bfcbd4006f805952aace8f2b1/mlmodels/dataloader.py", line 236, in __init__
<br />    self.data_info                = data_pars['data_info']
<br />KeyError: 'data_info'



### Error 54, [Traceback at line 1879](https://github.com/arita37/mlmodels_store/blob/master/log_json/log_json.py#L1879)<br />1879..Traceback (most recent call last):
<br />  File "/opt/hostedtoolcache/Python/3.6.10/x64/bin/ml_models", line 11, in <module>
<br />    load_entry_point('mlmodels', 'console_scripts', 'ml_models')()
<br />  File "https://github.com/arita37/mlmodels/tree/a463a24ea257f46bfcbd4006f805952aace8f2b1/mlmodels/models.py", line 530, in main
<br />    fit_cli(arg)
<br />  File "https://github.com/arita37/mlmodels/tree/a463a24ea257f46bfcbd4006f805952aace8f2b1/mlmodels/models.py", line 413, in fit_cli
<br />    model_p, data_p, compute_p, out_p = config_get_pars(config_file, arg.config_mode)
<br />  File "https://github.com/arita37/mlmodels/tree/a463a24ea257f46bfcbd4006f805952aace8f2b1/mlmodels/models.py", line 299, in config_get_pars
<br />    out_p     = path_norm_dict( js.get("out_pars") )
<br />  File "https://github.com/arita37/mlmodels/tree/a463a24ea257f46bfcbd4006f805952aace8f2b1/mlmodels/util.py", line 201, in path_norm_dict
<br />    for k,v in ddict.items():
<br />AttributeError: 'NoneType' object has no attribute 'items'



### Error 55, [Traceback at line 1912](https://github.com/arita37/mlmodels_store/blob/master/log_json/log_json.py#L1912)<br />1912..Traceback (most recent call last):
<br />  File "/opt/hostedtoolcache/Python/3.6.10/x64/bin/ml_models", line 11, in <module>
<br />    load_entry_point('mlmodels', 'console_scripts', 'ml_models')()
<br />  File "https://github.com/arita37/mlmodels/tree/a463a24ea257f46bfcbd4006f805952aace8f2b1/mlmodels/models.py", line 530, in main
<br />    fit_cli(arg)
<br />  File "https://github.com/arita37/mlmodels/tree/a463a24ea257f46bfcbd4006f805952aace8f2b1/mlmodels/models.py", line 424, in fit_cli
<br />    model, sess = fit(module, model, data_pars=data_p, compute_pars=compute_p, out_pars=out_p)
<br />  File "https://github.com/arita37/mlmodels/tree/a463a24ea257f46bfcbd4006f805952aace8f2b1/mlmodels/models.py", line 125, in fit
<br />    return module.fit(model, data_pars=data_pars, compute_pars=compute_pars, out_pars=out_pars, **kwarg)
<br />  File "https://github.com/arita37/mlmodels/tree/a463a24ea257f46bfcbd4006f805952aace8f2b1/mlmodels/model_tch/torchhub.py", line 222, in fit
<br />    train_iter, valid_iter = get_dataset(data_pars)
<br />  File "https://github.com/arita37/mlmodels/tree/a463a24ea257f46bfcbd4006f805952aace8f2b1/mlmodels/model_tch/torchhub.py", line 190, in get_dataset
<br />    loader = DataLoader(data_pars)
<br />  File "https://github.com/arita37/mlmodels/tree/a463a24ea257f46bfcbd4006f805952aace8f2b1/mlmodels/dataloader.py", line 236, in __init__
<br />    self.data_info                = data_pars['data_info']
<br />KeyError: 'data_info'



### Error 56, [Traceback at line 1939](https://github.com/arita37/mlmodels_store/blob/master/log_json/log_json.py#L1939)<br />1939..Traceback (most recent call last):
<br />  File "/opt/hostedtoolcache/Python/3.6.10/x64/bin/ml_models", line 11, in <module>
<br />    load_entry_point('mlmodels', 'console_scripts', 'ml_models')()
<br />  File "https://github.com/arita37/mlmodels/tree/a463a24ea257f46bfcbd4006f805952aace8f2b1/mlmodels/models.py", line 530, in main
<br />    fit_cli(arg)
<br />  File "https://github.com/arita37/mlmodels/tree/a463a24ea257f46bfcbd4006f805952aace8f2b1/mlmodels/models.py", line 413, in fit_cli
<br />    model_p, data_p, compute_p, out_p = config_get_pars(config_file, arg.config_mode)
<br />  File "https://github.com/arita37/mlmodels/tree/a463a24ea257f46bfcbd4006f805952aace8f2b1/mlmodels/models.py", line 299, in config_get_pars
<br />    out_p     = path_norm_dict( js.get("out_pars") )
<br />  File "https://github.com/arita37/mlmodels/tree/a463a24ea257f46bfcbd4006f805952aace8f2b1/mlmodels/util.py", line 201, in path_norm_dict
<br />    for k,v in ddict.items():
<br />AttributeError: 'NoneType' object has no attribute 'items'



### Error 57, [Traceback at line 1972](https://github.com/arita37/mlmodels_store/blob/master/log_json/log_json.py#L1972)<br />1972..Traceback (most recent call last):
<br />  File "/opt/hostedtoolcache/Python/3.6.10/x64/bin/ml_models", line 11, in <module>
<br />    load_entry_point('mlmodels', 'console_scripts', 'ml_models')()
<br />  File "https://github.com/arita37/mlmodels/tree/a463a24ea257f46bfcbd4006f805952aace8f2b1/mlmodels/models.py", line 530, in main
<br />    fit_cli(arg)
<br />  File "https://github.com/arita37/mlmodels/tree/a463a24ea257f46bfcbd4006f805952aace8f2b1/mlmodels/models.py", line 424, in fit_cli
<br />    model, sess = fit(module, model, data_pars=data_p, compute_pars=compute_p, out_pars=out_p)
<br />  File "https://github.com/arita37/mlmodels/tree/a463a24ea257f46bfcbd4006f805952aace8f2b1/mlmodels/models.py", line 125, in fit
<br />    return module.fit(model, data_pars=data_pars, compute_pars=compute_pars, out_pars=out_pars, **kwarg)
<br />  File "https://github.com/arita37/mlmodels/tree/a463a24ea257f46bfcbd4006f805952aace8f2b1/mlmodels/model_tch/torchhub.py", line 222, in fit
<br />    train_iter, valid_iter = get_dataset(data_pars)
<br />  File "https://github.com/arita37/mlmodels/tree/a463a24ea257f46bfcbd4006f805952aace8f2b1/mlmodels/model_tch/torchhub.py", line 190, in get_dataset
<br />    loader = DataLoader(data_pars)
<br />  File "https://github.com/arita37/mlmodels/tree/a463a24ea257f46bfcbd4006f805952aace8f2b1/mlmodels/dataloader.py", line 236, in __init__
<br />    self.data_info                = data_pars['data_info']
<br />KeyError: 'data_info'



### Error 58, [Traceback at line 1999](https://github.com/arita37/mlmodels_store/blob/master/log_json/log_json.py#L1999)<br />1999..Traceback (most recent call last):
<br />  File "/opt/hostedtoolcache/Python/3.6.10/x64/bin/ml_models", line 11, in <module>
<br />    load_entry_point('mlmodels', 'console_scripts', 'ml_models')()
<br />  File "https://github.com/arita37/mlmodels/tree/a463a24ea257f46bfcbd4006f805952aace8f2b1/mlmodels/models.py", line 530, in main
<br />    fit_cli(arg)
<br />  File "https://github.com/arita37/mlmodels/tree/a463a24ea257f46bfcbd4006f805952aace8f2b1/mlmodels/models.py", line 413, in fit_cli
<br />    model_p, data_p, compute_p, out_p = config_get_pars(config_file, arg.config_mode)
<br />  File "https://github.com/arita37/mlmodels/tree/a463a24ea257f46bfcbd4006f805952aace8f2b1/mlmodels/models.py", line 299, in config_get_pars
<br />    out_p     = path_norm_dict( js.get("out_pars") )
<br />  File "https://github.com/arita37/mlmodels/tree/a463a24ea257f46bfcbd4006f805952aace8f2b1/mlmodels/util.py", line 201, in path_norm_dict
<br />    for k,v in ddict.items():
<br />AttributeError: 'NoneType' object has no attribute 'items'



### Error 59, [Traceback at line 2032](https://github.com/arita37/mlmodels_store/blob/master/log_json/log_json.py#L2032)<br />2032..Traceback (most recent call last):
<br />  File "/opt/hostedtoolcache/Python/3.6.10/x64/bin/ml_models", line 11, in <module>
<br />    load_entry_point('mlmodels', 'console_scripts', 'ml_models')()
<br />  File "https://github.com/arita37/mlmodels/tree/a463a24ea257f46bfcbd4006f805952aace8f2b1/mlmodels/models.py", line 530, in main
<br />    fit_cli(arg)
<br />  File "https://github.com/arita37/mlmodels/tree/a463a24ea257f46bfcbd4006f805952aace8f2b1/mlmodels/models.py", line 424, in fit_cli
<br />    model, sess = fit(module, model, data_pars=data_p, compute_pars=compute_p, out_pars=out_p)
<br />  File "https://github.com/arita37/mlmodels/tree/a463a24ea257f46bfcbd4006f805952aace8f2b1/mlmodels/models.py", line 125, in fit
<br />    return module.fit(model, data_pars=data_pars, compute_pars=compute_pars, out_pars=out_pars, **kwarg)
<br />  File "https://github.com/arita37/mlmodels/tree/a463a24ea257f46bfcbd4006f805952aace8f2b1/mlmodels/model_tch/torchhub.py", line 222, in fit
<br />    train_iter, valid_iter = get_dataset(data_pars)
<br />  File "https://github.com/arita37/mlmodels/tree/a463a24ea257f46bfcbd4006f805952aace8f2b1/mlmodels/model_tch/torchhub.py", line 190, in get_dataset
<br />    loader = DataLoader(data_pars)
<br />  File "https://github.com/arita37/mlmodels/tree/a463a24ea257f46bfcbd4006f805952aace8f2b1/mlmodels/dataloader.py", line 236, in __init__
<br />    self.data_info                = data_pars['data_info']
<br />KeyError: 'data_info'



### Error 60, [Traceback at line 2059](https://github.com/arita37/mlmodels_store/blob/master/log_json/log_json.py#L2059)<br />2059..Traceback (most recent call last):
<br />  File "/opt/hostedtoolcache/Python/3.6.10/x64/bin/ml_models", line 11, in <module>
<br />    load_entry_point('mlmodels', 'console_scripts', 'ml_models')()
<br />  File "https://github.com/arita37/mlmodels/tree/a463a24ea257f46bfcbd4006f805952aace8f2b1/mlmodels/models.py", line 530, in main
<br />    fit_cli(arg)
<br />  File "https://github.com/arita37/mlmodels/tree/a463a24ea257f46bfcbd4006f805952aace8f2b1/mlmodels/models.py", line 413, in fit_cli
<br />    model_p, data_p, compute_p, out_p = config_get_pars(config_file, arg.config_mode)
<br />  File "https://github.com/arita37/mlmodels/tree/a463a24ea257f46bfcbd4006f805952aace8f2b1/mlmodels/models.py", line 299, in config_get_pars
<br />    out_p     = path_norm_dict( js.get("out_pars") )
<br />  File "https://github.com/arita37/mlmodels/tree/a463a24ea257f46bfcbd4006f805952aace8f2b1/mlmodels/util.py", line 201, in path_norm_dict
<br />    for k,v in ddict.items():
<br />AttributeError: 'NoneType' object has no attribute 'items'



### Error 61, [Traceback at line 2092](https://github.com/arita37/mlmodels_store/blob/master/log_json/log_json.py#L2092)<br />2092..Traceback (most recent call last):
<br />  File "/opt/hostedtoolcache/Python/3.6.10/x64/bin/ml_models", line 11, in <module>
<br />    load_entry_point('mlmodels', 'console_scripts', 'ml_models')()
<br />  File "https://github.com/arita37/mlmodels/tree/a463a24ea257f46bfcbd4006f805952aace8f2b1/mlmodels/models.py", line 530, in main
<br />    fit_cli(arg)
<br />  File "https://github.com/arita37/mlmodels/tree/a463a24ea257f46bfcbd4006f805952aace8f2b1/mlmodels/models.py", line 424, in fit_cli
<br />    model, sess = fit(module, model, data_pars=data_p, compute_pars=compute_p, out_pars=out_p)
<br />  File "https://github.com/arita37/mlmodels/tree/a463a24ea257f46bfcbd4006f805952aace8f2b1/mlmodels/models.py", line 125, in fit
<br />    return module.fit(model, data_pars=data_pars, compute_pars=compute_pars, out_pars=out_pars, **kwarg)
<br />  File "https://github.com/arita37/mlmodels/tree/a463a24ea257f46bfcbd4006f805952aace8f2b1/mlmodels/model_tch/torchhub.py", line 222, in fit
<br />    train_iter, valid_iter = get_dataset(data_pars)
<br />  File "https://github.com/arita37/mlmodels/tree/a463a24ea257f46bfcbd4006f805952aace8f2b1/mlmodels/model_tch/torchhub.py", line 190, in get_dataset
<br />    loader = DataLoader(data_pars)
<br />  File "https://github.com/arita37/mlmodels/tree/a463a24ea257f46bfcbd4006f805952aace8f2b1/mlmodels/dataloader.py", line 236, in __init__
<br />    self.data_info                = data_pars['data_info']
<br />KeyError: 'data_info'



### Error 62, [Traceback at line 2119](https://github.com/arita37/mlmodels_store/blob/master/log_json/log_json.py#L2119)<br />2119..Traceback (most recent call last):
<br />  File "/opt/hostedtoolcache/Python/3.6.10/x64/bin/ml_models", line 11, in <module>
<br />    load_entry_point('mlmodels', 'console_scripts', 'ml_models')()
<br />  File "https://github.com/arita37/mlmodels/tree/a463a24ea257f46bfcbd4006f805952aace8f2b1/mlmodels/models.py", line 530, in main
<br />    fit_cli(arg)
<br />  File "https://github.com/arita37/mlmodels/tree/a463a24ea257f46bfcbd4006f805952aace8f2b1/mlmodels/models.py", line 413, in fit_cli
<br />    model_p, data_p, compute_p, out_p = config_get_pars(config_file, arg.config_mode)
<br />  File "https://github.com/arita37/mlmodels/tree/a463a24ea257f46bfcbd4006f805952aace8f2b1/mlmodels/models.py", line 299, in config_get_pars
<br />    out_p     = path_norm_dict( js.get("out_pars") )
<br />  File "https://github.com/arita37/mlmodels/tree/a463a24ea257f46bfcbd4006f805952aace8f2b1/mlmodels/util.py", line 201, in path_norm_dict
<br />    for k,v in ddict.items():
<br />AttributeError: 'NoneType' object has no attribute 'items'



### Error 63, [Traceback at line 2152](https://github.com/arita37/mlmodels_store/blob/master/log_json/log_json.py#L2152)<br />2152..Traceback (most recent call last):
<br />  File "/opt/hostedtoolcache/Python/3.6.10/x64/bin/ml_models", line 11, in <module>
<br />    load_entry_point('mlmodels', 'console_scripts', 'ml_models')()
<br />  File "https://github.com/arita37/mlmodels/tree/a463a24ea257f46bfcbd4006f805952aace8f2b1/mlmodels/models.py", line 530, in main
<br />    fit_cli(arg)
<br />  File "https://github.com/arita37/mlmodels/tree/a463a24ea257f46bfcbd4006f805952aace8f2b1/mlmodels/models.py", line 424, in fit_cli
<br />    model, sess = fit(module, model, data_pars=data_p, compute_pars=compute_p, out_pars=out_p)
<br />  File "https://github.com/arita37/mlmodels/tree/a463a24ea257f46bfcbd4006f805952aace8f2b1/mlmodels/models.py", line 125, in fit
<br />    return module.fit(model, data_pars=data_pars, compute_pars=compute_pars, out_pars=out_pars, **kwarg)
<br />  File "https://github.com/arita37/mlmodels/tree/a463a24ea257f46bfcbd4006f805952aace8f2b1/mlmodels/model_tch/torchhub.py", line 222, in fit
<br />    train_iter, valid_iter = get_dataset(data_pars)
<br />  File "https://github.com/arita37/mlmodels/tree/a463a24ea257f46bfcbd4006f805952aace8f2b1/mlmodels/model_tch/torchhub.py", line 190, in get_dataset
<br />    loader = DataLoader(data_pars)
<br />  File "https://github.com/arita37/mlmodels/tree/a463a24ea257f46bfcbd4006f805952aace8f2b1/mlmodels/dataloader.py", line 236, in __init__
<br />    self.data_info                = data_pars['data_info']
<br />KeyError: 'data_info'



### Error 64, [Traceback at line 2179](https://github.com/arita37/mlmodels_store/blob/master/log_json/log_json.py#L2179)<br />2179..Traceback (most recent call last):
<br />  File "/opt/hostedtoolcache/Python/3.6.10/x64/bin/ml_models", line 11, in <module>
<br />    load_entry_point('mlmodels', 'console_scripts', 'ml_models')()
<br />  File "https://github.com/arita37/mlmodels/tree/a463a24ea257f46bfcbd4006f805952aace8f2b1/mlmodels/models.py", line 530, in main
<br />    fit_cli(arg)
<br />  File "https://github.com/arita37/mlmodels/tree/a463a24ea257f46bfcbd4006f805952aace8f2b1/mlmodels/models.py", line 413, in fit_cli
<br />    model_p, data_p, compute_p, out_p = config_get_pars(config_file, arg.config_mode)
<br />  File "https://github.com/arita37/mlmodels/tree/a463a24ea257f46bfcbd4006f805952aace8f2b1/mlmodels/models.py", line 299, in config_get_pars
<br />    out_p     = path_norm_dict( js.get("out_pars") )
<br />  File "https://github.com/arita37/mlmodels/tree/a463a24ea257f46bfcbd4006f805952aace8f2b1/mlmodels/util.py", line 201, in path_norm_dict
<br />    for k,v in ddict.items():
<br />AttributeError: 'NoneType' object has no attribute 'items'



### Error 65, [Traceback at line 2212](https://github.com/arita37/mlmodels_store/blob/master/log_json/log_json.py#L2212)<br />2212..Traceback (most recent call last):
<br />  File "/opt/hostedtoolcache/Python/3.6.10/x64/bin/ml_models", line 11, in <module>
<br />    load_entry_point('mlmodels', 'console_scripts', 'ml_models')()
<br />  File "https://github.com/arita37/mlmodels/tree/a463a24ea257f46bfcbd4006f805952aace8f2b1/mlmodels/models.py", line 530, in main
<br />    fit_cli(arg)
<br />  File "https://github.com/arita37/mlmodels/tree/a463a24ea257f46bfcbd4006f805952aace8f2b1/mlmodels/models.py", line 424, in fit_cli
<br />    model, sess = fit(module, model, data_pars=data_p, compute_pars=compute_p, out_pars=out_p)
<br />  File "https://github.com/arita37/mlmodels/tree/a463a24ea257f46bfcbd4006f805952aace8f2b1/mlmodels/models.py", line 125, in fit
<br />    return module.fit(model, data_pars=data_pars, compute_pars=compute_pars, out_pars=out_pars, **kwarg)
<br />  File "https://github.com/arita37/mlmodels/tree/a463a24ea257f46bfcbd4006f805952aace8f2b1/mlmodels/model_tch/torchhub.py", line 222, in fit
<br />    train_iter, valid_iter = get_dataset(data_pars)
<br />  File "https://github.com/arita37/mlmodels/tree/a463a24ea257f46bfcbd4006f805952aace8f2b1/mlmodels/model_tch/torchhub.py", line 190, in get_dataset
<br />    loader = DataLoader(data_pars)
<br />  File "https://github.com/arita37/mlmodels/tree/a463a24ea257f46bfcbd4006f805952aace8f2b1/mlmodels/dataloader.py", line 236, in __init__
<br />    self.data_info                = data_pars['data_info']
<br />KeyError: 'data_info'



### Error 66, [Traceback at line 2239](https://github.com/arita37/mlmodels_store/blob/master/log_json/log_json.py#L2239)<br />2239..Traceback (most recent call last):
<br />  File "/opt/hostedtoolcache/Python/3.6.10/x64/bin/ml_models", line 11, in <module>
<br />    load_entry_point('mlmodels', 'console_scripts', 'ml_models')()
<br />  File "https://github.com/arita37/mlmodels/tree/a463a24ea257f46bfcbd4006f805952aace8f2b1/mlmodels/models.py", line 530, in main
<br />    fit_cli(arg)
<br />  File "https://github.com/arita37/mlmodels/tree/a463a24ea257f46bfcbd4006f805952aace8f2b1/mlmodels/models.py", line 413, in fit_cli
<br />    model_p, data_p, compute_p, out_p = config_get_pars(config_file, arg.config_mode)
<br />  File "https://github.com/arita37/mlmodels/tree/a463a24ea257f46bfcbd4006f805952aace8f2b1/mlmodels/models.py", line 299, in config_get_pars
<br />    out_p     = path_norm_dict( js.get("out_pars") )
<br />  File "https://github.com/arita37/mlmodels/tree/a463a24ea257f46bfcbd4006f805952aace8f2b1/mlmodels/util.py", line 201, in path_norm_dict
<br />    for k,v in ddict.items():
<br />AttributeError: 'NoneType' object has no attribute 'items'



### Error 67, [Traceback at line 2272](https://github.com/arita37/mlmodels_store/blob/master/log_json/log_json.py#L2272)<br />2272..Traceback (most recent call last):
<br />  File "/opt/hostedtoolcache/Python/3.6.10/x64/bin/ml_models", line 11, in <module>
<br />    load_entry_point('mlmodels', 'console_scripts', 'ml_models')()
<br />  File "https://github.com/arita37/mlmodels/tree/a463a24ea257f46bfcbd4006f805952aace8f2b1/mlmodels/models.py", line 530, in main
<br />    fit_cli(arg)
<br />  File "https://github.com/arita37/mlmodels/tree/a463a24ea257f46bfcbd4006f805952aace8f2b1/mlmodels/models.py", line 424, in fit_cli
<br />    model, sess = fit(module, model, data_pars=data_p, compute_pars=compute_p, out_pars=out_p)
<br />  File "https://github.com/arita37/mlmodels/tree/a463a24ea257f46bfcbd4006f805952aace8f2b1/mlmodels/models.py", line 125, in fit
<br />    return module.fit(model, data_pars=data_pars, compute_pars=compute_pars, out_pars=out_pars, **kwarg)
<br />  File "https://github.com/arita37/mlmodels/tree/a463a24ea257f46bfcbd4006f805952aace8f2b1/mlmodels/model_tch/torchhub.py", line 222, in fit
<br />    train_iter, valid_iter = get_dataset(data_pars)
<br />  File "https://github.com/arita37/mlmodels/tree/a463a24ea257f46bfcbd4006f805952aace8f2b1/mlmodels/model_tch/torchhub.py", line 190, in get_dataset
<br />    loader = DataLoader(data_pars)
<br />  File "https://github.com/arita37/mlmodels/tree/a463a24ea257f46bfcbd4006f805952aace8f2b1/mlmodels/dataloader.py", line 236, in __init__
<br />    self.data_info                = data_pars['data_info']
<br />KeyError: 'data_info'



### Error 68, [Traceback at line 2299](https://github.com/arita37/mlmodels_store/blob/master/log_json/log_json.py#L2299)<br />2299..Traceback (most recent call last):
<br />  File "/opt/hostedtoolcache/Python/3.6.10/x64/bin/ml_models", line 11, in <module>
<br />    load_entry_point('mlmodels', 'console_scripts', 'ml_models')()
<br />  File "https://github.com/arita37/mlmodels/tree/a463a24ea257f46bfcbd4006f805952aace8f2b1/mlmodels/models.py", line 530, in main
<br />    fit_cli(arg)
<br />  File "https://github.com/arita37/mlmodels/tree/a463a24ea257f46bfcbd4006f805952aace8f2b1/mlmodels/models.py", line 413, in fit_cli
<br />    model_p, data_p, compute_p, out_p = config_get_pars(config_file, arg.config_mode)
<br />  File "https://github.com/arita37/mlmodels/tree/a463a24ea257f46bfcbd4006f805952aace8f2b1/mlmodels/models.py", line 299, in config_get_pars
<br />    out_p     = path_norm_dict( js.get("out_pars") )
<br />  File "https://github.com/arita37/mlmodels/tree/a463a24ea257f46bfcbd4006f805952aace8f2b1/mlmodels/util.py", line 201, in path_norm_dict
<br />    for k,v in ddict.items():
<br />AttributeError: 'NoneType' object has no attribute 'items'



### Error 69, [Traceback at line 2332](https://github.com/arita37/mlmodels_store/blob/master/log_json/log_json.py#L2332)<br />2332..Traceback (most recent call last):
<br />  File "/opt/hostedtoolcache/Python/3.6.10/x64/bin/ml_models", line 11, in <module>
<br />    load_entry_point('mlmodels', 'console_scripts', 'ml_models')()
<br />  File "https://github.com/arita37/mlmodels/tree/a463a24ea257f46bfcbd4006f805952aace8f2b1/mlmodels/models.py", line 530, in main
<br />    fit_cli(arg)
<br />  File "https://github.com/arita37/mlmodels/tree/a463a24ea257f46bfcbd4006f805952aace8f2b1/mlmodels/models.py", line 424, in fit_cli
<br />    model, sess = fit(module, model, data_pars=data_p, compute_pars=compute_p, out_pars=out_p)
<br />  File "https://github.com/arita37/mlmodels/tree/a463a24ea257f46bfcbd4006f805952aace8f2b1/mlmodels/models.py", line 125, in fit
<br />    return module.fit(model, data_pars=data_pars, compute_pars=compute_pars, out_pars=out_pars, **kwarg)
<br />  File "https://github.com/arita37/mlmodels/tree/a463a24ea257f46bfcbd4006f805952aace8f2b1/mlmodels/model_tch/torchhub.py", line 222, in fit
<br />    train_iter, valid_iter = get_dataset(data_pars)
<br />  File "https://github.com/arita37/mlmodels/tree/a463a24ea257f46bfcbd4006f805952aace8f2b1/mlmodels/model_tch/torchhub.py", line 190, in get_dataset
<br />    loader = DataLoader(data_pars)
<br />  File "https://github.com/arita37/mlmodels/tree/a463a24ea257f46bfcbd4006f805952aace8f2b1/mlmodels/dataloader.py", line 236, in __init__
<br />    self.data_info                = data_pars['data_info']
<br />KeyError: 'data_info'



### Error 70, [Traceback at line 2359](https://github.com/arita37/mlmodels_store/blob/master/log_json/log_json.py#L2359)<br />2359..Traceback (most recent call last):
<br />  File "/opt/hostedtoolcache/Python/3.6.10/x64/bin/ml_models", line 11, in <module>
<br />    load_entry_point('mlmodels', 'console_scripts', 'ml_models')()
<br />  File "https://github.com/arita37/mlmodels/tree/a463a24ea257f46bfcbd4006f805952aace8f2b1/mlmodels/models.py", line 530, in main
<br />    fit_cli(arg)
<br />  File "https://github.com/arita37/mlmodels/tree/a463a24ea257f46bfcbd4006f805952aace8f2b1/mlmodels/models.py", line 413, in fit_cli
<br />    model_p, data_p, compute_p, out_p = config_get_pars(config_file, arg.config_mode)
<br />  File "https://github.com/arita37/mlmodels/tree/a463a24ea257f46bfcbd4006f805952aace8f2b1/mlmodels/models.py", line 299, in config_get_pars
<br />    out_p     = path_norm_dict( js.get("out_pars") )
<br />  File "https://github.com/arita37/mlmodels/tree/a463a24ea257f46bfcbd4006f805952aace8f2b1/mlmodels/util.py", line 201, in path_norm_dict
<br />    for k,v in ddict.items():
<br />AttributeError: 'NoneType' object has no attribute 'items'



### Error 71, [Traceback at line 2392](https://github.com/arita37/mlmodels_store/blob/master/log_json/log_json.py#L2392)<br />2392..Traceback (most recent call last):
<br />  File "/opt/hostedtoolcache/Python/3.6.10/x64/bin/ml_models", line 11, in <module>
<br />    load_entry_point('mlmodels', 'console_scripts', 'ml_models')()
<br />  File "https://github.com/arita37/mlmodels/tree/a463a24ea257f46bfcbd4006f805952aace8f2b1/mlmodels/models.py", line 530, in main
<br />    fit_cli(arg)
<br />  File "https://github.com/arita37/mlmodels/tree/a463a24ea257f46bfcbd4006f805952aace8f2b1/mlmodels/models.py", line 424, in fit_cli
<br />    model, sess = fit(module, model, data_pars=data_p, compute_pars=compute_p, out_pars=out_p)
<br />  File "https://github.com/arita37/mlmodels/tree/a463a24ea257f46bfcbd4006f805952aace8f2b1/mlmodels/models.py", line 125, in fit
<br />    return module.fit(model, data_pars=data_pars, compute_pars=compute_pars, out_pars=out_pars, **kwarg)
<br />  File "https://github.com/arita37/mlmodels/tree/a463a24ea257f46bfcbd4006f805952aace8f2b1/mlmodels/model_tch/torchhub.py", line 222, in fit
<br />    train_iter, valid_iter = get_dataset(data_pars)
<br />  File "https://github.com/arita37/mlmodels/tree/a463a24ea257f46bfcbd4006f805952aace8f2b1/mlmodels/model_tch/torchhub.py", line 190, in get_dataset
<br />    loader = DataLoader(data_pars)
<br />  File "https://github.com/arita37/mlmodels/tree/a463a24ea257f46bfcbd4006f805952aace8f2b1/mlmodels/dataloader.py", line 236, in __init__
<br />    self.data_info                = data_pars['data_info']
<br />KeyError: 'data_info'



### Error 72, [Traceback at line 2419](https://github.com/arita37/mlmodels_store/blob/master/log_json/log_json.py#L2419)<br />2419..Traceback (most recent call last):
<br />  File "/opt/hostedtoolcache/Python/3.6.10/x64/bin/ml_models", line 11, in <module>
<br />    load_entry_point('mlmodels', 'console_scripts', 'ml_models')()
<br />  File "https://github.com/arita37/mlmodels/tree/a463a24ea257f46bfcbd4006f805952aace8f2b1/mlmodels/models.py", line 530, in main
<br />    fit_cli(arg)
<br />  File "https://github.com/arita37/mlmodels/tree/a463a24ea257f46bfcbd4006f805952aace8f2b1/mlmodels/models.py", line 413, in fit_cli
<br />    model_p, data_p, compute_p, out_p = config_get_pars(config_file, arg.config_mode)
<br />  File "https://github.com/arita37/mlmodels/tree/a463a24ea257f46bfcbd4006f805952aace8f2b1/mlmodels/models.py", line 299, in config_get_pars
<br />    out_p     = path_norm_dict( js.get("out_pars") )
<br />  File "https://github.com/arita37/mlmodels/tree/a463a24ea257f46bfcbd4006f805952aace8f2b1/mlmodels/util.py", line 201, in path_norm_dict
<br />    for k,v in ddict.items():
<br />AttributeError: 'NoneType' object has no attribute 'items'



### Error 73, [Traceback at line 2452](https://github.com/arita37/mlmodels_store/blob/master/log_json/log_json.py#L2452)<br />2452..Traceback (most recent call last):
<br />  File "/opt/hostedtoolcache/Python/3.6.10/x64/bin/ml_models", line 11, in <module>
<br />    load_entry_point('mlmodels', 'console_scripts', 'ml_models')()
<br />  File "https://github.com/arita37/mlmodels/tree/a463a24ea257f46bfcbd4006f805952aace8f2b1/mlmodels/models.py", line 530, in main
<br />    fit_cli(arg)
<br />  File "https://github.com/arita37/mlmodels/tree/a463a24ea257f46bfcbd4006f805952aace8f2b1/mlmodels/models.py", line 424, in fit_cli
<br />    model, sess = fit(module, model, data_pars=data_p, compute_pars=compute_p, out_pars=out_p)
<br />  File "https://github.com/arita37/mlmodels/tree/a463a24ea257f46bfcbd4006f805952aace8f2b1/mlmodels/models.py", line 125, in fit
<br />    return module.fit(model, data_pars=data_pars, compute_pars=compute_pars, out_pars=out_pars, **kwarg)
<br />  File "https://github.com/arita37/mlmodels/tree/a463a24ea257f46bfcbd4006f805952aace8f2b1/mlmodels/model_tch/torchhub.py", line 222, in fit
<br />    train_iter, valid_iter = get_dataset(data_pars)
<br />  File "https://github.com/arita37/mlmodels/tree/a463a24ea257f46bfcbd4006f805952aace8f2b1/mlmodels/model_tch/torchhub.py", line 190, in get_dataset
<br />    loader = DataLoader(data_pars)
<br />  File "https://github.com/arita37/mlmodels/tree/a463a24ea257f46bfcbd4006f805952aace8f2b1/mlmodels/dataloader.py", line 236, in __init__
<br />    self.data_info                = data_pars['data_info']
<br />KeyError: 'data_info'



### Error 74, [Traceback at line 2479](https://github.com/arita37/mlmodels_store/blob/master/log_json/log_json.py#L2479)<br />2479..Traceback (most recent call last):
<br />  File "/opt/hostedtoolcache/Python/3.6.10/x64/bin/ml_models", line 11, in <module>
<br />    load_entry_point('mlmodels', 'console_scripts', 'ml_models')()
<br />  File "https://github.com/arita37/mlmodels/tree/a463a24ea257f46bfcbd4006f805952aace8f2b1/mlmodels/models.py", line 530, in main
<br />    fit_cli(arg)
<br />  File "https://github.com/arita37/mlmodels/tree/a463a24ea257f46bfcbd4006f805952aace8f2b1/mlmodels/models.py", line 413, in fit_cli
<br />    model_p, data_p, compute_p, out_p = config_get_pars(config_file, arg.config_mode)
<br />  File "https://github.com/arita37/mlmodels/tree/a463a24ea257f46bfcbd4006f805952aace8f2b1/mlmodels/models.py", line 299, in config_get_pars
<br />    out_p     = path_norm_dict( js.get("out_pars") )
<br />  File "https://github.com/arita37/mlmodels/tree/a463a24ea257f46bfcbd4006f805952aace8f2b1/mlmodels/util.py", line 201, in path_norm_dict
<br />    for k,v in ddict.items():
<br />AttributeError: 'NoneType' object has no attribute 'items'



### Error 75, [Traceback at line 2512](https://github.com/arita37/mlmodels_store/blob/master/log_json/log_json.py#L2512)<br />2512..Traceback (most recent call last):
<br />  File "/opt/hostedtoolcache/Python/3.6.10/x64/bin/ml_models", line 11, in <module>
<br />    load_entry_point('mlmodels', 'console_scripts', 'ml_models')()
<br />  File "https://github.com/arita37/mlmodels/tree/a463a24ea257f46bfcbd4006f805952aace8f2b1/mlmodels/models.py", line 530, in main
<br />    fit_cli(arg)
<br />  File "https://github.com/arita37/mlmodels/tree/a463a24ea257f46bfcbd4006f805952aace8f2b1/mlmodels/models.py", line 424, in fit_cli
<br />    model, sess = fit(module, model, data_pars=data_p, compute_pars=compute_p, out_pars=out_p)
<br />  File "https://github.com/arita37/mlmodels/tree/a463a24ea257f46bfcbd4006f805952aace8f2b1/mlmodels/models.py", line 125, in fit
<br />    return module.fit(model, data_pars=data_pars, compute_pars=compute_pars, out_pars=out_pars, **kwarg)
<br />  File "https://github.com/arita37/mlmodels/tree/a463a24ea257f46bfcbd4006f805952aace8f2b1/mlmodels/model_tch/torchhub.py", line 222, in fit
<br />    train_iter, valid_iter = get_dataset(data_pars)
<br />  File "https://github.com/arita37/mlmodels/tree/a463a24ea257f46bfcbd4006f805952aace8f2b1/mlmodels/model_tch/torchhub.py", line 190, in get_dataset
<br />    loader = DataLoader(data_pars)
<br />  File "https://github.com/arita37/mlmodels/tree/a463a24ea257f46bfcbd4006f805952aace8f2b1/mlmodels/dataloader.py", line 236, in __init__
<br />    self.data_info                = data_pars['data_info']
<br />KeyError: 'data_info'



### Error 76, [Traceback at line 2539](https://github.com/arita37/mlmodels_store/blob/master/log_json/log_json.py#L2539)<br />2539..Traceback (most recent call last):
<br />  File "/opt/hostedtoolcache/Python/3.6.10/x64/bin/ml_models", line 11, in <module>
<br />    load_entry_point('mlmodels', 'console_scripts', 'ml_models')()
<br />  File "https://github.com/arita37/mlmodels/tree/a463a24ea257f46bfcbd4006f805952aace8f2b1/mlmodels/models.py", line 530, in main
<br />    fit_cli(arg)
<br />  File "https://github.com/arita37/mlmodels/tree/a463a24ea257f46bfcbd4006f805952aace8f2b1/mlmodels/models.py", line 413, in fit_cli
<br />    model_p, data_p, compute_p, out_p = config_get_pars(config_file, arg.config_mode)
<br />  File "https://github.com/arita37/mlmodels/tree/a463a24ea257f46bfcbd4006f805952aace8f2b1/mlmodels/models.py", line 299, in config_get_pars
<br />    out_p     = path_norm_dict( js.get("out_pars") )
<br />  File "https://github.com/arita37/mlmodels/tree/a463a24ea257f46bfcbd4006f805952aace8f2b1/mlmodels/util.py", line 201, in path_norm_dict
<br />    for k,v in ddict.items():
<br />AttributeError: 'NoneType' object has no attribute 'items'



### Error 77, [Traceback at line 2572](https://github.com/arita37/mlmodels_store/blob/master/log_json/log_json.py#L2572)<br />2572..Traceback (most recent call last):
<br />  File "/opt/hostedtoolcache/Python/3.6.10/x64/bin/ml_models", line 11, in <module>
<br />    load_entry_point('mlmodels', 'console_scripts', 'ml_models')()
<br />  File "https://github.com/arita37/mlmodels/tree/a463a24ea257f46bfcbd4006f805952aace8f2b1/mlmodels/models.py", line 530, in main
<br />    fit_cli(arg)
<br />  File "https://github.com/arita37/mlmodels/tree/a463a24ea257f46bfcbd4006f805952aace8f2b1/mlmodels/models.py", line 424, in fit_cli
<br />    model, sess = fit(module, model, data_pars=data_p, compute_pars=compute_p, out_pars=out_p)
<br />  File "https://github.com/arita37/mlmodels/tree/a463a24ea257f46bfcbd4006f805952aace8f2b1/mlmodels/models.py", line 125, in fit
<br />    return module.fit(model, data_pars=data_pars, compute_pars=compute_pars, out_pars=out_pars, **kwarg)
<br />  File "https://github.com/arita37/mlmodels/tree/a463a24ea257f46bfcbd4006f805952aace8f2b1/mlmodels/model_tch/torchhub.py", line 222, in fit
<br />    train_iter, valid_iter = get_dataset(data_pars)
<br />  File "https://github.com/arita37/mlmodels/tree/a463a24ea257f46bfcbd4006f805952aace8f2b1/mlmodels/model_tch/torchhub.py", line 190, in get_dataset
<br />    loader = DataLoader(data_pars)
<br />  File "https://github.com/arita37/mlmodels/tree/a463a24ea257f46bfcbd4006f805952aace8f2b1/mlmodels/dataloader.py", line 236, in __init__
<br />    self.data_info                = data_pars['data_info']
<br />KeyError: 'data_info'



### Error 78, [Traceback at line 2599](https://github.com/arita37/mlmodels_store/blob/master/log_json/log_json.py#L2599)<br />2599..Traceback (most recent call last):
<br />  File "/opt/hostedtoolcache/Python/3.6.10/x64/bin/ml_models", line 11, in <module>
<br />    load_entry_point('mlmodels', 'console_scripts', 'ml_models')()
<br />  File "https://github.com/arita37/mlmodels/tree/a463a24ea257f46bfcbd4006f805952aace8f2b1/mlmodels/models.py", line 530, in main
<br />    fit_cli(arg)
<br />  File "https://github.com/arita37/mlmodels/tree/a463a24ea257f46bfcbd4006f805952aace8f2b1/mlmodels/models.py", line 413, in fit_cli
<br />    model_p, data_p, compute_p, out_p = config_get_pars(config_file, arg.config_mode)
<br />  File "https://github.com/arita37/mlmodels/tree/a463a24ea257f46bfcbd4006f805952aace8f2b1/mlmodels/models.py", line 299, in config_get_pars
<br />    out_p     = path_norm_dict( js.get("out_pars") )
<br />  File "https://github.com/arita37/mlmodels/tree/a463a24ea257f46bfcbd4006f805952aace8f2b1/mlmodels/util.py", line 201, in path_norm_dict
<br />    for k,v in ddict.items():
<br />AttributeError: 'NoneType' object has no attribute 'items'



### Error 79, [Traceback at line 2632](https://github.com/arita37/mlmodels_store/blob/master/log_json/log_json.py#L2632)<br />2632..Traceback (most recent call last):
<br />  File "/opt/hostedtoolcache/Python/3.6.10/x64/bin/ml_models", line 11, in <module>
<br />    load_entry_point('mlmodels', 'console_scripts', 'ml_models')()
<br />  File "https://github.com/arita37/mlmodels/tree/a463a24ea257f46bfcbd4006f805952aace8f2b1/mlmodels/models.py", line 530, in main
<br />    fit_cli(arg)
<br />  File "https://github.com/arita37/mlmodels/tree/a463a24ea257f46bfcbd4006f805952aace8f2b1/mlmodels/models.py", line 424, in fit_cli
<br />    model, sess = fit(module, model, data_pars=data_p, compute_pars=compute_p, out_pars=out_p)
<br />  File "https://github.com/arita37/mlmodels/tree/a463a24ea257f46bfcbd4006f805952aace8f2b1/mlmodels/models.py", line 125, in fit
<br />    return module.fit(model, data_pars=data_pars, compute_pars=compute_pars, out_pars=out_pars, **kwarg)
<br />  File "https://github.com/arita37/mlmodels/tree/a463a24ea257f46bfcbd4006f805952aace8f2b1/mlmodels/model_tch/torchhub.py", line 222, in fit
<br />    train_iter, valid_iter = get_dataset(data_pars)
<br />  File "https://github.com/arita37/mlmodels/tree/a463a24ea257f46bfcbd4006f805952aace8f2b1/mlmodels/model_tch/torchhub.py", line 190, in get_dataset
<br />    loader = DataLoader(data_pars)
<br />  File "https://github.com/arita37/mlmodels/tree/a463a24ea257f46bfcbd4006f805952aace8f2b1/mlmodels/dataloader.py", line 236, in __init__
<br />    self.data_info                = data_pars['data_info']
<br />KeyError: 'data_info'



### Error 80, [Traceback at line 2659](https://github.com/arita37/mlmodels_store/blob/master/log_json/log_json.py#L2659)<br />2659..Traceback (most recent call last):
<br />  File "/opt/hostedtoolcache/Python/3.6.10/x64/bin/ml_models", line 11, in <module>
<br />    load_entry_point('mlmodels', 'console_scripts', 'ml_models')()
<br />  File "https://github.com/arita37/mlmodels/tree/a463a24ea257f46bfcbd4006f805952aace8f2b1/mlmodels/models.py", line 530, in main
<br />    fit_cli(arg)
<br />  File "https://github.com/arita37/mlmodels/tree/a463a24ea257f46bfcbd4006f805952aace8f2b1/mlmodels/models.py", line 413, in fit_cli
<br />    model_p, data_p, compute_p, out_p = config_get_pars(config_file, arg.config_mode)
<br />  File "https://github.com/arita37/mlmodels/tree/a463a24ea257f46bfcbd4006f805952aace8f2b1/mlmodels/models.py", line 299, in config_get_pars
<br />    out_p     = path_norm_dict( js.get("out_pars") )
<br />  File "https://github.com/arita37/mlmodels/tree/a463a24ea257f46bfcbd4006f805952aace8f2b1/mlmodels/util.py", line 201, in path_norm_dict
<br />    for k,v in ddict.items():
<br />AttributeError: 'NoneType' object has no attribute 'items'



### Error 81, [Traceback at line 2692](https://github.com/arita37/mlmodels_store/blob/master/log_json/log_json.py#L2692)<br />2692..Traceback (most recent call last):
<br />  File "/opt/hostedtoolcache/Python/3.6.10/x64/bin/ml_models", line 11, in <module>
<br />    load_entry_point('mlmodels', 'console_scripts', 'ml_models')()
<br />  File "https://github.com/arita37/mlmodels/tree/a463a24ea257f46bfcbd4006f805952aace8f2b1/mlmodels/models.py", line 530, in main
<br />    fit_cli(arg)
<br />  File "https://github.com/arita37/mlmodels/tree/a463a24ea257f46bfcbd4006f805952aace8f2b1/mlmodels/models.py", line 424, in fit_cli
<br />    model, sess = fit(module, model, data_pars=data_p, compute_pars=compute_p, out_pars=out_p)
<br />  File "https://github.com/arita37/mlmodels/tree/a463a24ea257f46bfcbd4006f805952aace8f2b1/mlmodels/models.py", line 125, in fit
<br />    return module.fit(model, data_pars=data_pars, compute_pars=compute_pars, out_pars=out_pars, **kwarg)
<br />  File "https://github.com/arita37/mlmodels/tree/a463a24ea257f46bfcbd4006f805952aace8f2b1/mlmodels/model_tch/torchhub.py", line 222, in fit
<br />    train_iter, valid_iter = get_dataset(data_pars)
<br />  File "https://github.com/arita37/mlmodels/tree/a463a24ea257f46bfcbd4006f805952aace8f2b1/mlmodels/model_tch/torchhub.py", line 190, in get_dataset
<br />    loader = DataLoader(data_pars)
<br />  File "https://github.com/arita37/mlmodels/tree/a463a24ea257f46bfcbd4006f805952aace8f2b1/mlmodels/dataloader.py", line 236, in __init__
<br />    self.data_info                = data_pars['data_info']
<br />KeyError: 'data_info'



### Error 82, [Traceback at line 2719](https://github.com/arita37/mlmodels_store/blob/master/log_json/log_json.py#L2719)<br />2719..Traceback (most recent call last):
<br />  File "/opt/hostedtoolcache/Python/3.6.10/x64/bin/ml_models", line 11, in <module>
<br />    load_entry_point('mlmodels', 'console_scripts', 'ml_models')()
<br />  File "https://github.com/arita37/mlmodels/tree/a463a24ea257f46bfcbd4006f805952aace8f2b1/mlmodels/models.py", line 530, in main
<br />    fit_cli(arg)
<br />  File "https://github.com/arita37/mlmodels/tree/a463a24ea257f46bfcbd4006f805952aace8f2b1/mlmodels/models.py", line 413, in fit_cli
<br />    model_p, data_p, compute_p, out_p = config_get_pars(config_file, arg.config_mode)
<br />  File "https://github.com/arita37/mlmodels/tree/a463a24ea257f46bfcbd4006f805952aace8f2b1/mlmodels/models.py", line 299, in config_get_pars
<br />    out_p     = path_norm_dict( js.get("out_pars") )
<br />  File "https://github.com/arita37/mlmodels/tree/a463a24ea257f46bfcbd4006f805952aace8f2b1/mlmodels/util.py", line 201, in path_norm_dict
<br />    for k,v in ddict.items():
<br />AttributeError: 'NoneType' object has no attribute 'items'



### Error 83, [Traceback at line 2752](https://github.com/arita37/mlmodels_store/blob/master/log_json/log_json.py#L2752)<br />2752..Traceback (most recent call last):
<br />  File "/opt/hostedtoolcache/Python/3.6.10/x64/bin/ml_models", line 11, in <module>
<br />    load_entry_point('mlmodels', 'console_scripts', 'ml_models')()
<br />  File "https://github.com/arita37/mlmodels/tree/a463a24ea257f46bfcbd4006f805952aace8f2b1/mlmodels/models.py", line 530, in main
<br />    fit_cli(arg)
<br />  File "https://github.com/arita37/mlmodels/tree/a463a24ea257f46bfcbd4006f805952aace8f2b1/mlmodels/models.py", line 424, in fit_cli
<br />    model, sess = fit(module, model, data_pars=data_p, compute_pars=compute_p, out_pars=out_p)
<br />  File "https://github.com/arita37/mlmodels/tree/a463a24ea257f46bfcbd4006f805952aace8f2b1/mlmodels/models.py", line 125, in fit
<br />    return module.fit(model, data_pars=data_pars, compute_pars=compute_pars, out_pars=out_pars, **kwarg)
<br />  File "https://github.com/arita37/mlmodels/tree/a463a24ea257f46bfcbd4006f805952aace8f2b1/mlmodels/model_tch/torchhub.py", line 222, in fit
<br />    train_iter, valid_iter = get_dataset(data_pars)
<br />  File "https://github.com/arita37/mlmodels/tree/a463a24ea257f46bfcbd4006f805952aace8f2b1/mlmodels/model_tch/torchhub.py", line 190, in get_dataset
<br />    loader = DataLoader(data_pars)
<br />  File "https://github.com/arita37/mlmodels/tree/a463a24ea257f46bfcbd4006f805952aace8f2b1/mlmodels/dataloader.py", line 236, in __init__
<br />    self.data_info                = data_pars['data_info']
<br />KeyError: 'data_info'



### Error 84, [Traceback at line 2779](https://github.com/arita37/mlmodels_store/blob/master/log_json/log_json.py#L2779)<br />2779..Traceback (most recent call last):
<br />  File "/opt/hostedtoolcache/Python/3.6.10/x64/bin/ml_models", line 11, in <module>
<br />    load_entry_point('mlmodels', 'console_scripts', 'ml_models')()
<br />  File "https://github.com/arita37/mlmodels/tree/a463a24ea257f46bfcbd4006f805952aace8f2b1/mlmodels/models.py", line 530, in main
<br />    fit_cli(arg)
<br />  File "https://github.com/arita37/mlmodels/tree/a463a24ea257f46bfcbd4006f805952aace8f2b1/mlmodels/models.py", line 413, in fit_cli
<br />    model_p, data_p, compute_p, out_p = config_get_pars(config_file, arg.config_mode)
<br />  File "https://github.com/arita37/mlmodels/tree/a463a24ea257f46bfcbd4006f805952aace8f2b1/mlmodels/models.py", line 299, in config_get_pars
<br />    out_p     = path_norm_dict( js.get("out_pars") )
<br />  File "https://github.com/arita37/mlmodels/tree/a463a24ea257f46bfcbd4006f805952aace8f2b1/mlmodels/util.py", line 201, in path_norm_dict
<br />    for k,v in ddict.items():
<br />AttributeError: 'NoneType' object has no attribute 'items'



### Error 85, [Traceback at line 2812](https://github.com/arita37/mlmodels_store/blob/master/log_json/log_json.py#L2812)<br />2812..Traceback (most recent call last):
<br />  File "/opt/hostedtoolcache/Python/3.6.10/x64/bin/ml_models", line 11, in <module>
<br />    load_entry_point('mlmodels', 'console_scripts', 'ml_models')()
<br />  File "https://github.com/arita37/mlmodels/tree/a463a24ea257f46bfcbd4006f805952aace8f2b1/mlmodels/models.py", line 530, in main
<br />    fit_cli(arg)
<br />  File "https://github.com/arita37/mlmodels/tree/a463a24ea257f46bfcbd4006f805952aace8f2b1/mlmodels/models.py", line 424, in fit_cli
<br />    model, sess = fit(module, model, data_pars=data_p, compute_pars=compute_p, out_pars=out_p)
<br />  File "https://github.com/arita37/mlmodels/tree/a463a24ea257f46bfcbd4006f805952aace8f2b1/mlmodels/models.py", line 125, in fit
<br />    return module.fit(model, data_pars=data_pars, compute_pars=compute_pars, out_pars=out_pars, **kwarg)
<br />  File "https://github.com/arita37/mlmodels/tree/a463a24ea257f46bfcbd4006f805952aace8f2b1/mlmodels/model_tch/torchhub.py", line 222, in fit
<br />    train_iter, valid_iter = get_dataset(data_pars)
<br />  File "https://github.com/arita37/mlmodels/tree/a463a24ea257f46bfcbd4006f805952aace8f2b1/mlmodels/model_tch/torchhub.py", line 190, in get_dataset
<br />    loader = DataLoader(data_pars)
<br />  File "https://github.com/arita37/mlmodels/tree/a463a24ea257f46bfcbd4006f805952aace8f2b1/mlmodels/dataloader.py", line 236, in __init__
<br />    self.data_info                = data_pars['data_info']
<br />KeyError: 'data_info'



### Error 86, [Traceback at line 2839](https://github.com/arita37/mlmodels_store/blob/master/log_json/log_json.py#L2839)<br />2839..Traceback (most recent call last):
<br />  File "/opt/hostedtoolcache/Python/3.6.10/x64/bin/ml_models", line 11, in <module>
<br />    load_entry_point('mlmodels', 'console_scripts', 'ml_models')()
<br />  File "https://github.com/arita37/mlmodels/tree/a463a24ea257f46bfcbd4006f805952aace8f2b1/mlmodels/models.py", line 530, in main
<br />    fit_cli(arg)
<br />  File "https://github.com/arita37/mlmodels/tree/a463a24ea257f46bfcbd4006f805952aace8f2b1/mlmodels/models.py", line 413, in fit_cli
<br />    model_p, data_p, compute_p, out_p = config_get_pars(config_file, arg.config_mode)
<br />  File "https://github.com/arita37/mlmodels/tree/a463a24ea257f46bfcbd4006f805952aace8f2b1/mlmodels/models.py", line 299, in config_get_pars
<br />    out_p     = path_norm_dict( js.get("out_pars") )
<br />  File "https://github.com/arita37/mlmodels/tree/a463a24ea257f46bfcbd4006f805952aace8f2b1/mlmodels/util.py", line 201, in path_norm_dict
<br />    for k,v in ddict.items():
<br />AttributeError: 'NoneType' object has no attribute 'items'



### Error 87, [Traceback at line 2872](https://github.com/arita37/mlmodels_store/blob/master/log_json/log_json.py#L2872)<br />2872..Traceback (most recent call last):
<br />  File "/opt/hostedtoolcache/Python/3.6.10/x64/bin/ml_models", line 11, in <module>
<br />    load_entry_point('mlmodels', 'console_scripts', 'ml_models')()
<br />  File "https://github.com/arita37/mlmodels/tree/a463a24ea257f46bfcbd4006f805952aace8f2b1/mlmodels/models.py", line 530, in main
<br />    fit_cli(arg)
<br />  File "https://github.com/arita37/mlmodels/tree/a463a24ea257f46bfcbd4006f805952aace8f2b1/mlmodels/models.py", line 424, in fit_cli
<br />    model, sess = fit(module, model, data_pars=data_p, compute_pars=compute_p, out_pars=out_p)
<br />  File "https://github.com/arita37/mlmodels/tree/a463a24ea257f46bfcbd4006f805952aace8f2b1/mlmodels/models.py", line 125, in fit
<br />    return module.fit(model, data_pars=data_pars, compute_pars=compute_pars, out_pars=out_pars, **kwarg)
<br />  File "https://github.com/arita37/mlmodels/tree/a463a24ea257f46bfcbd4006f805952aace8f2b1/mlmodels/model_tch/torchhub.py", line 222, in fit
<br />    train_iter, valid_iter = get_dataset(data_pars)
<br />  File "https://github.com/arita37/mlmodels/tree/a463a24ea257f46bfcbd4006f805952aace8f2b1/mlmodels/model_tch/torchhub.py", line 190, in get_dataset
<br />    loader = DataLoader(data_pars)
<br />  File "https://github.com/arita37/mlmodels/tree/a463a24ea257f46bfcbd4006f805952aace8f2b1/mlmodels/dataloader.py", line 236, in __init__
<br />    self.data_info                = data_pars['data_info']
<br />KeyError: 'data_info'



### Error 88, [Traceback at line 2899](https://github.com/arita37/mlmodels_store/blob/master/log_json/log_json.py#L2899)<br />2899..Traceback (most recent call last):
<br />  File "/opt/hostedtoolcache/Python/3.6.10/x64/bin/ml_models", line 11, in <module>
<br />    load_entry_point('mlmodels', 'console_scripts', 'ml_models')()
<br />  File "https://github.com/arita37/mlmodels/tree/a463a24ea257f46bfcbd4006f805952aace8f2b1/mlmodels/models.py", line 530, in main
<br />    fit_cli(arg)
<br />  File "https://github.com/arita37/mlmodels/tree/a463a24ea257f46bfcbd4006f805952aace8f2b1/mlmodels/models.py", line 413, in fit_cli
<br />    model_p, data_p, compute_p, out_p = config_get_pars(config_file, arg.config_mode)
<br />  File "https://github.com/arita37/mlmodels/tree/a463a24ea257f46bfcbd4006f805952aace8f2b1/mlmodels/models.py", line 299, in config_get_pars
<br />    out_p     = path_norm_dict( js.get("out_pars") )
<br />  File "https://github.com/arita37/mlmodels/tree/a463a24ea257f46bfcbd4006f805952aace8f2b1/mlmodels/util.py", line 201, in path_norm_dict
<br />    for k,v in ddict.items():
<br />AttributeError: 'NoneType' object has no attribute 'items'



### Error 89, [Traceback at line 2932](https://github.com/arita37/mlmodels_store/blob/master/log_json/log_json.py#L2932)<br />2932..Traceback (most recent call last):
<br />  File "/opt/hostedtoolcache/Python/3.6.10/x64/bin/ml_models", line 11, in <module>
<br />    load_entry_point('mlmodels', 'console_scripts', 'ml_models')()
<br />  File "https://github.com/arita37/mlmodels/tree/a463a24ea257f46bfcbd4006f805952aace8f2b1/mlmodels/models.py", line 530, in main
<br />    fit_cli(arg)
<br />  File "https://github.com/arita37/mlmodels/tree/a463a24ea257f46bfcbd4006f805952aace8f2b1/mlmodels/models.py", line 424, in fit_cli
<br />    model, sess = fit(module, model, data_pars=data_p, compute_pars=compute_p, out_pars=out_p)
<br />  File "https://github.com/arita37/mlmodels/tree/a463a24ea257f46bfcbd4006f805952aace8f2b1/mlmodels/models.py", line 125, in fit
<br />    return module.fit(model, data_pars=data_pars, compute_pars=compute_pars, out_pars=out_pars, **kwarg)
<br />  File "https://github.com/arita37/mlmodels/tree/a463a24ea257f46bfcbd4006f805952aace8f2b1/mlmodels/model_tch/torchhub.py", line 222, in fit
<br />    train_iter, valid_iter = get_dataset(data_pars)
<br />  File "https://github.com/arita37/mlmodels/tree/a463a24ea257f46bfcbd4006f805952aace8f2b1/mlmodels/model_tch/torchhub.py", line 190, in get_dataset
<br />    loader = DataLoader(data_pars)
<br />  File "https://github.com/arita37/mlmodels/tree/a463a24ea257f46bfcbd4006f805952aace8f2b1/mlmodels/dataloader.py", line 236, in __init__
<br />    self.data_info                = data_pars['data_info']
<br />KeyError: 'data_info'



### Error 90, [Traceback at line 2959](https://github.com/arita37/mlmodels_store/blob/master/log_json/log_json.py#L2959)<br />2959..Traceback (most recent call last):
<br />  File "/opt/hostedtoolcache/Python/3.6.10/x64/bin/ml_models", line 11, in <module>
<br />    load_entry_point('mlmodels', 'console_scripts', 'ml_models')()
<br />  File "https://github.com/arita37/mlmodels/tree/a463a24ea257f46bfcbd4006f805952aace8f2b1/mlmodels/models.py", line 530, in main
<br />    fit_cli(arg)
<br />  File "https://github.com/arita37/mlmodels/tree/a463a24ea257f46bfcbd4006f805952aace8f2b1/mlmodels/models.py", line 413, in fit_cli
<br />    model_p, data_p, compute_p, out_p = config_get_pars(config_file, arg.config_mode)
<br />  File "https://github.com/arita37/mlmodels/tree/a463a24ea257f46bfcbd4006f805952aace8f2b1/mlmodels/models.py", line 299, in config_get_pars
<br />    out_p     = path_norm_dict( js.get("out_pars") )
<br />  File "https://github.com/arita37/mlmodels/tree/a463a24ea257f46bfcbd4006f805952aace8f2b1/mlmodels/util.py", line 201, in path_norm_dict
<br />    for k,v in ddict.items():
<br />AttributeError: 'NoneType' object has no attribute 'items'



### Error 91, [Traceback at line 2992](https://github.com/arita37/mlmodels_store/blob/master/log_json/log_json.py#L2992)<br />2992..Traceback (most recent call last):
<br />  File "/opt/hostedtoolcache/Python/3.6.10/x64/bin/ml_models", line 11, in <module>
<br />    load_entry_point('mlmodels', 'console_scripts', 'ml_models')()
<br />  File "https://github.com/arita37/mlmodels/tree/a463a24ea257f46bfcbd4006f805952aace8f2b1/mlmodels/models.py", line 530, in main
<br />    fit_cli(arg)
<br />  File "https://github.com/arita37/mlmodels/tree/a463a24ea257f46bfcbd4006f805952aace8f2b1/mlmodels/models.py", line 424, in fit_cli
<br />    model, sess = fit(module, model, data_pars=data_p, compute_pars=compute_p, out_pars=out_p)
<br />  File "https://github.com/arita37/mlmodels/tree/a463a24ea257f46bfcbd4006f805952aace8f2b1/mlmodels/models.py", line 125, in fit
<br />    return module.fit(model, data_pars=data_pars, compute_pars=compute_pars, out_pars=out_pars, **kwarg)
<br />  File "https://github.com/arita37/mlmodels/tree/a463a24ea257f46bfcbd4006f805952aace8f2b1/mlmodels/model_tch/torchhub.py", line 222, in fit
<br />    train_iter, valid_iter = get_dataset(data_pars)
<br />  File "https://github.com/arita37/mlmodels/tree/a463a24ea257f46bfcbd4006f805952aace8f2b1/mlmodels/model_tch/torchhub.py", line 190, in get_dataset
<br />    loader = DataLoader(data_pars)
<br />  File "https://github.com/arita37/mlmodels/tree/a463a24ea257f46bfcbd4006f805952aace8f2b1/mlmodels/dataloader.py", line 236, in __init__
<br />    self.data_info                = data_pars['data_info']
<br />KeyError: 'data_info'



### Error 92, [Traceback at line 3019](https://github.com/arita37/mlmodels_store/blob/master/log_json/log_json.py#L3019)<br />3019..Traceback (most recent call last):
<br />  File "/opt/hostedtoolcache/Python/3.6.10/x64/bin/ml_models", line 11, in <module>
<br />    load_entry_point('mlmodels', 'console_scripts', 'ml_models')()
<br />  File "https://github.com/arita37/mlmodels/tree/a463a24ea257f46bfcbd4006f805952aace8f2b1/mlmodels/models.py", line 530, in main
<br />    fit_cli(arg)
<br />  File "https://github.com/arita37/mlmodels/tree/a463a24ea257f46bfcbd4006f805952aace8f2b1/mlmodels/models.py", line 413, in fit_cli
<br />    model_p, data_p, compute_p, out_p = config_get_pars(config_file, arg.config_mode)
<br />  File "https://github.com/arita37/mlmodels/tree/a463a24ea257f46bfcbd4006f805952aace8f2b1/mlmodels/models.py", line 299, in config_get_pars
<br />    out_p     = path_norm_dict( js.get("out_pars") )
<br />  File "https://github.com/arita37/mlmodels/tree/a463a24ea257f46bfcbd4006f805952aace8f2b1/mlmodels/util.py", line 201, in path_norm_dict
<br />    for k,v in ddict.items():
<br />AttributeError: 'NoneType' object has no attribute 'items'



### Error 93, [Traceback at line 3049](https://github.com/arita37/mlmodels_store/blob/master/log_json/log_json.py#L3049)<br />3049..Traceback (most recent call last):
<br />  File "https://github.com/arita37/mlmodels/tree/a463a24ea257f46bfcbd4006f805952aace8f2b1/mlmodels/models.py", line 72, in module_load
<br />    module = import_module(f"mlmodels.{model_name}")
<br />  File "/opt/hostedtoolcache/Python/3.6.10/x64/lib/python3.6/importlib/__init__.py", line 126, in import_module
<br />    return _bootstrap._gcd_import(name[level:], package, level)
<br />  File "<frozen importlib._bootstrap>", line 994, in _gcd_import
<br />  File "<frozen importlib._bootstrap>", line 971, in _find_and_load
<br />  File "<frozen importlib._bootstrap>", line 955, in _find_and_load_unlocked
<br />  File "<frozen importlib._bootstrap>", line 665, in _load_unlocked
<br />  File "<frozen importlib._bootstrap_external>", line 678, in exec_module
<br />  File "<frozen importlib._bootstrap>", line 219, in _call_with_frames_removed
<br />  File "https://github.com/arita37/mlmodels/tree/a463a24ea257f46bfcbd4006f805952aace8f2b1/mlmodels/model_keras/Autokeras.py", line 12, in <module>
<br />    import autokeras as ak
<br />ModuleNotFoundError: No module named 'autokeras'



### Error 94, [Traceback at line 3066](https://github.com/arita37/mlmodels_store/blob/master/log_json/log_json.py#L3066)<br />3066..Traceback (most recent call last):
<br />  File "https://github.com/arita37/mlmodels/tree/a463a24ea257f46bfcbd4006f805952aace8f2b1/mlmodels/models.py", line 84, in module_load
<br />    model_name = str(Path(model_uri).parts[-2]) + "." + str(model_name)
<br />IndexError: tuple index out of range



### Error 95, [Traceback at line 3073](https://github.com/arita37/mlmodels_store/blob/master/log_json/log_json.py#L3073)<br />3073..Traceback (most recent call last):
<br />  File "/opt/hostedtoolcache/Python/3.6.10/x64/bin/ml_models", line 11, in <module>
<br />    load_entry_point('mlmodels', 'console_scripts', 'ml_models')()
<br />  File "https://github.com/arita37/mlmodels/tree/a463a24ea257f46bfcbd4006f805952aace8f2b1/mlmodels/models.py", line 530, in main
<br />    fit_cli(arg)
<br />  File "https://github.com/arita37/mlmodels/tree/a463a24ea257f46bfcbd4006f805952aace8f2b1/mlmodels/models.py", line 420, in fit_cli
<br />    module = module_load(model_uri)  # '1_lstm.py
<br />  File "https://github.com/arita37/mlmodels/tree/a463a24ea257f46bfcbd4006f805952aace8f2b1/mlmodels/models.py", line 89, in module_load
<br />    raise NameError(f"Module {model_name} notfound, {e1}, {e2}")
<br />NameError: Module model_keras.Autokeras notfound, No module named 'autokeras', tuple index out of range



### Error 96, [Traceback at line 3094](https://github.com/arita37/mlmodels_store/blob/master/log_json/log_json.py#L3094)<br />3094..Traceback (most recent call last):
<br />  File "/opt/hostedtoolcache/Python/3.6.10/x64/bin/ml_models", line 11, in <module>
<br />    load_entry_point('mlmodels', 'console_scripts', 'ml_models')()
<br />  File "https://github.com/arita37/mlmodels/tree/a463a24ea257f46bfcbd4006f805952aace8f2b1/mlmodels/models.py", line 530, in main
<br />    fit_cli(arg)
<br />  File "https://github.com/arita37/mlmodels/tree/a463a24ea257f46bfcbd4006f805952aace8f2b1/mlmodels/models.py", line 413, in fit_cli
<br />    model_p, data_p, compute_p, out_p = config_get_pars(config_file, arg.config_mode)
<br />  File "https://github.com/arita37/mlmodels/tree/a463a24ea257f46bfcbd4006f805952aace8f2b1/mlmodels/models.py", line 299, in config_get_pars
<br />    out_p     = path_norm_dict( js.get("out_pars") )
<br />  File "https://github.com/arita37/mlmodels/tree/a463a24ea257f46bfcbd4006f805952aace8f2b1/mlmodels/util.py", line 201, in path_norm_dict
<br />    for k,v in ddict.items():
<br />AttributeError: 'NoneType' object has no attribute 'items'



### Error 97, [Traceback at line 3175](https://github.com/arita37/mlmodels_store/blob/master/log_json/log_json.py#L3175)<br />3175..Traceback (most recent call last):
<br />  File "/opt/hostedtoolcache/Python/3.6.10/x64/bin/ml_models", line 11, in <module>
<br />    load_entry_point('mlmodels', 'console_scripts', 'ml_models')()
<br />  File "https://github.com/arita37/mlmodels/tree/a463a24ea257f46bfcbd4006f805952aace8f2b1/mlmodels/models.py", line 530, in main
<br />    fit_cli(arg)
<br />  File "https://github.com/arita37/mlmodels/tree/a463a24ea257f46bfcbd4006f805952aace8f2b1/mlmodels/models.py", line 413, in fit_cli
<br />    model_p, data_p, compute_p, out_p = config_get_pars(config_file, arg.config_mode)
<br />  File "https://github.com/arita37/mlmodels/tree/a463a24ea257f46bfcbd4006f805952aace8f2b1/mlmodels/models.py", line 299, in config_get_pars
<br />    out_p     = path_norm_dict( js.get("out_pars") )
<br />  File "https://github.com/arita37/mlmodels/tree/a463a24ea257f46bfcbd4006f805952aace8f2b1/mlmodels/util.py", line 201, in path_norm_dict
<br />    for k,v in ddict.items():
<br />AttributeError: 'NoneType' object has no attribute 'items'



### Error 98, [Traceback at line 3203](https://github.com/arita37/mlmodels_store/blob/master/log_json/log_json.py#L3203)<br />3203..Traceback (most recent call last):
<br />  File "/opt/hostedtoolcache/Python/3.6.10/x64/bin/ml_models", line 11, in <module>
<br />    load_entry_point('mlmodels', 'console_scripts', 'ml_models')()
<br />  File "https://github.com/arita37/mlmodels/tree/a463a24ea257f46bfcbd4006f805952aace8f2b1/mlmodels/models.py", line 530, in main
<br />    fit_cli(arg)
<br />  File "https://github.com/arita37/mlmodels/tree/a463a24ea257f46bfcbd4006f805952aace8f2b1/mlmodels/models.py", line 415, in fit_cli
<br />    path      = out_p['path']
<br />KeyError: 'path'



### Error 99, [Traceback at line 3222](https://github.com/arita37/mlmodels_store/blob/master/log_json/log_json.py#L3222)<br />3222..Traceback (most recent call last):
<br />  File "/opt/hostedtoolcache/Python/3.6.10/x64/bin/ml_models", line 11, in <module>
<br />    load_entry_point('mlmodels', 'console_scripts', 'ml_models')()
<br />  File "https://github.com/arita37/mlmodels/tree/a463a24ea257f46bfcbd4006f805952aace8f2b1/mlmodels/models.py", line 530, in main
<br />    fit_cli(arg)
<br />  File "https://github.com/arita37/mlmodels/tree/a463a24ea257f46bfcbd4006f805952aace8f2b1/mlmodels/models.py", line 413, in fit_cli
<br />    model_p, data_p, compute_p, out_p = config_get_pars(config_file, arg.config_mode)
<br />  File "https://github.com/arita37/mlmodels/tree/a463a24ea257f46bfcbd4006f805952aace8f2b1/mlmodels/models.py", line 299, in config_get_pars
<br />    out_p     = path_norm_dict( js.get("out_pars") )
<br />  File "https://github.com/arita37/mlmodels/tree/a463a24ea257f46bfcbd4006f805952aace8f2b1/mlmodels/util.py", line 201, in path_norm_dict
<br />    for k,v in ddict.items():
<br />AttributeError: 'NoneType' object has no attribute 'items'



### Error 100, [Traceback at line 3350](https://github.com/arita37/mlmodels_store/blob/master/log_json/log_json.py#L3350)<br />3350..Traceback (most recent call last):
<br />  File "/opt/hostedtoolcache/Python/3.6.10/x64/bin/ml_models", line 11, in <module>
<br />    load_entry_point('mlmodels', 'console_scripts', 'ml_models')()
<br />  File "https://github.com/arita37/mlmodels/tree/a463a24ea257f46bfcbd4006f805952aace8f2b1/mlmodels/models.py", line 530, in main
<br />    fit_cli(arg)
<br />  File "https://github.com/arita37/mlmodels/tree/a463a24ea257f46bfcbd4006f805952aace8f2b1/mlmodels/models.py", line 413, in fit_cli
<br />    model_p, data_p, compute_p, out_p = config_get_pars(config_file, arg.config_mode)
<br />  File "https://github.com/arita37/mlmodels/tree/a463a24ea257f46bfcbd4006f805952aace8f2b1/mlmodels/models.py", line 299, in config_get_pars
<br />    out_p     = path_norm_dict( js.get("out_pars") )
<br />  File "https://github.com/arita37/mlmodels/tree/a463a24ea257f46bfcbd4006f805952aace8f2b1/mlmodels/util.py", line 201, in path_norm_dict
<br />    for k,v in ddict.items():
<br />AttributeError: 'NoneType' object has no attribute 'items'



### Error 101, [Traceback at line 3381](https://github.com/arita37/mlmodels_store/blob/master/log_json/log_json.py#L3381)<br />3381..Traceback (most recent call last):
<br />  File "/opt/hostedtoolcache/Python/3.6.10/x64/bin/ml_models", line 11, in <module>
<br />    load_entry_point('mlmodels', 'console_scripts', 'ml_models')()
<br />  File "https://github.com/arita37/mlmodels/tree/a463a24ea257f46bfcbd4006f805952aace8f2b1/mlmodels/models.py", line 530, in main
<br />    fit_cli(arg)
<br />  File "https://github.com/arita37/mlmodels/tree/a463a24ea257f46bfcbd4006f805952aace8f2b1/mlmodels/models.py", line 421, in fit_cli
<br />    model = model_create(module, model_p, data_p, compute_p)  # Exact map JSON and paramters
<br />  File "https://github.com/arita37/mlmodels/tree/a463a24ea257f46bfcbd4006f805952aace8f2b1/mlmodels/models.py", line 113, in model_create
<br />    model = module.Model(model_pars=model_pars, data_pars=data_pars, compute_pars=compute_pars, **kwarg)
<br />  File "https://github.com/arita37/mlmodels/tree/a463a24ea257f46bfcbd4006f805952aace8f2b1/mlmodels/model_keras/textvae.py", line 51, in __init__
<br />    texts, embeddings_index = get_dataset(data_pars)
<br />  File "https://github.com/arita37/mlmodels/tree/a463a24ea257f46bfcbd4006f805952aace8f2b1/mlmodels/model_keras/textvae.py", line 269, in get_dataset
<br />    with codecs.open(data_pars["train_data_path"], encoding='utf-8') as f:
<br />  File "/opt/hostedtoolcache/Python/3.6.10/x64/lib/python3.6/codecs.py", line 897, in open
<br />    file = builtins.open(filename, mode, buffering)
<br />FileNotFoundError: [Errno 2] No such file or directory: 'https://github.com/arita37/mlmodels/tree/a463a24ea257f46bfcbd4006f805952aace8f2b1/mlmodels/dataset/text/quora/train.csv'



### Error 102, [Traceback at line 3408](https://github.com/arita37/mlmodels_store/blob/master/log_json/log_json.py#L3408)<br />3408..Traceback (most recent call last):
<br />  File "/opt/hostedtoolcache/Python/3.6.10/x64/bin/ml_models", line 11, in <module>
<br />    load_entry_point('mlmodels', 'console_scripts', 'ml_models')()
<br />  File "https://github.com/arita37/mlmodels/tree/a463a24ea257f46bfcbd4006f805952aace8f2b1/mlmodels/models.py", line 530, in main
<br />    fit_cli(arg)
<br />  File "https://github.com/arita37/mlmodels/tree/a463a24ea257f46bfcbd4006f805952aace8f2b1/mlmodels/models.py", line 413, in fit_cli
<br />    model_p, data_p, compute_p, out_p = config_get_pars(config_file, arg.config_mode)
<br />  File "https://github.com/arita37/mlmodels/tree/a463a24ea257f46bfcbd4006f805952aace8f2b1/mlmodels/models.py", line 299, in config_get_pars
<br />    out_p     = path_norm_dict( js.get("out_pars") )
<br />  File "https://github.com/arita37/mlmodels/tree/a463a24ea257f46bfcbd4006f805952aace8f2b1/mlmodels/util.py", line 201, in path_norm_dict
<br />    for k,v in ddict.items():
<br />AttributeError: 'NoneType' object has no attribute 'items'



### Error 103, [Traceback at line 3483](https://github.com/arita37/mlmodels_store/blob/master/log_json/log_json.py#L3483)<br />3483..Traceback (most recent call last):
<br />  File "https://github.com/arita37/mlmodels/tree/a463a24ea257f46bfcbd4006f805952aace8f2b1/mlmodels/model_tch/textcnn.py", line 153, in create_tabular_dataset
<br />    spacy_en = spacy.load( f'{lang}_core_web_sm', disable= disable)
<br />  File "/opt/hostedtoolcache/Python/3.6.10/x64/lib/python3.6/site-packages/spacy/__init__.py", line 30, in load
<br />    return util.load_model(name, **overrides)
<br />  File "/opt/hostedtoolcache/Python/3.6.10/x64/lib/python3.6/site-packages/spacy/util.py", line 169, in load_model
<br />    raise IOError(Errors.E050.format(name=name))
<br />OSError: [E050] Can't find model 'en_core_web_sm'. It doesn't seem to be a shortcut link, a Python package or a valid path to a data directory.



### Error 104, [Traceback at line 3494](https://github.com/arita37/mlmodels_store/blob/master/log_json/log_json.py#L3494)<br />3494..Traceback (most recent call last):
<br />  File "/opt/hostedtoolcache/Python/3.6.10/x64/bin/ml_models", line 11, in <module>
<br />    load_entry_point('mlmodels', 'console_scripts', 'ml_models')()
<br />  File "https://github.com/arita37/mlmodels/tree/a463a24ea257f46bfcbd4006f805952aace8f2b1/mlmodels/models.py", line 530, in main
<br />    fit_cli(arg)
<br />  File "https://github.com/arita37/mlmodels/tree/a463a24ea257f46bfcbd4006f805952aace8f2b1/mlmodels/models.py", line 424, in fit_cli
<br />    model, sess = fit(module, model, data_pars=data_p, compute_pars=compute_p, out_pars=out_p)
<br />  File "https://github.com/arita37/mlmodels/tree/a463a24ea257f46bfcbd4006f805952aace8f2b1/mlmodels/models.py", line 125, in fit
<br />    return module.fit(model, data_pars=data_pars, compute_pars=compute_pars, out_pars=out_pars, **kwarg)
<br />  File "https://github.com/arita37/mlmodels/tree/a463a24ea257f46bfcbd4006f805952aace8f2b1/mlmodels/model_tch/textcnn.py", line 291, in fit
<br />    train_iter, valid_iter, vocab = get_dataset(data_pars, out_pars)
<br />  File "https://github.com/arita37/mlmodels/tree/a463a24ea257f46bfcbd4006f805952aace8f2b1/mlmodels/model_tch/textcnn.py", line 334, in get_dataset
<br />    trainset, validset, vocab = create_tabular_dataset( data_pars['train_path'], data_pars['valid_path'], lang, pretrained_emb)
<br />  File "https://github.com/arita37/mlmodels/tree/a463a24ea257f46bfcbd4006f805952aace8f2b1/mlmodels/model_tch/textcnn.py", line 159, in create_tabular_dataset
<br />    spacy_en = spacy.load( f'{lang}_core_web_sm', disable= disable)  
<br />  File "/opt/hostedtoolcache/Python/3.6.10/x64/lib/python3.6/site-packages/spacy/__init__.py", line 30, in load
<br />    return util.load_model(name, **overrides)
<br />  File "/opt/hostedtoolcache/Python/3.6.10/x64/lib/python3.6/site-packages/spacy/util.py", line 169, in load_model
<br />    raise IOError(Errors.E050.format(name=name))
<br />OSError: [E050] Can't find model 'en_core_web_sm'. It doesn't seem to be a shortcut link, a Python package or a valid path to a data directory.



### Error 105, [Traceback at line 3525](https://github.com/arita37/mlmodels_store/blob/master/log_json/log_json.py#L3525)<br />3525..Traceback (most recent call last):
<br />  File "/opt/hostedtoolcache/Python/3.6.10/x64/bin/ml_models", line 11, in <module>
<br />    load_entry_point('mlmodels', 'console_scripts', 'ml_models')()
<br />  File "https://github.com/arita37/mlmodels/tree/a463a24ea257f46bfcbd4006f805952aace8f2b1/mlmodels/models.py", line 530, in main
<br />    fit_cli(arg)
<br />  File "https://github.com/arita37/mlmodels/tree/a463a24ea257f46bfcbd4006f805952aace8f2b1/mlmodels/models.py", line 413, in fit_cli
<br />    model_p, data_p, compute_p, out_p = config_get_pars(config_file, arg.config_mode)
<br />  File "https://github.com/arita37/mlmodels/tree/a463a24ea257f46bfcbd4006f805952aace8f2b1/mlmodels/models.py", line 297, in config_get_pars
<br />    data_p    = path_norm_dict( js.get("data_pars") )
<br />  File "https://github.com/arita37/mlmodels/tree/a463a24ea257f46bfcbd4006f805952aace8f2b1/mlmodels/util.py", line 201, in path_norm_dict
<br />    for k,v in ddict.items():
<br />AttributeError: 'NoneType' object has no attribute 'items'
