Deprecaton set to False

  {'model_uri': 'model_tf.1_lstm', 'learning_rate': 0.001, 'num_layers': 1, 'size': 6, 'size_layer': 128, 'output_size': 6, 'timestep': 4, 'epoch': 2} {'data_path': '/home/runner/work/mlmodels/mlmodels/mlmodels/dataset/timeseries/GOOG-year_small.csv', 'data_type': 'pandas', 'size': [0, 0, 6], 'output_size': [0, 6]} {'engine': 'optuna', 'method': 'prune', 'ntrials': 5} {'engine_pars': {'engine': 'optuna', 'method': 'normal', 'ntrials': 2, 'metric_target': 'loss'}, 'learning_rate': {'type': 'log_uniform', 'init': 0.01, 'range': [0.001, 0.1]}, 'num_layers': {'type': 'int', 'init': 2, 'range': [2, 4]}, 'size': {'type': 'int', 'init': 6, 'range': [6, 6]}, 'output_size': {'type': 'int', 'init': 6, 'range': [6, 6]}, 'size_layer': {'type': 'categorical', 'value': [128, 256]}, 'timestep': {'type': 'categorical', 'value': [5]}, 'epoch': {'type': 'categorical', 'value': [2]}} 
Traceback (most recent call last):
  File "/home/runner/work/mlmodels/mlmodels/mlmodels/models.py", line 72, in module_load
    module = import_module(f"mlmodels.{model_name}")
  File "/opt/hostedtoolcache/Python/3.6.11/x64/lib/python3.6/importlib/__init__.py", line 126, in import_module
    return _bootstrap._gcd_import(name[level:], package, level)
  File "<frozen importlib._bootstrap>", line 994, in _gcd_import
  File "<frozen importlib._bootstrap>", line 971, in _find_and_load
  File "<frozen importlib._bootstrap>", line 955, in _find_and_load_unlocked
  File "<frozen importlib._bootstrap>", line 665, in _load_unlocked
  File "<frozen importlib._bootstrap_external>", line 674, in exec_module
  File "<frozen importlib._bootstrap_external>", line 781, in get_code
  File "<frozen importlib._bootstrap_external>", line 741, in source_to_code
  File "<frozen importlib._bootstrap>", line 219, in _call_with_frames_removed
  File "/home/runner/work/mlmodels/mlmodels/mlmodels/model_tf/1_lstm.py", line 38
    def init(**kw,  **kwargs):
                     ^
SyntaxError: invalid syntax

During handling of the above exception, another exception occurred:

Traceback (most recent call last):
  File "/home/runner/work/mlmodels/mlmodels/mlmodels/models.py", line 84, in module_load
    model_name = str(Path(model_uri).parts[-2]) + "." + str(model_name)
IndexError: tuple index out of range

During handling of the above exception, another exception occurred:

Traceback (most recent call last):
  File "/opt/hostedtoolcache/Python/3.6.11/x64/bin/ml_optim", line 11, in <module>
    load_entry_point('mlmodels', 'console_scripts', 'ml_optim')()
  File "/home/runner/work/mlmodels/mlmodels/mlmodels/optim.py", line 384, in main
    test_json( path_json="template/optim_config_prune.json", config_mode= arg.config_mode )
  File "/home/runner/work/mlmodels/mlmodels/mlmodels/optim.py", line 232, in test_json
    out_pars        = out_pars
  File "/home/runner/work/mlmodels/mlmodels/mlmodels/optim.py", line 57, in optim
    out_pars)
  File "/home/runner/work/mlmodels/mlmodels/mlmodels/optim.py", line 117, in optim_optuna
    module = module_load(model_uri)
  File "/home/runner/work/mlmodels/mlmodels/mlmodels/models.py", line 89, in module_load
    raise NameError(f"Module {model_name} notfound, {e1}, {e2}")
NameError: Module model_tf notfound, invalid syntax (1_lstm.py, line 38), tuple index out of range
