## Original File URL: https://github.com/arita37/mlmodels_store/blob/master/log_jupyter/log_jupyter.py


### Error 1, [Traceback at line 44](https://github.com/arita37/mlmodels_store/blob/master/log_jupyter/log_jupyter.py#L44)<br />44..[0;31mModuleNotFoundError[0m                       Traceback (most recent call last)
<br />[0;32m~/work/mlmodels/mlmodels/mlmodels/models.py[0m in [0;36mmodule_load[0;34m(model_uri, verbose, env_build)[0m
<br />[1;32m     71[0m         [0mmodel_name[0m [0;34m=[0m [0mmodel_uri[0m[0;34m.[0m[0mreplace[0m[0;34m([0m[0;34m".py"[0m[0;34m,[0m [0;34m""[0m[0;34m)[0m[0;34m[0m[0;34m[0m[0m
<br />[0;32m---> 72[0;31m         [0mmodule[0m [0;34m=[0m [0mimport_module[0m[0;34m([0m[0;34mf"mlmodels.{model_name}"[0m[0;34m)[0m[0;34m[0m[0;34m[0m[0m
<br />[0m[1;32m     73[0m         [0;31m# module    = import_module("mlmodels.model_tf.1_lstm")[0m[0;34m[0m[0;34m[0m[0;34m[0m[0m
<br />
<br />[0;32m/opt/hostedtoolcache/Python/3.6.10/x64/lib/python3.6/importlib/__init__.py[0m in [0;36mimport_module[0;34m(name, package)[0m
<br />[1;32m    125[0m             [0mlevel[0m [0;34m+=[0m [0;36m1[0m[0;34m[0m[0;34m[0m[0m
<br />[0;32m--> 126[0;31m     [0;32mreturn[0m [0m_bootstrap[0m[0;34m.[0m[0m_gcd_import[0m[0;34m([0m[0mname[0m[0;34m[[0m[0mlevel[0m[0;34m:[0m[0;34m][0m[0;34m,[0m [0mpackage[0m[0;34m,[0m [0mlevel[0m[0;34m)[0m[0;34m[0m[0;34m[0m[0m
<br />[0m[1;32m    127[0m [0;34m[0m[0m
<br />
<br />[0;32m/opt/hostedtoolcache/Python/3.6.10/x64/lib/python3.6/importlib/_bootstrap.py[0m in [0;36m_gcd_import[0;34m(name, package, level)[0m
<br />
<br />[0;32m/opt/hostedtoolcache/Python/3.6.10/x64/lib/python3.6/importlib/_bootstrap.py[0m in [0;36m_find_and_load[0;34m(name, import_)[0m
<br />
<br />[0;32m/opt/hostedtoolcache/Python/3.6.10/x64/lib/python3.6/importlib/_bootstrap.py[0m in [0;36m_find_and_load_unlocked[0;34m(name, import_)[0m
<br />
<br />[0;31mModuleNotFoundError[0m: No module named 'mlmodels.model_sklearn.sklearn'
<br />
<br />During handling of the above exception, another exception occurred:
<br />



### Error 2, [Traceback at line 65](https://github.com/arita37/mlmodels_store/blob/master/log_jupyter/log_jupyter.py#L65)<br />65..[0;31mIndexError[0m                                Traceback (most recent call last)
<br />[0;32m~/work/mlmodels/mlmodels/mlmodels/models.py[0m in [0;36mmodule_load[0;34m(model_uri, verbose, env_build)[0m
<br />[1;32m     83[0m             [0mmodel_name[0m [0;34m=[0m [0mPath[0m[0;34m([0m[0mmodel_uri[0m[0;34m)[0m[0;34m.[0m[0mstem[0m  [0;31m# remove .py[0m[0;34m[0m[0;34m[0m[0m
<br />[0;32m---> 84[0;31m             [0mmodel_name[0m [0;34m=[0m [0mstr[0m[0;34m([0m[0mPath[0m[0;34m([0m[0mmodel_uri[0m[0;34m)[0m[0;34m.[0m[0mparts[0m[0;34m[[0m[0;34m-[0m[0;36m2[0m[0;34m][0m[0;34m)[0m [0;34m+[0m [0;34m"."[0m [0;34m+[0m [0mstr[0m[0;34m([0m[0mmodel_name[0m[0;34m)[0m[0;34m[0m[0;34m[0m[0m
<br />[0m[1;32m     85[0m             [0;31m# print(model_name)[0m[0;34m[0m[0;34m[0m[0;34m[0m[0m
<br />
<br />[0;31mIndexError[0m: tuple index out of range
<br />
<br />During handling of the above exception, another exception occurred:
<br />



### Error 3, [Traceback at line 75](https://github.com/arita37/mlmodels_store/blob/master/log_jupyter/log_jupyter.py#L75)<br />75..[0;31mNameError[0m                                 Traceback (most recent call last)
<br />[0;32m~/work/mlmodels/mlmodels/mlmodels/example//sklearn_titanic_svm.ipynb[0m in [0;36m<module>[0;34m[0m
<br />[1;32m      3[0m [0;34m[0m[0m
<br />[1;32m      4[0m [0mmodel_uri[0m    [0;34m=[0m [0;34m"model_sklearn.sklearn.py"[0m[0;34m[0m[0;34m[0m[0m
<br />[0;32m----> 5[0;31m [0mmodule[0m        [0;34m=[0m  [0mmodule_load[0m[0;34m([0m [0mmodel_uri[0m[0;34m=[0m [0mmodel_uri[0m [0;34m)[0m                           [0;31m# Load file definition[0m[0;34m[0m[0;34m[0m[0m
<br />[0m[1;32m      6[0m [0;34m[0m[0m
<br />[1;32m      7[0m model_pars, data_pars, compute_pars, out_pars = module.get_params(param_pars={
<br />
<br />[0;32m~/work/mlmodels/mlmodels/mlmodels/models.py[0m in [0;36mmodule_load[0;34m(model_uri, verbose, env_build)[0m
<br />[1;32m     87[0m [0;34m[0m[0m
<br />[1;32m     88[0m         [0;32mexcept[0m [0mException[0m [0;32mas[0m [0me2[0m[0;34m:[0m[0;34m[0m[0;34m[0m[0m
<br />[0;32m---> 89[0;31m             [0;32mraise[0m [0mNameError[0m[0;34m([0m[0;34mf"Module {model_name} notfound, {e1}, {e2}"[0m[0;34m)[0m[0;34m[0m[0;34m[0m[0m
<br />[0m[1;32m     90[0m [0;34m[0m[0m
<br />[1;32m     91[0m     [0;32mif[0m [0mverbose[0m[0;34m:[0m [0mprint[0m[0;34m([0m[0mmodule[0m[0;34m)[0m[0;34m[0m[0;34m[0m[0m
<br />
<br />[0;31mNameError[0m: Module model_sklearn.sklearn notfound, No module named 'mlmodels.model_sklearn.sklearn', tuple index out of range
<br />
<br />
<br />
<br />
<br />
<br /> ************************************************************************************************************************
<br />ipython https://github.com/arita37/mlmodels/blob/dev/mlmodels/example//sklearn_titanic_randomForest_example2.ipynb 
<br />
<br />Deprecaton set to False
<br />[0;31m---------------------------------------------------------------------------[0m



### Error 4, [Traceback at line 101](https://github.com/arita37/mlmodels_store/blob/master/log_jupyter/log_jupyter.py#L101)<br />101..[0;31mFileNotFoundError[0m                         Traceback (most recent call last)
<br />[0;32m~/work/mlmodels/mlmodels/mlmodels/example//sklearn_titanic_randomForest_example2.ipynb[0m in [0;36m<module>[0;34m[0m
<br />[1;32m      3[0m [0;32mimport[0m [0mjson[0m[0;34m[0m[0;34m[0m[0m
<br />[1;32m      4[0m [0mdata_path[0m [0;34m=[0m [0;34m'../mlmodels/dataset/json/hyper_titanic_randomForest.json'[0m[0;34m[0m[0;34m[0m[0m
<br />[0;32m----> 5[0;31m [0mpars[0m [0;34m=[0m [0mjson[0m[0;34m.[0m[0mload[0m[0;34m([0m[0mopen[0m[0;34m([0m [0mdata_path[0m [0;34m,[0m [0mmode[0m[0;34m=[0m[0;34m'r'[0m[0;34m)[0m[0;34m)[0m[0;34m[0m[0;34m[0m[0m
<br />[0m[1;32m      6[0m [0;32mfor[0m [0mkey[0m[0;34m,[0m [0mpdict[0m [0;32min[0m  [0mpars[0m[0;34m.[0m[0mitems[0m[0;34m([0m[0;34m)[0m [0;34m:[0m[0;34m[0m[0;34m[0m[0m
<br />[1;32m      7[0m   [0mglobals[0m[0;34m([0m[0;34m)[0m[0;34m[[0m[0mkey[0m[0;34m][0m [0;34m=[0m [0mpdict[0m[0;34m[0m[0;34m[0m[0m
<br />
<br />[0;31mFileNotFoundError[0m: [Errno 2] No such file or directory: '../mlmodels/dataset/json/hyper_titanic_randomForest.json'
<br />
<br />
<br />
<br />
<br />
<br /> ************************************************************************************************************************
<br />ipython https://github.com/arita37/mlmodels/blob/dev/mlmodels/example//gluon_automl_titanic.ipynb 
<br />
<br />[0;31m---------------------------------------------------------------------------[0m



### Error 5, [Traceback at line 119](https://github.com/arita37/mlmodels_store/blob/master/log_jupyter/log_jupyter.py#L119)<br />119..[0;31mFileNotFoundError[0m                         Traceback (most recent call last)
<br />[0;32m~/work/mlmodels/mlmodels/mlmodels/example//gluon_automl_titanic.ipynb[0m in [0;36m<module>[0;34m[0m
<br />[1;32m      8[0m     [0mchoice[0m[0;34m=[0m[0;34m'json'[0m[0;34m,[0m[0;34m[0m[0;34m[0m[0m
<br />[1;32m      9[0m     [0mconfig_mode[0m[0;34m=[0m [0;34m'test'[0m[0;34m,[0m[0;34m[0m[0;34m[0m[0m
<br />[0;32m---> 10[0;31m     [0mdata_path[0m[0;34m=[0m [0;34m'../mlmodels/dataset/json/gluon_automl.json'[0m[0;34m[0m[0;34m[0m[0m
<br />[0m[1;32m     11[0m )
<br />
<br />[0;32m~/work/mlmodels/mlmodels/mlmodels/model_gluon/gluon_automl.py[0m in [0;36mget_params[0;34m(choice, data_path, config_mode, **kw)[0m
<br />[1;32m     80[0m             __file__)).parent.parent / "model_gluon/gluon_automl.json" if data_path == "dataset/" else data_path
<br />[1;32m     81[0m [0;34m[0m[0m
<br />[0;32m---> 82[0;31m         [0;32mwith[0m [0mopen[0m[0;34m([0m[0mdata_path[0m[0;34m,[0m [0mencoding[0m[0;34m=[0m[0;34m'utf-8'[0m[0;34m)[0m [0;32mas[0m [0mconfig_f[0m[0;34m:[0m[0;34m[0m[0;34m[0m[0m
<br />[0m[1;32m     83[0m             [0mconfig[0m [0;34m=[0m [0mjson[0m[0;34m.[0m[0mload[0m[0;34m([0m[0mconfig_f[0m[0;34m)[0m[0;34m[0m[0;34m[0m[0m
<br />[1;32m     84[0m             [0mconfig[0m [0;34m=[0m [0mconfig[0m[0;34m[[0m[0mconfig_mode[0m[0;34m][0m[0;34m[0m[0;34m[0m[0m
<br />
<br />[0;31mFileNotFoundError[0m: [Errno 2] No such file or directory: '../mlmodels/dataset/json/gluon_automl.json'
<br />/opt/hostedtoolcache/Python/3.6.10/x64/lib/python3.6/site-packages/mxnet/optimizer/optimizer.py:167: UserWarning: WARNING: New optimizer gluonnlp.optimizer.lamb.LAMB is overriding existing optimizer mxnet.optimizer.optimizer.LAMB
<br />  Optimizer.opt_registry[name].__name__))
<br />
<br />
<br />
<br />
<br />
<br /> ************************************************************************************************************************
<br />ipython https://github.com/arita37/mlmodels/blob/dev/mlmodels/example//lightgbm_glass.ipynb 
<br />
<br />[0;31m---------------------------------------------------------------------------[0m



### Error 6, [Traceback at line 145](https://github.com/arita37/mlmodels_store/blob/master/log_jupyter/log_jupyter.py#L145)<br />145..[0;31mNameError[0m                                 Traceback (most recent call last)
<br />[0;32m~/work/mlmodels/mlmodels/mlmodels/example//lightgbm_glass.ipynb[0m in [0;36m<module>[0;34m[0m
<br />[1;32m      8[0m [0;32mimport[0m [0mjson[0m[0;34m[0m[0;34m[0m[0m
<br />[1;32m      9[0m [0;34m[0m[0m
<br />[0;32m---> 10[0;31m [0mprint[0m[0;34m([0m [0mos[0m[0;34m.[0m[0mgetcwd[0m[0;34m([0m[0;34m)[0m[0;34m)[0m[0;34m[0m[0;34m[0m[0m
<br />[0m
<br />[0;31mNameError[0m: name 'os' is not defined
<br />
<br />
<br />
<br />
<br />
<br /> ************************************************************************************************************************
<br />ipython https://github.com/arita37/mlmodels/blob/dev/mlmodels/example//lightgbm_home_retail.ipynb 
<br />
<br />Deprecaton set to False
<br />[0;31m---------------------------------------------------------------------------[0m



### Error 7, [Traceback at line 162](https://github.com/arita37/mlmodels_store/blob/master/log_jupyter/log_jupyter.py#L162)<br />162..[0;31mFileNotFoundError[0m                         Traceback (most recent call last)
<br />[0;32m~/work/mlmodels/mlmodels/mlmodels/example//lightgbm_home_retail.ipynb[0m in [0;36m<module>[0;34m[0m
<br />[1;32m      1[0m [0mdata_path[0m [0;34m=[0m [0;34m'hyper_lightgbm_home_retail.json'[0m[0;34m[0m[0;34m[0m[0m
<br />[1;32m      2[0m [0;34m[0m[0m
<br />[0;32m----> 3[0;31m [0mpars[0m [0;34m=[0m [0mjson[0m[0;34m.[0m[0mload[0m[0;34m([0m[0mopen[0m[0;34m([0m [0mdata_path[0m [0;34m,[0m [0mmode[0m[0;34m=[0m[0;34m'r'[0m[0;34m)[0m[0;34m)[0m[0;34m[0m[0;34m[0m[0m
<br />[0m[1;32m      4[0m [0;32mfor[0m [0mkey[0m[0;34m,[0m [0mpdict[0m [0;32min[0m  [0mpars[0m[0;34m.[0m[0mitems[0m[0;34m([0m[0;34m)[0m [0;34m:[0m[0;34m[0m[0;34m[0m[0m
<br />[1;32m      5[0m   [0mglobals[0m[0;34m([0m[0;34m)[0m[0;34m[[0m[0mkey[0m[0;34m][0m [0;34m=[0m [0mpdict[0m[0;34m[0m[0;34m[0m[0m
<br />
<br />[0;31mFileNotFoundError[0m: [Errno 2] No such file or directory: 'hyper_lightgbm_home_retail.json'
<br />
<br />
<br />
<br />
<br />
<br /> ************************************************************************************************************************
<br />ipython https://github.com/arita37/mlmodels/blob/dev/mlmodels/example//sklearn_titanic_randomForest.ipynb 
<br />
<br />[0;31m---------------------------------------------------------------------------[0m



### Error 8, [Traceback at line 180](https://github.com/arita37/mlmodels_store/blob/master/log_jupyter/log_jupyter.py#L180)<br />180..[0;31mModuleNotFoundError[0m                       Traceback (most recent call last)
<br />[0;32m~/work/mlmodels/mlmodels/mlmodels/models.py[0m in [0;36mmodule_load[0;34m(model_uri, verbose, env_build)[0m
<br />[1;32m     71[0m         [0mmodel_name[0m [0;34m=[0m [0mmodel_uri[0m[0;34m.[0m[0mreplace[0m[0;34m([0m[0;34m".py"[0m[0;34m,[0m [0;34m""[0m[0;34m)[0m[0;34m[0m[0;34m[0m[0m
<br />[0;32m---> 72[0;31m         [0mmodule[0m [0;34m=[0m [0mimport_module[0m[0;34m([0m[0;34mf"mlmodels.{model_name}"[0m[0;34m)[0m[0;34m[0m[0;34m[0m[0m
<br />[0m[1;32m     73[0m         [0;31m# module    = import_module("mlmodels.model_tf.1_lstm")[0m[0;34m[0m[0;34m[0m[0;34m[0m[0m
<br />
<br />[0;32m/opt/hostedtoolcache/Python/3.6.10/x64/lib/python3.6/importlib/__init__.py[0m in [0;36mimport_module[0;34m(name, package)[0m
<br />[1;32m    125[0m             [0mlevel[0m [0;34m+=[0m [0;36m1[0m[0;34m[0m[0;34m[0m[0m
<br />[0;32m--> 126[0;31m     [0;32mreturn[0m [0m_bootstrap[0m[0;34m.[0m[0m_gcd_import[0m[0;34m([0m[0mname[0m[0;34m[[0m[0mlevel[0m[0;34m:[0m[0;34m][0m[0;34m,[0m [0mpackage[0m[0;34m,[0m [0mlevel[0m[0;34m)[0m[0;34m[0m[0;34m[0m[0m
<br />[0m[1;32m    127[0m [0;34m[0m[0m
<br />
<br />[0;32m/opt/hostedtoolcache/Python/3.6.10/x64/lib/python3.6/importlib/_bootstrap.py[0m in [0;36m_gcd_import[0;34m(name, package, level)[0m
<br />
<br />[0;32m/opt/hostedtoolcache/Python/3.6.10/x64/lib/python3.6/importlib/_bootstrap.py[0m in [0;36m_find_and_load[0;34m(name, import_)[0m
<br />
<br />[0;32m/opt/hostedtoolcache/Python/3.6.10/x64/lib/python3.6/importlib/_bootstrap.py[0m in [0;36m_find_and_load_unlocked[0;34m(name, import_)[0m
<br />
<br />[0;31mModuleNotFoundError[0m: No module named 'mlmodels.model_sklearn.sklearn'
<br />
<br />During handling of the above exception, another exception occurred:
<br />



### Error 9, [Traceback at line 201](https://github.com/arita37/mlmodels_store/blob/master/log_jupyter/log_jupyter.py#L201)<br />201..[0;31mIndexError[0m                                Traceback (most recent call last)
<br />[0;32m~/work/mlmodels/mlmodels/mlmodels/models.py[0m in [0;36mmodule_load[0;34m(model_uri, verbose, env_build)[0m
<br />[1;32m     83[0m             [0mmodel_name[0m [0;34m=[0m [0mPath[0m[0;34m([0m[0mmodel_uri[0m[0;34m)[0m[0;34m.[0m[0mstem[0m  [0;31m# remove .py[0m[0;34m[0m[0;34m[0m[0m
<br />[0;32m---> 84[0;31m             [0mmodel_name[0m [0;34m=[0m [0mstr[0m[0;34m([0m[0mPath[0m[0;34m([0m[0mmodel_uri[0m[0;34m)[0m[0;34m.[0m[0mparts[0m[0;34m[[0m[0;34m-[0m[0;36m2[0m[0;34m][0m[0;34m)[0m [0;34m+[0m [0;34m"."[0m [0;34m+[0m [0mstr[0m[0;34m([0m[0mmodel_name[0m[0;34m)[0m[0;34m[0m[0;34m[0m[0m
<br />[0m[1;32m     85[0m             [0;31m# print(model_name)[0m[0;34m[0m[0;34m[0m[0;34m[0m[0m
<br />
<br />[0;31mIndexError[0m: tuple index out of range
<br />
<br />During handling of the above exception, another exception occurred:
<br />



### Error 10, [Traceback at line 211](https://github.com/arita37/mlmodels_store/blob/master/log_jupyter/log_jupyter.py#L211)<br />211..[0;31mNameError[0m                                 Traceback (most recent call last)
<br />[0;32m~/work/mlmodels/mlmodels/mlmodels/example//sklearn_titanic_randomForest.ipynb[0m in [0;36m<module>[0;34m[0m
<br />[1;32m      2[0m [0;34m[0m[0m
<br />[1;32m      3[0m [0mmodel_uri[0m    [0;34m=[0m [0;34m"model_sklearn.sklearn.py"[0m[0;34m[0m[0;34m[0m[0m
<br />[0;32m----> 4[0;31m [0mmodule[0m        [0;34m=[0m  [0mmodule_load[0m[0;34m([0m [0mmodel_uri[0m[0;34m=[0m [0mmodel_uri[0m [0;34m)[0m                           [0;31m# Load file definition[0m[0;34m[0m[0;34m[0m[0m
<br />[0m[1;32m      5[0m [0;34m[0m[0m
<br />[1;32m      6[0m model_pars, data_pars, compute_pars, out_pars = module.get_params(param_pars={
<br />
<br />[0;32m~/work/mlmodels/mlmodels/mlmodels/models.py[0m in [0;36mmodule_load[0;34m(model_uri, verbose, env_build)[0m
<br />[1;32m     87[0m [0;34m[0m[0m
<br />[1;32m     88[0m         [0;32mexcept[0m [0mException[0m [0;32mas[0m [0me2[0m[0;34m:[0m[0;34m[0m[0;34m[0m[0m
<br />[0;32m---> 89[0;31m             [0;32mraise[0m [0mNameError[0m[0;34m([0m[0;34mf"Module {model_name} notfound, {e1}, {e2}"[0m[0;34m)[0m[0;34m[0m[0;34m[0m[0m
<br />[0m[1;32m     90[0m [0;34m[0m[0m
<br />[1;32m     91[0m     [0;32mif[0m [0mverbose[0m[0;34m:[0m [0mprint[0m[0;34m([0m[0mmodule[0m[0;34m)[0m[0;34m[0m[0;34m[0m[0m
<br />
<br />[0;31mNameError[0m: Module model_sklearn.sklearn notfound, No module named 'mlmodels.model_sklearn.sklearn', tuple index out of range
<br />
<br />
<br />
<br />
<br />
<br /> ************************************************************************************************************************
<br />ipython https://github.com/arita37/mlmodels/blob/dev/mlmodels/example//mnist_mlmodels_.ipynb 
<br />
<br />[0;31m---------------------------------------------------------------------------[0m



### Error 11, [Traceback at line 236](https://github.com/arita37/mlmodels_store/blob/master/log_jupyter/log_jupyter.py#L236)<br />236..[0;31mModuleNotFoundError[0m                       Traceback (most recent call last)
<br />[0;32m~/work/mlmodels/mlmodels/mlmodels/example//mnist_mlmodels_.ipynb[0m in [0;36m<module>[0;34m[0m
<br />[0;32m----> 1[0;31m [0;32mfrom[0m [0mgoogle[0m[0;34m.[0m[0mcolab[0m [0;32mimport[0m [0mdrive[0m[0;34m[0m[0;34m[0m[0m
<br />[0m[1;32m      2[0m [0mdrive[0m[0;34m.[0m[0mmount[0m[0;34m([0m[0;34m'/content/drive'[0m[0;34m)[0m[0;34m[0m[0;34m[0m[0m
<br />
<br />[0;31mModuleNotFoundError[0m: No module named 'google.colab'
<br />
<br />
<br />
<br />
<br />
<br /> ************************************************************************************************************************
<br />ipython https://github.com/arita37/mlmodels/blob/dev/mlmodels/example//fashion_MNIST_mlmodels.ipynb 
<br />
<br />[0;31m---------------------------------------------------------------------------[0m



### Error 12, [Traceback at line 251](https://github.com/arita37/mlmodels_store/blob/master/log_jupyter/log_jupyter.py#L251)<br />251..[0;31mModuleNotFoundError[0m                       Traceback (most recent call last)
<br />[0;32m~/work/mlmodels/mlmodels/mlmodels/example//fashion_MNIST_mlmodels.ipynb[0m in [0;36m<module>[0;34m[0m
<br />[0;32m----> 1[0;31m [0;32mfrom[0m [0mgoogle[0m[0;34m.[0m[0mcolab[0m [0;32mimport[0m [0mdrive[0m[0;34m[0m[0;34m[0m[0m
<br />[0m[1;32m      2[0m [0mdrive[0m[0;34m.[0m[0mmount[0m[0;34m([0m[0;34m'/content/drive'[0m[0;34m)[0m[0;34m[0m[0;34m[0m[0m
<br />
<br />[0;31mModuleNotFoundError[0m: No module named 'google.colab'
<br />
<br />
<br />
<br />
<br />
<br /> ************************************************************************************************************************
<br />ipython https://github.com/arita37/mlmodels/blob/dev/mlmodels/example//tensorflow__lstm_json.ipynb 
<br />
<br />[0;31m---------------------------------------------------------------------------[0m



### Error 13, [Traceback at line 266](https://github.com/arita37/mlmodels_store/blob/master/log_jupyter/log_jupyter.py#L266)<br />266..[0;31mNameError[0m                                 Traceback (most recent call last)
<br />[0;32m~/work/mlmodels/mlmodels/mlmodels/example//tensorflow__lstm_json.ipynb[0m in [0;36m<module>[0;34m[0m
<br />[1;32m      5[0m [0;32mimport[0m [0mjson[0m[0;34m[0m[0;34m[0m[0m
<br />[1;32m      6[0m [0;34m[0m[0m
<br />[0;32m----> 7[0;31m [0mprint[0m[0;34m([0m [0mos[0m[0;34m.[0m[0mgetcwd[0m[0;34m([0m[0;34m)[0m[0;34m)[0m[0;34m[0m[0;34m[0m[0m
<br />[0m
<br />[0;31mNameError[0m: name 'os' is not defined
<br />
<br />
<br />
<br />
<br />
<br /> ************************************************************************************************************************
<br />ipython https://github.com/arita37/mlmodels/blob/dev/mlmodels/example//lightgbm_titanic.ipynb 
<br />
<br />Deprecaton set to False
<br />[0;31m---------------------------------------------------------------------------[0m



### Error 14, [Traceback at line 283](https://github.com/arita37/mlmodels_store/blob/master/log_jupyter/log_jupyter.py#L283)<br />283..[0;31mFileNotFoundError[0m                         Traceback (most recent call last)
<br />[0;32m~/work/mlmodels/mlmodels/mlmodels/example//lightgbm_titanic.ipynb[0m in [0;36m<module>[0;34m[0m
<br />[1;32m      1[0m [0mdata_path[0m [0;34m=[0m [0;34m'hyper_lightgbm_titanic.json'[0m[0;34m[0m[0;34m[0m[0m
<br />[1;32m      2[0m [0;34m[0m[0m
<br />[0;32m----> 3[0;31m [0mpars[0m [0;34m=[0m [0mjson[0m[0;34m.[0m[0mload[0m[0;34m([0m[0mopen[0m[0;34m([0m [0mdata_path[0m [0;34m,[0m [0mmode[0m[0;34m=[0m[0;34m'r'[0m[0;34m)[0m[0;34m)[0m[0;34m[0m[0;34m[0m[0m
<br />[0m[1;32m      4[0m [0;32mfor[0m [0mkey[0m[0;34m,[0m [0mpdict[0m [0;32min[0m  [0mpars[0m[0;34m.[0m[0mitems[0m[0;34m([0m[0;34m)[0m [0;34m:[0m[0;34m[0m[0;34m[0m[0m
<br />[1;32m      5[0m   [0mglobals[0m[0;34m([0m[0;34m)[0m[0;34m[[0m[0mkey[0m[0;34m][0m [0;34m=[0m [0mpdict[0m[0;34m[0m[0;34m[0m[0m
<br />
<br />[0;31mFileNotFoundError[0m: [Errno 2] No such file or directory: 'hyper_lightgbm_titanic.json'
<br />
<br />
<br />
<br />
<br />
<br /> ************************************************************************************************************************
<br />ipython https://github.com/arita37/mlmodels/blob/dev/mlmodels/example//keras_charcnn_reuters.ipynb 
<br />
<br />[0;31m---------------------------------------------------------------------------[0m



### Error 15, [Traceback at line 301](https://github.com/arita37/mlmodels_store/blob/master/log_jupyter/log_jupyter.py#L301)<br />301..[0;31mFileNotFoundError[0m                         Traceback (most recent call last)
<br />[0;32m~/work/mlmodels/mlmodels/mlmodels/example//keras_charcnn_reuters.ipynb[0m in [0;36m<module>[0;34m[0m
<br />[0;32m----> 1[0;31m [0mpars[0m [0;34m=[0m [0mjson[0m[0;34m.[0m[0mload[0m[0;34m([0m[0mopen[0m[0;34m([0m [0mconfig_path[0m [0;34m,[0m [0mmode[0m[0;34m=[0m[0;34m'r'[0m[0;34m)[0m[0;34m)[0m[0;34m[[0m[0mconfig_mode[0m[0;34m][0m[0;34m[0m[0;34m[0m[0m
<br />[0m[1;32m      2[0m [0mmodel_pars[0m      [0;34m=[0m [0mpath_norm_dict[0m[0;34m([0m [0mpars[0m[0;34m[[0m[0;34m'model_pars'[0m[0;34m][0m [0;34m)[0m[0;34m[0m[0;34m[0m[0m
<br />[1;32m      3[0m [0mdata_pars[0m       [0;34m=[0m [0mpath_norm_dict[0m[0;34m([0m [0mpars[0m[0;34m[[0m[0;34m'data_pars'[0m[0;34m][0m [0;34m)[0m[0;34m[0m[0;34m[0m[0m
<br />[1;32m      4[0m [0mcompute_pars[0m    [0;34m=[0m [0mpath_norm_dict[0m[0;34m([0m [0mpars[0m[0;34m[[0m[0;34m'compute_pars'[0m[0;34m][0m [0;34m)[0m[0;34m[0m[0;34m[0m[0m
<br />[1;32m      5[0m [0mout_pars[0m        [0;34m=[0m [0mpath_norm_dict[0m[0;34m([0m [0mpars[0m[0;34m[[0m[0;34m'out_pars'[0m[0;34m][0m [0;34m)[0m[0;34m[0m[0;34m[0m[0m
<br />
<br />[0;31mFileNotFoundError[0m: [Errno 2] No such file or directory: 'reuters_charcnn.json'
<br />
<br />
<br />
<br />
<br />
<br /> ************************************************************************************************************************
<br />ipython https://github.com/arita37/mlmodels/blob/dev/mlmodels/example//tensorflow_1_lstm.ipynb 
<br />
<br />/home/runner/work/mlmodels/mlmodels
<br />{'data_path': 'https://github.com/arita37/mlmodels/tree/51b64e342c7b2661e79b8abaa33db92672ae95c7/mlmodels/dataset/timeseries/GOOG-year.csv', 'data_type': 'pandas', 'size': [0, 0, 6], 'output_size': [0, 6]}
<br />WARNING:tensorflow:From /opt/hostedtoolcache/Python/3.6.10/x64/lib/python3.6/site-packages/tensorflow_core/python/compat/v2_compat.py:68: disable_resource_variables (from tensorflow.python.ops.variable_scope) is deprecated and will be removed in a future version.
<br />Instructions for updating:
<br />non-resource variables are not supported in the long term
<br />{'data_path': 'https://github.com/arita37/mlmodels/tree/51b64e342c7b2661e79b8abaa33db92672ae95c7/mlmodels/dataset/timeseries/GOOG-year.csv', 'data_type': 'pandas', 'size': [0, 0, 6], 'output_size': [0, 6]}
<br />https://github.com/arita37/mlmodels/tree/51b64e342c7b2661e79b8abaa33db92672ae95c7/mlmodels/dataset/timeseries/GOOG-year.csv
<br />         Date        Open        High  ...       Close   Adj Close   Volume
<br />0  2016-11-02  778.200012  781.650024  ...  768.700012  768.700012  1872400
<br />1  2016-11-03  767.250000  769.950012  ...  762.130005  762.130005  1943200
<br />2  2016-11-04  750.659973  770.359985  ...  762.020020  762.020020  2134800
<br />3  2016-11-07  774.500000  785.190002  ...  782.520020  782.520020  1585100
<br />4  2016-11-08  783.400024  795.632996  ...  790.510010  790.510010  1350800
<br />
<br />[5 rows x 7 columns]
<br />          0         1         2         3         4         5
<br />0  0.706562  0.629914  0.682052  0.599302  0.599302  0.153665
<br />1  0.458824  0.320251  0.598101  0.478596  0.478596  0.174523
<br />2  0.083484  0.331101  0.437246  0.476576  0.476576  0.230969
<br />3  0.622851  0.723606  0.854891  0.853206  0.853206  0.069025
<br />4  0.824209  1.000000  1.000000  1.000000  1.000000  0.000000
<br />{'data_path': 'https://github.com/arita37/mlmodels/tree/51b64e342c7b2661e79b8abaa33db92672ae95c7/mlmodels/dataset/timeseries/GOOG-year.csv', 'data_type': 'pandas', 'size': [0, 0, 6], 'output_size': [0, 6]}
<br />https://github.com/arita37/mlmodels/tree/51b64e342c7b2661e79b8abaa33db92672ae95c7/mlmodels/dataset/timeseries/GOOG-year.csv
<br />         Date        Open        High  ...       Close   Adj Close   Volume
<br />0  2016-11-02  778.200012  781.650024  ...  768.700012  768.700012  1872400
<br />1  2016-11-03  767.250000  769.950012  ...  762.130005  762.130005  1943200
<br />2  2016-11-04  750.659973  770.359985  ...  762.020020  762.020020  2134800
<br />3  2016-11-07  774.500000  785.190002  ...  782.520020  782.520020  1585100
<br />4  2016-11-08  783.400024  795.632996  ...  790.510010  790.510010  1350800
<br />
<br />[5 rows x 7 columns]
<br />          0         1         2         3         4         5
<br />0  0.706562  0.629914  0.682052  0.599302  0.599302  0.153665
<br />1  0.458824  0.320251  0.598101  0.478596  0.478596  0.174523
<br />2  0.083484  0.331101  0.437246  0.476576  0.476576  0.230969
<br />3  0.622851  0.723606  0.854891  0.853206  0.853206  0.069025
<br />4  0.824209  1.000000  1.000000  1.000000  1.000000  0.000000
<br />5  0.745928  0.883387  0.838176  0.904464  0.904464  0.370110
<br />6  1.000000  0.881878  0.467996  0.486496  0.486496  1.000000
<br />7  0.216516  0.077549  0.433808  0.329598  0.329598  0.318466
<br />8  0.195249  0.000000  0.000000  0.000000  0.000000  0.671960
<br />9  0.000000  0.173783  0.369041  0.411721  0.411721  0.304384
<br />test
<br />
<br />  #### Module init   ############################################ 
<br />WARNING:tensorflow:From /opt/hostedtoolcache/Python/3.6.10/x64/lib/python3.6/site-packages/tensorflow_core/python/compat/v2_compat.py:68: disable_resource_variables (from tensorflow.python.ops.variable_scope) is deprecated and will be removed in a future version.
<br />Instructions for updating:
<br />non-resource variables are not supported in the long term
<br />
<br />  <module 'mlmodels.model_tf.1_lstm' from 'https://github.com/arita37/mlmodels/tree/51b64e342c7b2661e79b8abaa33db92672ae95c7/mlmodels/model_tf/1_lstm.py'> 
<br />
<br />  #### Loading params   ############################################## 
<br />
<br />  ############# Data, Params preparation   ################# 
<br />
<br />  #### Model init   ############################################ 
<br />
<br />  <mlmodels.model_tf.1_lstm.Model object at 0x7f7bc400e978> 
<br />
<br />  #### Fit   ######################################################## 
<br />{'data_path': 'https://github.com/arita37/mlmodels/tree/51b64e342c7b2661e79b8abaa33db92672ae95c7/mlmodels/dataset/timeseries/GOOG-year.csv', 'data_type': 'pandas'}
<br />https://github.com/arita37/mlmodels/tree/51b64e342c7b2661e79b8abaa33db92672ae95c7/mlmodels/dataset/timeseries/GOOG-year.csv
<br />         Date        Open        High  ...       Close   Adj Close   Volume
<br />0  2016-11-02  778.200012  781.650024  ...  768.700012  768.700012  1872400
<br />1  2016-11-03  767.250000  769.950012  ...  762.130005  762.130005  1943200
<br />2  2016-11-04  750.659973  770.359985  ...  762.020020  762.020020  2134800
<br />3  2016-11-07  774.500000  785.190002  ...  782.520020  782.520020  1585100
<br />4  2016-11-08  783.400024  795.632996  ...  790.510010  790.510010  1350800
<br />
<br />[5 rows x 7 columns]
<br />          0         1         2         3         4         5
<br />0  0.706562  0.629914  0.682052  0.599302  0.599302  0.153665
<br />1  0.458824  0.320251  0.598101  0.478596  0.478596  0.174523
<br />2  0.083484  0.331101  0.437246  0.476576  0.476576  0.230969
<br />3  0.622851  0.723606  0.854891  0.853206  0.853206  0.069025
<br />4  0.824209  1.000000  1.000000  1.000000  1.000000  0.000000
<br />
<br />  #### Predict   #################################################### 
<br />{'data_path': 'https://github.com/arita37/mlmodels/tree/51b64e342c7b2661e79b8abaa33db92672ae95c7/mlmodels/dataset/timeseries/GOOG-year.csv', 'data_type': 'pandas'}
<br />https://github.com/arita37/mlmodels/tree/51b64e342c7b2661e79b8abaa33db92672ae95c7/mlmodels/dataset/timeseries/GOOG-year.csv
<br />         Date        Open        High  ...       Close   Adj Close   Volume
<br />0  2016-11-02  778.200012  781.650024  ...  768.700012  768.700012  1872400
<br />1  2016-11-03  767.250000  769.950012  ...  762.130005  762.130005  1943200
<br />2  2016-11-04  750.659973  770.359985  ...  762.020020  762.020020  2134800
<br />3  2016-11-07  774.500000  785.190002  ...  782.520020  782.520020  1585100
<br />4  2016-11-08  783.400024  795.632996  ...  790.510010  790.510010  1350800
<br />
<br />[5 rows x 7 columns]
<br />          0         1         2         3         4         5
<br />0  0.706562  0.629914  0.682052  0.599302  0.599302  0.153665
<br />1  0.458824  0.320251  0.598101  0.478596  0.478596  0.174523
<br />2  0.083484  0.331101  0.437246  0.476576  0.476576  0.230969
<br />3  0.622851  0.723606  0.854891  0.853206  0.853206  0.069025
<br />4  0.824209  1.000000  1.000000  1.000000  1.000000  0.000000
<br />5  0.745928  0.883387  0.838176  0.904464  0.904464  0.370110
<br />6  1.000000  0.881878  0.467996  0.486496  0.486496  1.000000
<br />7  0.216516  0.077549  0.433808  0.329598  0.329598  0.318466
<br />8  0.195249  0.000000  0.000000  0.000000  0.000000  0.671960
<br />9  0.000000  0.173783  0.369041  0.411721  0.411721  0.304384
<br />[[ 0.          0.          0.          0.          0.          0.        ]
<br /> [ 0.08123612  0.10678238 -0.13828902 -0.02387247 -0.09859572  0.07707776]
<br /> [-0.07677779 -0.29342708  0.00329654  0.127727   -0.12296977 -0.0536702 ]
<br /> [-0.12737514  0.33139446 -0.03929861 -0.13191609 -0.05625334  0.10951345]
<br /> [ 0.41307169  0.209218   -0.20678246 -0.15634294  0.12702893 -0.41774842]
<br /> [ 0.6271227  -0.36628574  0.23482159  0.09714145  0.58740789  0.09225899]
<br /> [ 0.54374141  0.27758351  0.07459636  0.44349837  0.10139409  0.26735377]
<br /> [ 0.96486115  0.15298501  0.52940637  0.72561699  0.22422807  0.9253003 ]
<br /> [ 0.24945585  0.40206471  0.06991131  0.18550409  0.12455186  0.08255732]
<br /> [ 0.          0.          0.          0.          0.          0.        ]]
<br />
<br />  #### Get  metrics   ################################################ 
<br />
<br />  #### Save   ######################################################## 
<br />
<br />  #### Load   ######################################################## 
<br />model_tf/1_lstm.py
<br />model_tf.1_lstm.py
<br /><module 'mlmodels.model_tf.1_lstm' from 'https://github.com/arita37/mlmodels/tree/51b64e342c7b2661e79b8abaa33db92672ae95c7/mlmodels/model_tf/1_lstm.py'>
<br /><module 'mlmodels.model_tf.1_lstm' from 'https://github.com/arita37/mlmodels/tree/51b64e342c7b2661e79b8abaa33db92672ae95c7/mlmodels/model_tf/1_lstm.py'>
<br />
<br />  #### Loading params   ############################################## 
<br />
<br />  ############# Data, Params preparation   ################# 
<br />
<br />  {'learning_rate': 0.001, 'num_layers': 1, 'size': 6, 'size_layer': 128, 'timestep': 4, 'epoch': 2, 'output_size': 6} {'data_path': 'https://github.com/arita37/mlmodels/tree/51b64e342c7b2661e79b8abaa33db92672ae95c7/mlmodels/dataset/timeseries/GOOG-year.csv', 'data_type': 'pandas'} {} {'path': 'https://github.com/arita37/mlmodels/tree/51b64e342c7b2661e79b8abaa33db92672ae95c7/mlmodels/ztest/model_tf/1_lstm/', 'model_path': 'https://github.com/arita37/mlmodels/tree/51b64e342c7b2661e79b8abaa33db92672ae95c7/mlmodels/ztest/model_tf/1_lstm/model'} 
<br />
<br />  #### Loading dataset   ############################################# 
<br />{'data_path': 'https://github.com/arita37/mlmodels/tree/51b64e342c7b2661e79b8abaa33db92672ae95c7/mlmodels/dataset/timeseries/GOOG-year.csv', 'data_type': 'pandas'}
<br />https://github.com/arita37/mlmodels/tree/51b64e342c7b2661e79b8abaa33db92672ae95c7/mlmodels/dataset/timeseries/GOOG-year.csv
<br />         Date        Open        High  ...       Close   Adj Close   Volume
<br />0  2016-11-02  778.200012  781.650024  ...  768.700012  768.700012  1872400
<br />1  2016-11-03  767.250000  769.950012  ...  762.130005  762.130005  1943200
<br />2  2016-11-04  750.659973  770.359985  ...  762.020020  762.020020  2134800
<br />3  2016-11-07  774.500000  785.190002  ...  782.520020  782.520020  1585100
<br />4  2016-11-08  783.400024  795.632996  ...  790.510010  790.510010  1350800
<br />
<br />[5 rows x 7 columns]
<br />
<br />  #### Model init  ############################################# 
<br />
<br />  #### Model fit   ############################################# 
<br />{'data_path': 'https://github.com/arita37/mlmodels/tree/51b64e342c7b2661e79b8abaa33db92672ae95c7/mlmodels/dataset/timeseries/GOOG-year.csv', 'data_type': 'pandas'}
<br />https://github.com/arita37/mlmodels/tree/51b64e342c7b2661e79b8abaa33db92672ae95c7/mlmodels/dataset/timeseries/GOOG-year.csv
<br />         Date        Open        High  ...       Close   Adj Close   Volume
<br />0  2016-11-02  778.200012  781.650024  ...  768.700012  768.700012  1872400
<br />1  2016-11-03  767.250000  769.950012  ...  762.130005  762.130005  1943200
<br />2  2016-11-04  750.659973  770.359985  ...  762.020020  762.020020  2134800
<br />3  2016-11-07  774.500000  785.190002  ...  782.520020  782.520020  1585100
<br />4  2016-11-08  783.400024  795.632996  ...  790.510010  790.510010  1350800
<br />
<br />[5 rows x 7 columns]
<br />          0         1         2         3         4         5
<br />0  0.706562  0.629914  0.682052  0.599302  0.599302  0.153665
<br />1  0.458824  0.320251  0.598101  0.478596  0.478596  0.174523
<br />2  0.083484  0.331101  0.437246  0.476576  0.476576  0.230969
<br />3  0.622851  0.723606  0.854891  0.853206  0.853206  0.069025
<br />4  0.824209  1.000000  1.000000  1.000000  1.000000  0.000000
<br />
<br />  #### Predict   ##################################################### 
<br />{'data_path': 'https://github.com/arita37/mlmodels/tree/51b64e342c7b2661e79b8abaa33db92672ae95c7/mlmodels/dataset/timeseries/GOOG-year.csv', 'data_type': 'pandas', 'train': 0}
<br />https://github.com/arita37/mlmodels/tree/51b64e342c7b2661e79b8abaa33db92672ae95c7/mlmodels/dataset/timeseries/GOOG-year.csv
<br />         Date        Open        High  ...       Close   Adj Close   Volume
<br />0  2016-11-02  778.200012  781.650024  ...  768.700012  768.700012  1872400
<br />1  2016-11-03  767.250000  769.950012  ...  762.130005  762.130005  1943200
<br />2  2016-11-04  750.659973  770.359985  ...  762.020020  762.020020  2134800
<br />3  2016-11-07  774.500000  785.190002  ...  782.520020  782.520020  1585100
<br />4  2016-11-08  783.400024  795.632996  ...  790.510010  790.510010  1350800
<br />
<br />[5 rows x 7 columns]
<br />          0         1         2         3         4         5
<br />0  0.706562  0.629914  0.682052  0.599302  0.599302  0.153665
<br />1  0.458824  0.320251  0.598101  0.478596  0.478596  0.174523
<br />2  0.083484  0.331101  0.437246  0.476576  0.476576  0.230969
<br />3  0.622851  0.723606  0.854891  0.853206  0.853206  0.069025
<br />4  0.824209  1.000000  1.000000  1.000000  1.000000  0.000000
<br />5  0.745928  0.883387  0.838176  0.904464  0.904464  0.370110
<br />6  1.000000  0.881878  0.467996  0.486496  0.486496  1.000000
<br />7  0.216516  0.077549  0.433808  0.329598  0.329598  0.318466
<br />8  0.195249  0.000000  0.000000  0.000000  0.000000  0.671960
<br />9  0.000000  0.173783  0.369041  0.411721  0.411721  0.304384
<br />
<br />  #### metrics   ##################################################### 
<br />{'loss': 0.5492658987641335, 'loss_history': []}
<br />
<br />  #### Plot   ######################################################## 
<br />
<br />  #### Save   ######################################################## 
<br />{'path': 'https://github.com/arita37/mlmodels/tree/51b64e342c7b2661e79b8abaa33db92672ae95c7/mlmodels/ztest/model_tf/1_lstm/'}
<br />Model saved in path: https://github.com/arita37/mlmodels/tree/51b64e342c7b2661e79b8abaa33db92672ae95c7/mlmodels/ztest/model_tf/1_lstm//model//model.ckpt
<br />
<br />  #### Load   ######################################################## 
<br />2020-05-22 00:21:48.859377: W tensorflow/core/framework/op_kernel.cc:1651] OP_REQUIRES failed at save_restore_v2_ops.cc:184 : Not found: Key Variable not found in checkpoint
<br />{'path': 'https://github.com/arita37/mlmodels/tree/51b64e342c7b2661e79b8abaa33db92672ae95c7/mlmodels/ztest/model_tf/1_lstm/', 'model_path': 'https://github.com/arita37/mlmodels/tree/51b64e342c7b2661e79b8abaa33db92672ae95c7/mlmodels/ztest/model_tf/1_lstm/model'}
<br />Failed Restoring from checkpoint failed. This is most likely due to a Variable name or other graph key that is missing from the checkpoint. Please ensure that you have not altered the graph expected based on the checkpoint. Original error:
<br />
<br />Key Variable not found in checkpoint
<br />	 [[node save_1/RestoreV2 (defined at opt/hostedtoolcache/Python/3.6.10/x64/lib/python3.6/site-packages/tensorflow_core/python/framework/ops.py:1748) ]]
<br />
<br />Original stack trace for 'save_1/RestoreV2':
<br />  File "opt/hostedtoolcache/Python/3.6.10/x64/bin/ml_models", line 11, in <module>
<br />    load_entry_point('mlmodels', 'console_scripts', 'ml_models')()
<br />  File "home/runner/work/mlmodels/mlmodels/mlmodels/models.py", line 526, in main
<br />    test_cli(arg)
<br />  File "home/runner/work/mlmodels/mlmodels/mlmodels/models.py", line 458, in test_cli
<br />    test(arg.model_uri)  # '1_lstm'
<br />  File "home/runner/work/mlmodels/mlmodels/mlmodels/models.py", line 189, in test
<br />    module.test()
<br />  File "home/runner/work/mlmodels/mlmodels/mlmodels/model_tf/1_lstm.py", line 320, in test
<br />    session = load(out_pars)
<br />  File "home/runner/work/mlmodels/mlmodels/mlmodels/model_tf/1_lstm.py", line 199, in load
<br />    return load_tf(load_pars)
<br />  File "home/runner/work/mlmodels/mlmodels/mlmodels/util.py", line 474, in load_tf
<br />    saver      = tf.compat.v1.train.Saver()
<br />  File "opt/hostedtoolcache/Python/3.6.10/x64/lib/python3.6/site-packages/tensorflow_core/python/training/saver.py", line 828, in __init__
<br />    self.build()
<br />  File "opt/hostedtoolcache/Python/3.6.10/x64/lib/python3.6/site-packages/tensorflow_core/python/training/saver.py", line 840, in build
<br />    self._build(self._filename, build_save=True, build_restore=True)
<br />  File "opt/hostedtoolcache/Python/3.6.10/x64/lib/python3.6/site-packages/tensorflow_core/python/training/saver.py", line 878, in _build
<br />    build_restore=build_restore)
<br />  File "opt/hostedtoolcache/Python/3.6.10/x64/lib/python3.6/site-packages/tensorflow_core/python/training/saver.py", line 508, in _build_internal
<br />    restore_sequentially, reshape)
<br />  File "opt/hostedtoolcache/Python/3.6.10/x64/lib/python3.6/site-packages/tensorflow_core/python/training/saver.py", line 328, in _AddRestoreOps
<br />    restore_sequentially)
<br />  File "opt/hostedtoolcache/Python/3.6.10/x64/lib/python3.6/site-packages/tensorflow_core/python/training/saver.py", line 575, in bulk_restore
<br />    return io_ops.restore_v2(filename_tensor, names, slices, dtypes)
<br />  File "opt/hostedtoolcache/Python/3.6.10/x64/lib/python3.6/site-packages/tensorflow_core/python/ops/gen_io_ops.py", line 1696, in restore_v2
<br />    name=name)
<br />  File "opt/hostedtoolcache/Python/3.6.10/x64/lib/python3.6/site-packages/tensorflow_core/python/framework/op_def_library.py", line 794, in _apply_op_helper
<br />    op_def=op_def)
<br />  File "opt/hostedtoolcache/Python/3.6.10/x64/lib/python3.6/site-packages/tensorflow_core/python/util/deprecation.py", line 507, in new_func
<br />    return func(*args, **kwargs)
<br />  File "opt/hostedtoolcache/Python/3.6.10/x64/lib/python3.6/site-packages/tensorflow_core/python/framework/ops.py", line 3357, in create_op
<br />    attrs, op_def, compute_device)
<br />  File "opt/hostedtoolcache/Python/3.6.10/x64/lib/python3.6/site-packages/tensorflow_core/python/framework/ops.py", line 3426, in _create_op_internal
<br />    op_def=op_def)
<br />  File "opt/hostedtoolcache/Python/3.6.10/x64/lib/python3.6/site-packages/tensorflow_core/python/framework/ops.py", line 1748, in __init__
<br />    self._traceback = tf_stack.extract_stack()
<br />
<br />model_tf/1_lstm.py
<br />model_tf.1_lstm.py
<br /><module 'mlmodels.model_tf.1_lstm' from 'https://github.com/arita37/mlmodels/tree/51b64e342c7b2661e79b8abaa33db92672ae95c7/mlmodels/model_tf/1_lstm.py'>
<br /><module 'mlmodels.model_tf.1_lstm' from 'https://github.com/arita37/mlmodels/tree/51b64e342c7b2661e79b8abaa33db92672ae95c7/mlmodels/model_tf/1_lstm.py'>
<br />
<br />  #### Loading params   ############################################## 
<br />
<br />  ############# Data, Params preparation   ################# 
<br />
<br />  {'learning_rate': 0.001, 'num_layers': 1, 'size': 6, 'size_layer': 128, 'timestep': 4, 'epoch': 2, 'output_size': 6} {'data_path': 'https://github.com/arita37/mlmodels/tree/51b64e342c7b2661e79b8abaa33db92672ae95c7/mlmodels/dataset/timeseries/GOOG-year.csv', 'data_type': 'pandas'} {} {'path': 'https://github.com/arita37/mlmodels/tree/51b64e342c7b2661e79b8abaa33db92672ae95c7/mlmodels/ztest/model_tf/1_lstm/', 'model_path': 'https://github.com/arita37/mlmodels/tree/51b64e342c7b2661e79b8abaa33db92672ae95c7/mlmodels/ztest/model_tf/1_lstm/model'} 
<br />
<br />  #### Loading dataset   ############################################# 
<br />{'data_path': 'https://github.com/arita37/mlmodels/tree/51b64e342c7b2661e79b8abaa33db92672ae95c7/mlmodels/dataset/timeseries/GOOG-year.csv', 'data_type': 'pandas'}
<br />https://github.com/arita37/mlmodels/tree/51b64e342c7b2661e79b8abaa33db92672ae95c7/mlmodels/dataset/timeseries/GOOG-year.csv
<br />         Date        Open        High  ...       Close   Adj Close   Volume
<br />0  2016-11-02  778.200012  781.650024  ...  768.700012  768.700012  1872400
<br />1  2016-11-03  767.250000  769.950012  ...  762.130005  762.130005  1943200
<br />2  2016-11-04  750.659973  770.359985  ...  762.020020  762.020020  2134800
<br />3  2016-11-07  774.500000  785.190002  ...  782.520020  782.520020  1585100
<br />4  2016-11-08  783.400024  795.632996  ...  790.510010  790.510010  1350800
<br />
<br />[5 rows x 7 columns]
<br />
<br />  #### Model init  ############################################# 
<br />
<br />  #### Model fit   ############################################# 
<br />{'data_path': 'https://github.com/arita37/mlmodels/tree/51b64e342c7b2661e79b8abaa33db92672ae95c7/mlmodels/dataset/timeseries/GOOG-year.csv', 'data_type': 'pandas'}
<br />https://github.com/arita37/mlmodels/tree/51b64e342c7b2661e79b8abaa33db92672ae95c7/mlmodels/dataset/timeseries/GOOG-year.csv
<br />         Date        Open        High  ...       Close   Adj Close   Volume
<br />0  2016-11-02  778.200012  781.650024  ...  768.700012  768.700012  1872400
<br />1  2016-11-03  767.250000  769.950012  ...  762.130005  762.130005  1943200
<br />2  2016-11-04  750.659973  770.359985  ...  762.020020  762.020020  2134800
<br />3  2016-11-07  774.500000  785.190002  ...  782.520020  782.520020  1585100
<br />4  2016-11-08  783.400024  795.632996  ...  790.510010  790.510010  1350800
<br />
<br />[5 rows x 7 columns]
<br />          0         1         2         3         4         5
<br />0  0.706562  0.629914  0.682052  0.599302  0.599302  0.153665
<br />1  0.458824  0.320251  0.598101  0.478596  0.478596  0.174523
<br />2  0.083484  0.331101  0.437246  0.476576  0.476576  0.230969
<br />3  0.622851  0.723606  0.854891  0.853206  0.853206  0.069025
<br />4  0.824209  1.000000  1.000000  1.000000  1.000000  0.000000
<br />
<br />  #### Predict   ##################################################### 
<br />{'data_path': 'https://github.com/arita37/mlmodels/tree/51b64e342c7b2661e79b8abaa33db92672ae95c7/mlmodels/dataset/timeseries/GOOG-year.csv', 'data_type': 'pandas', 'train': 0}
<br />https://github.com/arita37/mlmodels/tree/51b64e342c7b2661e79b8abaa33db92672ae95c7/mlmodels/dataset/timeseries/GOOG-year.csv
<br />         Date        Open        High  ...       Close   Adj Close   Volume
<br />0  2016-11-02  778.200012  781.650024  ...  768.700012  768.700012  1872400
<br />1  2016-11-03  767.250000  769.950012  ...  762.130005  762.130005  1943200
<br />2  2016-11-04  750.659973  770.359985  ...  762.020020  762.020020  2134800
<br />3  2016-11-07  774.500000  785.190002  ...  782.520020  782.520020  1585100
<br />4  2016-11-08  783.400024  795.632996  ...  790.510010  790.510010  1350800
<br />
<br />[5 rows x 7 columns]
<br />          0         1         2         3         4         5
<br />0  0.706562  0.629914  0.682052  0.599302  0.599302  0.153665
<br />1  0.458824  0.320251  0.598101  0.478596  0.478596  0.174523
<br />2  0.083484  0.331101  0.437246  0.476576  0.476576  0.230969
<br />3  0.622851  0.723606  0.854891  0.853206  0.853206  0.069025
<br />4  0.824209  1.000000  1.000000  1.000000  1.000000  0.000000
<br />5  0.745928  0.883387  0.838176  0.904464  0.904464  0.370110
<br />6  1.000000  0.881878  0.467996  0.486496  0.486496  1.000000
<br />7  0.216516  0.077549  0.433808  0.329598  0.329598  0.318466
<br />8  0.195249  0.000000  0.000000  0.000000  0.000000  0.671960
<br />9  0.000000  0.173783  0.369041  0.411721  0.411721  0.304384
<br />
<br />  #### metrics   ##################################################### 
<br />{'loss': 0.44782213121652603, 'loss_history': []}
<br />
<br />  #### Plot   ######################################################## 
<br />
<br />  #### Save   ######################################################## 
<br />{'path': 'https://github.com/arita37/mlmodels/tree/51b64e342c7b2661e79b8abaa33db92672ae95c7/mlmodels/ztest/model_tf/1_lstm/'}
<br />Model saved in path: https://github.com/arita37/mlmodels/tree/51b64e342c7b2661e79b8abaa33db92672ae95c7/mlmodels/ztest/model_tf/1_lstm//model//model.ckpt
<br />
<br />  #### Load   ######################################################## 
<br />2020-05-22 00:21:49.942860: W tensorflow/core/framework/op_kernel.cc:1651] OP_REQUIRES failed at save_restore_v2_ops.cc:184 : Not found: Key Variable not found in checkpoint
<br />{'path': 'https://github.com/arita37/mlmodels/tree/51b64e342c7b2661e79b8abaa33db92672ae95c7/mlmodels/ztest/model_tf/1_lstm/', 'model_path': 'https://github.com/arita37/mlmodels/tree/51b64e342c7b2661e79b8abaa33db92672ae95c7/mlmodels/ztest/model_tf/1_lstm/model'}
<br />Failed Restoring from checkpoint failed. This is most likely due to a Variable name or other graph key that is missing from the checkpoint. Please ensure that you have not altered the graph expected based on the checkpoint. Original error:
<br />
<br />Key Variable not found in checkpoint
<br />	 [[node save_1/RestoreV2 (defined at opt/hostedtoolcache/Python/3.6.10/x64/lib/python3.6/site-packages/tensorflow_core/python/framework/ops.py:1748) ]]
<br />
<br />Original stack trace for 'save_1/RestoreV2':
<br />  File "opt/hostedtoolcache/Python/3.6.10/x64/bin/ml_models", line 11, in <module>
<br />    load_entry_point('mlmodels', 'console_scripts', 'ml_models')()
<br />  File "home/runner/work/mlmodels/mlmodels/mlmodels/models.py", line 526, in main
<br />    test_cli(arg)
<br />  File "home/runner/work/mlmodels/mlmodels/mlmodels/models.py", line 460, in test_cli
<br />    test_global(arg.model_uri)  # '1_lstm'
<br />  File "home/runner/work/mlmodels/mlmodels/mlmodels/models.py", line 200, in test_global
<br />    module.test()
<br />  File "home/runner/work/mlmodels/mlmodels/mlmodels/model_tf/1_lstm.py", line 320, in test
<br />    session = load(out_pars)
<br />  File "home/runner/work/mlmodels/mlmodels/mlmodels/model_tf/1_lstm.py", line 199, in load
<br />    return load_tf(load_pars)
<br />  File "home/runner/work/mlmodels/mlmodels/mlmodels/util.py", line 474, in load_tf
<br />    saver      = tf.compat.v1.train.Saver()
<br />  File "opt/hostedtoolcache/Python/3.6.10/x64/lib/python3.6/site-packages/tensorflow_core/python/training/saver.py", line 828, in __init__
<br />    self.build()
<br />  File "opt/hostedtoolcache/Python/3.6.10/x64/lib/python3.6/site-packages/tensorflow_core/python/training/saver.py", line 840, in build
<br />    self._build(self._filename, build_save=True, build_restore=True)
<br />  File "opt/hostedtoolcache/Python/3.6.10/x64/lib/python3.6/site-packages/tensorflow_core/python/training/saver.py", line 878, in _build
<br />    build_restore=build_restore)
<br />  File "opt/hostedtoolcache/Python/3.6.10/x64/lib/python3.6/site-packages/tensorflow_core/python/training/saver.py", line 508, in _build_internal
<br />    restore_sequentially, reshape)
<br />  File "opt/hostedtoolcache/Python/3.6.10/x64/lib/python3.6/site-packages/tensorflow_core/python/training/saver.py", line 328, in _AddRestoreOps
<br />    restore_sequentially)
<br />  File "opt/hostedtoolcache/Python/3.6.10/x64/lib/python3.6/site-packages/tensorflow_core/python/training/saver.py", line 575, in bulk_restore
<br />    return io_ops.restore_v2(filename_tensor, names, slices, dtypes)
<br />  File "opt/hostedtoolcache/Python/3.6.10/x64/lib/python3.6/site-packages/tensorflow_core/python/ops/gen_io_ops.py", line 1696, in restore_v2
<br />    name=name)
<br />  File "opt/hostedtoolcache/Python/3.6.10/x64/lib/python3.6/site-packages/tensorflow_core/python/framework/op_def_library.py", line 794, in _apply_op_helper
<br />    op_def=op_def)
<br />  File "opt/hostedtoolcache/Python/3.6.10/x64/lib/python3.6/site-packages/tensorflow_core/python/util/deprecation.py", line 507, in new_func
<br />    return func(*args, **kwargs)
<br />  File "opt/hostedtoolcache/Python/3.6.10/x64/lib/python3.6/site-packages/tensorflow_core/python/framework/ops.py", line 3357, in create_op
<br />    attrs, op_def, compute_device)
<br />  File "opt/hostedtoolcache/Python/3.6.10/x64/lib/python3.6/site-packages/tensorflow_core/python/framework/ops.py", line 3426, in _create_op_internal
<br />    op_def=op_def)
<br />  File "opt/hostedtoolcache/Python/3.6.10/x64/lib/python3.6/site-packages/tensorflow_core/python/framework/ops.py", line 1748, in __init__
<br />    self._traceback = tf_stack.extract_stack()
<br />
<br />
<br />
<br />
<br />
<br />
<br /> ************************************************************************************************************************
<br />ipython https://github.com/arita37/mlmodels/blob/dev/mlmodels/example//lightgbm.ipynb 
<br />
<br />[0;31m---------------------------------------------------------------------------[0m



### Error 16, [Traceback at line 688](https://github.com/arita37/mlmodels_store/blob/master/log_jupyter/log_jupyter.py#L688)<br />688..[0;31mFileNotFoundError[0m                         Traceback (most recent call last)
<br />[0;32m~/work/mlmodels/mlmodels/mlmodels/example//lightgbm.ipynb[0m in [0;36m<module>[0;34m[0m
<br />[1;32m      4[0m [0mdata_path[0m [0;34m=[0m [0;34m'lightgbm_titanic.json'[0m[0;34m[0m[0;34m[0m[0m
<br />[1;32m      5[0m [0;34m[0m[0m
<br />[0;32m----> 6[0;31m [0mpars[0m [0;34m=[0m [0mjson[0m[0;34m.[0m[0mload[0m[0;34m([0m[0mopen[0m[0;34m([0m [0mdata_path[0m [0;34m,[0m [0mmode[0m[0;34m=[0m[0;34m'r'[0m[0;34m)[0m[0;34m)[0m[0;34m[0m[0;34m[0m[0m
<br />[0m[1;32m      7[0m [0;32mfor[0m [0mkey[0m[0;34m,[0m [0mpdict[0m [0;32min[0m  [0mpars[0m[0;34m.[0m[0mitems[0m[0;34m([0m[0;34m)[0m [0;34m:[0m[0;34m[0m[0;34m[0m[0m
<br />[1;32m      8[0m   [0mglobals[0m[0;34m([0m[0;34m)[0m[0;34m[[0m[0mkey[0m[0;34m][0m [0;34m=[0m [0mpdict[0m[0;34m[0m[0;34m[0m[0m
<br />
<br />[0;31mFileNotFoundError[0m: [Errno 2] No such file or directory: 'lightgbm_titanic.json'
<br />
<br />
<br />
<br />
<br />
<br /> ************************************************************************************************************************
<br />ipython https://github.com/arita37/mlmodels/blob/dev/mlmodels/example//sklearn.ipynb 
<br />
<br />[0;31m---------------------------------------------------------------------------[0m



### Error 17, [Traceback at line 706](https://github.com/arita37/mlmodels_store/blob/master/log_jupyter/log_jupyter.py#L706)<br />706..[0;31mModuleNotFoundError[0m                       Traceback (most recent call last)
<br />[0;32m~/work/mlmodels/mlmodels/mlmodels/models.py[0m in [0;36mmodule_load[0;34m(model_uri, verbose, env_build)[0m
<br />[1;32m     71[0m         [0mmodel_name[0m [0;34m=[0m [0mmodel_uri[0m[0;34m.[0m[0mreplace[0m[0;34m([0m[0;34m".py"[0m[0;34m,[0m [0;34m""[0m[0;34m)[0m[0;34m[0m[0;34m[0m[0m
<br />[0;32m---> 72[0;31m         [0mmodule[0m [0;34m=[0m [0mimport_module[0m[0;34m([0m[0;34mf"mlmodels.{model_name}"[0m[0;34m)[0m[0;34m[0m[0;34m[0m[0m
<br />[0m[1;32m     73[0m         [0;31m# module    = import_module("mlmodels.model_tf.1_lstm")[0m[0;34m[0m[0;34m[0m[0;34m[0m[0m
<br />
<br />[0;32m/opt/hostedtoolcache/Python/3.6.10/x64/lib/python3.6/importlib/__init__.py[0m in [0;36mimport_module[0;34m(name, package)[0m
<br />[1;32m    125[0m             [0mlevel[0m [0;34m+=[0m [0;36m1[0m[0;34m[0m[0;34m[0m[0m
<br />[0;32m--> 126[0;31m     [0;32mreturn[0m [0m_bootstrap[0m[0;34m.[0m[0m_gcd_import[0m[0;34m([0m[0mname[0m[0;34m[[0m[0mlevel[0m[0;34m:[0m[0;34m][0m[0;34m,[0m [0mpackage[0m[0;34m,[0m [0mlevel[0m[0;34m)[0m[0;34m[0m[0;34m[0m[0m
<br />[0m[1;32m    127[0m [0;34m[0m[0m
<br />
<br />[0;32m/opt/hostedtoolcache/Python/3.6.10/x64/lib/python3.6/importlib/_bootstrap.py[0m in [0;36m_gcd_import[0;34m(name, package, level)[0m
<br />
<br />[0;32m/opt/hostedtoolcache/Python/3.6.10/x64/lib/python3.6/importlib/_bootstrap.py[0m in [0;36m_find_and_load[0;34m(name, import_)[0m
<br />
<br />[0;32m/opt/hostedtoolcache/Python/3.6.10/x64/lib/python3.6/importlib/_bootstrap.py[0m in [0;36m_find_and_load_unlocked[0;34m(name, import_)[0m
<br />
<br />[0;31mModuleNotFoundError[0m: No module named 'mlmodels.model_sklearn.sklearn'
<br />
<br />During handling of the above exception, another exception occurred:
<br />



### Error 18, [Traceback at line 727](https://github.com/arita37/mlmodels_store/blob/master/log_jupyter/log_jupyter.py#L727)<br />727..[0;31mIndexError[0m                                Traceback (most recent call last)
<br />[0;32m~/work/mlmodels/mlmodels/mlmodels/models.py[0m in [0;36mmodule_load[0;34m(model_uri, verbose, env_build)[0m
<br />[1;32m     83[0m             [0mmodel_name[0m [0;34m=[0m [0mPath[0m[0;34m([0m[0mmodel_uri[0m[0;34m)[0m[0;34m.[0m[0mstem[0m  [0;31m# remove .py[0m[0;34m[0m[0;34m[0m[0m
<br />[0;32m---> 84[0;31m             [0mmodel_name[0m [0;34m=[0m [0mstr[0m[0;34m([0m[0mPath[0m[0;34m([0m[0mmodel_uri[0m[0;34m)[0m[0;34m.[0m[0mparts[0m[0;34m[[0m[0;34m-[0m[0;36m2[0m[0;34m][0m[0;34m)[0m [0;34m+[0m [0;34m"."[0m [0;34m+[0m [0mstr[0m[0;34m([0m[0mmodel_name[0m[0;34m)[0m[0;34m[0m[0;34m[0m[0m
<br />[0m[1;32m     85[0m             [0;31m# print(model_name)[0m[0;34m[0m[0;34m[0m[0;34m[0m[0m
<br />
<br />[0;31mIndexError[0m: tuple index out of range
<br />
<br />During handling of the above exception, another exception occurred:
<br />



### Error 19, [Traceback at line 737](https://github.com/arita37/mlmodels_store/blob/master/log_jupyter/log_jupyter.py#L737)<br />737..[0;31mNameError[0m                                 Traceback (most recent call last)
<br />[0;32m~/work/mlmodels/mlmodels/mlmodels/example//sklearn.ipynb[0m in [0;36m<module>[0;34m[0m
<br />[1;32m      1[0m [0;32mfrom[0m [0mmlmodels[0m[0;34m.[0m[0mmodels[0m [0;32mimport[0m [0mmodule_load[0m[0;34m[0m[0;34m[0m[0m
<br />[1;32m      2[0m [0;34m[0m[0m
<br />[0;32m----> 3[0;31m [0mmodule[0m        [0;34m=[0m  [0mmodule_load[0m[0;34m([0m [0mmodel_uri[0m[0;34m=[0m [0mmodel_uri[0m [0;34m)[0m                           [0;31m# Load file definition[0m[0;34m[0m[0;34m[0m[0m
<br />[0m[1;32m      4[0m [0mmodel[0m         [0;34m=[0m  [0mmodule[0m[0;34m.[0m[0mModel[0m[0;34m([0m[0mmodel_pars[0m[0;34m=[0m[0mmodel_pars[0m[0;34m,[0m [0mdata_pars[0m[0;34m=[0m[0mdata_pars[0m[0;34m,[0m [0mcompute_pars[0m[0;34m=[0m[0mcompute_pars[0m[0;34m)[0m             [0;31m# Create Model instance[0m[0;34m[0m[0;34m[0m[0m
<br />[1;32m      5[0m [0mmodel[0m[0;34m,[0m [0msess[0m   [0;34m=[0m  [0mmodule[0m[0;34m.[0m[0mfit[0m[0;34m([0m[0mmodel[0m[0;34m,[0m [0mdata_pars[0m[0;34m=[0m[0mdata_pars[0m[0;34m,[0m [0mcompute_pars[0m[0;34m=[0m[0mcompute_pars[0m[0;34m,[0m [0mout_pars[0m[0;34m=[0m[0mout_pars[0m[0;34m)[0m          [0;31m# fit the model[0m[0;34m[0m[0;34m[0m[0m
<br />
<br />[0;32m~/work/mlmodels/mlmodels/mlmodels/models.py[0m in [0;36mmodule_load[0;34m(model_uri, verbose, env_build)[0m
<br />[1;32m     87[0m [0;34m[0m[0m
<br />[1;32m     88[0m         [0;32mexcept[0m [0mException[0m [0;32mas[0m [0me2[0m[0;34m:[0m[0;34m[0m[0;34m[0m[0m
<br />[0;32m---> 89[0;31m             [0;32mraise[0m [0mNameError[0m[0;34m([0m[0;34mf"Module {model_name} notfound, {e1}, {e2}"[0m[0;34m)[0m[0;34m[0m[0;34m[0m[0m
<br />[0m[1;32m     90[0m [0;34m[0m[0m
<br />[1;32m     91[0m     [0;32mif[0m [0mverbose[0m[0;34m:[0m [0mprint[0m[0;34m([0m[0mmodule[0m[0;34m)[0m[0;34m[0m[0;34m[0m[0m
<br />
<br />[0;31mNameError[0m: Module model_sklearn.sklearn notfound, No module named 'mlmodels.model_sklearn.sklearn', tuple index out of range
<br />
<br />
<br />
<br />
<br />
<br /> ************************************************************************************************************************
<br />ipython https://github.com/arita37/mlmodels/blob/dev/mlmodels/example//gluon_automl.ipynb 
<br />
<br />/opt/hostedtoolcache/Python/3.6.10/x64/lib/python3.6/site-packages/mxnet/optimizer/optimizer.py:167: UserWarning: WARNING: New optimizer gluonnlp.optimizer.lamb.LAMB is overriding existing optimizer mxnet.optimizer.optimizer.LAMB
<br />  Optimizer.opt_registry[name].__name__))
<br />Loaded data from: https://autogluon.s3.amazonaws.com/datasets/Inc/train.csv | Columns = 15 / 15 | Rows = 39073 -> 39073
<br />Warning: `hyperparameter_tune=True` is currently experimental and may cause the process to hang. Setting `auto_stack=True` instead is recommended to achieve maximum quality models.
<br />Beginning AutoGluon training ... Time limit = 120s
<br />AutoGluon will save models to dataset/
<br />Train Data Rows:    39073
<br />Train Data Columns: 15
<br />Preprocessing data ...
<br />Here are the first 10 unique label values in your data:  [' Tech-support' ' Transport-moving' ' Other-service' ' ?'
<br /> ' Handlers-cleaners' ' Sales' ' Craft-repair' ' Adm-clerical'
<br /> ' Exec-managerial' ' Prof-specialty']
<br />AutoGluon infers your prediction problem is: multiclass  (because dtype of label-column == object)
<br />If this is wrong, please specify `problem_type` argument in fit() instead (You may specify problem_type as one of: ['binary', 'multiclass', 'regression'])
<br />
<br />Feature Generator processed 39073 data points with 14 features
<br />Original Features:
<br />	int features: 6
<br />	object features: 8
<br />Generated Features:
<br />	int features: 0
<br />All Features:
<br />	int features: 6
<br />	object features: 8
<br />	Data preprocessing and feature engineering runtime = 0.22s ...
<br />AutoGluon will gauge predictive performance using evaluation metric: accuracy
<br />To change this, specify the eval_metric argument of fit()
<br />AutoGluon will early stop models using evaluation metric: accuracy
<br />Saving dataset/learner.pkl
<br />Beginning hyperparameter tuning for Gradient Boosting Model...
<br />Hyperparameter search space for Gradient Boosting Model: 
<br />num_leaves:   Int: lower=26, upper=30
<br />learning_rate:   Real: lower=0.005, upper=0.2
<br />feature_fraction:   Real: lower=0.75, upper=1.0
<br />min_data_in_leaf:   Int: lower=2, upper=30
<br />  File "/opt/hostedtoolcache/Python/3.6.10/x64/lib/python3.6/site-packages/autogluon/utils/tabular/ml/trainer/abstract_trainer.py", line 360, in train_single_full
<br />    Y_train=y_train, Y_test=y_test, scheduler_options=(self.scheduler_func, self.scheduler_options), verbosity=self.verbosity)
<br />  File "/opt/hostedtoolcache/Python/3.6.10/x64/lib/python3.6/site-packages/autogluon/utils/tabular/ml/models/lgb/lgb_model.py", line 283, in hyperparameter_tune
<br />    directory=directory, lgb_model=self, **params_copy)
<br />  File "/opt/hostedtoolcache/Python/3.6.10/x64/lib/python3.6/site-packages/autogluon/core/decorator.py", line 69, in register_args
<br />    self.update(**kwvars)
<br />  File "/opt/hostedtoolcache/Python/3.6.10/x64/lib/python3.6/site-packages/autogluon/core/decorator.py", line 79, in update
<br />    hp = v.get_hp(name=k)
<br />  File "/opt/hostedtoolcache/Python/3.6.10/x64/lib/python3.6/site-packages/autogluon/core/space.py", line 451, in get_hp
<br />    default_value=self._default)
<br />  File "ConfigSpace/hyperparameters.pyx", line 773, in ConfigSpace.hyperparameters.UniformIntegerHyperparameter.__init__
<br />  File "ConfigSpace/hyperparameters.pyx", line 843, in ConfigSpace.hyperparameters.UniformIntegerHyperparameter.check_default
<br />Warning: Exception caused LightGBMClassifier to fail during hyperparameter tuning... Skipping this model.



### Error 20, [Traceback at line 809](https://github.com/arita37/mlmodels_store/blob/master/log_jupyter/log_jupyter.py#L809)<br />809..Traceback (most recent call last):
<br />  File "/opt/hostedtoolcache/Python/3.6.10/x64/lib/python3.6/site-packages/autogluon/utils/tabular/ml/trainer/abstract_trainer.py", line 360, in train_single_full
<br />    Y_train=y_train, Y_test=y_test, scheduler_options=(self.scheduler_func, self.scheduler_options), verbosity=self.verbosity)
<br />  File "/opt/hostedtoolcache/Python/3.6.10/x64/lib/python3.6/site-packages/autogluon/utils/tabular/ml/models/lgb/lgb_model.py", line 283, in hyperparameter_tune
<br />    directory=directory, lgb_model=self, **params_copy)
<br />  File "/opt/hostedtoolcache/Python/3.6.10/x64/lib/python3.6/site-packages/autogluon/core/decorator.py", line 69, in register_args
<br />    self.update(**kwvars)
<br />  File "/opt/hostedtoolcache/Python/3.6.10/x64/lib/python3.6/site-packages/autogluon/core/decorator.py", line 79, in update
<br />    hp = v.get_hp(name=k)
<br />  File "/opt/hostedtoolcache/Python/3.6.10/x64/lib/python3.6/site-packages/autogluon/core/space.py", line 451, in get_hp
<br />    default_value=self._default)
<br />  File "ConfigSpace/hyperparameters.pyx", line 773, in ConfigSpace.hyperparameters.UniformIntegerHyperparameter.__init__
<br />  File "ConfigSpace/hyperparameters.pyx", line 843, in ConfigSpace.hyperparameters.UniformIntegerHyperparameter.check_default
<br />ValueError: Illegal default value 36



### Error 21, [Traceback at line 971](https://github.com/arita37/mlmodels_store/blob/master/log_jupyter/log_jupyter.py#L971)<br />971..Traceback (most recent call last):
<br />  File "/opt/hostedtoolcache/Python/3.6.10/x64/bin/ml_models", line 11, in <module>
<br />    load_entry_point('mlmodels', 'console_scripts', 'ml_models')()
<br />  File "https://github.com/arita37/mlmodels/tree/51b64e342c7b2661e79b8abaa33db92672ae95c7/mlmodels/models.py", line 526, in main
<br />    test_cli(arg)
<br />  File "https://github.com/arita37/mlmodels/tree/51b64e342c7b2661e79b8abaa33db92672ae95c7/mlmodels/models.py", line 456, in test_cli
<br />    test_module(arg.model_uri, param_pars=param_pars)  # '1_lstm'
<br />  File "https://github.com/arita37/mlmodels/tree/51b64e342c7b2661e79b8abaa33db92672ae95c7/mlmodels/models.py", line 257, in test_module
<br />    model_pars, data_pars, compute_pars, out_pars = module.get_params(param_pars)
<br />  File "https://github.com/arita37/mlmodels/tree/51b64e342c7b2661e79b8abaa33db92672ae95c7/mlmodels/model_gluon/gluon_automl.py", line 109, in get_params
<br />    return model_pars, data_pars, compute_pars, out_pars
<br />UnboundLocalError: local variable 'model_pars' referenced before assignment



### Error 22, [Traceback at line 992](https://github.com/arita37/mlmodels_store/blob/master/log_jupyter/log_jupyter.py#L992)<br />992..[0;31mModuleNotFoundError[0m                       Traceback (most recent call last)
<br />[0;32m~/work/mlmodels/mlmodels/mlmodels/example//vison_fashion_MNIST.ipynb[0m in [0;36m<module>[0;34m[0m
<br />[0;32m----> 1[0;31m [0;32mfrom[0m [0mgoogle[0m[0;34m.[0m[0mcolab[0m [0;32mimport[0m [0mdrive[0m[0;34m[0m[0;34m[0m[0m
<br />[0m[1;32m      2[0m [0mdrive[0m[0;34m.[0m[0mmount[0m[0;34m([0m[0;34m'/content/drive'[0m[0;34m)[0m[0;34m[0m[0;34m[0m[0m
<br />
<br />[0;31mModuleNotFoundError[0m: No module named 'google.colab'
<br />
<br />
<br />
<br />
<br />
<br /> ************************************************************************************************************************
<br />ipython https://github.com/arita37/mlmodels/blob/dev/mlmodels/example//timeseries_m5_deepar.ipynb 
<br />
<br />UsageError: Line magic function `%%capture` not found.



### Error 23, [Traceback at line 1862](https://github.com/arita37/mlmodels_store/blob/master/log_jupyter/log_jupyter.py#L1862)<br />1862..[0;31mModuleNotFoundError[0m                       Traceback (most recent call last)
<br />[0;32m~/work/mlmodels/mlmodels/mlmodels/example//vision_mnist.ipynb[0m in [0;36m<module>[0;34m[0m
<br />[0;32m----> 1[0;31m [0;32mfrom[0m [0mgoogle[0m[0;34m.[0m[0mcolab[0m [0;32mimport[0m [0mdrive[0m[0;34m[0m[0;34m[0m[0m
<br />[0m[1;32m      2[0m [0mdrive[0m[0;34m.[0m[0mmount[0m[0;34m([0m[0;34m'/content/drive'[0m[0;34m)[0m[0;34m[0m[0;34m[0m[0m
<br />
<br />[0;31mModuleNotFoundError[0m: No module named 'google.colab'
<br />
<br />
<br />
<br />
<br />
<br /> ************************************************************************************************************************
<br />ipython https://github.com/arita37/mlmodels/blob/dev/mlmodels/example/benchmark_timeseries_m5.py 
<br />
<br />[0;31m---------------------------------------------------------------------------[0m



### Error 24, [Traceback at line 1877](https://github.com/arita37/mlmodels_store/blob/master/log_jupyter/log_jupyter.py#L1877)<br />1877..[0;31mFileNotFoundError[0m                         Traceback (most recent call last)
<br />[0;32m~/work/mlmodels/mlmodels/mlmodels/example/benchmark_timeseries_m5.py[0m in [0;36m<module>[0;34m[0m
<br />[1;32m     84[0m [0;34m[0m[0m
<br />[1;32m     85[0m """
<br />[0;32m---> 86[0;31m [0mcalendar[0m               [0;34m=[0m [0mpd[0m[0;34m.[0m[0mread_csv[0m[0;34m([0m[0;34mf'{m5_input_path}/calendar.csv'[0m[0;34m)[0m[0;34m[0m[0;34m[0m[0m
<br />[0m[1;32m     87[0m [0msales_train_val[0m        [0;34m=[0m [0mpd[0m[0;34m.[0m[0mread_csv[0m[0;34m([0m[0;34mf'{m5_input_path}/sales_train_val.csv'[0m[0;34m)[0m[0;34m[0m[0;34m[0m[0m
<br />[1;32m     88[0m [0msample_submission[0m      [0;34m=[0m [0mpd[0m[0;34m.[0m[0mread_csv[0m[0;34m([0m[0;34mf'{m5_input_path}/sample_submission.csv'[0m[0;34m)[0m[0;34m[0m[0;34m[0m[0m
<br />
<br />[0;32m/opt/hostedtoolcache/Python/3.6.10/x64/lib/python3.6/site-packages/pandas/io/parsers.py[0m in [0;36mparser_f[0;34m(filepath_or_buffer, sep, delimiter, header, names, index_col, usecols, squeeze, prefix, mangle_dupe_cols, dtype, engine, converters, true_values, false_values, skipinitialspace, skiprows, skipfooter, nrows, na_values, keep_default_na, na_filter, verbose, skip_blank_lines, parse_dates, infer_datetime_format, keep_date_col, date_parser, dayfirst, cache_dates, iterator, chunksize, compression, thousands, decimal, lineterminator, quotechar, quoting, doublequote, escapechar, comment, encoding, dialect, error_bad_lines, warn_bad_lines, delim_whitespace, low_memory, memory_map, float_precision)[0m
<br />[1;32m    683[0m         )
<br />[1;32m    684[0m [0;34m[0m[0m
<br />[0;32m--> 685[0;31m         [0;32mreturn[0m [0m_read[0m[0;34m([0m[0mfilepath_or_buffer[0m[0;34m,[0m [0mkwds[0m[0;34m)[0m[0;34m[0m[0;34m[0m[0m
<br />[0m[1;32m    686[0m [0;34m[0m[0m
<br />[1;32m    687[0m     [0mparser_f[0m[0;34m.[0m[0m__name__[0m [0;34m=[0m [0mname[0m[0;34m[0m[0;34m[0m[0m
<br />
<br />[0;32m/opt/hostedtoolcache/Python/3.6.10/x64/lib/python3.6/site-packages/pandas/io/parsers.py[0m in [0;36m_read[0;34m(filepath_or_buffer, kwds)[0m
<br />[1;32m    455[0m [0;34m[0m[0m
<br />[1;32m    456[0m     [0;31m# Create the parser.[0m[0;34m[0m[0;34m[0m[0;34m[0m[0m
<br />[0;32m--> 457[0;31m     [0mparser[0m [0;34m=[0m [0mTextFileReader[0m[0;34m([0m[0mfp_or_buf[0m[0;34m,[0m [0;34m**[0m[0mkwds[0m[0;34m)[0m[0;34m[0m[0;34m[0m[0m
<br />[0m[1;32m    458[0m [0;34m[0m[0m
<br />[1;32m    459[0m     [0;32mif[0m [0mchunksize[0m [0;32mor[0m [0miterator[0m[0;34m:[0m[0;34m[0m[0;34m[0m[0m
<br />
<br />[0;32m/opt/hostedtoolcache/Python/3.6.10/x64/lib/python3.6/site-packages/pandas/io/parsers.py[0m in [0;36m__init__[0;34m(self, f, engine, **kwds)[0m
<br />[1;32m    893[0m             [0mself[0m[0;34m.[0m[0moptions[0m[0;34m[[0m[0;34m"has_index_names"[0m[0;34m][0m [0;34m=[0m [0mkwds[0m[0;34m[[0m[0;34m"has_index_names"[0m[0;34m][0m[0;34m[0m[0;34m[0m[0m
<br />[1;32m    894[0m [0;34m[0m[0m
<br />[0;32m--> 895[0;31m         [0mself[0m[0;34m.[0m[0m_make_engine[0m[0;34m([0m[0mself[0m[0;34m.[0m[0mengine[0m[0;34m)[0m[0;34m[0m[0;34m[0m[0m
<br />[0m[1;32m    896[0m [0;34m[0m[0m
<br />[1;32m    897[0m     [0;32mdef[0m [0mclose[0m[0;34m([0m[0mself[0m[0;34m)[0m[0;34m:[0m[0;34m[0m[0;34m[0m[0m
<br />
<br />[0;32m/opt/hostedtoolcache/Python/3.6.10/x64/lib/python3.6/site-packages/pandas/io/parsers.py[0m in [0;36m_make_engine[0;34m(self, engine)[0m
<br />[1;32m   1133[0m     [0;32mdef[0m [0m_make_engine[0m[0;34m([0m[0mself[0m[0;34m,[0m [0mengine[0m[0;34m=[0m[0;34m"c"[0m[0;34m)[0m[0;34m:[0m[0;34m[0m[0;34m[0m[0m
<br />[1;32m   1134[0m         [0;32mif[0m [0mengine[0m [0;34m==[0m [0;34m"c"[0m[0;34m:[0m[0;34m[0m[0;34m[0m[0m
<br />[0;32m-> 1135[0;31m             [0mself[0m[0;34m.[0m[0m_engine[0m [0;34m=[0m [0mCParserWrapper[0m[0;34m([0m[0mself[0m[0;34m.[0m[0mf[0m[0;34m,[0m [0;34m**[0m[0mself[0m[0;34m.[0m[0moptions[0m[0;34m)[0m[0;34m[0m[0;34m[0m[0m
<br />[0m[1;32m   1136[0m         [0;32melse[0m[0;34m:[0m[0;34m[0m[0;34m[0m[0m
<br />[1;32m   1137[0m             [0;32mif[0m [0mengine[0m [0;34m==[0m [0;34m"python"[0m[0;34m:[0m[0;34m[0m[0;34m[0m[0m
<br />
<br />[0;32m/opt/hostedtoolcache/Python/3.6.10/x64/lib/python3.6/site-packages/pandas/io/parsers.py[0m in [0;36m__init__[0;34m(self, src, **kwds)[0m
<br />[1;32m   1915[0m         [0mkwds[0m[0;34m[[0m[0;34m"usecols"[0m[0;34m][0m [0;34m=[0m [0mself[0m[0;34m.[0m[0musecols[0m[0;34m[0m[0;34m[0m[0m
<br />[1;32m   1916[0m [0;34m[0m[0m
<br />[0;32m-> 1917[0;31m         [0mself[0m[0;34m.[0m[0m_reader[0m [0;34m=[0m [0mparsers[0m[0;34m.[0m[0mTextReader[0m[0;34m([0m[0msrc[0m[0;34m,[0m [0;34m**[0m[0mkwds[0m[0;34m)[0m[0;34m[0m[0;34m[0m[0m
<br />[0m[1;32m   1918[0m         [0mself[0m[0;34m.[0m[0munnamed_cols[0m [0;34m=[0m [0mself[0m[0;34m.[0m[0m_reader[0m[0;34m.[0m[0munnamed_cols[0m[0;34m[0m[0;34m[0m[0m
<br />[1;32m   1919[0m [0;34m[0m[0m
<br />
<br />[0;32mpandas/_libs/parsers.pyx[0m in [0;36mpandas._libs.parsers.TextReader.__cinit__[0;34m()[0m
<br />
<br />[0;32mpandas/_libs/parsers.pyx[0m in [0;36mpandas._libs.parsers.TextReader._setup_parser_source[0;34m()[0m
<br />
<br />[0;31mFileNotFoundError[0m: [Errno 2] File b'./m5-forecasting-accuracy/calendar.csv' does not exist: b'./m5-forecasting-accuracy/calendar.csv'
<br />
<br />
<br />
<br />
<br />
<br /> ************************************************************************************************************************
<br />ipython https://github.com/arita37/mlmodels/blob/dev/mlmodels/example/benchmark_timeseries_m4.py 
<br />
<br />
<br />
<br />
<br />
<br />
<br /> ************************************************************************************************************************
<br />ipython https://github.com/arita37/mlmodels/blob/dev/mlmodels/example//vision_mnist.py 
<br />
<br />[0;36m  File [0;32m"https://github.com/arita37/mlmodels/tree/51b64e342c7b2661e79b8abaa33db92672ae95c7/mlmodels/example/vision_mnist.py"[0;36m, line [0;32m15[0m
<br />[0;31m    !git clone https://github.com/ahmed3bbas/mlmodels.git[0m
<br />[0m    ^[0m
<br />[0;31mSyntaxError[0m[0;31m:[0m invalid syntax
<br />
<br />
<br />
<br />
<br />
<br />
<br /> ************************************************************************************************************************
<br />ipython https://github.com/arita37/mlmodels/blob/dev/mlmodels/example//benchmark_timeseries_m5.py 
<br />
<br />[0;31m---------------------------------------------------------------------------[0m



### Error 25, [Traceback at line 1955](https://github.com/arita37/mlmodels_store/blob/master/log_jupyter/log_jupyter.py#L1955)<br />1955..[0;31mFileNotFoundError[0m                         Traceback (most recent call last)
<br />[0;32m~/work/mlmodels/mlmodels/mlmodels/example/benchmark_timeseries_m5.py[0m in [0;36m<module>[0;34m[0m
<br />[1;32m     84[0m [0;34m[0m[0m
<br />[1;32m     85[0m """
<br />[0;32m---> 86[0;31m [0mcalendar[0m               [0;34m=[0m [0mpd[0m[0;34m.[0m[0mread_csv[0m[0;34m([0m[0;34mf'{m5_input_path}/calendar.csv'[0m[0;34m)[0m[0;34m[0m[0;34m[0m[0m
<br />[0m[1;32m     87[0m [0msales_train_val[0m        [0;34m=[0m [0mpd[0m[0;34m.[0m[0mread_csv[0m[0;34m([0m[0;34mf'{m5_input_path}/sales_train_val.csv'[0m[0;34m)[0m[0;34m[0m[0;34m[0m[0m
<br />[1;32m     88[0m [0msample_submission[0m      [0;34m=[0m [0mpd[0m[0;34m.[0m[0mread_csv[0m[0;34m([0m[0;34mf'{m5_input_path}/sample_submission.csv'[0m[0;34m)[0m[0;34m[0m[0;34m[0m[0m
<br />
<br />[0;32m/opt/hostedtoolcache/Python/3.6.10/x64/lib/python3.6/site-packages/pandas/io/parsers.py[0m in [0;36mparser_f[0;34m(filepath_or_buffer, sep, delimiter, header, names, index_col, usecols, squeeze, prefix, mangle_dupe_cols, dtype, engine, converters, true_values, false_values, skipinitialspace, skiprows, skipfooter, nrows, na_values, keep_default_na, na_filter, verbose, skip_blank_lines, parse_dates, infer_datetime_format, keep_date_col, date_parser, dayfirst, cache_dates, iterator, chunksize, compression, thousands, decimal, lineterminator, quotechar, quoting, doublequote, escapechar, comment, encoding, dialect, error_bad_lines, warn_bad_lines, delim_whitespace, low_memory, memory_map, float_precision)[0m
<br />[1;32m    683[0m         )
<br />[1;32m    684[0m [0;34m[0m[0m
<br />[0;32m--> 685[0;31m         [0;32mreturn[0m [0m_read[0m[0;34m([0m[0mfilepath_or_buffer[0m[0;34m,[0m [0mkwds[0m[0;34m)[0m[0;34m[0m[0;34m[0m[0m
<br />[0m[1;32m    686[0m [0;34m[0m[0m
<br />[1;32m    687[0m     [0mparser_f[0m[0;34m.[0m[0m__name__[0m [0;34m=[0m [0mname[0m[0;34m[0m[0;34m[0m[0m
<br />
<br />[0;32m/opt/hostedtoolcache/Python/3.6.10/x64/lib/python3.6/site-packages/pandas/io/parsers.py[0m in [0;36m_read[0;34m(filepath_or_buffer, kwds)[0m
<br />[1;32m    455[0m [0;34m[0m[0m
<br />[1;32m    456[0m     [0;31m# Create the parser.[0m[0;34m[0m[0;34m[0m[0;34m[0m[0m
<br />[0;32m--> 457[0;31m     [0mparser[0m [0;34m=[0m [0mTextFileReader[0m[0;34m([0m[0mfp_or_buf[0m[0;34m,[0m [0;34m**[0m[0mkwds[0m[0;34m)[0m[0;34m[0m[0;34m[0m[0m
<br />[0m[1;32m    458[0m [0;34m[0m[0m
<br />[1;32m    459[0m     [0;32mif[0m [0mchunksize[0m [0;32mor[0m [0miterator[0m[0;34m:[0m[0;34m[0m[0;34m[0m[0m
<br />
<br />[0;32m/opt/hostedtoolcache/Python/3.6.10/x64/lib/python3.6/site-packages/pandas/io/parsers.py[0m in [0;36m__init__[0;34m(self, f, engine, **kwds)[0m
<br />[1;32m    893[0m             [0mself[0m[0;34m.[0m[0moptions[0m[0;34m[[0m[0;34m"has_index_names"[0m[0;34m][0m [0;34m=[0m [0mkwds[0m[0;34m[[0m[0;34m"has_index_names"[0m[0;34m][0m[0;34m[0m[0;34m[0m[0m
<br />[1;32m    894[0m [0;34m[0m[0m
<br />[0;32m--> 895[0;31m         [0mself[0m[0;34m.[0m[0m_make_engine[0m[0;34m([0m[0mself[0m[0;34m.[0m[0mengine[0m[0;34m)[0m[0;34m[0m[0;34m[0m[0m
<br />[0m[1;32m    896[0m [0;34m[0m[0m
<br />[1;32m    897[0m     [0;32mdef[0m [0mclose[0m[0;34m([0m[0mself[0m[0;34m)[0m[0;34m:[0m[0;34m[0m[0;34m[0m[0m
<br />
<br />[0;32m/opt/hostedtoolcache/Python/3.6.10/x64/lib/python3.6/site-packages/pandas/io/parsers.py[0m in [0;36m_make_engine[0;34m(self, engine)[0m
<br />[1;32m   1133[0m     [0;32mdef[0m [0m_make_engine[0m[0;34m([0m[0mself[0m[0;34m,[0m [0mengine[0m[0;34m=[0m[0;34m"c"[0m[0;34m)[0m[0;34m:[0m[0;34m[0m[0;34m[0m[0m
<br />[1;32m   1134[0m         [0;32mif[0m [0mengine[0m [0;34m==[0m [0;34m"c"[0m[0;34m:[0m[0;34m[0m[0;34m[0m[0m
<br />[0;32m-> 1135[0;31m             [0mself[0m[0;34m.[0m[0m_engine[0m [0;34m=[0m [0mCParserWrapper[0m[0;34m([0m[0mself[0m[0;34m.[0m[0mf[0m[0;34m,[0m [0;34m**[0m[0mself[0m[0;34m.[0m[0moptions[0m[0;34m)[0m[0;34m[0m[0;34m[0m[0m
<br />[0m[1;32m   1136[0m         [0;32melse[0m[0;34m:[0m[0;34m[0m[0;34m[0m[0m
<br />[1;32m   1137[0m             [0;32mif[0m [0mengine[0m [0;34m==[0m [0;34m"python"[0m[0;34m:[0m[0;34m[0m[0;34m[0m[0m
<br />
<br />[0;32m/opt/hostedtoolcache/Python/3.6.10/x64/lib/python3.6/site-packages/pandas/io/parsers.py[0m in [0;36m__init__[0;34m(self, src, **kwds)[0m
<br />[1;32m   1915[0m         [0mkwds[0m[0;34m[[0m[0;34m"usecols"[0m[0;34m][0m [0;34m=[0m [0mself[0m[0;34m.[0m[0musecols[0m[0;34m[0m[0;34m[0m[0m
<br />[1;32m   1916[0m [0;34m[0m[0m
<br />[0;32m-> 1917[0;31m         [0mself[0m[0;34m.[0m[0m_reader[0m [0;34m=[0m [0mparsers[0m[0;34m.[0m[0mTextReader[0m[0;34m([0m[0msrc[0m[0;34m,[0m [0;34m**[0m[0mkwds[0m[0;34m)[0m[0;34m[0m[0;34m[0m[0m
<br />[0m[1;32m   1918[0m         [0mself[0m[0;34m.[0m[0munnamed_cols[0m [0;34m=[0m [0mself[0m[0;34m.[0m[0m_reader[0m[0;34m.[0m[0munnamed_cols[0m[0;34m[0m[0;34m[0m[0m
<br />[1;32m   1919[0m [0;34m[0m[0m
<br />
<br />[0;32mpandas/_libs/parsers.pyx[0m in [0;36mpandas._libs.parsers.TextReader.__cinit__[0;34m()[0m
<br />
<br />[0;32mpandas/_libs/parsers.pyx[0m in [0;36mpandas._libs.parsers.TextReader._setup_parser_source[0;34m()[0m
<br />
<br />[0;31mFileNotFoundError[0m: [Errno 2] File b'./m5-forecasting-accuracy/calendar.csv' does not exist: b'./m5-forecasting-accuracy/calendar.csv'
<br />
<br />
<br />
<br />
<br />
<br /> ************************************************************************************************************************
<br />ipython https://github.com/arita37/mlmodels/blob/dev/mlmodels/example//arun_model.py 
<br />
<br /><module 'mlmodels' from 'https://github.com/arita37/mlmodels/tree/51b64e342c7b2661e79b8abaa33db92672ae95c7/mlmodels/__init__.py'>
<br />https://github.com/arita37/mlmodels/tree/51b64e342c7b2661e79b8abaa33db92672ae95c7/mlmodels/model_keras/ardmn.json
<br />[0;31m---------------------------------------------------------------------------[0m



### Error 26, [Traceback at line 2014](https://github.com/arita37/mlmodels_store/blob/master/log_jupyter/log_jupyter.py#L2014)<br />2014..[0;31mFileNotFoundError[0m                         Traceback (most recent call last)
<br />[0;32m~/work/mlmodels/mlmodels/mlmodels/example/arun_model.py[0m in [0;36m<module>[0;34m[0m
<br />[1;32m     25[0m [0;31m# Model Parameters[0m[0;34m[0m[0;34m[0m[0;34m[0m[0m
<br />[1;32m     26[0m [0;31m# model_pars, data_pars, compute_pars, out_pars[0m[0;34m[0m[0;34m[0m[0;34m[0m[0m
<br />[0;32m---> 27[0;31m [0mpars[0m [0;34m=[0m [0mjson[0m[0;34m.[0m[0mload[0m[0;34m([0m[0mopen[0m[0;34m([0m[0mconfig_path[0m [0;34m,[0m [0mmode[0m[0;34m=[0m[0;34m'r'[0m[0;34m)[0m[0;34m)[0m[0;34m[[0m[0mconfig_mode[0m[0;34m][0m[0;34m[0m[0;34m[0m[0m
<br />[0m[1;32m     28[0m [0;32mfor[0m [0mkey[0m[0;34m,[0m [0mpdict[0m [0;32min[0m  [0mpars[0m[0;34m.[0m[0mitems[0m[0;34m([0m[0;34m)[0m [0;34m:[0m[0;34m[0m[0;34m[0m[0m
<br />[1;32m     29[0m   [0mglobals[0m[0;34m([0m[0;34m)[0m[0;34m[[0m[0mkey[0m[0;34m][0m [0;34m=[0m [0mpath_norm_dict[0m[0;34m([0m [0mpdict[0m   [0;34m)[0m   [0;31m###Normalize path[0m[0;34m[0m[0;34m[0m[0m
<br />
<br />[0;31mFileNotFoundError[0m: [Errno 2] No such file or directory: 'https://github.com/arita37/mlmodels/tree/51b64e342c7b2661e79b8abaa33db92672ae95c7/mlmodels/model_keras/ardmn.json'
<br />
<br />
<br />
<br />
<br />
<br /> ************************************************************************************************************************
<br />ipython https://github.com/arita37/mlmodels/blob/dev/mlmodels/example//lightgbm_glass.py 
<br />
<br />Deprecaton set to False
<br />/home/runner/work/mlmodels/mlmodels
<br />[0;31m---------------------------------------------------------------------------[0m



### Error 27, [Traceback at line 2034](https://github.com/arita37/mlmodels_store/blob/master/log_jupyter/log_jupyter.py#L2034)<br />2034..[0;31mFileNotFoundError[0m                         Traceback (most recent call last)
<br />[0;32m~/work/mlmodels/mlmodels/mlmodels/example/lightgbm_glass.py[0m in [0;36m<module>[0;34m[0m
<br />[1;32m     20[0m [0;34m[0m[0m
<br />[1;32m     21[0m [0;34m[0m[0m
<br />[0;32m---> 22[0;31m [0mpars[0m [0;34m=[0m [0mjson[0m[0;34m.[0m[0mload[0m[0;34m([0m[0mopen[0m[0;34m([0m [0mconfig_path[0m [0;34m,[0m [0mmode[0m[0;34m=[0m[0;34m'r'[0m[0;34m)[0m[0;34m)[0m[0;34m[[0m[0mconfig_mode[0m[0;34m][0m[0;34m[0m[0;34m[0m[0m
<br />[0m[1;32m     23[0m [0mprint[0m[0;34m([0m[0mpars[0m[0;34m)[0m[0;34m[0m[0;34m[0m[0m
<br />[1;32m     24[0m [0;34m[0m[0m
<br />
<br />[0;31mFileNotFoundError[0m: [Errno 2] No such file or directory: 'lightgbm_glass.json'
<br />
<br />
<br />
<br />
<br />
<br /> ************************************************************************************************************************
<br />ipython https://github.com/arita37/mlmodels/blob/dev/mlmodels/example//arun_hyper.py 
<br />
<br />[0;31m---------------------------------------------------------------------------[0m



### Error 28, [Traceback at line 2052](https://github.com/arita37/mlmodels_store/blob/master/log_jupyter/log_jupyter.py#L2052)<br />2052..[0;31mNameError[0m                                 Traceback (most recent call last)
<br />[0;32m~/work/mlmodels/mlmodels/mlmodels/example/arun_hyper.py[0m in [0;36m<module>[0;34m[0m
<br />[1;32m      3[0m [0;32mfrom[0m [0mmlmodels[0m[0;34m.[0m[0mmodels[0m [0;32mimport[0m [0mmodule_load[0m[0;34m[0m[0;34m[0m[0m
<br />[1;32m      4[0m [0;32mfrom[0m [0mmlmodels[0m[0;34m.[0m[0mutil[0m [0;32mimport[0m [0mpath_norm_dict[0m[0;34m,[0m [0mpath_norm[0m[0;34m,[0m [0mparams_json_load[0m[0;34m[0m[0;34m[0m[0m
<br />[0;32m----> 5[0;31m [0mprint[0m[0;34m([0m[0mmlmodels[0m[0;34m)[0m[0;34m[0m[0;34m[0m[0m
<br />[0m[1;32m      6[0m [0;34m[0m[0m
<br />[1;32m      7[0m [0;34m[0m[0m
<br />
<br />[0;31mNameError[0m: name 'mlmodels' is not defined
<br />
<br />
<br />
<br />
<br />
<br /> ************************************************************************************************************************
<br />ipython https://github.com/arita37/mlmodels/blob/dev/mlmodels/example//benchmark_timeseries_m4.py 
<br />
